Workbook
Name \0: #REF!
Name \a: #REF!
Name \b: #REF!
Name \c: #REF!
Name \D: #REF!
Name \i: #N/A
Name \M: #REF!
Name \P: #REF!
Name \q: #REF!
Name \R: #REF!
Name \S: #REF!
Name \T: #REF!
Name \U: #REF!
Name \W: #REF!
Name \WQ: '[1]BAG-2'!#REF!
Name \X: #REF!
Name __________________EEE02: '[2]Sewa AlatBerat08'!$AW$9
Name __________________EEE03: '[2]Sewa AlatBerat08'!$AW$10
Name __________________EEE05: '[2]Sewa AlatBerat08'!$AW$12
Name __________________EEE15: '[2]Sewa AlatBerat08'!$AW$22
Name __________________EEE16: '[2]Sewa AlatBerat08'!$AW$23
Name __________________EEE18: '[2]Sewa AlatBerat08'!$AW$25
Name __________________EEE19: '[2]Sewa AlatBerat08'!$AW$26
Name __________________EEE23: '[2]Sewa AlatBerat08'!$AW$30
Name _________________EEE15: #REF!
Name ________________EEE15: #REF!
Name ________________EEE17: #REF!
Name _______________EEE02: '[3]Sewa AlatBerat08'!$AW$9
Name _______________EEE03: '[3]Sewa AlatBerat08'!$AW$10
Name _______________EEE05: '[3]Sewa AlatBerat08'!$AW$12
Name _______________EEE08: #REF!
Name _______________EEE10: #REF!
Name _______________EEE15: #REF!
Name _______________EEE16: '[3]Sewa AlatBerat08'!$AW$23
Name _______________EEE17: #REF!
Name _______________EEE18: '[3]Sewa AlatBerat08'!$AW$25
Name _______________EEE19: '[3]Sewa AlatBerat08'!$AW$26
Name _______________EEE23: #REF!
Name ______________EEE08: #REF!
Name ______________EEE10: #REF!
Name ______________EEE15: #REF!
Name ______________EEE17: #REF!
Name ______________EEE23: #REF!
Name ______________MMM05: #REF!
Name ______________MMM26: #REF!
Name _____________bsc100: #REF!
Name _____________EEE01: #REF!
Name _____________EEE02: #REF!
Name _____________EEE03: #REF!
Name _____________EEE05: '[3]Sewa AlatBerat08'!$AW$12
Name _____________EEE07: #REF!
Name _____________EEE08: #REF!
Name _____________EEE10: #REF!
Name _____________EEE13: #REF!
Name _____________EEE15: #REF!
Name _____________EEE16: #REF!
Name _____________EEE17: #REF!
Name _____________EEE18: #REF!
Name _____________EEE19: #REF!
Name _____________EEE23: #REF!

Sheet ABK
A1: ANGGARAN BIAYA KONSTRUKSI
B2: Nama Proyek | C2: : Poyek Konstruksi Bangunan Rumah Tinggal 2 Lantai - Bpk. A
B3: Lokasi | C3: : Bogor
B4: Tahun Proyek | C4: : 2024
A6: NO | B6: URAIAN PEKERJAAN | C6: VOLUME | D6: SATUAN | E6: HARGA SATUAN | F6: JUMLAH HARGA
A7: a | B7: b | C7: c | D7: d | E7: e | F7: f
B8: =KBP!B8 -> LANTAI 1
A9: =KBP!A9 -> I | B9: =KBP!B9 -> TAHAP AWAL PEMBANGUNAN
A10: =KBP!A10 -> 1 | B10: =KBP!B10 -> Tahap Pembersihan Area Lahan Bangunan | C10: =KBP!C10 -> 83.7 | D10: =KBP!D10 -> m2 | E10: =EVALUASI!$F$32 -> 17500 | F10: =C10*E10 -> 1464750
A11: =KBP!A11 -> 2 | B11: =KBP!B11 -> Tahap Pembuatan Papan Konstruksi (Bouwplank) | C11: =KBP!C11 -> 21 | D11: =KBP!D11 -> titik | E11: =EVALUASI!$F$18 -> 99286 | F11: =C11*E11 -> 2085006
F12: =SUM(F10:F11) -> 3549756
A13: =KBP!A13 -> II | B13: =KBP!B13 -> TAHAP PROYEK GALIAN TANAH
A14: =KBP!A14 -> 1 | B14: =KBP!B14 -> Penggalian Tanah Dasar Bangunan dengan Tapak Setempat (150x100x100 cm) | C14: =KBP!C14 -> 13.5 | D14: =KBP!D14 -> m3 | E14: =EVALUASI!$F$39 -> 78750 | F14: =C14*E14 -> 1063125
A15: =KBP!A15 -> 2 | B15: =KBP!B15 -> Penggalian Tanah Dasar Bangunan dengan Batu Kali | C15: =KBP!C15 -> 49.11075 | D15: =KBP!D15 -> m3 | E15: =EVALUASI!$F$39 -> 78750 | F15: =C15*E15 -> 3867471.6
A16: =KBP!A18 -> 3 | B16: =KBP!B18 -> Penggalian Tanah Sloof S1 15x30 cm | C16: =KBP!C18 -> 2.0025 | D16: =KBP!D18 -> m3 | E16: =EVALUASI!$F$39 -> 78750 | F16: =C16*E16 -> 157696.88
A17: =KBP!A19 -> 4 | B17: =KBP!B19 -> Penggalian Tanah Sloof S2 15x25 cm | C17: =KBP!C19 -> 0.89625 | D17: =KBP!D19 -> m3 | E17: =EVALUASI!$F$39 -> 78750 | F17: =C17*E17 -> 70579.687
A18: =KBP!A20 -> 5 | B18: =KBP!B20 -> Penggalian Tanah Sloof S3 15x20 cm | C18: =KBP!C20 -> 0.03 | D18: =KBP!D20 -> m3 | E18: =EVALUASI!$F$39 -> 78750 | F18: =C18*E18 -> 2362.5
A19: =KBP!A21 -> 6 | B19: =KBP!B21 -> Pengurukan Tanah Kembali 1/3 Galian | C19: =KBP!C21 -> 21.8465 | D19: =KBP!D21 -> m3 | E19: =EVALUASI!$F$46 -> 13050 | F19: =C19*E19 -> 285096.83
A20: =KBP!A22 -> 7 | B20: =KBP!B22 -> Pengurukan Pasir Bawah Pondasi Tapak (ketebalan 5 cm) | C20: =KBP!C22 -> 0.45 | D20: =KBP!D22 -> m3 | E20: =EVALUASI!$F$55 -> 207500 | F20: =C20*E20 -> 93375
A21: =KBP!A23 -> 8 | B21: =KBP!B23 -> Pengurukan Pasir Bawah Pondasi Batu Kali (ketebalan 5 cm) | C21: =KBP!C23 -> 1.1865 | D21: =KBP!D23 -> m3 | E21: =EVALUASI!$F$55 -> 207500 | F21: =C21*E21 -> 246198.75
A22: =KBP!A25 -> 9 | B22: =KBP!B25 -> Pengurukan Pasir Bawah Lantai (ketebalan 10 cm) | C22: =KBP!C25 -> 8.37 | D22: =KBP!D25 -> m3 | E22: =EVALUASI!$F$55 -> 207500 | F22: =C22*E22 -> 1736775
A23: =KBP!A27 -> 10 | B23: =KBP!B27 -> Pengurukan Tanah Peninggi Lantai (tinggi 40 cm) | C23: =KBP!C27 -> 23.427 | D23: =KBP!D27 -> m3 | E23: =EVALUASI!$F$64 -> 207500 | F23: =C23*E23 -> 4861102.5
A24: =KBP!A30 -> 11 | B24: =KBP!B30 -> Pembuatan Tanah Ruang Terbuka Hijau | C24: =KBP!C30 -> 20.8875 | D24: =KBP!D30 -> m2 | E24: 150000 | F24: =C24*E24 -> 3133125
F25: =SUM(F14:F24) -> 15516909
A26: =KBP!A32 -> III | B26: =KBP!B32 -> TAHAP PEMBANGUNAN RANGKA
A27: =KBP!A33 -> 1 | B27: =KBP!B33 -> Pekerjaan Tata Letak Semen Cor Bawah Lantai (ketebalan 5 cm) | C27: =KBP!C33 -> 4.41 | D27: =KBP!D33 -> m3 | E27: =EVALUASI!$F$121 -> 703675.33 | F27: =C27*E27 -> 3103208.2
A28: =KBP!A36 -> 2 | B28: =KBP!B36 -> Pekerjaan Batu Kosong Pondasi (ketebalan 20 cm) | C28: =KBP!C36 -> 8.541 | D28: =KBP!D36 -> m3 | E28: =EVALUASI!$F$108 -> 757020 | F28: =C28*E28 -> 6465707.8
A29: =KBP!A39 -> 3 | B29: =KBP!B39 -> Pemasangan Dasar Bangunan dengan Batu Kali | C29: =KBP!C39 -> 15.9165 | D29: =KBP!D39 -> m | E29: =EVALUASI!$F$96 -> 1142173.3 | F29: =C29*E29 -> 18179402
A30: =KBP!A42 -> 4 | B30: =KBP!B42 -> Pemasangan Dasar Bangunan dengan Tapak Setempat | C30: =KBP!C42 -> 2.4861 | D30: =KBP!D42 -> m3 | E30: =EVALUASI!$F$278 -> 3165778.2 | F30: =C30*E30 -> 7870441.1
A31: =KBP!A45 -> 5 | B31: =KBP!B45 -> Pekerjaan Cor Balok Beton S1 (15x30 cm) | C31: =KBP!C45 -> 2.0025 | D31: =KBP!D45 -> m3 | E31: =EVALUASI!$F$293 -> 4758249.9 | F31: =C31*E31 -> 9528395.3
A32: =KBP!A46 -> 6 | B32: =KBP!B46 -> Pekerjaan Cor Balok Beton S2 (15x25 cm) | C32: =KBP!C46 -> 0.89625 | D32: =KBP!D46 -> m3 | E32: =EVALUASI!$F$301 -> 4799526.2 | F32: =C32*E32 -> 4301575.3
A33: =KBP!A47 -> 7 | B33: =KBP!B47 -> Pekerjaan Cor Balok Beton S3 (15x20 cm) | C33: =KBP!C47 -> 0.03 | D33: =KBP!D47 -> m3 | E33: =EVALUASI!$F$309 -> 4460430.2 | F33: =C33*E33 -> 133812.91
A34: =KBP!A48 -> 8 | B34: =KBP!B48 -> Pekerjaan Cor Tiang Dinding K1 (15x35 cm) | C34: =KBP!C48 -> 2.149875 | D34: =KBP!D48 -> m3 | E34: =EVALUASI!$F$317 -> 5256799.3 | F34: =C34*E34 -> 11301461
A35: =KBP!A49 -> 9 | B35: =KBP!B49 -> Pekerjaan Cor Tiang Dasar Bangunan (15x15 cm) | C35: =KBP!C49 -> 54.6 | D35: =KBP!D49 -> m | E35: =EVALUASI!$F$224 -> 77157.5 | F35: =C35*E35 -> 4212799.5
A36: =KBP!A50 -> 10 | B36: =KBP!B50 -> Pekerjaan Cor Balok B1 (15x35 cm) | C36: =KBP!C50 -> 2.53575 | D36: =KBP!D50 -> m3 | E36: =EVALUASI!$F$332 -> 5628182.4 | F36: =C36*E36 -> 14271664
A37: =KBP!A51 -> 11 | B37: =KBP!B51 -> Pekerjaan Cor Balok B3 (15x25 cm) | C37: =KBP!C51 -> 1.258125 | D37: =KBP!D51 -> m3 | E37: =EVALUASI!$F$348 -> 4810546.4 | F37: =C37*E37 -> 6052268.7
A38: =KBP!A52 -> 12 | B38: =KBP!B52 -> Pekerjaan Cor Balok BL (15x35 cm) | C38: =KBP!C52 -> 0.315 | D38: =KBP!D52 -> m3 | E38: =EVALUASI!$F$332 -> 5628182.4 | F38: =C38*E38 -> 1772877.5
A39: =KBP!A53 -> 13 | B39: =KBP!B53 -> Pekerjaan Cor Balok Beton Ambang Atas (15x15 cm) | C39: =KBP!C53 -> 11 | D39: =KBP!D53 -> m | E39: =EVALUASI!$F$243 -> 109205 | F39: =C39*E39 -> 1201255
A40: =KBP!A54 -> 14 | B40: =KBP!B54 -> Pekerjaan Cor Atap Kanopi Beton | C40: =KBP!C54 -> 0.3015 | D40: =KBP!D54 -> m3 | E40: =EVALUASI!$F$379 -> 5697132.3 | F40: =C40*E40 -> 1717685.4
A41: =KBP!A55 -> 15 | B41: =KBP!B55 -> Pekerjaan Cor Lantai Beton (ketebalan 12 cm) | C41: =KBP!C55 -> 5.11164 | D41: =KBP!D55 -> m3 | E41: =EVALUASI!$F$371 -> 4883372.3 | F41: =C41*E41 -> 24962041
...

Sheet KBP
A1: KALKULASI BAHAN PROYEK BANGUNAN
B2: Nama Proyek | C2: : Poyek Konstruksi Bangunan Rumah Tinggal 2 Lantai - Bpk. A
B3: Lokasi | C3: : Bogor
B4: Tahun Proyek | C4: : 2024
A6: NO | B6: DESKRIPSI KEGIATAN | C6: VOLUME | D6: SATUAN | E6: SUB TOTAL | G6: PANJANG | I6: LEBAR | K6: TINGGI | M6: JUMLAH | N6: KET
A7: a | B7: b | C7: c | D7: d | E7: e | G7: f | I7: g | K7: h | M7: i | N7: j
B8: LANTAI 1
A9: I | B9: TAHAP AWAL PEMBANGUNAN
A10: 1 | B10: Tahap Pembersihan Area Lahan Bangunan | C10: =E10 -> 83.7 | D10: m2 | E10: =G10*I10 -> 83.7 | G10: 6 | H10: x | I10: 13.95
A11: 2 | B11: Tahap Pembuatan Papan Konstruksi (Bouwplank) | C11: =M48+M49 -> 21 | D11: titik
A13: II | B13: TAHAP PROYEK GALIAN TANAH
A14: 1 | B14: Penggalian Tanah Dasar Bangunan dengan Tapak Setempat (150x100x100 cm) | C14: =E14 -> 13.5 | D14: m3 | E14: =G14*I14*K14*M14 -> 13.5 | G14: 1.5 | H14: x | I14: 1 | J14: x | K14: 1 | L14: x | M14: 9
A15: 2 | B15: Penggalian Tanah Dasar Bangunan dengan Batu Kali | C15: =E15+E16 -> 49.11075 | D15: m3 | E15: =G15*I15*K15 -> 27.2895 | G15: 33.9 | H15: x | I15: 0.7 | J15: x | K15: 1.15 | N15: pinggir
E16: =G16*I16*K16 -> 21.82125 | G16: 34.5 | H16: x | I16: 0.55 | J16: x | K16: 1.15 | N16: tengah
A18: 3 | B18: Penggalian Tanah Sloof S1 15x30 cm | C18: =E18 -> 2.0025 | D18: m3 | E18: =G18*I18*K18 -> 2.0025 | G18: 44.5 | H18: x | I18: 0.15 | J18: x | K18: 0.3 | N18: white
A19: 4 | B19: Penggalian Tanah Sloof S2 15x25 cm | C19: =E19 -> 0.89625 | D19: m3 | E19: =G19*I19*K19 -> 0.89625 | G19: 23.9 | H19: x | I19: 0.15 | J19: x | K19: 0.25 | N19: green
A20: 5 | B20: Penggalian Tanah Sloof S3 15x20 cm | C20: =E20 -> 0.03 | D20: m3 | E20: =G20*I20*K20 -> 0.03 | G20: 1 | H20: x | I20: 0.15 | J20: x | K20: 0.2 | N20: magenta
A21: 6 | B21: Pengurukan Tanah Kembali 1/3 Galian | C21: =E21 -> 21.8465 | D21: m3 | E21: =G21*I21 -> 21.8465 | G21: =C20+C19+C18+C15+C14 -> 65.5395 | H21: x | I21: =1/3 -> 0.33333333
A22: 7 | B22: Pengurukan Pasir Bawah Pondasi Tapak (ketebalan 5 cm) | C22: =E22 -> 0.45 | D22: m3 | E22: =G22*I22*K22*M22 -> 0.45 | G22: 1 | H22: x | I22: 1 | J22: x | K22: 0.05 | L22: x | M22: =M14 -> 9
A23: 8 | B23: Pengurukan Pasir Bawah Pondasi Batu Kali (ketebalan 5 cm) | C23: =E23 -> 1.1865 | D23: m3 | E23: =G23*I23*K23 -> 1.1865 | G23: =G15 -> 33.9 | H23: x | I23: =I15 -> 0.7 | J23: x | K23: 0.05 | N23: pinggir
E24: =G24*I24*K24 -> 0.94875 | G24: =G16 -> 34.5 | H24: x | I24: =I16 -> 0.55 | J24: x | K24: 0.05 | N24: tengah
A25: 9 | B25: Pengurukan Pasir Bawah Lantai (ketebalan 10 cm) | C25: =E25 -> 8.37 | D25: m3 | E25: =G25*I25 -> 8.37 | G25: =G27+G28 -> 83.7 | H25: x | I25: 0.1
A27: 10 | B27: Pengurukan Tanah Peninggi Lantai (tinggi 40 cm) | C27: =E27+E28 -> 23.427 | D27: m3 | E27: =G27*I27 -> 14.04 | G27: 39 | H27: x | I27: 0.36 | N27: ffl 0.00
E28: =G28*I28 -> 9.387 | G28: =30+14.7 -> 44.7 | H28: x | I28: =I27-0.15 -> 0.21 | N28: ffl -0.15
A30: 11 | B30: Pembuatan Tanah Ruang Terbuka Hijau | C30: =E30 -> 20.8875 | D30: m2 | E30: =G30+I30 -> 20.8875 | G30: =2.45*6 -> 14.7 | H30: + | I30: =1.5*4.125 -> 6.1875
A32: III | B32: TAHAP PEMBANGUNAN RANGKA
A33: 1 | B33: Pekerjaan Tata Letak Semen Cor Bawah Lantai (ketebalan 5 cm) | C33: =E33+E34 -> 4.41 | D33: m3 | E33: =G33*I33 -> 4.185 | G33: =G25 -> 83.7 | H33: x | I33: 0.05
E34: =G34*I34 -> 0.225 | G34: 0.0375 | H34: x | I34: 6 | N34: ram beton
A36: 2 | B36: Pekerjaan Batu Kosong Pondasi (ketebalan 20 cm) | C36: =E36+E37 -> 8.541 | D36: m3 | E36: =G36*I36*K36 -> 4.746 | G36: =G23 -> 33.9 | H36: x | I36: =I23 -> 0.7 | J36: x | K36: 0.2 | N36: pinggir
E37: =G37*I37*K37 -> 3.795 | G37: =G24 -> 34.5 | H37: x | I37: =I24 -> 0.55 | J37: x | K37: 0.2 | N37: tengah
A39: 3 | B39: Pemasangan Dasar Bangunan dengan Batu Kali | C39: =E39+E40 -> 15.9165 | D39: m | E39: =G39*I39 -> 7.119 | G39: =G36 -> 33.9 | H39: x | I39: 0.21 | N39: pinggir
E40: =G40*I40 -> 8.7975 | G40: =G37 -> 34.5 | H40: x | I40: 0.255 | N40: tengah
A42: 4 | B42: Pemasangan Dasar Bangunan dengan Tapak Setempat | C42: =E42+E43 -> 2.4861 | D42: m3 | E42: =G42*I42*K42 -> 1.65 | G42: 0.275 | H42: x | I42: 1 | J42: x | K42: 6 | N42: pinggir
E43: =G43*I43*K43 -> 0.8361 | G43: 0.2787 | H43: x | I43: 1 | J43: x | K43: 3 | N43: tengah
A45: 5 | B45: Pekerjaan Cor Balok Beton S1 (15x30 cm) | C45: =C18 -> 2.0025 | D45: m3
A46: 6 | B46: Pekerjaan Cor Balok Beton S2 (15x25 cm) | C46: =C19 -> 0.89625 | D46: m3
A47: 7 | B47: Pekerjaan Cor Balok Beton S3 (15x20 cm) | C47: =C20 -> 0.03 | D47: m3
A48: 8 | B48: Pekerjaan Cor Tiang Dinding K1 (15x35 cm) | C48: =E48 -> 2.149875 | D48: m3 | E48: =G48*I48*K48*M48 -> 2.149875 | G48: 0.15 | H48: x | I48: 0.35 | J48: x | K48: =1.15+3.4 -> 4.55 | L48: x | M48: 9
A49: 9 | B49: Pekerjaan Cor Tiang Dasar Bangunan (15x15 cm) | C49: =E49 -> 54.6 | D49: m | E49: =K49*M49 -> 54.6 | K49: =K48 -> 4.55 | L49: x | M49: 12
A50: 10 | B50: Pekerjaan Cor Balok B1 (15x35 cm) | C50: =E50 -> 2.53575 | D50: m3 | E50: =G50*I50*K50 -> 2.53575 | G50: 48.3 | H50: x | I50: 0.15 | J50: x | K50: 0.35 | N50: green
...

Sheet RBK
A1: RINGKASAN BIAYA KONSTRUKSI BANGUNAN
A3: Nama Proyek | C3: : Poyek Konstruksi Bangunan Rumah Tinggal 2 Lantai - Bpk. A
A4: Lokasi | C4: : Bogor
A5: Tahun Proyek | C5: : 2024
A7: No. | B7: Deskripsi Kegiatan Proyek Konstruksi | E7: Jumlah Harga ( Rp )
B10: PROYEK KONSTRUKSI BANGUNAN RUMAH TINGGAL 2 LANTAI
A11: A. | B11: LANTAI 1
A12: I. | B12: =ABK!B9 -> TAHAP AWAL PEMBANGUNAN | E12: =ABK!F12 -> 3549756
A13: II. | B13: =ABK!B13 -> TAHAP PROYEK GALIAN TANAH | E13: =ABK!F25 -> 15516909
A14: III. | B14: =ABK!B26 -> TAHAP PEMBANGUNAN RANGKA | E14: =ABK!F43 -> 1.1820781e+08
A15: IV. | B15: =ABK!B44 -> TAHAP PEKERJAAN KONSTRUKSI BANGUNAN | E15: =ABK!F89 -> 1.0970007e+08
A16: V. | B16: =ABK!B90 -> TAHAP PEKERJAAN INSTALASI ELEKTRIK DAN PIPA LEDENG | E16: =ABK!F119 -> 34211248
A17: VI. | B17: =ABK!B120 -> TAHAP PEMASANGAN LANGIT-LANGIT DAN GENTENG | E17: =ABK!F125 -> 10151418
A18: VII. | B18: =ABK!B126 -> TAHAP PENYELESAIAN KONSTRUKSI BANGUNAN | E18: =ABK!F132 -> 12665127 | G18: Per m2
A19: TOTAL LT.01 | E19: =SUM(E12:E18) -> 3.0400233e+08 | F19: 39 | G19: =E19/F19 -> 7794931.5
A20: B. | B20: LANTAI 2
A21: I. | B21: =ABK!B135 -> TAHAP PEMBANGUNAN RANGKA | E21: =ABK!F144 -> 40385358
A22: II. | B22: =ABK!B145 -> TAHAP PEKERJAAN KONSTRUKSI BANGUNAN | E22: =ABK!F187 -> 85528784
A23: III. | B23: =ABK!B188 -> TAHAP PEKERJAAN INSTALASI ELEKTRIK DAN PIPA LEDENG | E23: =ABK!F210 -> 14710940
A24: IV. | B24: =ABK!B211 -> TAHAP PEMASANGAN LANGIT-LANGIT DAN GENTENG | E24: =ABK!F220 -> 27467205
A25: V. | B25: =ABK!B221 -> TAHAP PENYELESAIAN KONSTRUKSI BANGUNAN | E25: =ABK!F228 -> 11088505
A26: TOTAL LT.02 | E26: =SUM(E21:E25) -> 1.7918079e+08
A27: TOTAL KESELURUHAN LT.01 + LT.02 | E27: =E26+E19 -> 4.8318312e+08
A28: DIBULATKAN | E28: =ROUNDDOWN(E27,-3) -> 483183000
A29: TERBILANG' :
E31: BOGOR, April 2024
E32: Perusahaan
E39: Nama terang

Sheet GAJI
A2: RINCIAN BIAYA GAJI
A6: No | B6: DAFTAR TENAGA PEKERJA BANGUNAN | C6: SATUAN | D6: UPAH HARIAN
A8: 1 | B8: KEPALA PROYEK | C8: ORG/HR | D8: 150000
A9: 2 | B9: KEPALA TIM PEKERJA GALIH TANAH | C9: ORG/HR | D9: 140000
A10: 3 | B10: KEPALA TIM PEKERJA BATU | C10: ORG/HR | D10: 140000
A11: 4 | B11: KEPALA TIM PEKERJA BATU | C11: ORG/HR | D11: 140000
A12: 5 | B12: KEPALA TIM PEKERJA BESI | C12: ORG/HR | D12: 140000
A13: 6 | B13: KEPALA TIM PEKERJA CAT | C13: ORG/HR | D13: 140000
A14: 7 | B14: KEPALA TIM PEKERJA SAMBUNGAN LISTRIK | C14: ORG/HR | D14: 140000
A15: 8 | B15: KEPALA TIM PEKERJA PIPA SALURAN | C15: ORG/HR | D15: 140000
A16: 9 | B16: PEKERJA GALIAN TANAH | C16: ORG/HR | D16: 135000
A17: 10 | B17: PEKERJA BATU | C17: ORG/HR | D17: 135000
A18: 11 | B18: PEKERJA KAYU | C18: ORG/HR | D18: 135000
A19: 12 | B19: PEKERJA BESI | C19: ORG/HR | D19: 135000
... A27: 20 | B27: PETUGAS AHLI UKUR TANAH | C27: ORG/HR | D27: 135000
A29: RINCIAN BIAYA BAHAN BANGUNAN
A32: No | B32: DAFTAR BAHAN BANGUNAN | C32: SATUAN | D32: HARGA
A34: 1 | B34: Paku Biasa (2 - 5 inchi) | C34: doz | D34: 29100 | F34: 29100
A35: 2 | B35: kayu meranti Usuk (4/6, 5/7) | C35: m3 | D35: 4188000 | F35: 4188000
A36: 3 | B36: Kayu Glugu Begesting | C36: m3 | D36: 2750000 | F36: 3350000
A37: 4 | B37: Semen PC (Portiand Cement) 50 kg ex. Tiga Roda | C37: Zak | D37: 53500 | F37: 72700
A38: 5 | B38: Pasir Pasang | C38: m3 | D38: =1400000/7.5 -> 186666.67 | F38: 272500
A39: 6 | B39: Pasir Urug | C39: m3 | D39: =1100000/7.5 -> 146666.67 | F39: 177000
A40: 7 | B40: Pasir Cor | C40: m3 | D40: =2400000/7.5 -> 320000 | F40: 272500
A41: 8 | B41: Semen PC (40 Kg) ex. Tiga Roda | C41: Zak | D41: 42800 | F41: 58500
A42: 9 | B42: Batu Pecah Mesin (1/2 cm) | C42: M3 | D42: =1400000/7.5 -> 186666.67 | F42: 278000
A43: 10 | B43: Biaya Air | C43: Liter | D43: 6 | F43: 6
A44: 11 | B44: Besi Beton Polos | C44: Kg | D44: 11500 | F44: 13500
A45: 12 | B45: Besi Baja WF | C45: Kg | D45: 14500 | F45: 20400
A46: 13 | B46: Kawat Beton | C46: Kg | D46: 17500 | F46: 26900
A47: 14 | B47: Paku Usuk | C47: Kg | D47: 20000 | F47: 14800
A48: 15 | B48: Minyak Bekisting | C48: Liter | D48: 11000 | F48: 30100
A49: 16 | B49: Plywood Uk. (122x 244 x 9 mm) Sengon | C49: Lembar | D49: 95000 | F49: 105000
A50: 17 | B50: Kayu Glugu Balok (6/12, 8/12) | C50: M3 | D50: 3000000 | F50: 4711500
A51: 18 | B51: Batu Bata Merah Kelas 1 (Uk. 22x11x4.5 cm) | C51: Press | D51: 550 | F51: 800
A52: 19 | B52: Kuas (4 inchi) | C52: Buah | D52: 25000 | F52: 34743
A53: 20 | B53: Coating Batu Alam | C53: Kg | D53: 65000 | F53: 65000
A54: 21 | B54: Kertas Gosok Halus | C54: Lembar | D54: 8500 | F54: 20467
... A63: 30 | B63: Paku Reng | C63: Kg | D63: 15933 | F63: 15933
A64: 31 | B64: Kalsiplang | C64: m1 | D64: =65000/3 -> 21666.667 | F64: =65000/3 -> 21666.667
...

Sheet EVALUASI
A2: BIAYA SATUAN DASAR PEKERJAAN
B4: DESKRIPSI KEGIATAN | C4: Koef. | D4: SATUAN | E4: HARGA SATUAN | F4: HARGA
B7: Pembuatan Bouwplank / Penandaan Titik Konstruksi | D7: Titik
B8: Gaji:
B9: Kepala Proyek | C9: 0.0045 | D9: Orang Hari | E9: =GAJI!D8 -> 150000 | F9: =C9*E9 -> 675
B10: Kepala Tim Pekerja Bangunan | C10: 0.01 | D10: Orang Hari | E10: =GAJI!D9 -> 140000 | F10: =C10*E10 -> 1400
B11: Pekerja Bangunan | C11: 0.1 | D11: Orang Hari | E11: =GAJI!D16 -> 135000 | F11: =C11*E11 -> 13500
B12: Asisten Pekerja Bangunan | C12: 0.1 | D12: Orang Hari | E12: =GAJI!D26 -> 100000 | F12: =C12*E12 -> 10000
B13: Bahan Bangunan: | E13: Jumlah: | F13: =SUM(F9:F12) -> 25575
B14: Paku Biasa 2 - 5 inchi | C14: 0.05 | D14: Doz | E14: =GAJI!D34 -> 29100 | F14: =C14*E14 -> 1455
B15: Kayu Meranti Usuk 4/6, 5/7 | C15: 0.012 | D15: m3 | E15: =GAJI!D35 -> 4188000 | F15: =C15*E15 -> 50256
B16: Kayu Meranti Bekisting | C16: 0.008 | D16: m3 | E16: =GAJI!D36 -> 2750000 | F16: =C16*E16 -> 22000
E17: Jumlah: | F17: =SUM(F14:F16) -> 73711
E18: Nilai HSPK : | F18: =F17+F13 -> 99286
B20: Pembongkaran Rangka dan Penutup Atap yang Tidak Digunakan Kembali | D20: m2
B21: Gaji:
B22: Kepala Proyek | C22: 0.005 | D22: Orang Hari | E22: =GAJI!D8 -> 150000 | F22: =C22*E22 -> 750
B23: Asisten Pekerja Bangunan | C23: 0.1 | D23: Orang Hari | E23: =GAJI!D26 -> 100000 | F23: =C23*E23 -> 10000
E24: Jumlah: | F24: =SUM(F22:F23) -> 10750
E25: Nilai HSPK : | F25: =SUM(F24) -> 10750
B27: Pembersihan Area dan Perataan Permukaan Tanah | D27: m2
B28: Gaji:
B29: Kepala Proyek | C29: 0.05 | D29: Orang Hari | E29: =GAJI!D8 -> 150000 | F29: =C29*E29 -> 7500
B30: Asisten Pekerja Bangunan | C30: 0.1 | D30: Orang Hari | E30: =GAJI!D26 -> 100000 | F30: =C30*E30 -> 10000
E31: Jumlah: | F31: =SUM(F29:F30) -> 17500
E32: Nilai HSPK : | F32: =SUM(F31) -> 17500
B34: Penggalian Tanah Standar untuk Keperluan Konstruksi | D34: m3
B35: Gaji:
B36: Kepala Proyek | C36: 0.025 | D36: Orang Hari | E36: =GAJI!D8 -> 150000 | F36: =C36*E36 -> 3750
B37: Asisten Pekerja Bangunan | C37: 0.75 | D37: Orang Hari | E37: =GAJI!D26 -> 100000 | F37: =C37*E37 -> 75000
E38: Jumlah: | F38: =SUM(F36:F37) -> 78750
E39: Nilai HSPK : | F39: =SUM(F38) -> 78750
B41: Pengurugan Tanah Kembali sebagai Bagian dari Konstruksi | D41: m3
B42: Gaji:
B43: Kepala Proyek | C43: 0.019 | D43: Orang Hari | E43: =GAJI!D8 -> 150000 | F43: =C43*E43 -> 2850
B44: Asisten Pekerja Bangunan | C44: 0.102 | D44: Orang Hari | E44: =GAJI!D26 -> 100000 | F44: =C44*E44 -> 10200
E45: Jumlah: | F45: =SUM(F43:F44) -> 13050
E46: Nilai HSPK : | F46: =SUM(F45) -> 13050
B48: Pengurugan dengan Pasir yang Dipadatkan | D48: m3
B49: Gaji:
...

Sheet JADWAL
A1: JADWAL PEKERJAAN
A3: Nama Proyek | C3: : Poyek Konstruksi Bangunan Rumah Tinggal 2 Lantai - Bpk. A
A4: Lokasi | C4: : Bogor
A5: Tahun Proyek | C5: : 2024
A7: No. | B7: Deskripsi Kegiatan Proyek Konstruksi | E7: Jumlah Harga ( Rp ) | F7: Bobot (%) | G7: Waktu Pelaksanaan
G8: Bulan 1 | K8: Bulan 2 | O8: Bulan 3 | S8: Bulan 4 | W8: JUMLAH (%) | X8: KETERANGAN
G9: 1 | H9: 2 | I9: 3 | J9: 4 | K9: 5 | L9: 6 | M9: 7 | N9: 8 | O9: 9 | P9: 10 | Q9: 11 | R9: 12 | S9: 13 | T9: 14 | U9: 15 | V9: 16
B10: PROYEK KONSTRUKSI BANGUNAN RUMAH TINGGAL 2 LANTAI
A11: A. | B11: LANTAI 1
A12: I. | B12: =[282]RAB!B9 -> TAHAP AWAL PEMBANGUNAN | E12: =[282]RAB!F12 -> 3549756 | F12: =E12/$E$27 -> 0.007346606 | G12: =F12 -> 0.007346606 | W12: =SUM(G12:V12) -> 0.007346606
A13: II. | B13: =[282]RAB!B13 -> TAHAP PROYEK GALIAN TANAH | E13: =[282]RAB!F25 -> 15516909 | F13: =E13/$E$27 -> 0.032113929 | H13: =F13 -> 0.032113929 | W13: =SUM(G13:V13) -> 0.032113929
A14: III. | B14: =[282]RAB!B26 -> TAHAP PEMBANGUNAN RANGKA | E14: =[282]RAB!F43 -> 1.1820781e+08 | F14: =E14/$E$27 -> 0.24464391 | I14: =$F$14/5 -> 0.048928781 | J14: =$F$14/5 -> 0.048928781 | K14: =$F$14/5 -> 0.048928781 | L14: =$F$14/5 -> 0.048928781 | M14: =$F$14/5 -> 0.048928781 | W14: =SUM(G14:V14) -> 0.24464391
A15: IV. | B15: =[282]RAB!B44 -> TAHAP PEKERJAAN KONSTRUKSI BANGUNAN | E15: =[282]RAB!F89 -> 1.0970007e+08 | F15: =E15/$E$27 -> 0.22703621 | K15: =$F$15/11 -> 0.020639656 | L15: =$F$15/11 -> 0.020639656 | M15: =$F$15/11 -> 0.020639656 | N15: =$F$15/11 -> 0.020639656 | O15: =$F$15/11 -> 0.020639656 | P15: =$F$15/11 -> 0.020639656 | Q15: =$F$15/11 -> 0.020639656 | R15: =$F$15/11 -> 0.020639656 | ... U15: =$F$15/11 -> 0.020639656 | W15: =SUM(G15:V15) -> 0.22703621
A16: V. | B16: =[282]RAB!B90 -> TAHAP PEKERJAAN INSTALASI ELEKTRIK DAN PIPA LEDENG | E16: =[282]RAB!F119 -> 34211248 | F16: =E16/$E$27 -> 0.070803896 | I16: =$F$16/10 -> 0.0070803896 | J16: =$F$16/10 -> 0.0070803896 | K16: =$F$16/10 -> 0.0070803896 | L16: =$F$16/10 -> 0.0070803896 | M16: =$F$16/10 -> 0.0070803896 | N16: =$F$16/10 -> 0.0070803896 | O16: =$F$16/10 -> 0.0070803896 | P16: =$F$16/10 -> 0.0070803896 | ... R16: =$F$16/10 -> 0.0070803896 | W16: =SUM(G16:V16) -> 0.070803896
A17: VI. | B17: =[282]RAB!B120 -> TAHAP PEMASANGAN LANGIT-LANGIT DAN GENTENG | E17: =[282]RAB!F125 -> 10151418 | F17: =E17/$E$27 -> 0.021009463 | M17: =$F$17/3 -> 0.0070031544 | N17: =$F$17/3 -> 0.0070031544 | O17: =$F$17/3 -> 0.0070031544 | W17: =SUM(G17:V17) -> 0.021009463
A18: VII. | B18: =[282]RAB!B126 -> TAHAP PENYELESAIAN KONSTRUKSI BANGUNAN | E18: =[282]RAB!F132 -> 12665127 | F18: =E18/$E$27 -> 0.026211858 | T18: =$F$18/3 -> 0.008737286 | U18: =$F$18/3 -> 0.008737286 | V18: =$F$18/3 -> 0.008737286 | W18: =SUM(G18:V18) -> 0.026211858
E19: =SUM(E12:E18) -> 3.0400233e+08
A20: B. | B20: LANTAI 2
A21: I. | B21: =[282]RAB!B135 -> TAHAP PEMBANGUNAN RANGKA | E21: =[282]RAB!F144 -> 40385358 | F21: =E21/$E$27 -> 0.083581888 | K21: =$F$21/3 -> 0.027860629 | L21: =$F$21/3 -> 0.027860629 | M21: =$F$21/3 -> 0.027860629 | W21: =SUM(G21:V21) -> 0.083581888
A22: II. | B22: =[282]RAB!B145 -> TAHAP PEKERJAAN KONSTRUKSI BANGUNAN | E22: =[282]RAB!F187 -> 85528784 | F22: =E22/$E$27 -> 0.17701112 | N22: =$F$22/8 -> 0.02212639 | O22: =$F$22/8 -> 0.02212639 | P22: =$F$22/8 -> 0.02212639 | Q22: =$F$22/8 -> 0.02212639 | R22: =$F$22/8 -> 0.02212639 | S22: =$F$22/8 -> 0.02212639 | T22: =$F$22/8 -> 0.02212639 | U22: =$F$22/8 -> 0.02212639 | W22: =SUM(G22:V22) -> 0.17701112
A23: III. | B23: =[282]RAB!B188 -> TAHAP PEKERJAAN INSTALASI ELEKTRIK DAN PIPA LEDENG | E23: =[282]RAB!F210 -> 14710940 | F23: =E23/$E$27 -> 0.03044589 | L23: =$F$23/10 -> 0.003044589 | M23: =$F$23/10 -> 0.003044589 | N23: =$F$23/10 -> 0.003044589 | O23: =$F$23/10 -> 0.003044589 | P23: =$F$23/10 -> 0.003044589 | Q23: =$F$23/10 -> 0.003044589 | R23: =$F$23/10 -> 0.003044589 | S23: =$F$23/10 -> 0.003044589 | ... U23: =$F$23/10 -> 0.003044589 | W23: =SUM(G23:V23) -> 0.03044589
A24: IV. | B24: =[282]RAB!B211 -> TAHAP PEMASANGAN LANGIT-LANGIT DAN GENTENG | E24: =[282]RAB!F220 -> 27467205 | F24: =E24/$E$27 -> 0.056846368 | M24: =$F$24/3 -> 0.018948789 | N24: =$F$24/3 -> 0.018948789 | O24: =$F$24/3 -> 0.018948789 | W24: =SUM(G24:V24) -> 0.056846368
A25: V. | B25: =[282]RAB!B221 -> TAHAP PENYELESAIAN KONSTRUKSI BANGUNAN | E25: =[282]RAB!F228 -> 11088505 | F25: =E25/$E$27 -> 0.022948866 | S25: =$F$25/3 -> 0.0076496221 | T25: =$F$25/3 -> 0.0076496221 | U25: =$F$25/3 -> 0.0076496221 | W25: =SUM(G25:V25) -> 0.022948866
E26: =SUM(E21:E25) -> 1.7918079e+08
A27: JADWAL PELAKSANAAN MINGGUAN | E27: =E26+E19 -> 4.8318312e+08 | F27: =SUM(F12:F26) -> 1 | G27: =SUM(G12:G26) -> 0.007346606 | H27: =SUM(H12:H26) -> 0.032113929 | I27: =SUM(I12:I26) -> 0.056009171 | J27: =SUM(J12:J26) -> 0.056009171 | K27: =SUM(K12:K26) -> 0.10450946 | L27: =SUM(L12:L26) -> 0.10755404 | M27: =SUM(M12:M26) -> 0.13350599 | ... W27: =SUM(W12:W26) -> 1
A28: PELAKSANAAN KOMULATIF MINGGUAN | E28: =E27+E20 -> 4.8318312e+08 | F28: =SUM(F13:F27) -> 1.9926534 | G28: =SUM(G13:G27) -> 0.007346606 | H28: =H27+G28 -> 0.039460535 | I28: =I27+H28 -> 0.095469706 | J28: =J27+I28 -> 0.15147888 | K28: =K27+J28 -> 0.25598833 | L28: =L27+K28 -> 0.36354238 | M28: =M27+L28 -> 0.49704837 | N28: =N27+M28 -> 0.57589133 | O28: =O27+N28 -> 0.6547343 | ... V28: =V27+U28 -> 1
E29: SIDOARJO, 18 Mei 2023
E30: Perusahaan
E37: Nama terang

Sheet PERHITUNGAN
A1: PERHITUNGAN KAPASITAS PEKERJAAN
A2: 1 | B2: PERHITUNGAN TAHAP AWAL PEMBANGUNAN
B4: a | C4: volume pembersihan lahan = panjang lahan x lebar lahan
C5: =14*8 -> 112 | D5: m²
B6: b | C6: volume pembuatan bedeng/ direksi seet = panjang x lebar
C7: =6*3 -> 18 | D7: m²
A9: 2 | B9: PERHITUNGAN PEMBUATAN PAPAN KONSTRUKSI (BOWPLANK)
B11: a | C11: volume keliling bangunan = (panjang + lebar)x 2 sisi
C12: =(14+8)*2 -> 44 | D12: m²
A14: 3 | B14: PERHITUNGAN GALIAN DASAR BANGUNAN
B16: A | C16: PENGGALIAN TANAH
C17: a.1 | D17: volume galian tanah sepanjang bangunan= (lebar galian bawah pondasi + lebar galian atas pondasi) / 2 x tinggi galian x panjang galian)
D18: =((0.8+1)/2)*0.75*42.5 -> 28.6875 | E18: m³
C19: a.2 | D19: volume galian sepanjang pondasi pagar = (lebar galian bawah pondasi + lebar galian atas pondasi) / 2 x tinggi galian x panjang galian)
D20: =((0.7+1)/2)*0.75*32.5 -> 20.71875 | E20: m³
C21: a.3 | D21: Total volume galian = Volume galian bangunan + Volume galian pagar
D22: =D18+D20 -> 49.40625 | E22: m³
B24: B | C24: PENGURUKAN PASIR DAN TANAH
C25: b.1 | D25: Pengurukan pasir bawah pondasi
D26: b.1.1 | E26: Volume urugan dibawah pondasi bangunan = tebal urugan x lebar urugan x panjang pondasi bangunan
E27: =0.05*0.8*42.5 -> 1.7 | F27: m³
D28: b.1.2 | E28: Volume urugan dibawah pondasi pagar = tebal urugan x lebar urugan x panjang pondasi pagar
E29: =0.05*0.8*32.5 -> 1.3 | F29: m³
D30: b.1.3 | E30: Total Volume urugan pasir dibawah pondasi = Volume urugan bangunan + vol urugan pagar
E31: =E27+E29 -> 3 | F31: m³
C33: b.2 | D33: Pengurukan pasir bawah lantai = tebal urugan x lebar ruangan
D34: =0.05*80 -> 4 | E34: m³
C36: b.3 | D36: Pengurukan tanah kembali = (Volume galian tanah - volume pasangan pondasi batu belah) + urugan pasir bawah pondasi
D37: =(49.41-28.31)+3 -> 24.1 | E37: m³
C39: b.4 | D39: Pengurukan tanah untuk tinggi lantai = tebal urugan x luas ruangan - sisa volume urugan
D40: =(0.4*80)-(49.41-24.09) -> 6.68 | E40: m³
A42: 4 | B42: PERHITUNGAN PEMASANGAN PONDASI BATU BELAH
B44: a | C44: Volume pondasi pada bangunan = lebar pondasi atas + lebar pondasi bawah / 2 x tinggi x panjang
C45: =((0.25+0.8)/2*(0.75*42.5)) -> 16.734375 | D45: m³
B47: b | C47: Volume pondasi pada pagar = lebar pondasi atas + lebar pondasi bawah / 2 x tinggi x panjang
C48: =((0.25+0.7)/2*(0.75*32.5)) -> 11.578125 | D48: m³
B50: c | C50: Total volume pondasi batu belah = Volume pondasi bangunan + Volume pondasi pagar
C51: =C45+C48 -> 28.3125 | D51: m³
A53: 5 | B53: PERHITUNGAN PEMASANGAN BETON BERTULANG
B55: a | C55: Volume pondasi plat setempat = panjang x lebar x ketebalan x jumlah pondasi plat
...

Sheet Pondasi
A1: BERAT BESI PER M3
A4: No. | B4: Uraian | G4: Besi | J4: PANJANG (meter) | N4: Potongan | Q4: Jumlah | R4: Berat | T4: Ket.
G5: Jml | H5: Dia | I5: Jrk | J5: a | K5: b | L5: c | M5: d | N5: Panjang | O5: Jumlah | P5: Tipikal | Q5: Panjang | R5: Kg/m' | S5: Jml Berat
N6: ( m' ) | O6: ( bh ) | P6: ( bh ) | Q6: ( m' ) | S6: ( Kg )
C7: b | E7: h
A8: I | B8: Sloof S1 | C8: 0.15 | D8: x | E8: 0.3
A10: 1 | B10: Sengkang
B11: Tumpuan | D11: = | F11: =1/4 -> 0.25 | H11: 8 | I11: 150 | J11: =C8-0.04-0.04 -> 0.07 | K11: =E8-0.04-0.04 -> 0.22 | N11: =(J11+K11)*2 -> 0.58 | O11: =F11/(I11/1000) -> 1.6666667 | P11: 2 | Q11: =N11*O11*P11 -> 1.9333333 | R11: =(H11^2)*0.006165 -> 0.39456 | S11: =Q11*R11 -> 0.762816
B13: Lapangan | D13: = | F13: =1/2 -> 0.5 | H13: 8 | I13: 200 | J13: =C8-0.04-0.04 -> 0.07 | K13: =E8-0.04-0.04 -> 0.22 | N13: =(J13+K13)*2 -> 0.58 | O13: =F13/(I13/1000) -> 2.5 | P13: 1 | Q13: =N13*O13*P13 -> 1.45 | R13: =(H13^2)*0.006165 -> 0.39456 | S13: =Q13*R13 -> 0.572112
A16: 2 | B16: Tulangan utama
B17: Atas | D17: = | G17: 2 | H17: 13 | J17: 1 | N17: 1 | O17: =G17 -> 2 | P17: 1 | Q17: =N17*O17*P17 -> 2 | R17: =(H17^2)*0.006165 -> 1.041885 | S17: =Q17*R17 -> 2.08377
B19: Bawah | D19: = | G19: 2 | H19: 13 | J19: 1 | N19: 1 | O19: =G19 -> 2 | P19: 1 | Q19: =N19*O19*P19 -> 2 | R19: =(H19^2)*0.006165 -> 1.041885 | S19: =Q19*R19 -> 2.08377
B21: Badan | D21: = | G21: 2 | H21: 13 | J21: 1 | N21: 1 | O21: =G21 -> 2 | P21: 1 | Q21: =N21*O21*P21 -> 2 | R21: =(H21^2)*0.006165 -> 1.041885 | S21: =Q21*R21 -> 2.08377
H25: Ø | I25: 12 | N25: @ | O25: 12 | P25: m/ljr | Q25: =SUM(Q11:Q13)/O25 -> 0.28194444 | R25: Ljr | S25: =SUM(S11:S13) -> 1.334928 | T25: kg
H26: D | I26: 13 | N26: @ | O26: 12 | P26: m/ljr | Q26: =SUM(Q17:Q19)/O26 -> 0.33333333 | R26: Ljr | S26: =SUM(S17:S21) -> 6.25131 | T26: kg
R28: Total Tulangan | S28: =SUM(S25:S26) -> 7.586238 | T28: kg
F30: Panjang | I30: = | J30: panjang | K30: / | L30: lebar | M30: x | N30: tinggi
I31: = | J31: 1 | K31: / | L31: =C8 -> 0.15 | M31: x | N31: =E8 -> 0.3
I32: = | J32: =J31/(L31*N31) -> 22.222222 | K32: m
F35: =B8 -> Sloof S1 | I35: = | J35: jumlah | K35: x | L35: panjang | M35: x | N35: lebar | O35: x | P35: tinggi
I36: = | J36: 1 | K36: x | L36: 1 | M36: x | N36: =C8 -> 0.15 | O36: x | P36: =E8 -> 0.3
I37: = | J37: =J36*L36*N36*P36 -> 0.045 | K37: m3
F40: Bekesting | I40: = | J40: jumlah | K40: x | L40: panjang | M40: x | N40: tinggi | O40: x | P40: sisi
I41: = | J41: 1 | K41: x | L41: 1 | M41: x | N41: =E8 -> 0.3 | O41: x | P41: 2
I42: = | J42: =J41*L41*N41*P41*J32 -> 13.333333 | K42: m2
F44: TOTAL PER M3
F45: - Besi | I45: = | J45: =S28/J37 -> 168.58307 | K45: kg
F46: - Bekesting | I46: = | J46: =J42/2 -> 6.6666667 | K46: m2
A49: No. | B49: Uraian | G49: Besi | J49: PANJANG (meter) | N49: Potongan | Q49: Jumlah | R49: Berat | T49: Ket.
G50: Jml | H50: Dia | I50: Jrk | J50: a | K50: b | L50: c | M50: d | N50: Panjang | O50: Jumlah | P50: Tipikal | Q50: Panjang | R50: Kg/m' | S50: Jml Berat
N51: ( m' ) | O51: ( bh ) | P51: ( bh ) | Q51: ( m' ) | S51: ( Kg )
C52: b | E52: h
A53: I | B53: Sloof S2 | C53: 0.15 | D53: x | E53: 0.25
A55: 1 | B55: Sengkang
B56: Tumpuan | D56: = | F56: =1/4 -> 0.25 | H56: 8 | I56: 150 | J56: =C53-0.04-0.04 -> 0.07 | K56: =E53-0.04-0.04 -> 0.17 | N56: =(J56+K56)*2 -> 0.48 | O56: =F56/(I56/1000) -> 1.6666667 | P56: 2 | Q56: =N56*O56*P56 -> 1.6 | R56: =(H56^2)*0.006165 -> 0.39456 | S56: =Q56*R56 -> 0.631296
B58: Lapangan | D58: = | F58: =1/2 -> 0.5 | H58: 8 | I58: 200 | J58: =C53-0.04-0.04 -> 0.07 | K58: =E53-0.04-0.04 -> 0.17 | N58: =(J58+K58)*2 -> 0.48 | O58: =F58/(I58/1000) -> 2.5 | P58: 1 | Q58: =N58*O58*P58 -> 1.2 | R58: =(H58^2)*0.006165 -> 0.39456 | S58: =Q58*R58 -> 0.473472
A61: 2 | B61: Tulangan utama
B62: Atas | D62: = | G62: 2 | H62: 12 | J62: 1 | N62: 1 | O62: =G62 -> 2 | P62: 1 | Q62: =N62*O62*P62 -> 2 | R62: =(H62^2)*0.006165 -> 0.88776 | S62: =Q62*R62 -> 1.77552
B64: Bawah | D64: = | G64: 2 | H64: 12 | J64: 1 | N64: 1 | O64: =G64 -> 2 | P64: 1 | Q64: =N64*O64*P64 -> 2 | R64: =(H64^2)*0.006165 -> 0.88776 | S64: =Q64*R64 -> 1.77552
B66: Badan | D66: = | G66: 2 | H66: 12 | J66: 1 | N66: 1 | O66: =G66 -> 2 | P66: 1 | Q66: =N66*O66*P66 -> 2 | R66: =(H66^2)*0.006165 -> 0.88776 | S66: =Q66*R66 -> 1.77552
...

Sheet Tiang
A1: BERAT BESI PER M3
A4: No. | B4: Deskripsi | G4: Besi | J4: PANJANG (meter) | N4: Potongan | Q4: Jumlah | R4: Berat | T4: Ket.
G5: Jml | H5: Dia | I5: Jrk | J5: a | K5: b | L5: c | M5: d | N5: Panjang | O5: Jumlah | P5: Tipikal | Q5: Panjang | R5: Kg/m' | S5: Jml Berat
N6: ( m' ) | O6: ( bh ) | P6: ( bh ) | Q6: ( m' ) | S6: ( Kg )
C7: b | E7: h
A8: I | B8: Balok B1 | C8: 0.15 | D8: x | E8: 0.35
A10: 1 | B10: Sengkang
B11: Tumpuan | D11: = | F11: =1/4 -> 0.25 | H11: 8 | I11: 150 | J11: =C8-0.04-0.04 -> 0.07 | K11: =E8-0.04-0.04 -> 0.27 | N11: =(J11+K11)*2 -> 0.68 | O11: =F11/(I11/1000) -> 1.6666667 | P11: 2 | Q11: =N11*O11*P11 -> 2.2666667 | R11: =(H11^2)*0.006165 -> 0.39456 | S11: =Q11*R11 -> 0.894336
B13: Lapangan | D13: = | F13: =1/2 -> 0.5 | H13: 8 | I13: 200 | J13: =C8-0.04-0.04 -> 0.07 | K13: =E8-0.04-0.04 -> 0.27 | N13: =(J13+K13)*2 -> 0.68 | O13: =F13/(I13/1000) -> 2.5 | P13: 1 | Q13: =N13*O13*P13 -> 1.7 | R13: =(H13^2)*0.006165 -> 0.39456 | S13: =Q13*R13 -> 0.670752
A16: 2 | B16: Tulangan utama
B17: Atas | D17: = | G17: 2 | H17: 13 | J17: 1 | N17: 1 | O17: =G17 -> 2 | P17: 1 | Q17: =N17*O17*P17 -> 2 | R17: =(H17^2)*0.006165 -> 1.041885 | S17: =Q17*R17 -> 2.08377
B19: Bawah | D19: = | G19: 2 | H19: 13 | J19: 1 | N19: 1 | O19: =G19 -> 2 | P19: 1 | Q19: =N19*O19*P19 -> 2 | R19: =(H19^2)*0.006165 -> 1.041885 | S19: =Q19*R19 -> 2.08377
B21: Badan | D21: = | G21: 2 | H21: 13 | J21: 1 | N21: 1 | O21: =G21 -> 2 | P21: 1 | Q21: =N21*O21*P21 -> 2 | R21: =(H21^2)*0.006165 -> 1.041885 | S21: =Q21*R21 -> 2.08377
H25: Ø | I25: 10 | N25: @ | O25: 12 | P25: m/ljr | Q25: =SUM(Q11:Q13)/O25 -> 0.33055556 | R25: Ljr | S25: =SUM(S11:S13) -> 1.565088 | T25: kg
H26: Ø | I26: 13 | N26: @ | O26: 12 | P26: m/ljr | Q26: =SUM(Q17:Q19)/O26 -> 0.33333333 | R26: Ljr | S26: =SUM(S17:S21) -> 6.25131 | T26: kg
R28: Total Tulangan | S28: =SUM(S25:S26) -> 7.816398 | T28: kg
F30: Meter | I30: = | J30: panjang | K30: / | L30: lebar | M30: x | N30: tinggi
I31: = | J31: 1 | K31: / | L31: =C8 -> 0.15 | M31: x | N31: =E8 -> 0.35
I32: = | J32: =J31/(L31*N31) -> 19.047619 | K32: m
F35: Bekesting | I35: = | J35: jumlah | K35: x | L35: lebar | M35: + | N35: tinggi | O35: x | P35: sisi
I36: = | J36: 1 | K36: x | L36: =C8 -> 0.15 | M36: + | N36: =E8 -> 0.35 | O36: x | P36: 2
I37: = | J37: =J36*(L36+(N36*P36)) -> 0.85 | K37: m2
F39: TOTAL PER M3
F40: - Besi | I40: = | J40: =J32*S28 -> 148.88377 | K40: kg
F41: - Bekesting | I41: = | J41: =J37*J32/2 -> 8.0952381 | K41: m2
A44: No. | B44: Deskripsi | G44: Besi | J44: PANJANG (meter) | N44: Potongan | Q44: Jumlah | R44: Berat | T44: Ket.
G45: Jml | H45: Dia | I45: Jrk | J45: a | K45: b | L45: c | M45: d | N45: Panjang | O45: Jumlah | P45: Tipikal | Q45: Panjang | R45: Kg/m' | S45: Jml Berat
N46: ( m' ) | O46: ( bh ) | P46: ( bh ) | Q46: ( m' ) | S46: ( Kg )
C47: b | E47: h
A48: I | B48: Balok B2 | C48: 0.15 | D48: x | E48: 0.3
A50: 1 | B50: Sengkang
B51: Tumpuan | D51: = | F51: =1/4 -> 0.25 | H51: 8 | I51: 150 | J51: =C48-0.04-0.04 -> 0.07 | K51: =E48-0.04-0.04 -> 0.22 | N51: =(J51+K51)*2 -> 0.58 | O51: =F51/(I51/1000) -> 1.6666667 | P51: 2 | Q51: =N51*O51*P51 -> 1.9333333 | R51: =(H51^2)*0.006165 -> 0.39456 | S51: =Q51*R51 -> 0.762816
B53: Lapangan | D53: = | F53: =1/2 -> 0.5 | H53: 8 | I53: 200 | J53: =C48-0.04-0.04 -> 0.07 | K53: =E48-0.04-0.04 -> 0.22 | N53: =(J53+K53)*2 -> 0.58 | O53: =F53/(I53/1000) -> 2.5 | P53: 1 | Q53: =N53*O53*P53 -> 1.45 | R53: =(H53^2)*0.006165 -> 0.39456 | S53: =Q53*R53 -> 0.572112
A56: 2 | B56: Tulangan utama
B57: Atas | D57: = | G57: 2 | H57: 13 | J57: 1 | N57: 1 | O57: =G57 -> 2 | P57: 1 | Q57: =N57*O57*P57 -> 2 | R57: =(H57^2)*0.006165 -> 1.041885 | S57: =Q57*R57 -> 2.08377
B59: Bawah | D59: = | G59: 2 | H59: 13 | J59: 1 | N59: 1 | O59: =G59 -> 2 | P59: 1 | Q59: =N59*O59*P59 -> 2 | R59: =(H59^2)*0.006165 -> 1.041885 | S59: =Q59*R59 -> 2.08377
B61: Badan | D61: = | G61: 2 | H61: 13 | J61: 1 | N61: 1 | O61: =G61 -> 2 | P61: 1 | Q61: =N61*O61*P61 -> 2 | R61: =(H61^2)*0.006165 -> 1.041885 | S61: =Q61*R61 -> 2.08377
H65: Ø | I65: 8 | N65: @ | O65: 12 | P65: m/ljr | Q65: =SUM(Q51:Q53)/O65 -> 0.28194444 | R65: Ljr | S65: =SUM(S51:S53) -> 1.334928 | T65: kg
H66: Ø | I66: 13 | N66: @ | O66: 12 | P66: m/ljr | Q66: =SUM(Q57:Q62)/O66 -> 0.5 | R66: Ljr | S66: =SUM(S57:S61) -> 6.25131 | T66: kg
R68: Total Tulangan | S68: =SUM(S65:S66) -> 7.586238 | T68: kg
...

Sheet Plat
B4: NO. | C4: NO. GMB | D4: DESKRIPSI KEGIATAN | F4: KALKULASI | AF4: PEMBAHASAN | AG4: VOL. | AH4: VOL RAB | AI4: VOL. SGS | AJ4: SAT | AK4: CATATAN
H6: T | J6: L | L6: P
H8: h plat | J8: Lx | L8: Ly | N8: 1/4 Lx | P8: 1/2 Lx
H9: 0.08 | J9: 3 | L9: 3.5 | N9: =J9/4 -> 0.75 | P9: =J9/2 -> 1.5
F10: jarak | H10: Dia | J10: L | L10: N | N10: Lapis | P10: Berat kg/m' | R10: Waste
E11: ="Plat 8 cm ( "&J9&" x "&L9&" x "&H9&" ) m" -> Plat 8 cm ( 3 x 3,5 x 0,08 ) m | R11: 1.15
E12: Tulangan arah X (Lap) | F12: 0.15 | H12: 10 | J12: =P9 -> 1.5 | L12: =IF(F12=0,0,J13/F12) -> 13.333333 | N12: 1 | P12: =0.25*PI()*(H12/1000)^2*7850 -> 0.61653756 | R12: =$R$11 -> 1.15 | AG12: =PRODUCT(J12:AD12) -> 14.180364 | AJ12: kg | AK12: begesting
E13: Tulangan Arah Y (Lap) | F13: 0.15 | H13: 8 | J13: =L9-P9 -> 2 | L13: =IF(F13=0,0,J12/F13) -> 10 | N13: 1 | P13: =0.25*PI()*(H13/1000)^2*7850 -> 0.39458404 | R13: =$R$11 -> 1.15 | AG13: =PRODUCT(J13:AD13) -> 9.0754329 | AJ13: kg | AK13: =1/H9 -> 12.5
E14: Tulangan arah X (Tump) bag. Atas kanan dan kiri | F14: 0.2 | H14: 0 | J14: =P9 -> 1.5 | L14: =IF(F14=0,0,J13/F14) -> 10 | P14: =0.25*PI()*(H14/1000)^2*7850 -> 0 | R14: =$R$11 -> 1.15 | AG14: =PRODUCT(J14:AD14) -> 0 | AJ14: kg
E15: Tulangan arah X (Tump) bag. Bawah | F15: 0.2 | H15: 10 | J15: =P9 -> 1.5 | L15: =IF(F15=0,0,J13/F15) -> 10 | N15: 1 | P15: =0.25*PI()*(H15/1000)^2*7850 -> 0.61653756 | R15: =$R$11 -> 1.15 | AG15: =PRODUCT(J15:AD15) -> 10.635273 | AJ15: kg
E16: Tulangan arah Y (Tump) bag. Atas | F16: 0.2 | H16: 8 | J16: =P9 -> 1.5 | L16: =IF(F16=0,0,J16/F16) -> 7.5 | P16: =0.25*PI()*(H16/1000)^2*7850 -> 0.39458404 | R16: =$R$11 -> 1.15 | AG16: =PRODUCT(J16:AD16) -> 5.104931 | AJ16: kg
E17: Tulangan arah Y (Tump) bag. Bawah | F17: 0.2 | H17: 8 | J17: =P9 -> 1.5 | L17: =IF(F17=0,0,J17/F17) -> 7.5 | N17: 1 | P17: =0.25*PI()*(H17/1000)^2*7850 -> 0.39458404 | R17: =$R$11 -> 1.15 | AG17: =PRODUCT(J17:AD17) -> 5.104931 | AJ17: kg
E18: Tulangan Susut/bagi bag. Arah X atas dan bawah | F18: 0.2 | H18: 8 | J18: =J9 -> 3 | L18: =IF(F18=0,0,P9/F18) -> 7.5 | N18: 1 | P18: =0.25*PI()*(H18/1000)^2*7850 -> 0.39458404 | R18: =$R$11 -> 1.15 | AG18: =PRODUCT(J18:AD18) -> 10.209862 | AJ18: kg
E19: Tulangan Susut/bagi bag. Arah Y atas dan bawah | F19: 0.2 | H19: 8 | J19: =L9 -> 3.5 | L19: =IF(F19=0,0,P9/F19) -> 7.5 | N19: 1 | P19: =0.25*PI()*(H19/1000)^2*7850 -> 0.39458404 | R19: =$R$11 -> 1.15 | AG19: =PRODUCT(J19:AD19) -> 11.911506 | AJ19: kg | AK19: per m3 beton
N20: Volume Beton | O20: = | P20: =J9*L9*H9 -> 0.84 | Q20: m3 | AG20: =SUM(AG12:AG19) -> 66.222299 | AJ20: kg | AK20: =ROUND(AG20/P20,2) -> 78.84
H22: h plat | J22: Lx | L22: Ly | N22: 1/4 Lx | P22: 1/2 Lx
H23: 0.1 | J23: 3.75 | L23: 2.45 | N23: =J23/4 -> 0.9375 | P23: =J23/2 -> 1.875
F24: jarak | H24: Dia | J24: L | L24: N | N24: Lapis | P24: Berat kg/m' | R24: Waste
E25: ="Plat Lantai ( "&J23&" x "&L23&" x "&H23&" )" -> Plat Lantai ( 3,75 x 2,45 x 0,1 ) | R25: 1.1
E26: Tulangan arah X (Lap) | F26: 0.15 | H26: 8 | J26: =P23 -> 1.875 | L26: =IF(F26=0,0,J27/F26) -> 3.8333333 | N26: 2 | P26: =0.25*PI()*(H26/1000)^2*7850 -> 0.39458404 | R26: =R25 -> 1.1 | AG26: =PRODUCT(J26:AD26) -> 6.2393601 | AJ26: kg | AK26: begesting
E27: Tulangan Arah Y (Lap) | F27: 0.15 | H27: 8 | J27: =L23-P23 -> 0.575 | L27: =IF(F27=0,0,J26/F27) -> 12.5 | N27: 2 | P27: =0.25*PI()*(H27/1000)^2*7850 -> 0.39458404 | R27: =R26 -> 1.1 | AG27: =PRODUCT(J27:AD27) -> 6.2393601 | AJ27: kg | AK27: =1/H23 -> 10
E28: Tulangan arah X (Tump) bag. Atas kanan dan kiri | F28: 0.15 | H28: 8 | J28: =P23 -> 1.875 | L28: =IF(F28=0,0,J27/F28) -> 3.8333333 | N28: 1 | P28: =0.25*PI()*(H28/1000)^2*7850 -> 0.39458404 | R28: =R27 -> 1.1 | AG28: =PRODUCT(J28:AD28) -> 3.11968 | AJ28: kg
E29: Tulangan arah X (Tump) bag. Bawah | F29: 0.15 | H29: 8 | J29: =P23 -> 1.875 | L29: =IF(F29=0,0,J27/F29) -> 3.8333333 | N29: 1 | P29: =0.25*PI()*(H29/1000)^2*7850 -> 0.39458404 | R29: =R28 -> 1.1 | AG29: =PRODUCT(J29:AD29) -> 3.11968 | AJ29: kg
E30: Tulangan arah Y (Tump) bag. Atas | F30: 0.15 | H30: 8 | J30: =P23 -> 1.875 | L30: =IF(F30=0,0,J30/F30) -> 12.5 | N30: 1 | P30: =0.25*PI()*(H30/1000)^2*7850 -> 0.39458404 | R30: =R29 -> 1.1 | AG30: =PRODUCT(J30:AD30) -> 10.17287 | AJ30: kg
E31: Tulangan arah Y (Tump) bag. Bawah | F31: 0.15 | H31: 8 | J31: =P23 -> 1.875 | L31: =IF(F31=0,0,J31/F31) -> 12.5 | N31: 1 | P31: =0.25*PI()*(H31/1000)^2*7850 -> 0.39458404 | R31: =R30 -> 1.1 | AG31: =PRODUCT(J31:AD31) -> 10.17287 | AJ31: kg
E32: Tulangan Susut/bagi bag. Arah X atas dan bawah | F32: 0.15 | H32: 8 | J32: =J23 -> 3.75 | L32: =IF(F32=0,0,P23/F32) -> 12.5 | N32: 2 | P32: =0.25*PI()*(H32/1000)^2*7850 -> 0.39458404 | R32: =R31 -> 1.1 | AG32: =PRODUCT(J32:AD32) -> 40.691479 | AJ32: kg
E33: Tulangan Susut/bagi bag. Arah Y atas dan bawah | F33: 0.15 | H33: 8 | J33: =L23 -> 2.45 | L33: =IF(F33=0,0,P23/F33) -> 12.5 | N33: 2 | P33: =0.25*PI()*(H33/1000)^2*7850 -> 0.39458404 | R33: =R32 -> 1.1 | AG33: =PRODUCT(J33:AD33) -> 26.5851 | AJ33: kg | AK33: per m3 beton
N34: Volume Beton | O34: = | P34: =J23*L23*H23 -> 0.91875 | Q34: m3 | AG34: =SUM(AG26:AG33) -> 106.3404 | AJ34: kg | AK34: =ROUND(AG34/P34,0) -> 116
H36: h plat | J36: Lx | L36: Ly | N36: 1/4 Lx | P36: 1/2 Lx
H37: 0.12 | J37: 3.75 | L37: 2.45 | N37: =J37/4 -> 0.9375 | P37: =J37/2 -> 1.875
F38: jarak | H38: Dia | J38: L | L38: N | N38: Lapis | P38: Berat kg/m' | R38: Waste
E39: ="Plat Lantai ( "&J37&" x "&L37&" x "&H37&" )" -> Plat Lantai ( 3,75 x 2,45 x 0,12 ) | R39: 1.1
E40: Tulangan arah X (Lap) | F40: 0.15 | H40: 8 | J40: =P37 -> 1.875 | L40: =IF(F40=0,0,J41/F40) -> 3.8333333 | N40: 2 | P40: =0.25*PI()*(H40/1000)^2*7850 -> 0.39458404 | R40: =R39 -> 1.1 | AG40: =PRODUCT(J40:AD40) -> 6.2393601 | AJ40: kg | AK40: begesting
E41: Tulangan Arah Y (Lap) | F41: 0.15 | H41: 8 | J41: =L37-P37 -> 0.575 | L41: =IF(F41=0,0,J40/F41) -> 12.5 | N41: 2 | P41: =0.25*PI()*(H41/1000)^2*7850 -> 0.39458404 | R41: =R40 -> 1.1 | AG41: =PRODUCT(J41:AD41) -> 6.2393601 | AJ41: kg | AK41: =1/H37 -> 8.3333333
E42: Tulangan arah X (Tump) bag. Atas kanan dan kiri | F42: 0.15 | H42: 8 | J42: =P37 -> 1.875 | L42: =IF(F42=0,0,J41/F42) -> 3.8333333 | N42: 1 | P42: =0.25*PI()*(H42/1000)^2*7850 -> 0.39458404 | R42: =R41 -> 1.1 | AG42: =PRODUCT(J42:AD42) -> 3.11968 | AJ42: kg
E43: Tulangan arah X (Tump) bag. Bawah | F43: 0.15 | H43: 8 | J43: =P37 -> 1.875 | L43: =IF(F43=0,0,J41/F43) -> 3.8333333 | N43: 1 | P43: =0.25*PI()*(H43/1000)^2*7850 -> 0.39458404 | R43: =R42 -> 1.1 | AG43: =PRODUCT(J43:AD43) -> 3.11968 | AJ43: kg
E44: Tulangan arah Y (Tump) bag. Atas | F44: 0.15 | H44: 8 | J44: =P37 -> 1.875 | L44: =IF(F44=0,0,J44/F44) -> 12.5 | N44: 1 | P44: =0.25*PI()*(H44/1000)^2*7850 -> 0.39458404 | R44: =R43 -> 1.1 | AG44: =PRODUCT(J44:AD44) -> 10.17287 | AJ44: kg
E45: Tulangan arah Y (Tump) bag. Bawah | F45: 0.15 | H45: 8 | J45: =P37 -> 1.875 | L45: =IF(F45=0,0,J45/F45) -> 12.5 | N45: 1 | P45: =0.25*PI()*(H45/1000)^2*7850 -> 0.39458404 | R45: =R44 -> 1.1 | AG45: =PRODUCT(J45:AD45) -> 10.17287 | AJ45: kg
E46: Tulangan Susut/bagi bag. Arah X atas dan bawah | F46: 0.15 | H46: 8 | J46: =J37 -> 3.75 | L46: =IF(F46=0,0,P37/F46) -> 12.5 | N46: 2 | P46: =0.25*PI()*(H46/1000)^2*7850 -> 0.39458404 | R46: =R45 -> 1.1 | AG46: =PRODUCT(J46:AD46) -> 40.691479 | AJ46: kg
E47: Tulangan Susut/bagi bag. Arah Y atas dan bawah | F47: 0.15 | H47: 8 | J47: =L37 -> 2.45 | L47: =IF(F47=0,0,P37/F47) -> 12.5 | N47: 2 | P47: =0.25*PI()*(H47/1000)^2*7850 -> 0.39458404 | R47: =R46 -> 1.1 | AG47: =PRODUCT(J47:AD47) -> 26.5851 | AJ47: kg | AK47: per m3 beton
...

Sheet Beton
C1: BERAT BESI PER M3 RANGKA BETON JENIS POER
B3: No | C3: Deskripsi | P3: Panjang | Q3: Jml. Tul | R3: Panjang Total | S3: Berat/M' | T3: Berat Total
B4: 1 | C4: 2 | P4: 3 | Q4: 4 | R4: 5 = 3 x 4 | S4: 6 | T4: 7 = 5 x 6
A6: 1 | B6: =B4 -> 1 | C6: ="Pondasi Poer P"&A6&" - ("&D6/10&" x "&F6/10&" x "&H6/10&" cm) - K-250 " -> Pondasi Poer P1 - (60 x 60 x 30 cm) - K-250 | D6: 600 | E6: x | F6: 600 | G6: x | H6: 300 | I6: mm | J6: (P1) = | K6: =(F6*H6*D6)/1000000000 -> 0.108 | L6: M3, | M6: 1 M3 (P1) = | N6: =1/K6 -> 9.2592593 | O6: BH
C7: Tulangan Vertikal
C8: Tulangan Bawah | E8: D | F8: 12 | G8: - | H8: 150 | I8: =I6 -> mm | P8: =((D6-(0.03*2))+(2*(H6-50)))/1000 -> 1.09994 | Q8: =FLOOR(F6/H8+1,1) -> 5 | R8: =Q8*P8 -> 5.4997 | S8: =0.25*(22/7)*((F8/1000)^2)*7850 -> 0.88817143 | T8: =S8*R8 -> 4.8846764
C9: Tulangan Atas | E9: D | F9: 12 | G9: - | H9: 150 | I9: =I8 -> mm | P9: =((D6-(0.03*2))+(2*6*F9))/1000 -> 0.74394 | Q9: =FLOOR(F6/H9+1,1) -> 5 | R9: =Q9*P9 -> 3.7197 | S9: =0.25*(22/7)*((F9/1000)^2)*7850 -> 0.88817143 | T9: =S9*R9 -> 3.3037313
C10: Tulangan Horisontal
C11: =C8 -> Tulangan Bawah | E11: =E8 -> D | F11: 12 | G11: - | H11: 150 | I11: =I8 -> mm | P11: =((F6-(0.03*2))+(2*(H6-50)))/1000 -> 1.09994 | Q11: =FLOOR(D6/H11+1,1) -> 5 | R11: =Q11*P11 -> 5.4997 | S11: =0.25*(22/7)*((F11/1000)^2)*7850 -> 0.88817143 | T11: =S11*R11 -> 4.8846764
C12: =C9 -> Tulangan Atas | E12: D | F12: 12 | G12: - | H12: 150 | I12: =I9 -> mm | P12: =((F6-(0.03*2))+(2*6*F12))/1000 -> 0.74394 | Q12: =FLOOR(D6/H12+1,1) -> 5 | R12: =Q12*P12 -> 3.7197 | S12: =0.25*(22/7)*((F12/1000)^2)*7850 -> 0.88817143 | T12: =S12*R12 -> 3.3037313
S14: Berat Besi 1 Bh | T14: =SUM(T8:T13) -> 16.376815 | U14: Kg | V14: begesting
S15: Berat Besi 1 M3 | T15: =T14*N6 -> 151.63718 | U15: =+U14 -> Kg | V15: =((D6*H6*2)+(F6*H6*2))/1000000 -> 0.72
B17: No | C17: Deskripsi | P17: Panjang | Q17: Jml. Tul | R17: Panjang Total | S17: Berat/M' | T17: Berat Total
B18: 2 | C18: 2 | P18: 3 | Q18: 4 | R18: 5 = 3 x 4 | S18: 6 | T18: 7 = 5 x 6
A20: 2 | B20: =B18 -> 2 | C20: ="Pondasi Poer PC"&A20&" - ("&D20/10&" x "&F20/10&" x "&H20/10&" cm) - K-250 " -> Pondasi Poer PC2 - (80 x 80 x 30 cm) - K-250 | D20: 800 | E20: x | F20: 800 | G20: x | H20: 300 | I20: mm | J20: (P1) = | K20: =(F20*H20*D20)/1000000000 -> 0.192 | L20: M3, | M20: 1 M3 (P1) = | N20: =1/K20 -> 5.2083333 | O20: BH | X20: =2.4*1.2 -> 2.88 | Z20: =2.4*2.1*0.4 -> 2.016
C21: Tulangan Vertikal | X21: =3.6/2*1.2 -> 2.16
C22: Tulangan Bawah | E22: D | F22: 13 | G22: - | H22: 150 | I22: =I20 -> mm | P22: =((D20-(0.03*2))+(2*(H20-50)))/1000 -> 1.29994 | Q22: =FLOOR(F20/H22+1,1) -> 6 | R22: =Q22*P22 -> 7.79964 | S22: =0.25*(22/7)*((F22/1000)^2)*7850 -> 1.0423679 | T22: =S22*R22 -> 8.130094 | X22: =X20+X21 -> 5.04 | Z22: =X22/2.4 -> 2.1
C23: Tulangan Atas | E23: D | F23: 13 | G23: - | H23: 150 | I23: =I22 -> mm | P23: =((D20-(0.03*2))+(2*6*F23))/1000 -> 0.95594 | Q23: =FLOOR(F20/H23+1,1) -> 6 | R23: =Q23*P23 -> 5.73564 | S23: =0.25*(22/7)*((F23/1000)^2)*7850 -> 1.0423679 | T23: =S23*R23 -> 5.9786468
C24: Tulangan Horisontal
C25: =C22 -> Tulangan Bawah | E25: =E22 -> D | F25: 13 | G25: - | H25: 150 | I25: =I22 -> mm | P25: =((F20-(0.03*2))+(2*(H20-50)))/1000 -> 1.29994 | Q25: =FLOOR(D20/H25+1,1) -> 6 | R25: =Q25*P25 -> 7.79964 | S25: =0.25*(22/7)*((F25/1000)^2)*7850 -> 1.0423679 | T25: =S25*R25 -> 8.130094
C26: =C23 -> Tulangan Atas | E26: D | F26: 13 | G26: - | H26: 150 | I26: =I23 -> mm | P26: =((F20-(0.03*2))+(2*6*F26))/1000 -> 0.95594 | Q26: =FLOOR(D20/H26+1,1) -> 6 | R26: =Q26*P26 -> 5.73564 | S26: =0.25*(22/7)*((F26/1000)^2)*7850 -> 1.0423679 | T26: =S26*R26 -> 5.9786468
S28: Berat Besi 1 Bh | T28: =SUM(T22:T27) -> 28.217482 | U28: Kg | V28: begesting
S29: Berat Besi 1 M3 | T29: =T28*N20 -> 146.96605 | U29: =+U28 -> Kg | V29: =((D20*H20*2)+(F20*H20*2))/1000000 -> 0.96
B31: No | C31: Deskripsi | P31: Panjang | Q31: Jml. Tul | R31: Panjang Total | S31: Berat/M' | T31: Berat Total
B32: 1 | C32: 2 | P32: 3 | Q32: 4 | R32: 5 = 3 x 4 | S32: 6 | T32: 7 = 5 x 6
A34: 3 | B34: 3 | C34: ="Pondasi Plat"&A34&" - ("&D34/10&" x "&F34/10&" x "&H34/10&" cm) - K-250 " -> Pondasi Plat3 - (50 x 50 x 30 cm) - K-250 | D34: 500 | E34: x | F34: 500 | G34: x | H34: 300 | I34: mm | J34: (P1) = | K34: =(F34*H34*D34)/1000000000 -> 0.075 | L34: M3, | M34: 1 M3 (P1) = | N34: =1/K34 -> 13.333333 | O34: BH
C35: Tulangan Vertikal
C36: Tulangan Bawah | E36: Ø | F36: 12 | G36: - | H36: 150 | I36: =I34 -> mm | P36: =((D34-(0.03*2))+(2*(H34-50)))/1000 -> 0.99994 | Q36: =FLOOR(F34/H36+1,1) -> 4 | R36: =Q36*P36 -> 3.99976 | S36: =0.25*(22/7)*((F36/1000)^2)*7850 -> 0.88817143 | T36: =S36*R36 -> 3.5524726
C37: Tulangan Atas | E37: Ø | F37: 12 | G37: =G36 -> - | H37: 150 | I37: =I36 -> mm | P37: =((D34-(0.03*2))+(2*6*F37))/1000 -> 0.64394 | Q37: =FLOOR(F34/H37+1,1) -> 4 | R37: =Q37*P37 -> 2.57576 | S37: =0.25*(22/7)*((F37/1000)^2)*7850 -> 0.88817143 | T37: =S37*R37 -> 2.2877164
C38: Tulangan Horisontal
C39: =C36 -> Tulangan Bawah | E39: =E36 -> Ø | F39: 12 | G39: - | H39: 150 | I39: =I36 -> mm | P39: =((F34-(0.03*2))+(2*(H34-50)))/1000 -> 0.99994 | Q39: =FLOOR(D34/H39+1,1) -> 4 | R39: =Q39*P39 -> 3.99976 | S39: =0.25*(22/7)*((F39/1000)^2)*7850 -> 0.88817143 | T39: =S39*R39 -> 3.5524726
C40: =C37 -> Tulangan Atas | E40: Ø | F40: 12 | G40: =G39 -> - | H40: 150 | I40: =I37 -> mm | P40: =((F34-(0.03*2))+(2*6*F40))/1000 -> 0.64394 | Q40: =FLOOR(D34/H40+1,1) -> 4 | R40: =Q40*P40 -> 2.57576 | S40: =0.25*(22/7)*((F40/1000)^2)*7850 -> 0.88817143 | T40: =S40*R40 -> 2.2877164
S42: Berat Besi 1 Bh | T42: =SUM(T36:T41) -> 11.680378 | U42: Kg | V42: begesting
S43: Berat Besi 1 M3 | T43: =T42*N34 -> 155.73837 | U43: =+U42 -> Kg | V43: =((D34*H34*2)+(F34*H34*2))/1000000 -> 0.6
B45: No | C45: Uraian | P45: Panjang | Q45: Jml. Tul | R45: Panjang Total | S45: Berat/M' | T45: Berat Total
B46: 1 | C46: 2 | P46: 3 | Q46: 4 | R46: 5 = 3 x 4 | S46: 6 | T46: 7 = 5 x 6
A48: 1' | B48: 4 | C48: ="Pondasi Poer P"&A48&" - ("&D48/10&" x "&F48/10&" x "&H48/10&" cm) - K-250 " -> Pondasi Poer P1' - (240 x 75 x 40 cm) - K-250 | D48: 2400 | E48: x | F48: 750 | G48: x | H48: 400 | I48: mm | J48: (P1) = | K48: =(F48*H48*D48)/1000000000 -> 0.72 | L48: M3, | M48: 1 M3 (P1) = | N48: =1/K48 -> 1.3888889 | O48: BH
C49: Tul. Vertikal
C50: Tulangan Bawah | E50: D | F50: 16 | G50: - | H50: 100 | I50: =I48 -> mm | P50: =((D48-(0.03*2))+(2*(H48-50)))/1000 -> 3.09994 | Q50: =FLOOR(F48/H50+1,1) -> 8 | R50: =Q50*P50 -> 24.79952 | S50: =0.25*(22/7)*((F50/1000)^2)*7850 -> 1.5789714 | T50: =S50*R50 -> 39.157734
C51: Tulangan Atas | E51: D | F51: 13 | G51: =G50 -> - | H51: 100 | I51: =I50 -> mm | P51: =((D48-(0.03*2))+(2*6*F51))/1000 -> 2.55594 | Q51: =FLOOR(F48/H51+1,1) -> 8 | R51: =Q51*P51 -> 20.44752 | S51: =0.25*(22/7)*((F51/1000)^2)*7850 -> 1.0423679 | T51: =S51*R51 -> 21.313838
...

Sheet Kolom
A1: BERAT BESI PER M3
A4: No. | B4: Deskripsi | G4: Besi | J4: PANJANG (meter) | N4: Potongan | Q4: Jumlah | R4: Berat | T4: Ket.
G5: Jml | H5: Dia | I5: Jrk | J5: a | K5: b | L5: c | M5: d | N5: Panjang | O5: Jumlah | P5: Tipikal | Q5: Panjang | R5: Kg/m' | S5: Jml Berat
N6: ( m' ) | O6: ( bh ) | P6: ( bh ) | Q6: ( m' ) | S6: ( Kg )
C7: b | E7: h
A8: I | B8: Kolom 1 | C8: 0.15 | D8: x | E8: 0.35
A10: 1 | B10: Sengkang
B11: Tumpuan | D11: = | F11: =1/4 -> 0.25 | H11: 8 | I11: 125 | J11: =C8-0.04-0.04 -> 0.07 | K11: =E8-0.04-0.04 -> 0.27 | N11: =(J11+K11)*2 -> 0.68 | O11: =F11/(I11/1000) -> 2 | P11: 2 | Q11: =N11*O11*P11 -> 2.72 | R11: =(H11^2)*0.006165 -> 0.39456 | S11: =Q11*R11 -> 1.0732032
B13: Lapangan | D13: = | F13: =1/2 -> 0.5 | H13: 8 | I13: 125 | J13: =C8-0.04-0.04 -> 0.07 | K13: =E8-0.04-0.04 -> 0.27 | N13: =(J13+K13)*2 -> 0.68 | O13: =F13/(I13/1000) -> 4 | P13: 1 | Q13: =N13*O13*P13 -> 2.72 | R13: =(H13^2)*0.006165 -> 0.39456 | S13: =Q13*R13 -> 1.0732032
A16: 2 | B16: Tulangan utama | D16: = | G16: 6 | H16: 13 | J16: 1 | N16: 1 | O16: =G16 -> 6 | P16: 1 | Q16: =N16*O16*P16 -> 6 | R16: =(H16^2)*0.006165 -> 1.041885 | S16: =Q16*R16 -> 6.25131
H25: Ø | I25: 8 | N25: @ | O25: 12 | P25: m/ljr | Q25: =SUM(Q11:Q13)/O25 -> 0.45333333 | R25: Ljr | S25: =SUM(S11:S13) -> 2.1464064 | T25: kg
H26: D | I26: 13 | N26: @ | O26: 12 | P26: m/ljr | Q26: =Q16/O26 -> 0.5 | R26: Ljr | S26: =S16 -> 6.25131 | T26: kg
R28: Total Tulangan | S28: =SUM(S25:S26) -> 8.3977164 | T28: kg
F30: Meter | I30: = | J30: panjang | K30: / | L30: lebar | M30: x | N30: tinggi
I31: = | J31: 1 | K31: / | L31: =C8 -> 0.15 | M31: x | N31: =E8 -> 0.35
I32: = | J32: =J31/(L31*N31) -> 19.047619 | K32: m
F35: Bekesting | I35: = | J35: jumlah | K35: x | L35: panjang | M35: x | N35: lebar | O35: x | P35: sisi
I36: = | J36: 1 | K36: x | L36: 1 | M36: x | N36: =E8 -> 0.35 | O36: x | P36: 2
I37: = | J37: =J36*L36*N36*P36 -> 0.7 | K37: m2
F39: TOTAL PER M3
F40: - Besi | I40: = | J40: =S28*J32 -> 159.9565 | K40: kg
F41: - Bekesting | I41: = | J41: =J32*J37/2 -> 6.6666667 | K41: m2
A43: No. | B43: Deskripsi | G43: Besi | J43: PANJANG (meter) | N43: Potongan | Q43: Jumlah | R43: Berat | T43: Ket.
G44: Jml | H44: Dia | I44: Jrk | J44: a | K44: b | L44: c | M44: d | N44: Panjang | O44: Jumlah | P44: Tipikal | Q44: Panjang | R44: Kg/m' | S44: Jml Berat
N45: ( m' ) | O45: ( bh ) | P45: ( bh ) | Q45: ( m' ) | S45: ( Kg )
C46: b | E46: h
A47: I | B47: Kolom 2 | C47: 0.15 | D47: x | E47: 0.3
A49: 1 | B49: Sengkang
B50: Tumpuan | D50: = | F50: =1/4 -> 0.25 | H50: 8 | I50: 125 | J50: =C47-0.04-0.04 -> 0.07 | K50: =E47-0.04-0.04 -> 0.22 | N50: =(J50+K50)*2 -> 0.58 | O50: =F50/(I50/1000) -> 2 | P50: 2 | Q50: =N50*O50*P50 -> 2.32 | R50: =(H50^2)*0.006165 -> 0.39456 | S50: =Q50*R50 -> 0.9153792
B52: Lapangan | D52: = | F52: =1/2 -> 0.5 | H52: 8 | I52: 125 | J52: =C47-0.04-0.04 -> 0.07 | K52: =E47-0.04-0.04 -> 0.22 | N52: =(J52+K52)*2 -> 0.58 | O52: =F52/(I52/1000) -> 4 | P52: 1 | Q52: =N52*O52*P52 -> 2.32 | R52: =(H52^2)*0.006165 -> 0.39456 | S52: =Q52*R52 -> 0.9153792
A55: 2 | B55: Tulangan utama | D55: = | G55: 6 | H55: 13 | J55: 1 | N55: 1 | O55: =G55 -> 6 | P55: 1 | Q55: =N55*O55*P55 -> 6 | R55: =(H55^2)*0.006165 -> 1.041885 | S55: =Q55*R55 -> 6.25131
H64: Ø | I64: 8 | N64: @ | O64: 12 | P64: m/ljr | Q64: =SUM(Q50:Q52)/O64 -> 0.38666667 | R64: Ljr | S64: =SUM(S50:S52) -> 1.8307584 | T64: kg
H65: D | I65: 13 | N65: @ | O65: 12 | P65: m/ljr | Q65: =Q55/O65 -> 0.5 | R65: Ljr | S65: =S55 -> 6.25131 | T65: kg
R67: Total Tulangan | S67: =SUM(S64:S65) -> 8.0820684 | T67: kg
F69: Meter | I69: = | J69: panjang | K69: / | L69: lebar | M69: x | N69: tinggi
I70: = | J70: 1 | K70: / | L70: =C47 -> 0.15 | M70: x | N70: =E47 -> 0.3
I71: = | J71: =J70/(L70*N70) -> 22.222222 | K71: m
F74: Bekesting | I74: = | J74: jumlah | K74: x | L74: panjang | M74: x | N74: lebar | O74: x | P74: sisi
I75: = | J75: 1 | K75: x | L75: 1 | M75: x | N75: =E47 -> 0.3 | O75: x | P75: 2
I76: = | J76: =J75*L75*N75*P75 -> 0.6 | K76: m2
...
