Workbook

Sheet Summary
B2: =JAN!B2 -> Mr.A
B4: Bulan | C4: Jam Kerja | D4: Jam Lembur | E4: Total Jam
B6: January | C6: =SUM(JAN!F6:F36) -> 189 | D6: =SUM(JAN!G6:G36) -> 90 | E6: =SUM(C6:D6) -> 279
B7: February | C7: =SUM(FEB!F6:F36) -> 207 | D7: =SUM(FEB!G6:G36) -> 72 | E7: =SUM(C7:D7) -> 279
B8: March | C8: =SUM(MAR!F6:F36) -> 207 | D8: =SUM(MAR!G6:G36) -> 72 | E8: =SUM(C8:D8) -> 279
B9: April | C9: =SUM(APR!F6:F36) -> 198 | D9: =SUM(APR!G6:G36) -> 81 | E9: =SUM(C9:D9) -> 279
B10: May | C10: =SUM(MAY!F6:F36) -> 198 | D10: =SUM(MAY!G6:G36) -> 81 | E10: =SUM(C10:D10) -> 279
B11: June | C11: =SUM(JUN!F6:F36) -> 207 | D11: =SUM(JUN!G6:G36) -> 72 | E11: =SUM(C11:D11) -> 279
B12: July | C12: =SUM(JUL!F6:F36) -> 189 | D12: =SUM(JUL!G6:G36) -> 90 | E12: =SUM(C12:D12) -> 279
B13: August | C13: =SUM(AUG!F6:F36) -> 207 | D13: =SUM(AUG!G6:G36) -> 72 | E13: =SUM(C13:D13) -> 279
B14: September | C14: =SUM(SEP!F6:F36) -> 207 | D14: =SUM(SEP!G6:G36) -> 72 | E14: =SUM(C14:D14) -> 279
B15: October | C15: =SUM(OCT!F6:F36) -> 189 | D15: =SUM(OCT!G6:G36) -> 90 | E15: =SUM(C15:D15) -> 279
B16: November | C16: =SUM(NOV!F6:F36) -> 207 | D16: =SUM(NOV!G6:G36) -> 72 | E16: =SUM(C16:D16) -> 279
B17: December | C17: =SUM(DEC!F6:F36) -> 198 | D17: =SUM(DEC!G6:G36) -> 81 | E17: =SUM(C17:D17) -> 279
B19: Total | C19: =SUM(C6:C17) -> 2403 | D19: =SUM(D6:D17) -> 945 | E19: =SUM(E6:E17) -> 3348

Sheet Dropdown List Data
B2: Dropdown List Data
B3: ENGINEER 2 | C3: TIPE KONTRAK | D3: Sifat Kegiatan | E3: FAB | F3: MODEL
B4: Wee Min | C4: Svc Contract | D4: Administrative | E4: AMF | F4: Aquabate
B5: Allen | C5: Warranty | D5: Service Meeting | E5: AMS | F5: Combibum
B6: Ronaldo | C6: Billable | D6: Facility Hookup | E6: Seris | F6: Escape Duo
B7: Yi Hong | D7: Signal Interface | E7: IME | F7: Escape Inline
B8: MR.A | D8: Commissioning | E8: Indo Solar | F8: Salix
D9: Round Check | E9: JA Solar | F9: Salix Mini
D10: Maintenance | E10: Jinko Solar | F10: Aquabate Flex
D11: MPM | E11: Leeden Gas | F11: Styrax
D12: QPM | E12: Linde Gas | F12: Styrax Duo
D13: APM | E13: Longi | F13: Uptimum
D14: CM | E14: Micron | F14: Uptimum Plus
E15: SSMC
E16: Sterlite Tech
E17: Trina Solar (VN)
E18: UMC
E19: X-Fab

Sheet JAN
B2: Mr.A | G2: Liburan | I2: Akhir Pekan
B4: TANGGAL | C4: HARI | D4: WAKTU KERJA | I4: KEGIATAN PELAYANAN | O4: INFORMASI TOOL | S4: PENYELESAIAN MASALAH
D5: Waktu Mulai (24:00) | E5: Waktu Selesai (24:00) | F5: Jam Kerja | G5: Jam Lembur | H5: Total Jam | I5: ENGINEER 2 | J5: TIPE KONTRAK | K5: ON CALL (YES/NO) | L5: FSR# | M5: SIFAT KEGIATAN | N5: MAT REG# | O5: FAB | P5: MODEL | Q5: NO SERIAL | R5: ID TOOL | S5: KODE ALARM | T5: AKAR MASALAH | U5: AKSI | V5: Parts Replacement (Parts Name) | W5: Parts Replacement (Parts No.) | X5: QTY
B6: 44562 | C6: =TEXT(B6,"dddd") -> Saturday | D6: 0.375 | E6: 0.75 | F6: =IF((OR(C6="Sunday",C6="Saturday")),0,(IF((IFERROR(((E6-D6)*24),""))<=9,(IFERROR(((E6-D6)*24),"")),9))) -> 0 | G6: =IF((OR(C6="Sunday",C6="Saturday")),(IFERROR(((E6-D6)*24),"")),(IF((IFERROR(((E6-D6)*24),""))>9,((IFERROR(((E6-D6)*24),""))-9),0))) -> 9 | H6: =IFERROR((F6+G6),"") -> 9 | I6: Wee Min | J6: Svc Contract
B7: =IFERROR((IF(MONTH(B6+1)=MONTH(B6),(B6+1),"")),"") -> 44563 | C7: =TEXT(B7,"dddd") -> Sunday | D7: 0.375 | E7: 0.75 | F7: =IF((OR(C7="Sunday",C7="Saturday")),0,(IF((IFERROR(((E7-D7)*24),""))<=9,(IFERROR(((E7-D7)*24),"")),9))) -> 0 | G7: =IF((OR(C7="Sunday",C7="Saturday")),(IFERROR(((E7-D7)*24),"")),(IF((IFERROR(((E7-D7)*24),""))>9,((IFERROR(((E7-D7)*24),""))-9),0))) -> 9 | H7: =IFERROR((F7+G7),"") -> 9 | K7: Yes
B8: =IFERROR((IF(MONTH(B7+1)=MONTH(B7),(B7+1),"")),"") -> 44564 | C8: =TEXT(B8,"dddd") -> Monday | D8: 0.375 | E8: 0.75 | F8: =IF((OR(C8="Sunday",C8="Saturday")),0,(IF((IFERROR(((E8-D8)*24),""))<=9,(IFERROR(((E8-D8)*24),"")),9))) -> 9 | G8: =IF((OR(C8="Sunday",C8="Saturday")),(IFERROR(((E8-D8)*24),"")),(IF((IFERROR(((E8-D8)*24),""))>9,((IFERROR(((E8-D8)*24),""))-9),0))) -> 0 | H8: =IFERROR((F8+G8),"") -> 9
B9: =IFERROR((IF(MONTH(B8+1)=MONTH(B8),(B8+1),"")),"") -> 44565 | C9: =TEXT(B9,"dddd") -> Tuesday | D9: 0.375 | E9: 0.75 | F9: =IF((OR(C9="Sunday",C9="Saturday")),0,(IF((IFERROR(((E9-D9)*24),""))<=9,(IFERROR(((E9-D9)*24),"")),9))) -> 9 | G9: =IF((OR(C9="Sunday",C9="Saturday")),(IFERROR(((E9-D9)*24),"")),(IF((IFERROR(((E9-D9)*24),""))>9,((IFERROR(((E9-D9)*24),""))-9),0))) -> 0 | H9: =IFERROR((F9+G9),"") -> 9
B10: =IFERROR((IF(MONTH(B9+1)=MONTH(B9),(B9+1),"")),"") -> 44566 | C10: =TEXT(B10,"dddd") -> Wednesday | D10: 0.375 | E10: 0.75 | F10: =IF((OR(C10="Sunday",C10="Saturday")),0,(IF((IFERROR(((E10-D10)*24),""))<=9,(IFERROR(((E10-D10)*24),"")),9))) -> 9 | G10: =IF((OR(C10="Sunday",C10="Saturday")),(IFERROR(((E10-D10)*24),"")),(IF((IFERROR(((E10-D10)*24),""))>9,((IFERROR(((E10-D10)*24),""))-9),0))) -> 0 | H10: =IFERROR((F10+G10),"") -> 9
B11: =IFERROR((IF(MONTH(B10+1)=MONTH(B10),(B10+1),"")),"") -> 44567 | C11: =TEXT(B11,"dddd") -> Thursday | D11: 0.375 | E11: 0.75 | F11: =IF((OR(C11="Sunday",C11="Saturday")),0,(IF((IFERROR(((E11-D11)*24),""))<=9,(IFERROR(((E11-D11)*24),"")),9))) -> 9 | G11: =IF((OR(C11="Sunday",C11="Saturday")),(IFERROR(((E11-D11)*24),"")),(IF((IFERROR(((E11-D11)*24),""))>9,((IFERROR(((E11-D11)*24),""))-9),0))) -> 0 | H11: =IFERROR((F11+G11),"") -> 9
B12: =IFERROR((IF(MONTH(B11+1)=MONTH(B11),(B11+1),"")),"") -> 44568 | C12: =TEXT(B12,"dddd") -> Friday | D12: 0.375 | E12: 0.75 | F12: =IF((OR(C12="Sunday",C12="Saturday")),0,(IF((IFERROR(((E12-D12)*24),""))<=9,(IFERROR(((E12-D12)*24),"")),9))) -> 9 | G12: =IF((OR(C12="Sunday",C12="Saturday")),(IFERROR(((E12-D12)*24),"")),(IF((IFERROR(((E12-D12)*24),""))>9,((IFERROR(((E12-D12)*24),""))-9),0))) -> 0 | H12: =IFERROR((F12+G12),"") -> 9
B13: =IFERROR((IF(MONTH(B12+1)=MONTH(B12),(B12+1),"")),"") -> 44569 | C13: =TEXT(B13,"dddd") -> Saturday | D13: 0.375 | E13: 0.75 | F13: =IF((OR(C13="Sunday",C13="Saturday")),0,(IF((IFERROR(((E13-D13)*24),""))<=9,(IFERROR(((E13-D13)*24),"")),9))) -> 0 | G13: =IF((OR(C13="Sunday",C13="Saturday")),(IFERROR(((E13-D13)*24),"")),(IF((IFERROR(((E13-D13)*24),""))>9,((IFERROR(((E13-D13)*24),""))-9),0))) -> 9 | H13: =IFERROR((F13+G13),"") -> 9
B14: =IFERROR((IF(MONTH(B13+1)=MONTH(B13),(B13+1),"")),"") -> 44570 | C14: =TEXT(B14,"dddd") -> Sunday | D14: 0.375 | E14: 0.75 | F14: =IF((OR(C14="Sunday",C14="Saturday")),0,(IF((IFERROR(((E14-D14)*24),""))<=9,(IFERROR(((E14-D14)*24),"")),9))) -> 0 | G14: =IF((OR(C14="Sunday",C14="Saturday")),(IFERROR(((E14-D14)*24),"")),(IF((IFERROR(((E14-D14)*24),""))>9,((IFERROR(((E14-D14)*24),""))-9),0))) -> 9 | H14: =IFERROR((F14+G14),"") -> 9
B15: =IFERROR((IF(MONTH(B14+1)=MONTH(B14),(B14+1),"")),"") -> 44571 | C15: =TEXT(B15,"dddd") -> Monday | D15: 0.375 | E15: 0.75 | F15: =IF((OR(C15="Sunday",C15="Saturday")),0,(IF((IFERROR(((E15-D15)*24),""))<=9,(IFERROR(((E15-D15)*24),"")),9))) -> 9 | G15: =IF((OR(C15="Sunday",C15="Saturday")),(IFERROR(((E15-D15)*24),"")),(IF((IFERROR(((E15-D15)*24),""))>9,((IFERROR(((E15-D15)*24),""))-9),0))) -> 0 | H15: =IFERROR((F15+G15),"") -> 9
B16: =IFERROR((IF(MONTH(B15+1)=MONTH(B15),(B15+1),"")),"") -> 44572 | C16: =TEXT(B16,"dddd") -> Tuesday | D16: 0.375 | E16: 0.75 | F16: =IF((OR(C16="Sunday",C16="Saturday")),0,(IF((IFERROR(((E16-D16)*24),""))<=9,(IFERROR(((E16-D16)*24),"")),9))) -> 9 | G16: =IF((OR(C16="Sunday",C16="Saturday")),(IFERROR(((E16-D16)*24),"")),(IF((IFERROR(((E16-D16)*24),""))>9,((IFERROR(((E16-D16)*24),""))-9),0))) -> 0 | H16: =IFERROR((F16+G16),"") -> 9
B17: =IFERROR((IF(MONTH(B16+1)=MONTH(B16),(B16+1),"")),"") -> 44573 | C17: =TEXT(B17,"dddd") -> Wednesday | D17: 0.375 | E17: 0.75 | F17: =IF((OR(C17="Sunday",C17="Saturday")),0,(IF((IFERROR(((E17-D17)*24),""))<=9,(IFERROR(((E17-D17)*24),"")),9))) -> 9 | G17: =IF((OR(C17="Sunday",C17="Saturday")),(IFERROR(((E17-D17)*24),"")),(IF((IFERROR(((E17-D17)*24),""))>9,((IFERROR(((E17-D17)*24),""))-9),0))) -> 0 | H17: =IFERROR((F17+G17),"") -> 9
B18: =IFERROR((IF(MONTH(B17+1)=MONTH(B17),(B17+1),"")),"") -> 44574 | C18: =TEXT(B18,"dddd") -> Thursday | D18: 0.375 | E18: 0.75 | F18: =IF((OR(C18="Sunday",C18="Saturday")),0,(IF((IFERROR(((E18-D18)*24),""))<=9,(IFERROR(((E18-D18)*24),"")),9))) -> 9 | G18: =IF((OR(C18="Sunday",C18="Saturday")),(IFERROR(((E18-D18)*24),"")),(IF((IFERROR(((E18-D18)*24),""))>9,((IFERROR(((E18-D18)*24),""))-9),0))) -> 0 | H18: =IFERROR((F18+G18),"") -> 9
B19: =IFERROR((IF(MONTH(B18+1)=MONTH(B18),(B18+1),"")),"") -> 44575 | C19: =TEXT(B19,"dddd") -> Friday | D19: 0.375 | E19: 0.75 | F19: =IF((OR(C19="Sunday",C19="Saturday")),0,(IF((IFERROR(((E19-D19)*24),""))<=9,(IFERROR(((E19-D19)*24),"")),9))) -> 9 | G19: =IF((OR(C19="Sunday",C19="Saturday")),(IFERROR(((E19-D19)*24),"")),(IF((IFERROR(((E19-D19)*24),""))>9,((IFERROR(((E19-D19)*24),""))-9),0))) -> 0 | H19: =IFERROR((F19+G19),"") -> 9
... B36: =IFERROR((IF(MONTH(B35+1)=MONTH(B35),(B35+1),"")),"") -> 44592 | C36: =TEXT(B36,"dddd") -> Monday | D36: 0.375 | E36: 0.75 | F36: =IF((OR(C36="Sunday",C36="Saturday")),0,(IF((IFERROR(((E36-D36)*24),""))<=9,(IFERROR(((E36-D36)*24),"")),9))) -> 9 | G36: =IF((OR(C36="Sunday",C36="Saturday")),(IFERROR(((E36-D36)*24),"")),(IF((IFERROR(((E36-D36)*24),""))>9,((IFERROR(((E36-D36)*24),""))-9),0))) -> 0 | H36: =IFERROR((F36+G36),"") -> 9

Sheet FEB
B2: =JAN!B2 -> Mr.A | G2: Liburan | I2: Akhir Pekan
B4: TANGGAL | C4: HARI | D4: WAKTU KERJA | I4: KEGIATAN PELAYANAN | O4: INFORMASI TOOL | S4: PENYELESAIAN MASALAH
D5: Waktu Mulai (24:00) | E5: Waktu Selesai (24:00) | F5: Jam Kerja | G5: Jam Lembur | H5: Total Jam | I5: ENGINEER 2 | J5: TIPE KONTRAK | K5: ON CALL (YES/NO) | L5: FSR# | M5: SIFAT KEGIATAN | N5: MAT REG# | O5: FAB | P5: MODEL | Q5: NO SERIAL | R5: ID TOOL | S5: KODE ALARM | T5: AKAR MASALAH | U5: AKSI | V5: Parts Replacement (Parts Name) | W5: Parts Replacement (Parts No.) | X5: QTY
B6: 44593 | C6: =TEXT(B6,"dddd") -> Tuesday | D6: 0.375 | E6: 0.75 | F6: =IF((OR(C6="Sunday",C6="Saturday")),0,(IF((IFERROR(((E6-D6)*24),""))<=9,(IFERROR(((E6-D6)*24),"")),9))) -> 9 | G6: =IF((OR(C6="Sunday",C6="Saturday")),(IFERROR(((E6-D6)*24),"")),(IF((IFERROR(((E6-D6)*24),""))>9,((IFERROR(((E6-D6)*24),""))-9),0))) -> 0 | H6: =IFERROR((F6+G6),"") -> 9 | I6: Allen | J6: Svc Contract
B7: =IFERROR((IF(MONTH(B6+1)=MONTH(B6),(B6+1),"")),"") -> 44594 | C7: =TEXT(B7,"dddd") -> Wednesday | D7: 0.375 | E7: 0.75 | F7: =IF((OR(C7="Sunday",C7="Saturday")),0,(IF((IFERROR(((E7-D7)*24),""))<=9,(IFERROR(((E7-D7)*24),"")),9))) -> 9 | G7: =IF((OR(C7="Sunday",C7="Saturday")),(IFERROR(((E7-D7)*24),"")),(IF((IFERROR(((E7-D7)*24),""))>9,((IFERROR(((E7-D7)*24),""))-9),0))) -> 0 | H7: =IFERROR((F7+G7),"") -> 9 | K7: Yes
B8: =IFERROR((IF(MONTH(B7+1)=MONTH(B7),(B7+1),"")),"") -> 44595 | C8: =TEXT(B8,"dddd") -> Thursday | D8: 0.375 | E8: 0.75 | F8: =IF((OR(C8="Sunday",C8="Saturday")),0,(IF((IFERROR(((E8-D8)*24),""))<=9,(IFERROR(((E8-D8)*24),"")),9))) -> 9 | G8: =IF((OR(C8="Sunday",C8="Saturday")),(IFERROR(((E8-D8)*24),"")),(IF((IFERROR(((E8-D8)*24),""))>9,((IFERROR(((E8-D8)*24),""))-9),0))) -> 0 | H8: =IFERROR((F8+G8),"") -> 9
B9: =IFERROR((IF(MONTH(B8+1)=MONTH(B8),(B8+1),"")),"") -> 44596 | C9: =TEXT(B9,"dddd") -> Friday | D9: 0.375 | E9: 0.75 | F9: =IF((OR(C9="Sunday",C9="Saturday")),0,(IF((IFERROR(((E9-D9)*24),""))<=9,(IFERROR(((E9-D9)*24),"")),9))) -> 9 | G9: =IF((OR(C9="Sunday",C9="Saturday")),(IFERROR(((E9-D9)*24),"")),(IF((IFERROR(((E9-D9)*24),""))>9,((IFERROR(((E9-D9)*24),""))-9),0))) -> 0 | H9: =IFERROR((F9+G9),"") -> 9
B10: =IFERROR((IF(MONTH(B9+1)=MONTH(B9),(B9+1),"")),"") -> 44597 | C10: =TEXT(B10,"dddd") -> Saturday | D10: 0.375 | E10: 0.75 | F10: =IF((OR(C10="Sunday",C10="Saturday")),0,(IF((IFERROR(((E10-D10)*24),""))<=9,(IFERROR(((E10-D10)*24),"")),9))) -> 0 | G10: =IF((OR(C10="Sunday",C10="Saturday")),(IFERROR(((E10-D10)*24),"")),(IF((IFERROR(((E10-D10)*24),""))>9,((IFERROR(((E10-D10)*24),""))-9),0))) -> 9 | H10: =IFERROR((F10+G10),"") -> 9
B11: =IFERROR((IF(MONTH(B10+1)=MONTH(B10),(B10+1),"")),"") -> 44598 | C11: =TEXT(B11,"dddd") -> Sunday | D11: 0.375 | E11: 0.75 | F11: =IF((OR(C11="Sunday",C11="Saturday")),0,(IF((IFERROR(((E11-D11)*24),""))<=9,(IFERROR(((E11-D11)*24),"")),9))) -> 0 | G11: =IF((OR(C11="Sunday",C11="Saturday")),(IFERROR(((E11-D11)*24),"")),(IF((IFERROR(((E11-D11)*24),""))>9,((IFERROR(((E11-D11)*24),""))-9),0))) -> 9 | H11: =IFERROR((F11+G11),"") -> 9
B12: =IFERROR((IF(MONTH(B11+1)=MONTH(B11),(B11+1),"")),"") -> 44599 | C12: =TEXT(B12,"dddd") -> Monday | D12: 0.375 | E12: 0.75 | F12: =IF((OR(C12="Sunday",C12="Saturday")),0,(IF((IFERROR(((E12-D12)*24),""))<=9,(IFERROR(((E12-D12)*24),"")),9))) -> 9 | G12: =IF((OR(C12="Sunday",C12="Saturday")),(IFERROR(((E12-D12)*24),"")),(IF((IFERROR(((E12-D12)*24),""))>9,((IFERROR(((E12-D12)*24),""))-9),0))) -> 0 | H12: =IFERROR((F12+G12),"") -> 9
B13: =IFERROR((IF(MONTH(B12+1)=MONTH(B12),(B12+1),"")),"") -> 44600 | C13: =TEXT(B13,"dddd") -> Tuesday | D13: 0.375 | E13: 0.75 | F13: =IF((OR(C13="Sunday",C13="Saturday")),0,(IF((IFERROR(((E13-D13)*24),""))<=9,(IFERROR(((E13-D13)*24),"")),9))) -> 9 | G13: =IF((OR(C13="Sunday",C13="Saturday")),(IFERROR(((E13-D13)*24),"")),(IF((IFERROR(((E13-D13)*24),""))>9,((IFERROR(((E13-D13)*24),""))-9),0))) -> 0 | H13: =IFERROR((F13+G13),"") -> 9
B14: =IFERROR((IF(MONTH(B13+1)=MONTH(B13),(B13+1),"")),"") -> 44601 | C14: =TEXT(B14,"dddd") -> Wednesday | D14: 0.375 | E14: 0.75 | F14: =IF((OR(C14="Sunday",C14="Saturday")),0,(IF((IFERROR(((E14-D14)*24),""))<=9,(IFERROR(((E14-D14)*24),"")),9))) -> 9 | G14: =IF((OR(C14="Sunday",C14="Saturday")),(IFERROR(((E14-D14)*24),"")),(IF((IFERROR(((E14-D14)*24),""))>9,((IFERROR(((E14-D14)*24),""))-9),0))) -> 0 | H14: =IFERROR((F14+G14),"") -> 9
B15: =IFERROR((IF(MONTH(B14+1)=MONTH(B14),(B14+1),"")),"") -> 44602 | C15: =TEXT(B15,"dddd") -> Thursday | D15: 0.375 | E15: 0.75 | F15: =IF((OR(C15="Sunday",C15="Saturday")),0,(IF((IFERROR(((E15-D15)*24),""))<=9,(IFERROR(((E15-D15)*24),"")),9))) -> 9 | G15: =IF((OR(C15="Sunday",C15="Saturday")),(IFERROR(((E15-D15)*24),"")),(IF((IFERROR(((E15-D15)*24),""))>9,((IFERROR(((E15-D15)*24),""))-9),0))) -> 0 | H15: =IFERROR((F15+G15),"") -> 9
B16: =IFERROR((IF(MONTH(B15+1)=MONTH(B15),(B15+1),"")),"") -> 44603 | C16: =TEXT(B16,"dddd") -> Friday | D16: 0.375 | E16: 0.75 | F16: =IF((OR(C16="Sunday",C16="Saturday")),0,(IF((IFERROR(((E16-D16)*24),""))<=9,(IFERROR(((E16-D16)*24),"")),9))) -> 9 | G16: =IF((OR(C16="Sunday",C16="Saturday")),(IFERROR(((E16-D16)*24),"")),(IF((IFERROR(((E16-D16)*24),""))>9,((IFERROR(((E16-D16)*24),""))-9),0))) -> 0 | H16: =IFERROR((F16+G16),"") -> 9
B17: =IFERROR((IF(MONTH(B16+1)=MONTH(B16),(B16+1),"")),"") -> 44604 | C17: =TEXT(B17,"dddd") -> Saturday | D17: 0.375 | E17: 0.75 | F17: =IF((OR(C17="Sunday",C17="Saturday")),0,(IF((IFERROR(((E17-D17)*24),""))<=9,(IFERROR(((E17-D17)*24),"")),9))) -> 0 | G17: =IF((OR(C17="Sunday",C17="Saturday")),(IFERROR(((E17-D17)*24),"")),(IF((IFERROR(((E17-D17)*24),""))>9,((IFERROR(((E17-D17)*24),""))-9),0))) -> 9 | H17: =IFERROR((F17+G17),"") -> 9
B18: =IFERROR((IF(MONTH(B17+1)=MONTH(B17),(B17+1),"")),"") -> 44605 | C18: =TEXT(B18,"dddd") -> Sunday | D18: 0.375 | E18: 0.75 | F18: =IF((OR(C18="Sunday",C18="Saturday")),0,(IF((IFERROR(((E18-D18)*24),""))<=9,(IFERROR(((E18-D18)*24),"")),9))) -> 0 | G18: =IF((OR(C18="Sunday",C18="Saturday")),(IFERROR(((E18-D18)*24),"")),(IF((IFERROR(((E18-D18)*24),""))>9,((IFERROR(((E18-D18)*24),""))-9),0))) -> 9 | H18: =IFERROR((F18+G18),"") -> 9
B19: =IFERROR((IF(MONTH(B18+1)=MONTH(B18),(B18+1),"")),"") -> 44606 | C19: =TEXT(B19,"dddd") -> Monday | D19: 0.375 | E19: 0.75 | F19: =IF((OR(C19="Sunday",C19="Saturday")),0,(IF((IFERROR(((E19-D19)*24),""))<=9,(IFERROR(((E19-D19)*24),"")),9))) -> 9 | G19: =IF((OR(C19="Sunday",C19="Saturday")),(IFERROR(((E19-D19)*24),"")),(IF((IFERROR(((E19-D19)*24),""))>9,((IFERROR(((E19-D19)*24),""))-9),0))) -> 0 | H19: =IFERROR((F19+G19),"") -> 9
... B36: =IFERROR((IF(MONTH(B35+1)=MONTH(B35),(B35+1),"")),"") | C36: =TEXT(B36,"dddd") | D36: 0.375 | E36: 0.75 | F36: =IF((OR(C36="Sunday",C36="Saturday")),0,(IF((IFERROR(((E36-D36)*24),""))<=9,(IFERROR(((E36-D36)*24),"")),9))) -> 9 | G36: =IF((OR(C36="Sunday",C36="Saturday")),(IFERROR(((E36-D36)*24),"")),(IF((IFERROR(((E36-D36)*24),""))>9,((IFERROR(((E36-D36)*24),""))-9),0))) -> 0 | H36: =IFERROR((F36+G36),"") -> 9

Sheet MAR
B2: =JAN!B2 -> Mr.A | G2: Hari Libur | I2: Akhir Pekan
B4: TANGGAL | C4: HARI | D4: WAKTU KERJA | I4: KEGIATAN PELAYANAN | O4: INFORMASI TOOL | S4: PENYELESAIAN MASALAH
D5: Waktu Mulai (24:00) | E5: Waktu Selesai (24:00) | F5: Jam Kerja | G5: Jam Lembur | H5: Total Jam | I5: ENGINEER 2 | J5: TIPE KONTRAK | K5: ON CALL (YES/NO) | L5: FSR# | M5: SIFAT KEGIATAN | N5: MAT REG# | O5: FAB | P5: MODEL | Q5: NO SERIAL | R5: ID TOOL | S5: KODE ALARM | T5: AKAR MASALAH | U5: AKSI | V5: Parts Replacement (Parts Name) | W5: Parts Replacement (Parts No.) | X5: QTY
B6: 44621 | C6: =TEXT(B6,"dddd") -> Tuesday | D6: 0.375 | E6: 0.75 | F6: =IF((OR(C6="Sunday",C6="Saturday")),0,(IF((IFERROR(((E6-D6)*24),""))<=9,(IFERROR(((E6-D6)*24),"")),9))) -> 9 | G6: =IF((OR(C6="Sunday",C6="Saturday")),(IFERROR(((E6-D6)*24),"")),(IF((IFERROR(((E6-D6)*24),""))>9,((IFERROR(((E6-D6)*24),""))-9),0))) -> 0 | H6: =IFERROR((F6+G6),"") -> 9 | I6: Wee Min | J6: Svc Contract
B7: =IFERROR((IF(MONTH(B6+1)=MONTH(B6),(B6+1),"")),"") -> 44622 | C7: =TEXT(B7,"dddd") -> Wednesday | D7: 0.375 | E7: 0.75 | F7: =IF((OR(C7="Sunday",C7="Saturday")),0,(IF((IFERROR(((E7-D7)*24),""))<=9,(IFERROR(((E7-D7)*24),"")),9))) -> 9 | G7: =IF((OR(C7="Sunday",C7="Saturday")),(IFERROR(((E7-D7)*24),"")),(IF((IFERROR(((E7-D7)*24),""))>9,((IFERROR(((E7-D7)*24),""))-9),0))) -> 0 | H7: =IFERROR((F7+G7),"") -> 9 | K7: Yes
B8: =IFERROR((IF(MONTH(B7+1)=MONTH(B7),(B7+1),"")),"") -> 44623 | C8: =TEXT(B8,"dddd") -> Thursday | D8: 0.375 | E8: 0.75 | F8: =IF((OR(C8="Sunday",C8="Saturday")),0,(IF((IFERROR(((E8-D8)*24),""))<=9,(IFERROR(((E8-D8)*24),"")),9))) -> 9 | G8: =IF((OR(C8="Sunday",C8="Saturday")),(IFERROR(((E8-D8)*24),"")),(IF((IFERROR(((E8-D8)*24),""))>9,((IFERROR(((E8-D8)*24),""))-9),0))) -> 0 | H8: =IFERROR((F8+G8),"") -> 9
B9: =IFERROR((IF(MONTH(B8+1)=MONTH(B8),(B8+1),"")),"") -> 44624 | C9: =TEXT(B9,"dddd") -> Friday | D9: 0.375 | E9: 0.75 | F9: =IF((OR(C9="Sunday",C9="Saturday")),0,(IF((IFERROR(((E9-D9)*24),""))<=9,(IFERROR(((E9-D9)*24),"")),9))) -> 9 | G9: =IF((OR(C9="Sunday",C9="Saturday")),(IFERROR(((E9-D9)*24),"")),(IF((IFERROR(((E9-D9)*24),""))>9,((IFERROR(((E9-D9)*24),""))-9),0))) -> 0 | H9: =IFERROR((F9+G9),"") -> 9
B10: =IFERROR((IF(MONTH(B9+1)=MONTH(B9),(B9+1),"")),"") -> 44625 | C10: =TEXT(B10,"dddd") -> Saturday | D10: 0.375 | E10: 0.75 | F10: =IF((OR(C10="Sunday",C10="Saturday")),0,(IF((IFERROR(((E10-D10)*24),""))<=9,(IFERROR(((E10-D10)*24),"")),9))) -> 0 | G10: =IF((OR(C10="Sunday",C10="Saturday")),(IFERROR(((E10-D10)*24),"")),(IF((IFERROR(((E10-D10)*24),""))>9,((IFERROR(((E10-D10)*24),""))-9),0))) -> 9 | H10: =IFERROR((F10+G10),"") -> 9
B11: =IFERROR((IF(MONTH(B10+1)=MONTH(B10),(B10+1),"")),"") -> 44626 | C11: =TEXT(B11,"dddd") -> Sunday | D11: 0.375 | E11: 0.75 | F11: =IF((OR(C11="Sunday",C11="Saturday")),0,(IF((IFERROR(((E11-D11)*24),""))<=9,(IFERROR(((E11-D11)*24),"")),9))) -> 0 | G11: =IF((OR(C11="Sunday",C11="Saturday")),(IFERROR(((E11-D11)*24),"")),(IF((IFERROR(((E11-D11)*24),""))>9,((IFERROR(((E11-D11)*24),""))-9),0))) -> 9 | H11: =IFERROR((F11+G11),"") -> 9
B12: =IFERROR((IF(MONTH(B11+1)=MONTH(B11),(B11+1),"")),"") -> 44627 | C12: =TEXT(B12,"dddd") -> Monday | D12: 0.375 | E12: 0.75 | F12: =IF((OR(C12="Sunday",C12="Saturday")),0,(IF((IFERROR(((E12-D12)*24),""))<=9,(IFERROR(((E12-D12)*24),"")),9))) -> 9 | G12: =IF((OR(C12="Sunday",C12="Saturday")),(IFERROR(((E12-D12)*24),"")),(IF((IFERROR(((E12-D12)*24),""))>9,((IFERROR(((E12-D12)*24),""))-9),0))) -> 0 | H12: =IFERROR((F12+G12),"") -> 9
B13: =IFERROR((IF(MONTH(B12+1)=MONTH(B12),(B12+1),"")),"") -> 44628 | C13: =TEXT(B13,"dddd") -> Tuesday | D13: 0.375 | E13: 0.75 | F13: =IF((OR(C13="Sunday",C13="Saturday")),0,(IF((IFERROR(((E13-D13)*24),""))<=9,(IFERROR(((E13-D13)*24),"")),9))) -> 9 | G13: =IF((OR(C13="Sunday",C13="Saturday")),(IFERROR(((E13-D13)*24),"")),(IF((IFERROR(((E13-D13)*24),""))>9,((IFERROR(((E13-D13)*24),""))-9),0))) -> 0 | H13: =IFERROR((F13+G13),"") -> 9
B14: =IFERROR((IF(MONTH(B13+1)=MONTH(B13),(B13+1),"")),"") -> 44629 | C14: =TEXT(B14,"dddd") -> Wednesday | D14: 0.375 | E14: 0.75 | F14: =IF((OR(C14="Sunday",C14="Saturday")),0,(IF((IFERROR(((E14-D14)*24),""))<=9,(IFERROR(((E14-D14)*24),"")),9))) -> 9 | G14: =IF((OR(C14="Sunday",C14="Saturday")),(IFERROR(((E14-D14)*24),"")),(IF((IFERROR(((E14-D14)*24),""))>9,((IFERROR(((E14-D14)*24),""))-9),0))) -> 0 | H14: =IFERROR((F14+G14),"") -> 9
B15: =IFERROR((IF(MONTH(B14+1)=MONTH(B14),(B14+1),"")),"") -> 44630 | C15: =TEXT(B15,"dddd") -> Thursday | D15: 0.375 | E15: 0.75 | F15: =IF((OR(C15="Sunday",C15="Saturday")),0,(IF((IFERROR(((E15-D15)*24),""))<=9,(IFERROR(((E15-D15)*24),"")),9))) -> 9 | G15: =IF((OR(C15="Sunday",C15="Saturday")),(IFERROR(((E15-D15)*24),"")),(IF((IFERROR(((E15-D15)*24),""))>9,((IFERROR(((E15-D15)*24),""))-9),0))) -> 0 | H15: =IFERROR((F15+G15),"") -> 9
B16: =IFERROR((IF(MONTH(B15+1)=MONTH(B15),(B15+1),"")),"") -> 44631 | C16: =TEXT(B16,"dddd") -> Friday | D16: 0.375 | E16: 0.75 | F16: =IF((OR(C16="Sunday",C16="Saturday")),0,(IF((IFERROR(((E16-D16)*24),""))<=9,(IFERROR(((E16-D16)*24),"")),9))) -> 9 | G16: =IF((OR(C16="Sunday",C16="Saturday")),(IFERROR(((E16-D16)*24),"")),(IF((IFERROR(((E16-D16)*24),""))>9,((IFERROR(((E16-D16)*24),""))-9),0))) -> 0 | H16: =IFERROR((F16+G16),"") -> 9
B17: =IFERROR((IF(MONTH(B16+1)=MONTH(B16),(B16+1),"")),"") -> 44632 | C17: =TEXT(B17,"dddd") -> Saturday | D17: 0.375 | E17: 0.75 | F17: =IF((OR(C17="Sunday",C17="Saturday")),0,(IF((IFERROR(((E17-D17)*24),""))<=9,(IFERROR(((E17-D17)*24),"")),9))) -> 0 | G17: =IF((OR(C17="Sunday",C17="Saturday")),(IFERROR(((E17-D17)*24),"")),(IF((IFERROR(((E17-D17)*24),""))>9,((IFERROR(((E17-D17)*24),""))-9),0))) -> 9 | H17: =IFERROR((F17+G17),"") -> 9
B18: =IFERROR((IF(MONTH(B17+1)=MONTH(B17),(B17+1),"")),"") -> 44633 | C18: =TEXT(B18,"dddd") -> Sunday | D18: 0.375 | E18: 0.75 | F18: =IF((OR(C18="Sunday",C18="Saturday")),0,(IF((IFERROR(((E18-D18)*24),""))<=9,(IFERROR(((E18-D18)*24),"")),9))) -> 0 | G18: =IF((OR(C18="Sunday",C18="Saturday")),(IFERROR(((E18-D18)*24),"")),(IF((IFERROR(((E18-D18)*24),""))>9,((IFERROR(((E18-D18)*24),""))-9),0))) -> 9 | H18: =IFERROR((F18+G18),"") -> 9
B19: =IFERROR((IF(MONTH(B18+1)=MONTH(B18),(B18+1),"")),"") -> 44634 | C19: =TEXT(B19,"dddd") -> Monday | D19: 0.375 | E19: 0.75 | F19: =IF((OR(C19="Sunday",C19="Saturday")),0,(IF((IFERROR(((E19-D19)*24),""))<=9,(IFERROR(((E19-D19)*24),"")),9))) -> 9 | G19: =IF((OR(C19="Sunday",C19="Saturday")),(IFERROR(((E19-D19)*24),"")),(IF((IFERROR(((E19-D19)*24),""))>9,((IFERROR(((E19-D19)*24),""))-9),0))) -> 0 | H19: =IFERROR((F19+G19),"") -> 9
... B36: =IFERROR((IF(MONTH(B35+1)=MONTH(B35),(B35+1),"")),"") -> 44651 | C36: =TEXT(B36,"dddd") -> Thursday | D36: 0.375 | E36: 0.75 | F36: =IF((OR(C36="Sunday",C36="Saturday")),0,(IF((IFERROR(((E36-D36)*24),""))<=9,(IFERROR(((E36-D36)*24),"")),9))) -> 9 | G36: =IF((OR(C36="Sunday",C36="Saturday")),(IFERROR(((E36-D36)*24),"")),(IF((IFERROR(((E36-D36)*24),""))>9,((IFERROR(((E36-D36)*24),""))-9),0))) -> 0 | H36: =IFERROR((F36+G36),"") -> 9

Sheet APR
B2: =JAN!B2 -> Mr.A | G2: Hari Libur | I2: Akhir Pekan
B4: TANGGAL | C4: HARI | D4: WAKTU KERJA | I4: KEGIATAN PELAYANAN | O4: INFORMASI TOOL | S4: PENYELESAIAN MASALAH
D5: Waktu Mulai (24:00) | E5: Waktu Selesai (24:00) | F5: Jam Kerja | G5: Jam Lembur | H5: Total Jam | I5: ENGINEER 2 | J5: TIPE KONTRAK | K5: ON CALL (YES/NO) | L5: FSR# | M5: SIFAT KEGIATAN | N5: MAT REG# | O5: FAB | P5: MODEL | Q5: NO SERIAL | R5: ID TOOL | S5: KODE ALARM | T5: AKAR MASALAH | U5: AKSI | V5: Parts Replacement (Parts Name) | W5: Parts Replacement (Parts No.) | X5: QTY
B6: 44652 | C6: =TEXT(B6,"dddd") -> Friday | D6: 0.375 | E6: 0.75 | F6: =IF((OR(C6="Sunday",C6="Saturday")),0,(IF((IFERROR(((E6-D6)*24),""))<=9,(IFERROR(((E6-D6)*24),"")),9))) -> 9 | G6: =IF((OR(C6="Sunday",C6="Saturday")),(IFERROR(((E6-D6)*24),"")),(IF((IFERROR(((E6-D6)*24),""))>9,((IFERROR(((E6-D6)*24),""))-9),0))) -> 0 | H6: =IFERROR((F6+G6),"") -> 9 | J6: Svc Contract
B7: =IFERROR((IF(MONTH(B6+1)=MONTH(B6),(B6+1),"")),"") -> 44653 | C7: =TEXT(B7,"dddd") -> Saturday | D7: 0.375 | E7: 0.75 | F7: =IF((OR(C7="Sunday",C7="Saturday")),0,(IF((IFERROR(((E7-D7)*24),""))<=9,(IFERROR(((E7-D7)*24),"")),9))) -> 0 | G7: =IF((OR(C7="Sunday",C7="Saturday")),(IFERROR(((E7-D7)*24),"")),(IF((IFERROR(((E7-D7)*24),""))>9,((IFERROR(((E7-D7)*24),""))-9),0))) -> 9 | H7: =IFERROR((F7+G7),"") -> 9 | K7: Yes
B8: =IFERROR((IF(MONTH(B7+1)=MONTH(B7),(B7+1),"")),"") -> 44654 | C8: =TEXT(B8,"dddd") -> Sunday | D8: 0.375 | E8: 0.75 | F8: =IF((OR(C8="Sunday",C8="Saturday")),0,(IF((IFERROR(((E8-D8)*24),""))<=9,(IFERROR(((E8-D8)*24),"")),9))) -> 0 | G8: =IF((OR(C8="Sunday",C8="Saturday")),(IFERROR(((E8-D8)*24),"")),(IF((IFERROR(((E8-D8)*24),""))>9,((IFERROR(((E8-D8)*24),""))-9),0))) -> 9 | H8: =IFERROR((F8+G8),"") -> 9
B9: =IFERROR((IF(MONTH(B8+1)=MONTH(B8),(B8+1),"")),"") -> 44655 | C9: =TEXT(B9,"dddd") -> Monday | D9: 0.375 | E9: 0.75 | F9: =IF((OR(C9="Sunday",C9="Saturday")),0,(IF((IFERROR(((E9-D9)*24),""))<=9,(IFERROR(((E9-D9)*24),"")),9))) -> 9 | G9: =IF((OR(C9="Sunday",C9="Saturday")),(IFERROR(((E9-D9)*24),"")),(IF((IFERROR(((E9-D9)*24),""))>9,((IFERROR(((E9-D9)*24),""))-9),0))) -> 0 | H9: =IFERROR((F9+G9),"") -> 9
B10: =IFERROR((IF(MONTH(B9+1)=MONTH(B9),(B9+1),"")),"") -> 44656 | C10: =TEXT(B10,"dddd") -> Tuesday | D10: 0.375 | E10: 0.75 | F10: =IF((OR(C10="Sunday",C10="Saturday")),0,(IF((IFERROR(((E10-D10)*24),""))<=9,(IFERROR(((E10-D10)*24),"")),9))) -> 9 | G10: =IF((OR(C10="Sunday",C10="Saturday")),(IFERROR(((E10-D10)*24),"")),(IF((IFERROR(((E10-D10)*24),""))>9,((IFERROR(((E10-D10)*24),""))-9),0))) -> 0 | H10: =IFERROR((F10+G10),"") -> 9
B11: =IFERROR((IF(MONTH(B10+1)=MONTH(B10),(B10+1),"")),"") -> 44657 | C11: =TEXT(B11,"dddd") -> Wednesday | D11: 0.375 | E11: 0.75 | F11: =IF((OR(C11="Sunday",C11="Saturday")),0,(IF((IFERROR(((E11-D11)*24),""))<=9,(IFERROR(((E11-D11)*24),"")),9))) -> 9 | G11: =IF((OR(C11="Sunday",C11="Saturday")),(IFERROR(((E11-D11)*24),"")),(IF((IFERROR(((E11-D11)*24),""))>9,((IFERROR(((E11-D11)*24),""))-9),0))) -> 0 | H11: =IFERROR((F11+G11),"") -> 9
B12: =IFERROR((IF(MONTH(B11+1)=MONTH(B11),(B11+1),"")),"") -> 44658 | C12: =TEXT(B12,"dddd") -> Thursday | D12: 0.375 | E12: 0.75 | F12: =IF((OR(C12="Sunday",C12="Saturday")),0,(IF((IFERROR(((E12-D12)*24),""))<=9,(IFERROR(((E12-D12)*24),"")),9))) -> 9 | G12: =IF((OR(C12="Sunday",C12="Saturday")),(IFERROR(((E12-D12)*24),"")),(IF((IFERROR(((E12-D12)*24),""))>9,((IFERROR(((E12-D12)*24),""))-9),0))) -> 0 | H12: =IFERROR((F12+G12),"") -> 9
B13: =IFERROR((IF(MONTH(B12+1)=MONTH(B12),(B12+1),"")),"") -> 44659 | C13: =TEXT(B13,"dddd") -> Friday | D13: 0.375 | E13: 0.75 | F13: =IF((OR(C13="Sunday",C13="Saturday")),0,(IF((IFERROR(((E13-D13)*24),""))<=9,(IFERROR(((E13-D13)*24),"")),9))) -> 9 | G13: =IF((OR(C13="Sunday",C13="Saturday")),(IFERROR(((E13-D13)*24),"")),(IF((IFERROR(((E13-D13)*24),""))>9,((IFERROR(((E13-D13)*24),""))-9),0))) -> 0 | H13: =IFERROR((F13+G13),"") -> 9
B14: =IFERROR((IF(MONTH(B13+1)=MONTH(B13),(B13+1),"")),"") -> 44660 | C14: =TEXT(B14,"dddd") -> Saturday | D14: 0.375 | E14: 0.75 | F14: =IF((OR(C14="Sunday",C14="Saturday")),0,(IF((IFERROR(((E14-D14)*24),""))<=9,(IFERROR(((E14-D14)*24),"")),9))) -> 0 | G14: =IF((OR(C14="Sunday",C14="Saturday")),(IFERROR(((E14-D14)*24),"")),(IF((IFERROR(((E14-D14)*24),""))>9,((IFERROR(((E14-D14)*24),""))-9),0))) -> 9 | H14: =IFERROR((F14+G14),"") -> 9
B15: =IFERROR((IF(MONTH(B14+1)=MONTH(B14),(B14+1),"")),"") -> 44661 | C15: =TEXT(B15,"dddd") -> Sunday | D15: 0.375 | E15: 0.75 | F15: =IF((OR(C15="Sunday",C15="Saturday")),0,(IF((IFERROR(((E15-D15)*24),""))<=9,(IFERROR(((E15-D15)*24),"")),9))) -> 0 | G15: =IF((OR(C15="Sunday",C15="Saturday")),(IFERROR(((E15-D15)*24),"")),(IF((IFERROR(((E15-D15)*24),""))>9,((IFERROR(((E15-D15)*24),""))-9),0))) -> 9 | H15: =IFERROR((F15+G15),"") -> 9
B16: =IFERROR((IF(MONTH(B15+1)=MONTH(B15),(B15+1),"")),"") -> 44662 | C16: =TEXT(B16,"dddd") -> Monday | D16: 0.375 | E16: 0.75 | F16: =IF((OR(C16="Sunday",C16="Saturday")),0,(IF((IFERROR(((E16-D16)*24),""))<=9,(IFERROR(((E16-D16)*24),"")),9))) -> 9 | G16: =IF((OR(C16="Sunday",C16="Saturday")),(IFERROR(((E16-D16)*24),"")),(IF((IFERROR(((E16-D16)*24),""))>9,((IFERROR(((E16-D16)*24),""))-9),0))) -> 0 | H16: =IFERROR((F16+G16),"") -> 9
B17: =IFERROR((IF(MONTH(B16+1)=MONTH(B16),(B16+1),"")),"") -> 44663 | C17: =TEXT(B17,"dddd") -> Tuesday | D17: 0.375 | E17: 0.75 | F17: =IF((OR(C17="Sunday",C17="Saturday")),0,(IF((IFERROR(((E17-D17)*24),""))<=9,(IFERROR(((E17-D17)*24),"")),9))) -> 9 | G17: =IF((OR(C17="Sunday",C17="Saturday")),(IFERROR(((E17-D17)*24),"")),(IF((IFERROR(((E17-D17)*24),""))>9,((IFERROR(((E17-D17)*24),""))-9),0))) -> 0 | H17: =IFERROR((F17+G17),"") -> 9
B18: =IFERROR((IF(MONTH(B17+1)=MONTH(B17),(B17+1),"")),"") -> 44664 | C18: =TEXT(B18,"dddd") -> Wednesday | D18: 0.375 | E18: 0.75 | F18: =IF((OR(C18="Sunday",C18="Saturday")),0,(IF((IFERROR(((E18-D18)*24),""))<=9,(IFERROR(((E18-D18)*24),"")),9))) -> 9 | G18: =IF((OR(C18="Sunday",C18="Saturday")),(IFERROR(((E18-D18)*24),"")),(IF((IFERROR(((E18-D18)*24),""))>9,((IFERROR(((E18-D18)*24),""))-9),0))) -> 0 | H18: =IFERROR((F18+G18),"") -> 9
B19: =IFERROR((IF(MONTH(B18+1)=MONTH(B18),(B18+1),"")),"") -> 44665 | C19: =TEXT(B19,"dddd") -> Thursday | D19: 0.375 | E19: 0.75 | F19: =IF((OR(C19="Sunday",C19="Saturday")),0,(IF((IFERROR(((E19-D19)*24),""))<=9,(IFERROR(((E19-D19)*24),"")),9))) -> 9 | G19: =IF((OR(C19="Sunday",C19="Saturday")),(IFERROR(((E19-D19)*24),"")),(IF((IFERROR(((E19-D19)*24),""))>9,((IFERROR(((E19-D19)*24),""))-9),0))) -> 0 | H19: =IFERROR((F19+G19),"") -> 9
... B36: =IFERROR((IF(MONTH(B35+1)=MONTH(B35),(B35+1),"")),"") | C36: =TEXT(B36,"dddd") | D36: 0.375 | E36: 0.75 | F36: =IF((OR(C36="Sunday",C36="Saturday")),0,(IF((IFERROR(((E36-D36)*24),""))<=9,(IFERROR(((E36-D36)*24),"")),9))) -> 9 | G36: =IF((OR(C36="Sunday",C36="Saturday")),(IFERROR(((E36-D36)*24),"")),(IF((IFERROR(((E36-D36)*24),""))>9,((IFERROR(((E36-D36)*24),""))-9),0))) -> 0 | H36: =IFERROR((F36+G36),"") -> 9

Sheet MAY
B2: =JAN!B2 -> Mr.A | G2: Hari Libur | I2: Akhir Pekan
B4: TANGGAL | C4: HARI | D4: WAKTU KERJA | I4: KEGIATAN PELAYANAN | O4: INFORMASI TOOL | S4: PENYELESAIAN MASALAH
D5: Waktu Mulai (24:00) | E5: Waktu Selesai (24:00) | F5: Jam Kerja | G5: Jam Lembur | H5: Total Jam | I5: ENGINEER 2 | J5: TIPE KONTRAK | K5: ON CALL (YES/NO) | L5: FSR# | M5: SIFAT KEGIATAN | N5: MAT REG# | O5: FAB | P5: MODEL | Q5: NO SERIAL | R5: ID TOOL | S5: KODE ALARM | T5: AKAR MASALAH | U5: AKSI | V5: Parts Replacement (Parts Name) | W5: Parts Replacement (Parts No.) | X5: QTY
B6: 44682 | C6: =TEXT(B6,"dddd") -> Sunday | D6: 0.375 | E6: 0.75 | F6: =IF((OR(C6="Sunday",C6="Saturday")),0,(IF((IFERROR(((E6-D6)*24),""))<=9,(IFERROR(((E6-D6)*24),"")),9))) -> 0 | G6: =IF((OR(C6="Sunday",C6="Saturday")),(IFERROR(((E6-D6)*24),"")),(IF((IFERROR(((E6-D6)*24),""))>9,((IFERROR(((E6-D6)*24),""))-9),0))) -> 9 | H6: =IFERROR((F6+G6),"") -> 9 | J6: Svc Contract
B7: =IFERROR((IF(MONTH(B6+1)=MONTH(B6),(B6+1),"")),"") -> 44683 | C7: =TEXT(B7,"dddd") -> Monday | D7: 0.375 | E7: 0.75 | F7: =IF((OR(C7="Sunday",C7="Saturday")),0,(IF((IFERROR(((E7-D7)*24),""))<=9,(IFERROR(((E7-D7)*24),"")),9))) -> 9 | G7: =IF((OR(C7="Sunday",C7="Saturday")),(IFERROR(((E7-D7)*24),"")),(IF((IFERROR(((E7-D7)*24),""))>9,((IFERROR(((E7-D7)*24),""))-9),0))) -> 0 | H7: =IFERROR((F7+G7),"") -> 9 | K7: Yes
B8: =IFERROR((IF(MONTH(B7+1)=MONTH(B7),(B7+1),"")),"") -> 44684 | C8: =TEXT(B8,"dddd") -> Tuesday | D8: 0.375 | E8: 0.75 | F8: =IF((OR(C8="Sunday",C8="Saturday")),0,(IF((IFERROR(((E8-D8)*24),""))<=9,(IFERROR(((E8-D8)*24),"")),9))) -> 9 | G8: =IF((OR(C8="Sunday",C8="Saturday")),(IFERROR(((E8-D8)*24),"")),(IF((IFERROR(((E8-D8)*24),""))>9,((IFERROR(((E8-D8)*24),""))-9),0))) -> 0 | H8: =IFERROR((F8+G8),"") -> 9
B9: =IFERROR((IF(MONTH(B8+1)=MONTH(B8),(B8+1),"")),"") -> 44685 | C9: =TEXT(B9,"dddd") -> Wednesday | D9: 0.375 | E9: 0.75 | F9: =IF((OR(C9="Sunday",C9="Saturday")),0,(IF((IFERROR(((E9-D9)*24),""))<=9,(IFERROR(((E9-D9)*24),"")),9))) -> 9 | G9: =IF((OR(C9="Sunday",C9="Saturday")),(IFERROR(((E9-D9)*24),"")),(IF((IFERROR(((E9-D9)*24),""))>9,((IFERROR(((E9-D9)*24),""))-9),0))) -> 0 | H9: =IFERROR((F9+G9),"") -> 9
B10: =IFERROR((IF(MONTH(B9+1)=MONTH(B9),(B9+1),"")),"") -> 44686 | C10: =TEXT(B10,"dddd") -> Thursday | D10: 0.375 | E10: 0.75 | F10: =IF((OR(C10="Sunday",C10="Saturday")),0,(IF((IFERROR(((E10-D10)*24),""))<=9,(IFERROR(((E10-D10)*24),"")),9))) -> 9 | G10: =IF((OR(C10="Sunday",C10="Saturday")),(IFERROR(((E10-D10)*24),"")),(IF((IFERROR(((E10-D10)*24),""))>9,((IFERROR(((E10-D10)*24),""))-9),0))) -> 0 | H10: =IFERROR((F10+G10),"") -> 9
B11: =IFERROR((IF(MONTH(B10+1)=MONTH(B10),(B10+1),"")),"") -> 44687 | C11: =TEXT(B11,"dddd") -> Friday | D11: 0.375 | E11: 0.75 | F11: =IF((OR(C11="Sunday",C11="Saturday")),0,(IF((IFERROR(((E11-D11)*24),""))<=9,(IFERROR(((E11-D11)*24),"")),9))) -> 9 | G11: =IF((OR(C11="Sunday",C11="Saturday")),(IFERROR(((E11-D11)*24),"")),(IF((IFERROR(((E11-D11)*24),""))>9,((IFERROR(((E11-D11)*24),""))-9),0))) -> 0 | H11: =IFERROR((F11+G11),"") -> 9
B12: =IFERROR((IF(MONTH(B11+1)=MONTH(B11),(B11+1),"")),"") -> 44688 | C12: =TEXT(B12,"dddd") -> Saturday | D12: 0.375 | E12: 0.75 | F12: =IF((OR(C12="Sunday",C12="Saturday")),0,(IF((IFERROR(((E12-D12)*24),""))<=9,(IFERROR(((E12-D12)*24),"")),9))) -> 0 | G12: =IF((OR(C12="Sunday",C12="Saturday")),(IFERROR(((E12-D12)*24),"")),(IF((IFERROR(((E12-D12)*24),""))>9,((IFERROR(((E12-D12)*24),""))-9),0))) -> 9 | H12: =IFERROR((F12+G12),"") -> 9
B13: =IFERROR((IF(MONTH(B12+1)=MONTH(B12),(B12+1),"")),"") -> 44689 | C13: =TEXT(B13,"dddd") -> Sunday | D13: 0.375 | E13: 0.75 | F13: =IF((OR(C13="Sunday",C13="Saturday")),0,(IF((IFERROR(((E13-D13)*24),""))<=9,(IFERROR(((E13-D13)*24),"")),9))) -> 0 | G13: =IF((OR(C13="Sunday",C13="Saturday")),(IFERROR(((E13-D13)*24),"")),(IF((IFERROR(((E13-D13)*24),""))>9,((IFERROR(((E13-D13)*24),""))-9),0))) -> 9 | H13: =IFERROR((F13+G13),"") -> 9 | J13: Svc Contract
B14: =IFERROR((IF(MONTH(B13+1)=MONTH(B13),(B13+1),"")),"") -> 44690 | C14: =TEXT(B14,"dddd") -> Monday | D14: 0.375 | E14: 0.75 | F14: =IF((OR(C14="Sunday",C14="Saturday")),0,(IF((IFERROR(((E14-D14)*24),""))<=9,(IFERROR(((E14-D14)*24),"")),9))) -> 9 | G14: =IF((OR(C14="Sunday",C14="Saturday")),(IFERROR(((E14-D14)*24),"")),(IF((IFERROR(((E14-D14)*24),""))>9,((IFERROR(((E14-D14)*24),""))-9),0))) -> 0 | H14: =IFERROR((F14+G14),"") -> 9
B15: =IFERROR((IF(MONTH(B14+1)=MONTH(B14),(B14+1),"")),"") -> 44691 | C15: =TEXT(B15,"dddd") -> Tuesday | D15: 0.375 | E15: 0.75 | F15: =IF((OR(C15="Sunday",C15="Saturday")),0,(IF((IFERROR(((E15-D15)*24),""))<=9,(IFERROR(((E15-D15)*24),"")),9))) -> 9 | G15: =IF((OR(C15="Sunday",C15="Saturday")),(IFERROR(((E15-D15)*24),"")),(IF((IFERROR(((E15-D15)*24),""))>9,((IFERROR(((E15-D15)*24),""))-9),0))) -> 0 | H15: =IFERROR((F15+G15),"") -> 9
B16: =IFERROR((IF(MONTH(B15+1)=MONTH(B15),(B15+1),"")),"") -> 44692 | C16: =TEXT(B16,"dddd") -> Wednesday | D16: 0.375 | E16: 0.75 | F16: =IF((OR(C16="Sunday",C16="Saturday")),0,(IF((IFERROR(((E16-D16)*24),""))<=9,(IFERROR(((E16-D16)*24),"")),9))) -> 9 | G16: =IF((OR(C16="Sunday",C16="Saturday")),(IFERROR(((E16-D16)*24),"")),(IF((IFERROR(((E16-D16)*24),""))>9,((IFERROR(((E16-D16)*24),""))-9),0))) -> 0 | H16: =IFERROR((F16+G16),"") -> 9
B17: =IFERROR((IF(MONTH(B16+1)=MONTH(B16),(B16+1),"")),"") -> 44693 | C17: =TEXT(B17,"dddd") -> Thursday | D17: 0.375 | E17: 0.75 | F17: =IF((OR(C17="Sunday",C17="Saturday")),0,(IF((IFERROR(((E17-D17)*24),""))<=9,(IFERROR(((E17-D17)*24),"")),9))) -> 9 | G17: =IF((OR(C17="Sunday",C17="Saturday")),(IFERROR(((E17-D17)*24),"")),(IF((IFERROR(((E17-D17)*24),""))>9,((IFERROR(((E17-D17)*24),""))-9),0))) -> 0 | H17: =IFERROR((F17+G17),"") -> 9
B18: =IFERROR((IF(MONTH(B17+1)=MONTH(B17),(B17+1),"")),"") -> 44694 | C18: =TEXT(B18,"dddd") -> Friday | D18: 0.375 | E18: 0.75 | F18: =IF((OR(C18="Sunday",C18="Saturday")),0,(IF((IFERROR(((E18-D18)*24),""))<=9,(IFERROR(((E18-D18)*24),"")),9))) -> 9 | G18: =IF((OR(C18="Sunday",C18="Saturday")),(IFERROR(((E18-D18)*24),"")),(IF((IFERROR(((E18-D18)*24),""))>9,((IFERROR(((E18-D18)*24),""))-9),0))) -> 0 | H18: =IFERROR((F18+G18),"") -> 9
B19: =IFERROR((IF(MONTH(B18+1)=MONTH(B18),(B18+1),"")),"") -> 44695 | C19: =TEXT(B19,"dddd") -> Saturday | D19: 0.375 | E19: 0.75 | F19: =IF((OR(C19="Sunday",C19="Saturday")),0,(IF((IFERROR(((E19-D19)*24),""))<=9,(IFERROR(((E19-D19)*24),"")),9))) -> 0 | G19: =IF((OR(C19="Sunday",C19="Saturday")),(IFERROR(((E19-D19)*24),"")),(IF((IFERROR(((E19-D19)*24),""))>9,((IFERROR(((E19-D19)*24),""))-9),0))) -> 9 | H19: =IFERROR((F19+G19),"") -> 9
B20: =IFERROR((IF(MONTH(B19+1)=MONTH(B19),(B19+1),"")),"") -> 44696 | C20: =TEXT(B20,"dddd") -> Sunday | D20: 0.375 | E20: 0.75 | F20: =IF((OR(C20="Sunday",C20="Saturday")),0,(IF((IFERROR(((E20-D20)*24),""))<=9,(IFERROR(((E20-D20)*24),"")),9))) -> 0 | G20: =IF((OR(C20="Sunday",C20="Saturday")),(IFERROR(((E20-D20)*24),"")),(IF((IFERROR(((E20-D20)*24),""))>9,((IFERROR(((E20-D20)*24),""))-9),0))) -> 9 | H20: =IFERROR((F20+G20),"") -> 9
B21: =IFERROR((IF(MONTH(B20+1)=MONTH(B20),(B20+1),"")),"") -> 44697 | C21: =TEXT(B21,"dddd") -> Monday | D21: 0.375 | E21: 0.75 | F21: =IF((OR(C21="Sunday",C21="Saturday")),0,(IF((IFERROR(((E21-D21)*24),""))<=9,(IFERROR(((E21-D21)*24),"")),9))) -> 9 | G21: =IF((OR(C21="Sunday",C21="Saturday")),(IFERROR(((E21-D21)*24),"")),(IF((IFERROR(((E21-D21)*24),""))>9,((IFERROR(((E21-D21)*24),""))-9),0))) -> 0 | H21: =IFERROR((F21+G21),"") -> 9
B22: =IFERROR((IF(MONTH(B21+1)=MONTH(B21),(B21+1),"")),"") -> 44698 | C22: =TEXT(B22,"dddd") -> Tuesday | D22: 0.375 | E22: 0.75 | F22: =IF((OR(C22="Sunday",C22="Saturday")),0,(IF((IFERROR(((E22-D22)*24),""))<=9,(IFERROR(((E22-D22)*24),"")),9))) -> 9 | G22: =IF((OR(C22="Sunday",C22="Saturday")),(IFERROR(((E22-D22)*24),"")),(IF((IFERROR(((E22-D22)*24),""))>9,((IFERROR(((E22-D22)*24),""))-9),0))) -> 0 | H22: =IFERROR((F22+G22),"") -> 9
B23: =IFERROR((IF(MONTH(B22+1)=MONTH(B22),(B22+1),"")),"") -> 44699 | C23: =TEXT(B23,"dddd") -> Wednesday | D23: 0.375 | E23: 0.75 | F23: =IF((OR(C23="Sunday",C23="Saturday")),0,(IF((IFERROR(((E23-D23)*24),""))<=9,(IFERROR(((E23-D23)*24),"")),9))) -> 9 | G23: =IF((OR(C23="Sunday",C23="Saturday")),(IFERROR(((E23-D23)*24),"")),(IF((IFERROR(((E23-D23)*24),""))>9,((IFERROR(((E23-D23)*24),""))-9),0))) -> 0 | H23: =IFERROR((F23+G23),"") -> 9
B24: =IFERROR((IF(MONTH(B23+1)=MONTH(B23),(B23+1),"")),"") -> 44700 | C24: =TEXT(B24,"dddd") -> Thursday | D24: 0.375 | E24: 0.75 | F24: =IF((OR(C24="Sunday",C24="Saturday")),0,(IF((IFERROR(((E24-D24)*24),""))<=9,(IFERROR(((E24-D24)*24),"")),9))) -> 9 | G24: =IF((OR(C24="Sunday",C24="Saturday")),(IFERROR(((E24-D24)*24),"")),(IF((IFERROR(((E24-D24)*24),""))>9,((IFERROR(((E24-D24)*24),""))-9),0))) -> 0 | H24: =IFERROR((F24+G24),"") -> 9
B25: =IFERROR((IF(MONTH(B24+1)=MONTH(B24),(B24+1),"")),"") -> 44701 | C25: =TEXT(B25,"dddd") -> Friday | D25: 0.375 | E25: 0.75 | F25: =IF((OR(C25="Sunday",C25="Saturday")),0,(IF((IFERROR(((E25-D25)*24),""))<=9,(IFERROR(((E25-D25)*24),"")),9))) -> 9 | G25: =IF((OR(C25="Sunday",C25="Saturday")),(IFERROR(((E25-D25)*24),"")),(IF((IFERROR(((E25-D25)*24),""))>9,((IFERROR(((E25-D25)*24),""))-9),0))) -> 0 | H25: =IFERROR((F25+G25),"") -> 9
... B36: =IFERROR((IF(MONTH(B35+1)=MONTH(B35),(B35+1),"")),"") -> 44712 | C36: =TEXT(B36,"dddd") -> Tuesday | D36: 0.375 | E36: 0.75 | F36: =IF((OR(C36="Sunday",C36="Saturday")),0,(IF((IFERROR(((E36-D36)*24),""))<=9,(IFERROR(((E36-D36)*24),"")),9))) -> 9 | G36: =IF((OR(C36="Sunday",C36="Saturday")),(IFERROR(((E36-D36)*24),"")),(IF((IFERROR(((E36-D36)*24),""))>9,((IFERROR(((E36-D36)*24),""))-9),0))) -> 0 | H36: =IFERROR((F36+G36),"") -> 9

Sheet JUN
B2: =JAN!B2 -> Mr.A | G2: Hari Libur | I2: Akhir Pekan
B4: TANGGAL | C4: HARI | D4: WAKTU KERJA | I4: KEGIATAN PELAYANAN | O4: INFORMASI TOOL | S4: PENYELESAIAN MASALAH
D5: Waktu Mulai (24:00) | E5: Waktu Selesai (24:00) | F5: Jam Kerja | G5: Jam Lembur | H5: Total Jam | I5: ENGINEER 2 | J5: TIPE KONTRAK | K5: ON CALL (YES/NO) | L5: FSR# | M5: SIFAT KEGIATAN | N5: MAT REG# | O5: FAB | P5: MODEL | Q5: NO SERIAL | R5: ID TOOL | S5: KODE ALARM | T5: AKAR MASALAH | U5: AKSI | V5: Parts Replacement (Parts Name) | W5: Parts Replacement (Parts No.) | X5: QTY
B6: 44713 | C6: =TEXT(B6,"dddd") -> Wednesday | D6: 0.375 | E6: 0.75 | F6: =IF((OR(C6="Sunday",C6="Saturday")),0,(IF((IFERROR(((E6-D6)*24),""))<=9,(IFERROR(((E6-D6)*24),"")),9))) -> 9 | G6: =IF((OR(C6="Sunday",C6="Saturday")),(IFERROR(((E6-D6)*24),"")),(IF((IFERROR(((E6-D6)*24),""))>9,((IFERROR(((E6-D6)*24),""))-9),0))) -> 0 | H6: =IFERROR((F6+G6),"") -> 9 | J6: Svc Contract
B7: =IFERROR((IF(MONTH(B6+1)=MONTH(B6),(B6+1),"")),"") -> 44714 | C7: =TEXT(B7,"dddd") -> Thursday | D7: 0.375 | E7: 0.75 | F7: =IF((OR(C7="Sunday",C7="Saturday")),0,(IF((IFERROR(((E7-D7)*24),""))<=9,(IFERROR(((E7-D7)*24),"")),9))) -> 9 | G7: =IF((OR(C7="Sunday",C7="Saturday")),(IFERROR(((E7-D7)*24),"")),(IF((IFERROR(((E7-D7)*24),""))>9,((IFERROR(((E7-D7)*24),""))-9),0))) -> 0 | H7: =IFERROR((F7+G7),"") -> 9 | K7: Yes
B8: =IFERROR((IF(MONTH(B7+1)=MONTH(B7),(B7+1),"")),"") -> 44715 | C8: =TEXT(B8,"dddd") -> Friday | D8: 0.375 | E8: 0.75 | F8: =IF((OR(C8="Sunday",C8="Saturday")),0,(IF((IFERROR(((E8-D8)*24),""))<=9,(IFERROR(((E8-D8)*24),"")),9))) -> 9 | G8: =IF((OR(C8="Sunday",C8="Saturday")),(IFERROR(((E8-D8)*24),"")),(IF((IFERROR(((E8-D8)*24),""))>9,((IFERROR(((E8-D8)*24),""))-9),0))) -> 0 | H8: =IFERROR((F8+G8),"") -> 9
B9: =IFERROR((IF(MONTH(B8+1)=MONTH(B8),(B8+1),"")),"") -> 44716 | C9: =TEXT(B9,"dddd") -> Saturday | D9: 0.375 | E9: 0.75 | F9: =IF((OR(C9="Sunday",C9="Saturday")),0,(IF((IFERROR(((E9-D9)*24),""))<=9,(IFERROR(((E9-D9)*24),"")),9))) -> 0 | G9: =IF((OR(C9="Sunday",C9="Saturday")),(IFERROR(((E9-D9)*24),"")),(IF((IFERROR(((E9-D9)*24),""))>9,((IFERROR(((E9-D9)*24),""))-9),0))) -> 9 | H9: =IFERROR((F9+G9),"") -> 9
B10: =IFERROR((IF(MONTH(B9+1)=MONTH(B9),(B9+1),"")),"") -> 44717 | C10: =TEXT(B10,"dddd") -> Sunday | D10: 0.375 | E10: 0.75 | F10: =IF((OR(C10="Sunday",C10="Saturday")),0,(IF((IFERROR(((E10-D10)*24),""))<=9,(IFERROR(((E10-D10)*24),"")),9))) -> 0 | G10: =IF((OR(C10="Sunday",C10="Saturday")),(IFERROR(((E10-D10)*24),"")),(IF((IFERROR(((E10-D10)*24),""))>9,((IFERROR(((E10-D10)*24),""))-9),0))) -> 9 | H10: =IFERROR((F10+G10),"") -> 9
B11: =IFERROR((IF(MONTH(B10+1)=MONTH(B10),(B10+1),"")),"") -> 44718 | C11: =TEXT(B11,"dddd") -> Monday | D11: 0.375 | E11: 0.75 | F11: =IF((OR(C11="Sunday",C11="Saturday")),0,(IF((IFERROR(((E11-D11)*24),""))<=9,(IFERROR(((E11-D11)*24),"")),9))) -> 9 | G11: =IF((OR(C11="Sunday",C11="Saturday")),(IFERROR(((E11-D11)*24),"")),(IF((IFERROR(((E11-D11)*24),""))>9,((IFERROR(((E11-D11)*24),""))-9),0))) -> 0 | H11: =IFERROR((F11+G11),"") -> 9
B12: =IFERROR((IF(MONTH(B11+1)=MONTH(B11),(B11+1),"")),"") -> 44719 | C12: =TEXT(B12,"dddd") -> Tuesday | D12: 0.375 | E12: 0.75 | F12: =IF((OR(C12="Sunday",C12="Saturday")),0,(IF((IFERROR(((E12-D12)*24),""))<=9,(IFERROR(((E12-D12)*24),"")),9))) -> 9 | G12: =IF((OR(C12="Sunday",C12="Saturday")),(IFERROR(((E12-D12)*24),"")),(IF((IFERROR(((E12-D12)*24),""))>9,((IFERROR(((E12-D12)*24),""))-9),0))) -> 0 | H12: =IFERROR((F12+G12),"") -> 9
B13: =IFERROR((IF(MONTH(B12+1)=MONTH(B12),(B12+1),"")),"") -> 44720 | C13: =TEXT(B13,"dddd") -> Wednesday | D13: 0.375 | E13: 0.75 | F13: =IF((OR(C13="Sunday",C13="Saturday")),0,(IF((IFERROR(((E13-D13)*24),""))<=9,(IFERROR(((E13-D13)*24),"")),9))) -> 9 | G13: =IF((OR(C13="Sunday",C13="Saturday")),(IFERROR(((E13-D13)*24),"")),(IF((IFERROR(((E13-D13)*24),""))>9,((IFERROR(((E13-D13)*24),""))-9),0))) -> 0 | H13: =IFERROR((F13+G13),"") -> 9
B14: =IFERROR((IF(MONTH(B13+1)=MONTH(B13),(B13+1),"")),"") -> 44721 | C14: =TEXT(B14,"dddd") -> Thursday | D14: 0.375 | E14: 0.75 | F14: =IF((OR(C14="Sunday",C14="Saturday")),0,(IF((IFERROR(((E14-D14)*24),""))<=9,(IFERROR(((E14-D14)*24),"")),9))) -> 9 | G14: =IF((OR(C14="Sunday",C14="Saturday")),(IFERROR(((E14-D14)*24),"")),(IF((IFERROR(((E14-D14)*24),""))>9,((IFERROR(((E14-D14)*24),""))-9),0))) -> 0 | H14: =IFERROR((F14+G14),"") -> 9
B15: =IFERROR((IF(MONTH(B14+1)=MONTH(B14),(B14+1),"")),"") -> 44722 | C15: =TEXT(B15,"dddd") -> Friday | D15: 0.375 | E15: 0.75 | F15: =IF((OR(C15="Sunday",C15="Saturday")),0,(IF((IFERROR(((E15-D15)*24),""))<=9,(IFERROR(((E15-D15)*24),"")),9))) -> 9 | G15: =IF((OR(C15="Sunday",C15="Saturday")),(IFERROR(((E15-D15)*24),"")),(IF((IFERROR(((E15-D15)*24),""))>9,((IFERROR(((E15-D15)*24),""))-9),0))) -> 0 | H15: =IFERROR((F15+G15),"") -> 9
B16: =IFERROR((IF(MONTH(B15+1)=MONTH(B15),(B15+1),"")),"") -> 44723 | C16: =TEXT(B16,"dddd") -> Saturday | D16: 0.375 | E16: 0.75 | F16: =IF((OR(C16="Sunday",C16="Saturday")),0,(IF((IFERROR(((E16-D16)*24),""))<=9,(IFERROR(((E16-D16)*24),"")),9))) -> 0 | G16: =IF((OR(C16="Sunday",C16="Saturday")),(IFERROR(((E16-D16)*24),"")),(IF((IFERROR(((E16-D16)*24),""))>9,((IFERROR(((E16-D16)*24),""))-9),0))) -> 9 | H16: =IFERROR((F16+G16),"") -> 9
B17: =IFERROR((IF(MONTH(B16+1)=MONTH(B16),(B16+1),"")),"") -> 44724 | C17: =TEXT(B17,"dddd") -> Sunday | D17: 0.375 | E17: 0.75 | F17: =IF((OR(C17="Sunday",C17="Saturday")),0,(IF((IFERROR(((E17-D17)*24),""))<=9,(IFERROR(((E17-D17)*24),"")),9))) -> 0 | G17: =IF((OR(C17="Sunday",C17="Saturday")),(IFERROR(((E17-D17)*24),"")),(IF((IFERROR(((E17-D17)*24),""))>9,((IFERROR(((E17-D17)*24),""))-9),0))) -> 9 | H17: =IFERROR((F17+G17),"") -> 9
B18: =IFERROR((IF(MONTH(B17+1)=MONTH(B17),(B17+1),"")),"") -> 44725 | C18: =TEXT(B18,"dddd") -> Monday | D18: 0.375 | E18: 0.75 | F18: =IF((OR(C18="Sunday",C18="Saturday")),0,(IF((IFERROR(((E18-D18)*24),""))<=9,(IFERROR(((E18-D18)*24),"")),9))) -> 9 | G18: =IF((OR(C18="Sunday",C18="Saturday")),(IFERROR(((E18-D18)*24),"")),(IF((IFERROR(((E18-D18)*24),""))>9,((IFERROR(((E18-D18)*24),""))-9),0))) -> 0 | H18: =IFERROR((F18+G18),"") -> 9
B19: =IFERROR((IF(MONTH(B18+1)=MONTH(B18),(B18+1),"")),"") -> 44726 | C19: =TEXT(B19,"dddd") -> Tuesday | D19: 0.375 | E19: 0.75 | F19: =IF((OR(C19="Sunday",C19="Saturday")),0,(IF((IFERROR(((E19-D19)*24),""))<=9,(IFERROR(((E19-D19)*24),"")),9))) -> 9 | G19: =IF((OR(C19="Sunday",C19="Saturday")),(IFERROR(((E19-D19)*24),"")),(IF((IFERROR(((E19-D19)*24),""))>9,((IFERROR(((E19-D19)*24),""))-9),0))) -> 0 | H19: =IFERROR((F19+G19),"") -> 9
... B36: =IFERROR((IF(MONTH(B35+1)=MONTH(B35),(B35+1),"")),"") | C36: =TEXT(B36,"dddd") | D36: 0.375 | E36: 0.75 | F36: =IF((OR(C36="Sunday",C36="Saturday")),0,(IF((IFERROR(((E36-D36)*24),""))<=9,(IFERROR(((E36-D36)*24),"")),9))) -> 9 | G36: =IF((OR(C36="Sunday",C36="Saturday")),(IFERROR(((E36-D36)*24),"")),(IF((IFERROR(((E36-D36)*24),""))>9,((IFERROR(((E36-D36)*24),""))-9),0))) -> 0 | H36: =IFERROR((F36+G36),"") -> 9

Sheet JUL
B2: =JAN!B2 -> Mr.A | G2: Hari Libur | I2: Akhir Pekan
B4: TANGGAL | C4: HARI | D4: WAKTU KERJA | I4: KEGIATAN PELAYANAN | O4: INFORMASI TOOL | S4: PENYELESAIAN MASALAH
D5: Waktu Mulai (24:00) | E5: Waktu Selesai (24:00) | F5: Jam Kerja | G5: Jam Lembur | H5: Total Jam | I5: ENGINEER 2 | J5: TIPE KONTRAK | K5: ON CALL (YES/NO) | L5: FSR# | M5: SIFAT KEGIATAN | N5: MAT REG# | O5: FAB | P5: MODEL | Q5: NO SERIAL | R5: ID TOOL | S5: KODE ALARM | T5: AKAR MASALAH | U5: AKSI | V5: Parts Replacement (Parts Name) | W5: Parts Replacement (Parts No.) | X5: QTY
B6: 44743 | C6: =TEXT(B6,"dddd") -> Friday | D6: 0.375 | E6: 0.75 | F6: =IF((OR(C6="Sunday",C6="Saturday")),0,(IF((IFERROR(((E6-D6)*24),""))<=9,(IFERROR(((E6-D6)*24),"")),9))) -> 9 | G6: =IF((OR(C6="Sunday",C6="Saturday")),(IFERROR(((E6-D6)*24),"")),(IF((IFERROR(((E6-D6)*24),""))>9,((IFERROR(((E6-D6)*24),""))-9),0))) -> 0 | H6: =IFERROR((F6+G6),"") -> 9 | J6: Svc Contract
B7: =IFERROR((IF(MONTH(B6+1)=MONTH(B6),(B6+1),"")),"") -> 44744 | C7: =TEXT(B7,"dddd") -> Saturday | D7: 0.375 | E7: 0.75 | F7: =IF((OR(C7="Sunday",C7="Saturday")),0,(IF((IFERROR(((E7-D7)*24),""))<=9,(IFERROR(((E7-D7)*24),"")),9))) -> 0 | G7: =IF((OR(C7="Sunday",C7="Saturday")),(IFERROR(((E7-D7)*24),"")),(IF((IFERROR(((E7-D7)*24),""))>9,((IFERROR(((E7-D7)*24),""))-9),0))) -> 9 | H7: =IFERROR((F7+G7),"") -> 9 | K7: Yes
B8: =IFERROR((IF(MONTH(B7+1)=MONTH(B7),(B7+1),"")),"") -> 44745 | C8: =TEXT(B8,"dddd") -> Sunday | D8: 0.375 | E8: 0.75 | F8: =IF((OR(C8="Sunday",C8="Saturday")),0,(IF((IFERROR(((E8-D8)*24),""))<=9,(IFERROR(((E8-D8)*24),"")),9))) -> 0 | G8: =IF((OR(C8="Sunday",C8="Saturday")),(IFERROR(((E8-D8)*24),"")),(IF((IFERROR(((E8-D8)*24),""))>9,((IFERROR(((E8-D8)*24),""))-9),0))) -> 9 | H8: =IFERROR((F8+G8),"") -> 9
B9: =IFERROR((IF(MONTH(B8+1)=MONTH(B8),(B8+1),"")),"") -> 44746 | C9: =TEXT(B9,"dddd") -> Monday | D9: 0.375 | E9: 0.75 | F9: =IF((OR(C9="Sunday",C9="Saturday")),0,(IF((IFERROR(((E9-D9)*24),""))<=9,(IFERROR(((E9-D9)*24),"")),9))) -> 9 | G9: =IF((OR(C9="Sunday",C9="Saturday")),(IFERROR(((E9-D9)*24),"")),(IF((IFERROR(((E9-D9)*24),""))>9,((IFERROR(((E9-D9)*24),""))-9),0))) -> 0 | H9: =IFERROR((F9+G9),"") -> 9
B10: =IFERROR((IF(MONTH(B9+1)=MONTH(B9),(B9+1),"")),"") -> 44747 | C10: =TEXT(B10,"dddd") -> Tuesday | D10: 0.375 | E10: 0.75 | F10: =IF((OR(C10="Sunday",C10="Saturday")),0,(IF((IFERROR(((E10-D10)*24),""))<=9,(IFERROR(((E10-D10)*24),"")),9))) -> 9 | G10: =IF((OR(C10="Sunday",C10="Saturday")),(IFERROR(((E10-D10)*24),"")),(IF((IFERROR(((E10-D10)*24),""))>9,((IFERROR(((E10-D10)*24),""))-9),0))) -> 0 | H10: =IFERROR((F10+G10),"") -> 9
B11: =IFERROR((IF(MONTH(B10+1)=MONTH(B10),(B10+1),"")),"") -> 44748 | C11: =TEXT(B11,"dddd") -> Wednesday | D11: 0.375 | E11: 0.75 | F11: =IF((OR(C11="Sunday",C11="Saturday")),0,(IF((IFERROR(((E11-D11)*24),""))<=9,(IFERROR(((E11-D11)*24),"")),9))) -> 9 | G11: =IF((OR(C11="Sunday",C11="Saturday")),(IFERROR(((E11-D11)*24),"")),(IF((IFERROR(((E11-D11)*24),""))>9,((IFERROR(((E11-D11)*24),""))-9),0))) -> 0 | H11: =IFERROR((F11+G11),"") -> 9
B12: =IFERROR((IF(MONTH(B11+1)=MONTH(B11),(B11+1),"")),"") -> 44749 | C12: =TEXT(B12,"dddd") -> Thursday | D12: 0.375 | E12: 0.75 | F12: =IF((OR(C12="Sunday",C12="Saturday")),0,(IF((IFERROR(((E12-D12)*24),""))<=9,(IFERROR(((E12-D12)*24),"")),9))) -> 9 | G12: =IF((OR(C12="Sunday",C12="Saturday")),(IFERROR(((E12-D12)*24),"")),(IF((IFERROR(((E12-D12)*24),""))>9,((IFERROR(((E12-D12)*24),""))-9),0))) -> 0 | H12: =IFERROR((F12+G12),"") -> 9
B13: =IFERROR((IF(MONTH(B12+1)=MONTH(B12),(B12+1),"")),"") -> 44750 | C13: =TEXT(B13,"dddd") -> Friday | D13: 0.375 | E13: 0.75 | F13: =IF((OR(C13="Sunday",C13="Saturday")),0,(IF((IFERROR(((E13-D13)*24),""))<=9,(IFERROR(((E13-D13)*24),"")),9))) -> 9 | G13: =IF((OR(C13="Sunday",C13="Saturday")),(IFERROR(((E13-D13)*24),"")),(IF((IFERROR(((E13-D13)*24),""))>9,((IFERROR(((E13-D13)*24),""))-9),0))) -> 0 | H13: =IFERROR((F13+G13),"") -> 9
B14: =IFERROR((IF(MONTH(B13+1)=MONTH(B13),(B13+1),"")),"") -> 44751 | C14: =TEXT(B14,"dddd") -> Saturday | D14: 0.375 | E14: 0.75 | F14: =IF((OR(C14="Sunday",C14="Saturday")),0,(IF((IFERROR(((E14-D14)*24),""))<=9,(IFERROR(((E14-D14)*24),"")),9))) -> 0 | G14: =IF((OR(C14="Sunday",C14="Saturday")),(IFERROR(((E14-D14)*24),"")),(IF((IFERROR(((E14-D14)*24),""))>9,((IFERROR(((E14-D14)*24),""))-9),0))) -> 9 | H14: =IFERROR((F14+G14),"") -> 9
B15: =IFERROR((IF(MONTH(B14+1)=MONTH(B14),(B14+1),"")),"") -> 44752 | C15: =TEXT(B15,"dddd") -> Sunday | D15: 0.375 | E15: 0.75 | F15: =IF((OR(C15="Sunday",C15="Saturday")),0,(IF((IFERROR(((E15-D15)*24),""))<=9,(IFERROR(((E15-D15)*24),"")),9))) -> 0 | G15: =IF((OR(C15="Sunday",C15="Saturday")),(IFERROR(((E15-D15)*24),"")),(IF((IFERROR(((E15-D15)*24),""))>9,((IFERROR(((E15-D15)*24),""))-9),0))) -> 9 | H15: =IFERROR((F15+G15),"") -> 9
B16: =IFERROR((IF(MONTH(B15+1)=MONTH(B15),(B15+1),"")),"") -> 44753 | C16: =TEXT(B16,"dddd") -> Monday | D16: 0.375 | E16: 0.75 | F16: =IF((OR(C16="Sunday",C16="Saturday")),0,(IF((IFERROR(((E16-D16)*24),""))<=9,(IFERROR(((E16-D16)*24),"")),9))) -> 9 | G16: =IF((OR(C16="Sunday",C16="Saturday")),(IFERROR(((E16-D16)*24),"")),(IF((IFERROR(((E16-D16)*24),""))>9,((IFERROR(((E16-D16)*24),""))-9),0))) -> 0 | H16: =IFERROR((F16+G16),"") -> 9
B17: =IFERROR((IF(MONTH(B16+1)=MONTH(B16),(B16+1),"")),"") -> 44754 | C17: =TEXT(B17,"dddd") -> Tuesday | D17: 0.375 | E17: 0.75 | F17: =IF((OR(C17="Sunday",C17="Saturday")),0,(IF((IFERROR(((E17-D17)*24),""))<=9,(IFERROR(((E17-D17)*24),"")),9))) -> 9 | G17: =IF((OR(C17="Sunday",C17="Saturday")),(IFERROR(((E17-D17)*24),"")),(IF((IFERROR(((E17-D17)*24),""))>9,((IFERROR(((E17-D17)*24),""))-9),0))) -> 0 | H17: =IFERROR((F17+G17),"") -> 9
B18: =IFERROR((IF(MONTH(B17+1)=MONTH(B17),(B17+1),"")),"") -> 44755 | C18: =TEXT(B18,"dddd") -> Wednesday | D18: 0.375 | E18: 0.75 | F18: =IF((OR(C18="Sunday",C18="Saturday")),0,(IF((IFERROR(((E18-D18)*24),""))<=9,(IFERROR(((E18-D18)*24),"")),9))) -> 9 | G18: =IF((OR(C18="Sunday",C18="Saturday")),(IFERROR(((E18-D18)*24),"")),(IF((IFERROR(((E18-D18)*24),""))>9,((IFERROR(((E18-D18)*24),""))-9),0))) -> 0 | H18: =IFERROR((F18+G18),"") -> 9
B19: =IFERROR((IF(MONTH(B18+1)=MONTH(B18),(B18+1),"")),"") -> 44756 | C19: =TEXT(B19,"dddd") -> Thursday | D19: 0.375 | E19: 0.75 | F19: =IF((OR(C19="Sunday",C19="Saturday")),0,(IF((IFERROR(((E19-D19)*24),""))<=9,(IFERROR(((E19-D19)*24),"")),9))) -> 9 | G19: =IF((OR(C19="Sunday",C19="Saturday")),(IFERROR(((E19-D19)*24),"")),(IF((IFERROR(((E19-D19)*24),""))>9,((IFERROR(((E19-D19)*24),""))-9),0))) -> 0 | H19: =IFERROR((F19+G19),"") -> 9
... B36: =IFERROR((IF(MONTH(B35+1)=MONTH(B35),(B35+1),"")),"") -> 44773 | C36: =TEXT(B36,"dddd") -> Sunday | D36: 0.375 | E36: 0.75 | F36: =IF((OR(C36="Sunday",C36="Saturday")),0,(IF((IFERROR(((E36-D36)*24),""))<=9,(IFERROR(((E36-D36)*24),"")),9))) -> 0 | G36: =IF((OR(C36="Sunday",C36="Saturday")),(IFERROR(((E36-D36)*24),"")),(IF((IFERROR(((E36-D36)*24),""))>9,((IFERROR(((E36-D36)*24),""))-9),0))) -> 9 | H36: =IFERROR((F36+G36),"") -> 9

Sheet AUG
B2: =JAN!B2 -> Mr.A | G2: Hari Libur | I2: Akhir Pekan
B4: TANGGAL | C4: HARI | D4: WAKTU KERJA | I4: KEGIATAN PELAYANAN | O4: INFORMASI TOOL | S4: PENYELESAIAN MASALAH
D5: Waktu Mulai (24:00) | E5: Waktu Selesai (24:00) | F5: Jam Kerja | G5: Jam Lembur | H5: Total Jam | I5: ENGINEER 2 | J5: TIPE KONTRAK | K5: ON CALL (YES/NO) | L5: FSR# | M5: SIFAT KEGIATAN | N5: MAT REG# | O5: FAB | P5: MODEL | Q5: NO SERIAL | R5: ID TOOL | S5: KODE ALARM | T5: AKAR MASALAH | U5: AKSI | V5: Parts Replacement (Parts Name) | W5: Parts Replacement (Parts No.) | X5: QTY
B6: 44774 | C6: =TEXT(B6,"dddd") -> Monday | D6: 0.375 | E6: 0.75 | F6: =IF((OR(C6="Sunday",C6="Saturday")),0,(IF((IFERROR(((E6-D6)*24),""))<=9,(IFERROR(((E6-D6)*24),"")),9))) -> 9 | G6: =IF((OR(C6="Sunday",C6="Saturday")),(IFERROR(((E6-D6)*24),"")),(IF((IFERROR(((E6-D6)*24),""))>9,((IFERROR(((E6-D6)*24),""))-9),0))) -> 0 | H6: =IFERROR((F6+G6),"") -> 9 | J6: Svc Contract
B7: =IFERROR((IF(MONTH(B6+1)=MONTH(B6),(B6+1),"")),"") -> 44775 | C7: =TEXT(B7,"dddd") -> Tuesday | D7: 0.375 | E7: 0.75 | F7: =IF((OR(C7="Sunday",C7="Saturday")),0,(IF((IFERROR(((E7-D7)*24),""))<=9,(IFERROR(((E7-D7)*24),"")),9))) -> 9 | G7: =IF((OR(C7="Sunday",C7="Saturday")),(IFERROR(((E7-D7)*24),"")),(IF((IFERROR(((E7-D7)*24),""))>9,((IFERROR(((E7-D7)*24),""))-9),0))) -> 0 | H7: =IFERROR((F7+G7),"") -> 9 | K7: Yes
B8: =IFERROR((IF(MONTH(B7+1)=MONTH(B7),(B7+1),"")),"") -> 44776 | C8: =TEXT(B8,"dddd") -> Wednesday | D8: 0.375 | E8: 0.75 | F8: =IF((OR(C8="Sunday",C8="Saturday")),0,(IF((IFERROR(((E8-D8)*24),""))<=9,(IFERROR(((E8-D8)*24),"")),9))) -> 9 | G8: =IF((OR(C8="Sunday",C8="Saturday")),(IFERROR(((E8-D8)*24),"")),(IF((IFERROR(((E8-D8)*24),""))>9,((IFERROR(((E8-D8)*24),""))-9),0))) -> 0 | H8: =IFERROR((F8+G8),"") -> 9
B9: =IFERROR((IF(MONTH(B8+1)=MONTH(B8),(B8+1),"")),"") -> 44777 | C9: =TEXT(B9,"dddd") -> Thursday | D9: 0.375 | E9: 0.75 | F9: =IF((OR(C9="Sunday",C9="Saturday")),0,(IF((IFERROR(((E9-D9)*24),""))<=9,(IFERROR(((E9-D9)*24),"")),9))) -> 9 | G9: =IF((OR(C9="Sunday",C9="Saturday")),(IFERROR(((E9-D9)*24),"")),(IF((IFERROR(((E9-D9)*24),""))>9,((IFERROR(((E9-D9)*24),""))-9),0))) -> 0 | H9: =IFERROR((F9+G9),"") -> 9
B10: =IFERROR((IF(MONTH(B9+1)=MONTH(B9),(B9+1),"")),"") -> 44778 | C10: =TEXT(B10,"dddd") -> Friday | D10: 0.375 | E10: 0.75 | F10: =IF((OR(C10="Sunday",C10="Saturday")),0,(IF((IFERROR(((E10-D10)*24),""))<=9,(IFERROR(((E10-D10)*24),"")),9))) -> 9 | G10: =IF((OR(C10="Sunday",C10="Saturday")),(IFERROR(((E10-D10)*24),"")),(IF((IFERROR(((E10-D10)*24),""))>9,((IFERROR(((E10-D10)*24),""))-9),0))) -> 0 | H10: =IFERROR((F10+G10),"") -> 9
B11: =IFERROR((IF(MONTH(B10+1)=MONTH(B10),(B10+1),"")),"") -> 44779 | C11: =TEXT(B11,"dddd") -> Saturday | D11: 0.375 | E11: 0.75 | F11: =IF((OR(C11="Sunday",C11="Saturday")),0,(IF((IFERROR(((E11-D11)*24),""))<=9,(IFERROR(((E11-D11)*24),"")),9))) -> 0 | G11: =IF((OR(C11="Sunday",C11="Saturday")),(IFERROR(((E11-D11)*24),"")),(IF((IFERROR(((E11-D11)*24),""))>9,((IFERROR(((E11-D11)*24),""))-9),0))) -> 9 | H11: =IFERROR((F11+G11),"") -> 9
B12: =IFERROR((IF(MONTH(B11+1)=MONTH(B11),(B11+1),"")),"") -> 44780 | C12: =TEXT(B12,"dddd") -> Sunday | D12: 0.375 | E12: 0.75 | F12: =IF((OR(C12="Sunday",C12="Saturday")),0,(IF((IFERROR(((E12-D12)*24),""))<=9,(IFERROR(((E12-D12)*24),"")),9))) -> 0 | G12: =IF((OR(C12="Sunday",C12="Saturday")),(IFERROR(((E12-D12)*24),"")),(IF((IFERROR(((E12-D12)*24),""))>9,((IFERROR(((E12-D12)*24),""))-9),0))) -> 9 | H12: =IFERROR((F12+G12),"") -> 9
B13: =IFERROR((IF(MONTH(B12+1)=MONTH(B12),(B12+1),"")),"") -> 44781 | C13: =TEXT(B13,"dddd") -> Monday | D13: 0.375 | E13: 0.75 | F13: =IF((OR(C13="Sunday",C13="Saturday")),0,(IF((IFERROR(((E13-D13)*24),""))<=9,(IFERROR(((E13-D13)*24),"")),9))) -> 9 | G13: =IF((OR(C13="Sunday",C13="Saturday")),(IFERROR(((E13-D13)*24),"")),(IF((IFERROR(((E13-D13)*24),""))>9,((IFERROR(((E13-D13)*24),""))-9),0))) -> 0 | H13: =IFERROR((F13+G13),"") -> 9
B14: =IFERROR((IF(MONTH(B13+1)=MONTH(B13),(B13+1),"")),"") -> 44782 | C14: =TEXT(B14,"dddd") -> Tuesday | D14: 0.375 | E14: 0.75 | F14: =IF((OR(C14="Sunday",C14="Saturday")),0,(IF((IFERROR(((E14-D14)*24),""))<=9,(IFERROR(((E14-D14)*24),"")),9))) -> 9 | G14: =IF((OR(C14="Sunday",C14="Saturday")),(IFERROR(((E14-D14)*24),"")),(IF((IFERROR(((E14-D14)*24),""))>9,((IFERROR(((E14-D14)*24),""))-9),0))) -> 0 | H14: =IFERROR((F14+G14),"") -> 9
B15: =IFERROR((IF(MONTH(B14+1)=MONTH(B14),(B14+1),"")),"") -> 44783 | C15: =TEXT(B15,"dddd") -> Wednesday | D15: 0.375 | E15: 0.75 | F15: =IF((OR(C15="Sunday",C15="Saturday")),0,(IF((IFERROR(((E15-D15)*24),""))<=9,(IFERROR(((E15-D15)*24),"")),9))) -> 9 | G15: =IF((OR(C15="Sunday",C15="Saturday")),(IFERROR(((E15-D15)*24),"")),(IF((IFERROR(((E15-D15)*24),""))>9,((IFERROR(((E15-D15)*24),""))-9),0))) -> 0 | H15: =IFERROR((F15+G15),"") -> 9
B16: =IFERROR((IF(MONTH(B15+1)=MONTH(B15),(B15+1),"")),"") -> 44784 | C16: =TEXT(B16,"dddd") -> Thursday | D16: 0.375 | E16: 0.75 | F16: =IF((OR(C16="Sunday",C16="Saturday")),0,(IF((IFERROR(((E16-D16)*24),""))<=9,(IFERROR(((E16-D16)*24),"")),9))) -> 9 | G16: =IF((OR(C16="Sunday",C16="Saturday")),(IFERROR(((E16-D16)*24),"")),(IF((IFERROR(((E16-D16)*24),""))>9,((IFERROR(((E16-D16)*24),""))-9),0))) -> 0 | H16: =IFERROR((F16+G16),"") -> 9
B17: =IFERROR((IF(MONTH(B16+1)=MONTH(B16),(B16+1),"")),"") -> 44785 | C17: =TEXT(B17,"dddd") -> Friday | D17: 0.375 | E17: 0.75 | F17: =IF((OR(C17="Sunday",C17="Saturday")),0,(IF((IFERROR(((E17-D17)*24),""))<=9,(IFERROR(((E17-D17)*24),"")),9))) -> 9 | G17: =IF((OR(C17="Sunday",C17="Saturday")),(IFERROR(((E17-D17)*24),"")),(IF((IFERROR(((E17-D17)*24),""))>9,((IFERROR(((E17-D17)*24),""))-9),0))) -> 0 | H17: =IFERROR((F17+G17),"") -> 9
