Workbook

Sheet Dashboard
B2: DASBOR
B4: Bulan | C4: Minggu 1 | E4: Minggu 2 | G4: Minggu 3 | I4: Minggu 4 | K4: Minggu 5 | N4: Bulanan
C5: Jam | D5: Membayar | E5: Jam | F5: Membayar | G5: Jam | H5: Membayar | I5: Jam | J5: Membayar | K5: Jam | L5: Membayar | N5: Jam | O5: Membayar
B6: April | C6: ='Data '!G18 -> 29.041667 | D6: ='Data '!H18 -> 1016.4583 | E6: ='Data '!G28 -> 73.041667 | F6: ='Data '!H28 -> 2556.4583 | G6: ='Data '!G38 -> 72.791667 | H6: ='Data '!H38 -> 2547.7083 | I6: ='Data '!G48 -> 73 | J6: ='Data '!H48 -> 2555 | K6: ='Data '!G58 -> 52.375 | L6: ='Data '!H58 -> 1833.125 | N6: =C6+E6+G6+K6+I6 -> 300.25 | O6: =D6+F6+H6+L6+J6 -> 10508.75
B7: May | C7: ='Data '!P18 -> 82.708333 | D7: ='Data '!Q18 -> 2894.7917 | E7: ='Data '!P28 -> 67.541667 | F7: ='Data '!Q28 -> 2363.9583 | G7: ='Data '!P38 -> 67.541667 | H7: ='Data '!Q38 -> 2363.9583 | I7: ='Data '!P48 -> 73 | J7: ='Data '!Q48 -> 2555 | K7: ='Data '!P58 -> 18.083333 | L7: ='Data '!Q58 -> 632.91667 | N7: =C7+E7+G7+K7+I7 -> 308.875 | O7: =D7+F7+H7+L7+J7 -> 10810.625
B8: June | C8: ='Data '!G68 -> 48.458333 | D8: ='Data '!H68 -> 1696.0417 | E8: ='Data '!G78 -> 73.041667 | F8: ='Data '!H78 -> 2556.4583 | G8: ='Data '!G88 -> 72.791667 | H8: ='Data '!H88 -> 2547.7083 | I8: ='Data '!G98 -> 73 | J8: ='Data '!H98 -> 2555 | K8: ='Data '!G108 -> 37.791667 | L8: ='Data '!H108 -> 1322.7083 | N8: =C8+E8+G8+K8+I8 -> 305.08333 | O8: =D8+F8+H8+L8+J8 -> 10677.917
B9: July | C9: ='Data '!P68 -> 29.291667 | D9: ='Data '!Q68 -> 1025.2083 | E9: ='Data '!P78 -> 73.041667 | F9: ='Data '!Q78 -> 2556.4583 | G9: ='Data '!P88 -> 72.791667 | H9: ='Data '!Q88 -> 2547.7083 | I9: ='Data '!P98 -> 73 | J9: ='Data '!Q98 -> 2555 | K9: ='Data '!P108 -> 60.75 | L9: ='Data '!Q108 -> 2126.25 | N9: =C9+E9+G9+K9+I9 -> 308.875 | O9: =D9+F9+H9+L9+J9 -> 10810.625
B10: August | C10: ='Data '!G118 -> 67.875 | D10: ='Data '!H118 -> 2375.625 | E10: ='Data '!G128 -> 73.041667 | F10: ='Data '!H128 -> 2556.4583 | G10: ='Data '!G138 -> 72.791667 | H10: ='Data '!H138 -> 2547.7083 | I10: ='Data '!G148 -> 73 | J10: ='Data '!H148 -> 2555 | K10: ='Data '!G158 -> 29.291667 | L10: ='Data '!H158 -> 1025.2083 | N10: =C10+E10+G10+K10+I10 -> 316 | O10: =D10+F10+H10+L10+J10 -> 11060
B11: September | C11: ='Data '!P118 -> 37.791667 | D11: ='Data '!Q118 -> 1322.7083 | E11: ='Data '!P128 -> 74.208333 | F11: ='Data '!Q128 -> 2597.2917 | G11: ='Data '!P138 -> 73.041667 | H11: ='Data '!Q138 -> 2556.4583 | I11: ='Data '!P148 -> 73 | J11: ='Data '!Q148 -> 2555 | K11: ='Data '!P158 -> 41.791667 | L11: ='Data '!Q158 -> 1462.7083 | N11: =C11+E11+G11+K11+I11 -> 299.83333 | O11: =D11+F11+H11+L11+J11 -> 10494.167
B12: October | C12: ='Data '!G168 -> 19.333333 | D12: ='Data '!H168 -> 676.66667 | E12: ='Data '!G178 -> 67.375 | F12: ='Data '!H178 -> 2358.125 | G12: ='Data '!G188 -> 67.541667 | H12: ='Data '!H188 -> 2363.9583 | I12: ='Data '!G198 -> 73.666667 | J12: ='Data '!H198 -> 2578.3333 | K12: ='Data '!G209 -> 85.666667 | L12: ='Data '!H209 -> 2998.3333 | N12: =C12+E12+G12+K12+I12 -> 313.58333 | O12: =D12+F12+H12+L12+J12 -> 10975.417
B13: November | C13: ='Data '!P168 -> 58.291667 | D13: ='Data '!Q168 -> 2040.2083 | E13: ='Data '!P178 -> 73.041667 | F13: ='Data '!Q178 -> 2556.4583 | G13: ='Data '!P188 -> 72.791667 | H13: ='Data '!Q188 -> 2547.7083 | I13: ='Data '!P198 -> 73 | J13: ='Data '!Q198 -> 2555 | K13: ='Data '!P209 -> 28.083333 | L13: ='Data '!Q209 -> 982.91667 | N13: =C13+E13+G13+K13+I13 -> 305.20833 | O13: =D13+F13+H13+L13+J13 -> 10682.292
B14: December | C14: ='Data '!G220 -> 38.666667 | D14: ='Data '!H220 -> 1353.3333 | E14: ='Data '!G230 -> 67.375 | F14: ='Data '!H230 -> 2358.125 | G14: ='Data '!G240 -> 67.541667 | H14: ='Data '!H240 -> 2363.9583 | I14: ='Data '!G250 -> 73.666667 | J14: ='Data '!H250 -> 2578.3333 | K14: ='Data '!G260 -> 68.666667 | L14: ='Data '!H260 -> 2403.3333 | N14: =C14+E14+G14+K14+I14 -> 315.91667 | O14: =D14+F14+H14+L14+J14 -> 11057.083
B15: January | C15: ='Data '!P220 -> 77.625 | D15: ='Data '!Q220 -> 2716.875 | E15: ='Data '!P230 -> 73.041667 | F15: ='Data '!Q230 -> 2556.4583 | G15: ='Data '!P240 -> 72.791667 | H15: ='Data '!Q240 -> 2547.7083 | I15: ='Data '!P250 -> 73 | J15: ='Data '!Q250 -> 2555 | K15: ='Data '!P260 -> 19.583333 | L15: ='Data '!Q260 -> 685.41667 | N15: =C15+E15+G15+K15+I15 -> 316.04167 | O15: =D15+F15+H15+L15+J15 -> 11061.458

Sheet Data 
B2: Nama : | G2: Departemen
B3: Alamat email : | G3: Judul :
B4: Tarif per Jam | C4: 35 | G4: Perusahaan :
B5: Occupancy | G5: Supervisor:
B8: MINGGU NO. 01 | H8: 1st April to 3rd April | K8: MINGGU NO. 01 | Q8: 1st May to 8th May
B9: Tanggal | C9: Hari | D9: Time In | E9: Lunch | F9: Time Out | G9: Total Jam | H9: Bayar Diperoleh | I9: Accomplishments | K9: Tanggal | L9: Hari | M9: Time In | N9: Lunch | O9: Time Out | P9: Total Jam | Q9: Bayar Diperoleh | R9: Accomplishments
B10: 44652 | C10: =TEXT(B10,"dddd") -> Friday | D10: 0.25 | E10: 0.33333333 | F10: 0.66666667 | G10: =((F10-D10)*24)-E10 -> 9.6666667 | H10: =$C$4*G10 -> 338.33333 | K10: 44682 | L10: =TEXT(K10,"dddd") -> Sunday | M10: 0.25 | N10: 0.29166667 | O10: 0.66666667 | P10: =((O10-M10)*24)-N10 -> 9.7083333 | Q10: =$C$4*P10 -> 339.79167
B11: =B10+1 -> 44653 | C11: =TEXT(B11,"dddd") -> Saturday | D11: 0.25 | E11: 0.33333333 | F11: 0.66666667 | G11: =((F11-D11)*24)-E11 -> 9.6666667 | H11: =$C$4*G11 -> 338.33333 | K11: =K10+1 -> 44683 | L11: =TEXT(K11,"dddd") -> Monday | M11: 0.29166667 | N11: 0.33333333 | O11: 0.71875 | P11: =((O11-M11)*24)-N11 -> 9.9166667 | Q11: =$C$4*P11 -> 347.08333
B12: =B11+1 -> 44654 | C12: =TEXT(B12,"dddd") -> Sunday | D12: 0.25 | E12: 0.29166667 | F12: 0.66666667 | G12: =((F12-D12)*24)-E12 -> 9.7083333 | H12: =$C$4*G12 -> 339.79167 | K12: =K11+1 -> 44684 | L12: =TEXT(K12,"dddd") -> Tuesday | M12: 0.25 | N12: 0.33333333 | O12: 0.66666667 | P12: =((O12-M12)*24)-N12 -> 9.6666667 | Q12: =$C$4*P12 -> 338.33333
K13: =K12+1 -> 44685 | L13: =TEXT(K13,"dddd") -> Wednesday | M13: 0.375 | N13: 0.33333333 | O13: 0.74305556 | P13: =((O13-M13)*24)-N13 -> 8.5 | Q13: =$C$4*P13 -> 297.5
K14: =K13+1 -> 44686 | L14: =TEXT(K14,"dddd") -> Thursday | M14: 0.41666667 | N14: 0.45833333 | O14: 0.66666667 | P14: =((O14-M14)*24)-N14 -> 5.5416667 | Q14: =$C$4*P14 -> 193.95833
K15: =K14+1 -> 44687 | L15: =TEXT(K15,"dddd") -> Friday | M15: 0.35416667 | N15: 0.45833333 | O15: 0.75 | P15: =((O15-M15)*24)-N15 -> 9.0416667 | Q15: =$C$4*P15 -> 316.45833
K16: =K15+1 -> 44688 | L16: =TEXT(K16,"dddd") -> Saturday | M16: 0.27083333 | N16: 0.33333333 | O16: 0.91666667 | P16: =((O16-M16)*24)-N16 -> 15.166667 | Q16: =$C$4*P16 -> 530.83333
K17: =K16+1 -> 44689 | L17: =TEXT(K17,"dddd") -> Sunday | M17: 0.27083333 | N17: 0.33333333 | O17: 0.91666667 | P17: =((O17-M17)*24)-N17 -> 15.166667 | Q17: =$C$4*P17 -> 530.83333
B18: Total | G18: =SUM(G10:G17) -> 29.041667 | H18: =SUM(H10:H17) -> 1016.4583 | K18: Total | P18: =SUM(P10:P17) -> 82.708333 | Q18: =SUM(Q10:Q17) -> 2894.7917
B19: MINGGU NO. 02 | H19: 4th Apr to 10th April | K19: MINGGU NO. 02 | Q19: 9th May to 15th May
B20: Tanggal | C20: Hari | D20: Time In | E20: Lunch | F20: Time Out | G20: Total Jam | H20: Bayar Diperoleh | I20: Accomplishments | K20: Tanggal | L20: Hari | M20: Time In | N20: Lunch | O20: Time Out | P20: Total Jam | Q20: Bayar Diperoleh | R20: Accomplishments
B21: =B12+1 -> 44655 | C21: =TEXT(B21,"dddd") -> Monday | D21: 0.375 | E21: 0.33333333 | F21: 0.74305556 | G21: =((F21-D21)*24)-E21 -> 8.5 | H21: =$C$4*G21 -> 297.5 | K21: =K17+1 -> 44690 | L21: =TEXT(K21,"dddd") -> Monday | M21: 0.25 | N21: 0.29166667 | O21: 0.66666667 | P21: =((O21-M21)*24)-N21 -> 9.7083333 | Q21: =$C$4*P21 -> 339.79167
B22: =B21+1 -> 44656 | C22: =TEXT(B22,"dddd") -> Tuesday | D22: 0.41666667 | E22: 0.45833333 | F22: 0.66666667 | G22: =((F22-D22)*24)-E22 -> 5.5416667 | H22: =$C$4*G22 -> 193.95833 | K22: =K21+1 -> 44691 | L22: =TEXT(K22,"dddd") -> Tuesday | M22: 0.29166667 | N22: 0.33333333 | O22: 0.71875 | P22: =((O22-M22)*24)-N22 -> 9.9166667 | Q22: =$C$4*P22 -> 347.08333
B23: =B22+1 -> 44657 | C23: =TEXT(B23,"dddd") -> Wednesday | D23: 0.35416667 | E23: 0.45833333 | F23: 0.75 | G23: =((F23-D23)*24)-E23 -> 9.0416667 | H23: =$C$4*G23 -> 316.45833 | K23: =K22+1 -> 44692 | L23: =TEXT(K23,"dddd") -> Wednesday | M23: 0.25 | N23: 0.33333333 | O23: 0.66666667 | P23: =((O23-M23)*24)-N23 -> 9.6666667 | Q23: =$C$4*P23 -> 338.33333
B24: =B23+1 -> 44658 | C24: =TEXT(B24,"dddd") -> Thursday | D24: 0.27083333 | E24: 0.33333333 | F24: 0.91666667 | G24: =((F24-D24)*24)-E24 -> 15.166667 | H24: =$C$4*G24 -> 530.83333 | K24: =K23+1 -> 44693 | L24: =TEXT(K24,"dddd") -> Thursday | M24: 0.375 | N24: 0.33333333 | O24: 0.74305556 | P24: =((O24-M24)*24)-N24 -> 8.5 | Q24: =$C$4*P24 -> 297.5
B25: =B24+1 -> 44659 | C25: =TEXT(B25,"dddd") -> Friday | D25: 0.27083333 | E25: 0.33333333 | F25: 0.91666667 | G25: =((F25-D25)*24)-E25 -> 15.166667 | H25: =$C$4*G25 -> 530.83333 | K25: =K24+1 -> 44694 | L25: =TEXT(K25,"dddd") -> Friday | M25: 0.41666667 | N25: 0.45833333 | O25: 0.66666667 | P25: =((O25-M25)*24)-N25 -> 5.5416667 | Q25: =$C$4*P25 -> 193.95833
B26: =B25+1 -> 44660 | C26: =TEXT(B26,"dddd") -> Saturday | D26: 0.25 | E26: 0.29166667 | F26: 0.66666667 | G26: =((F26-D26)*24)-E26 -> 9.7083333 | H26: =$C$4*G26 -> 339.79167 | K26: =K25+1 -> 44695 | L26: =TEXT(K26,"dddd") -> Saturday | M26: 0.35416667 | N26: 0.45833333 | O26: 0.75 | P26: =((O26-M26)*24)-N26 -> 9.0416667 | Q26: =$C$4*P26 -> 316.45833
B27: =B26+1 -> 44661 | C27: =TEXT(B27,"dddd") -> Sunday | D27: 0.29166667 | E27: 0.33333333 | F27: 0.71875 | G27: =((F27-D27)*24)-E27 -> 9.9166667 | H27: =$C$4*G27 -> 347.08333 | K27: =K26+1 -> 44696 | L27: =TEXT(K27,"dddd") -> Sunday | M27: 0.27083333 | N27: 0.33333333 | O27: 0.91666667 | P27: =((O27-M27)*24)-N27 -> 15.166667 | Q27: =$C$4*P27 -> 530.83333
B28: Total | G28: =SUM(G21:G27) -> 73.041667 | H28: =SUM(H21:H27) -> 2556.4583 | K28: Total | P28: =SUM(P21:P27) -> 67.541667 | Q28: =SUM(Q21:Q27) -> 2363.9583
B29: MINGGU NO. 03 | H29: 11th Apr to 17th April | K29: MINGGU NO. 03 | Q29: 16th May to 22nd May
B30: Tanggal | C30: Hari | D30: Time In | E30: Lunch | F30: Time Out | G30: Total Jam | H30: Bayar Diperoleh | I30: Accomplishments | K30: Tanggal | L30: Hari | M30: Time In | N30: Lunch | O30: Time Out | P30: Total Jam | Q30: Bayar Diperoleh | R30: Accomplishments
B31: =B27+1 -> 44662 | C31: =TEXT(B31,"dddd") -> Monday | D31: 0.25 | E31: 0.33333333 | F31: 0.66666667 | G31: =((F31-D31)*24)-E31 -> 9.6666667 | H31: =$C$4*G31 -> 338.33333 | K31: =K27+1 -> 44697 | L31: =TEXT(K31,"dddd") -> Monday | M31: 0.27083333 | N31: 0.33333333 | O31: 0.91666667 | P31: =((O31-M31)*24)-N31 -> 15.166667 | Q31: =$C$4*P31 -> 530.83333
B32: =B31+1 -> 44663 | C32: =TEXT(B32,"dddd") -> Tuesday | D32: 0.375 | E32: 0.33333333 | F32: 0.74305556 | G32: =((F32-D32)*24)-E32 -> 8.5 | H32: =$C$4*G32 -> 297.5 | K32: =K31+1 -> 44698 | L32: =TEXT(K32,"dddd") -> Tuesday | M32: 0.25 | N32: 0.29166667 | O32: 0.66666667 | P32: =((O32-M32)*24)-N32 -> 9.7083333 | Q32: =$C$4*P32 -> 339.79167
B33: =B32+1 -> 44664 | C33: =TEXT(B33,"dddd") -> Wednesday | D33: 0.41666667 | E33: 0.45833333 | F33: 0.66666667 | G33: =((F33-D33)*24)-E33 -> 5.5416667 | H33: =$C$4*G33 -> 193.95833 | K33: =K32+1 -> 44699 | L33: =TEXT(K33,"dddd") -> Wednesday | M33: 0.29166667 | N33: 0.33333333 | O33: 0.71875 | P33: =((O33-M33)*24)-N33 -> 9.9166667 | Q33: =$C$4*P33 -> 347.08333
B34: =B33+1 -> 44665 | C34: =TEXT(B34,"dddd") -> Thursday | D34: 0.35416667 | E34: 0.45833333 | F34: 0.75 | G34: =((F34-D34)*24)-E34 -> 9.0416667 | H34: =$C$4*G34 -> 316.45833 | K34: =K33+1 -> 44700 | L34: =TEXT(K34,"dddd") -> Thursday | M34: 0.25 | N34: 0.33333333 | O34: 0.66666667 | P34: =((O34-M34)*24)-N34 -> 9.6666667 | Q34: =$C$4*P34 -> 338.33333
B35: =B34+1 -> 44666 | C35: =TEXT(B35,"dddd") -> Friday | D35: 0.27083333 | E35: 0.33333333 | F35: 0.91666667 | G35: =((F35-D35)*24)-E35 -> 15.166667 | H35: =$C$4*G35 -> 530.83333 | K35: =K34+1 -> 44701 | L35: =TEXT(K35,"dddd") -> Friday | M35: 0.375 | N35: 0.33333333 | O35: 0.74305556 | P35: =((O35-M35)*24)-N35 -> 8.5 | Q35: =$C$4*P35 -> 297.5
B36: =B35+1 -> 44667 | C36: =TEXT(B36,"dddd") -> Saturday | D36: 0.27083333 | E36: 0.33333333 | F36: 0.91666667 | G36: =((F36-D36)*24)-E36 -> 15.166667 | H36: =$C$4*G36 -> 530.83333 | K36: =K35+1 -> 44702 | L36: =TEXT(K36,"dddd") -> Saturday | M36: 0.41666667 | N36: 0.45833333 | O36: 0.66666667 | P36: =((O36-M36)*24)-N36 -> 5.5416667 | Q36: =$C$4*P36 -> 193.95833
B37: =B36+1 -> 44668 | C37: =TEXT(B37,"dddd") -> Sunday | D37: 0.25 | E37: 0.29166667 | F37: 0.66666667 | G37: =((F37-D37)*24)-E37 -> 9.7083333 | H37: =$C$4*G37 -> 339.79167 | K37: =K36+1 -> 44703 | L37: =TEXT(K37,"dddd") -> Sunday | M37: 0.35416667 | N37: 0.45833333 | O37: 0.75 | P37: =((O37-M37)*24)-N37 -> 9.0416667 | Q37: =$C$4*P37 -> 316.45833
B38: Total | G38: =SUM(G31:G37) -> 72.791667 | H38: =SUM(H31:H37) -> 2547.7083 | K38: Total | P38: =SUM(P31:P37) -> 67.541667 | Q38: =SUM(Q31:Q37) -> 2363.9583
B39: WEEK NO. 04 | H39: 18th Apr to 24th April | K39: WEEK NO. 04 | Q39: 23rd May to 29th May
B40: Tanggal | C40: Hari | D40: Time In | E40: Lunch | F40: Time Out | G40: Total Jam | H40: Bayar Diperoleh | I40: Accomplishments | K40: Tanggal | L40: Hari | M40: Time In | N40: Lunch | O40: Time Out | P40: Total Jam | Q40: Bayar Diperoleh | R40: Accomplishments
B41: =B37+1 -> 44669 | C41: =TEXT(B41,"dddd") -> Monday | D41: 0.29166667 | E41: 0.33333333 | F41: 0.71875 | G41: =((F41-D41)*24)-E41 -> 9.9166667 | H41: =$C$4*G41 -> 347.08333 | K41: =K37+1 -> 44704 | L41: =TEXT(K41,"dddd") -> Monday | M41: 0.27083333 | N41: 0.33333333 | O41: 0.91666667 | P41: =((O41-M41)*24)-N41 -> 15.166667 | Q41: =$C$4*P41 -> 530.83333
B42: =B41+1 -> 44670 | C42: =TEXT(B42,"dddd") -> Tuesday | D42: 0.25 | E42: 0.33333333 | F42: 0.66666667 | G42: =((F42-D42)*24)-E42 -> 9.6666667 | H42: =$C$4*G42 -> 338.33333 | K42: =K41+1 -> 44705 | L42: =TEXT(K42,"dddd") -> Tuesday | M42: 0.27083333 | N42: 0.33333333 | O42: 0.91666667 | P42: =((O42-M42)*24)-N42 -> 15.166667 | Q42: =$C$4*P42 -> 530.83333
B43: =B42+1 -> 44671 | C43: =TEXT(B43,"dddd") -> Wednesday | D43: 0.375 | E43: 0.33333333 | F43: 0.74305556 | G43: =((F43-D43)*24)-E43 -> 8.5 | H43: =$C$4*G43 -> 297.5 | K43: =K42+1 -> 44706 | L43: =TEXT(K43,"dddd") -> Wednesday | M43: 0.29166667 | N43: 0.33333333 | O43: 0.71875 | P43: =((O43-M43)*24)-N43 -> 9.9166667 | Q43: =$C$4*P43 -> 347.08333
...
