Workbook

Sheet Summary
B2: RINGKASAN
B4: S.No | C4: Nama | D4: Minggu ke 1 | G4: Minggu ke 2 | J4: Minggu ke 3 | M4: Minggu ke 4 | P4: Minggu ke 5 | T4: Total semua Minggu
D6: Total Dibayar | E6: Total Belum Dibayar | F6: Jumlah Minggu | G6: Total Dibayar | H6: Total Belum Dibayar | I6: Jumlah Minggu | J6: Total Dibayar | K6: Total Belum Dibayar | L6: Jumlah Minggu | M6: Total Dibayar | N6: Total Belum Dibayar | O6: Jumlah Minggu | P6: Total Dibayar | Q6: Total Belum Dibayar | R6: Jumlah Minggu | T6: Total Dibayar | U6: Total Belum Dibayar | V6: Total
B7: 1 | C7: Mr. A | D7: =SUMIF('Week 1'!$C$7:$C$36,Summary!C7,'Week 1'!$S$7:$S$36) -> 14 | E7: =SUMIF('Week 1'!$C$7:$C$36,Summary!C7,'Week 1'!$T$7:$T$36) -> 0 | F7: =SUMIF('Week 1'!$C$7:$C$36,Summary!C7,'Week 1'!$U$7:$U$36) -> 14 | G7: =SUMIF('Week 2'!$C$7:$C$36,Summary!C7,'Week 2'!$S$7:$S$36) -> 0 | H7: =SUMIF('Week 2'!$C$7:$C$36,Summary!C7,'Week 2'!$T$7:$T$36) -> 0 | I7: =SUMIF('Week 2'!$C$7:$C$36,Summary!C7,'Week 2'!$U$7:$U$36) -> 0 | J7: =SUMIF('Week 3'!$C$7:$C$36,Summary!C7,'Week 3'!$S$7:$S$36) -> 0 | K7: =SUMIF('Week 3'!$C$7:$C$36,Summary!C7,'Week 3'!$T$7:$T$36) -> 0 | L7: =SUMIF('Week 3'!$C$7:$C$36,Summary!C7,'Week 3'!$U$7:$U$36) -> 0 | M7: =SUMIF('Week 4'!$C$7:$C$36,Summary!C7,'Week 4'!$S$7:$S$36) -> 0 | N7: =SUMIF('Week 4'!$C$7:$C$36,Summary!C7,'Week 4'!$T$7:$T$36) -> 0 | O7: =SUMIF('Week 4'!$C$7:$C$36,Summary!C7,'Week 4'!$U$7:$U$36) -> 0 | P7: =SUMIF('Week 5'!$C$7:$C$36,Summary!C7,'Week 5'!$S$7:$S$36) -> 0 | Q7: =SUMIF('Week 5'!$C$7:$C$36,Summary!C7,'Week 5'!$T$7:$T$36) -> 0 | R7: =SUMIF('Week 5'!$C$7:$C$36,Summary!C7,'Week 5'!$U$7:$U$36) -> 0 | T7: =D7+G7+J7+M7+P7 -> 14 | U7: =E7+H7+K7+N7+Q7 -> 0 | V7: =U7+T7 -> 14
B8: =B7+1 -> 2 | C8: Mr. B | D8: =SUMIF('Week 1'!$C$7:$C$36,Summary!C8,'Week 1'!$S$7:$S$36) -> 30 | E8: =SUMIF('Week 1'!$C$7:$C$36,Summary!C8,'Week 1'!$T$7:$T$36) -> 12 | F8: =SUMIF('Week 1'!$C$7:$C$36,Summary!C8,'Week 1'!$U$7:$U$36) -> 42 | G8: =SUMIF('Week 2'!$C$7:$C$36,Summary!C8,'Week 2'!$S$7:$S$36) -> 0 | H8: =SUMIF('Week 2'!$C$7:$C$36,Summary!C8,'Week 2'!$T$7:$T$36) -> 0 | I8: =SUMIF('Week 2'!$C$7:$C$36,Summary!C8,'Week 2'!$U$7:$U$36) -> 0 | J8: =SUMIF('Week 3'!$C$7:$C$36,Summary!C8,'Week 3'!$S$7:$S$36) -> 0 | K8: =SUMIF('Week 3'!$C$7:$C$36,Summary!C8,'Week 3'!$T$7:$T$36) -> 0 | L8: =SUMIF('Week 3'!$C$7:$C$36,Summary!C8,'Week 3'!$U$7:$U$36) -> 0 | M8: =SUMIF('Week 4'!$C$7:$C$36,Summary!C8,'Week 4'!$S$7:$S$36) -> 0 | N8: =SUMIF('Week 4'!$C$7:$C$36,Summary!C8,'Week 4'!$T$7:$T$36) -> 0 | O8: =SUMIF('Week 4'!$C$7:$C$36,Summary!C8,'Week 4'!$U$7:$U$36) -> 0 | P8: =SUMIF('Week 5'!$C$7:$C$36,Summary!C8,'Week 5'!$S$7:$S$36) -> 0 | Q8: =SUMIF('Week 5'!$C$7:$C$36,Summary!C8,'Week 5'!$T$7:$T$36) -> 0 | R8: =SUMIF('Week 5'!$C$7:$C$36,Summary!C8,'Week 5'!$U$7:$U$36) -> 0 | T8: =D8+G8+J8+M8+P8 -> 30 | U8: =E8+H8+K8+N8+Q8 -> 12 | V8: =U8+T8 -> 42
B9: =B8+1 -> 3 | C9: Mr. C | D9: =SUMIF('Week 1'!$C$7:$C$36,Summary!C9,'Week 1'!$S$7:$S$36) -> 21 | E9: =SUMIF('Week 1'!$C$7:$C$36,Summary!C9,'Week 1'!$T$7:$T$36) -> 0 | F9: =SUMIF('Week 1'!$C$7:$C$36,Summary!C9,'Week 1'!$U$7:$U$36) -> 21 | G9: =SUMIF('Week 2'!$C$7:$C$36,Summary!C9,'Week 2'!$S$7:$S$36) -> 0 | H9: =SUMIF('Week 2'!$C$7:$C$36,Summary!C9,'Week 2'!$T$7:$T$36) -> 0 | I9: =SUMIF('Week 2'!$C$7:$C$36,Summary!C9,'Week 2'!$U$7:$U$36) -> 0 | J9: =SUMIF('Week 3'!$C$7:$C$36,Summary!C9,'Week 3'!$S$7:$S$36) -> 0 | K9: =SUMIF('Week 3'!$C$7:$C$36,Summary!C9,'Week 3'!$T$7:$T$36) -> 0 | L9: =SUMIF('Week 3'!$C$7:$C$36,Summary!C9,'Week 3'!$U$7:$U$36) -> 0 | M9: =SUMIF('Week 4'!$C$7:$C$36,Summary!C9,'Week 4'!$S$7:$S$36) -> 0 | N9: =SUMIF('Week 4'!$C$7:$C$36,Summary!C9,'Week 4'!$T$7:$T$36) -> 0 | O9: =SUMIF('Week 4'!$C$7:$C$36,Summary!C9,'Week 4'!$U$7:$U$36) -> 0 | P9: =SUMIF('Week 5'!$C$7:$C$36,Summary!C9,'Week 5'!$S$7:$S$36) -> 0 | Q9: =SUMIF('Week 5'!$C$7:$C$36,Summary!C9,'Week 5'!$T$7:$T$36) -> 0 | R9: =SUMIF('Week 5'!$C$7:$C$36,Summary!C9,'Week 5'!$U$7:$U$36) -> 0 | T9: =D9+G9+J9+M9+P9 -> 21 | U9: =E9+H9+K9+N9+Q9 -> 0 | V9: =U9+T9 -> 21
B10: =B9+1 -> 4 | C10: Mr. D | D10: =SUMIF('Week 1'!$C$7:$C$36,Summary!C10,'Week 1'!$S$7:$S$36) -> 0 | E10: =SUMIF('Week 1'!$C$7:$C$36,Summary!C10,'Week 1'!$T$7:$T$36) -> 0 | F10: =SUMIF('Week 1'!$C$7:$C$36,Summary!C10,'Week 1'!$U$7:$U$36) -> 0 | G10: =SUMIF('Week 2'!$C$7:$C$36,Summary!C10,'Week 2'!$S$7:$S$36) -> 0 | H10: =SUMIF('Week 2'!$C$7:$C$36,Summary!C10,'Week 2'!$T$7:$T$36) -> 0 | I10: =SUMIF('Week 2'!$C$7:$C$36,Summary!C10,'Week 2'!$U$7:$U$36) -> 0 | J10: =SUMIF('Week 3'!$C$7:$C$36,Summary!C10,'Week 3'!$S$7:$S$36) -> 0 | K10: =SUMIF('Week 3'!$C$7:$C$36,Summary!C10,'Week 3'!$T$7:$T$36) -> 0 | L10: =SUMIF('Week 3'!$C$7:$C$36,Summary!C10,'Week 3'!$U$7:$U$36) -> 0 | M10: =SUMIF('Week 4'!$C$7:$C$36,Summary!C10,'Week 4'!$S$7:$S$36) -> 0 | N10: =SUMIF('Week 4'!$C$7:$C$36,Summary!C10,'Week 4'!$T$7:$T$36) -> 0 | O10: =SUMIF('Week 4'!$C$7:$C$36,Summary!C10,'Week 4'!$U$7:$U$36) -> 0 | P10: =SUMIF('Week 5'!$C$7:$C$36,Summary!C10,'Week 5'!$S$7:$S$36) -> 0 | Q10: =SUMIF('Week 5'!$C$7:$C$36,Summary!C10,'Week 5'!$T$7:$T$36) -> 0 | R10: =SUMIF('Week 5'!$C$7:$C$36,Summary!C10,'Week 5'!$U$7:$U$36) -> 0 | T10: =D10+G10+J10+M10+P10 -> 0 | U10: =E10+H10+K10+N10+Q10 -> 0 | V10: =U10+T10 -> 0
B11: =B10+1 -> 5 | C11: Mr. E | D11: =SUMIF('Week 1'!$C$7:$C$36,Summary!C11,'Week 1'!$S$7:$S$36) -> 0 | E11: =SUMIF('Week 1'!$C$7:$C$36,Summary!C11,'Week 1'!$T$7:$T$36) -> 0 | F11: =SUMIF('Week 1'!$C$7:$C$36,Summary!C11,'Week 1'!$U$7:$U$36) -> 0 | G11: =SUMIF('Week 2'!$C$7:$C$36,Summary!C11,'Week 2'!$S$7:$S$36) -> 0 | H11: =SUMIF('Week 2'!$C$7:$C$36,Summary!C11,'Week 2'!$T$7:$T$36) -> 0 | I11: =SUMIF('Week 2'!$C$7:$C$36,Summary!C11,'Week 2'!$U$7:$U$36) -> 0 | J11: =SUMIF('Week 3'!$C$7:$C$36,Summary!C11,'Week 3'!$S$7:$S$36) -> 0 | K11: =SUMIF('Week 3'!$C$7:$C$36,Summary!C11,'Week 3'!$T$7:$T$36) -> 0 | L11: =SUMIF('Week 3'!$C$7:$C$36,Summary!C11,'Week 3'!$U$7:$U$36) -> 0 | M11: =SUMIF('Week 4'!$C$7:$C$36,Summary!C11,'Week 4'!$S$7:$S$36) -> 0 | N11: =SUMIF('Week 4'!$C$7:$C$36,Summary!C11,'Week 4'!$T$7:$T$36) -> 0 | O11: =SUMIF('Week 4'!$C$7:$C$36,Summary!C11,'Week 4'!$U$7:$U$36) -> 0 | P11: =SUMIF('Week 5'!$C$7:$C$36,Summary!C11,'Week 5'!$S$7:$S$36) -> 0 | Q11: =SUMIF('Week 5'!$C$7:$C$36,Summary!C11,'Week 5'!$T$7:$T$36) -> 0 | R11: =SUMIF('Week 5'!$C$7:$C$36,Summary!C11,'Week 5'!$U$7:$U$36) -> 0 | T11: =D11+G11+J11+M11+P11 -> 0 | U11: =E11+H11+K11+N11+Q11 -> 0 | V11: =U11+T11 -> 0
B12: =B11+1 -> 6 | D12: =SUMIF('Week 1'!$C$7:$C$36,Summary!C12,'Week 1'!$S$7:$S$36) -> 0 | E12: =SUMIF('Week 1'!$C$7:$C$36,Summary!C12,'Week 1'!$T$7:$T$36) -> 0 | F12: =SUMIF('Week 1'!$C$7:$C$36,Summary!C12,'Week 1'!$U$7:$U$36) -> 0 | G12: =SUMIF('Week 2'!$C$7:$C$36,Summary!C12,'Week 2'!$S$7:$S$36) -> 0 | H12: =SUMIF('Week 2'!$C$7:$C$36,Summary!C12,'Week 2'!$T$7:$T$36) -> 0 | I12: =SUMIF('Week 2'!$C$7:$C$36,Summary!C12,'Week 2'!$U$7:$U$36) -> 0 | J12: =SUMIF('Week 3'!$C$7:$C$36,Summary!C12,'Week 3'!$S$7:$S$36) -> 0 | K12: =SUMIF('Week 3'!$C$7:$C$36,Summary!C12,'Week 3'!$T$7:$T$36) -> 0 | L12: =SUMIF('Week 3'!$C$7:$C$36,Summary!C12,'Week 3'!$U$7:$U$36) -> 0 | M12: =SUMIF('Week 4'!$C$7:$C$36,Summary!C12,'Week 4'!$S$7:$S$36) -> 0 | N12: =SUMIF('Week 4'!$C$7:$C$36,Summary!C12,'Week 4'!$T$7:$T$36) -> 0 | O12: =SUMIF('Week 4'!$C$7:$C$36,Summary!C12,'Week 4'!$U$7:$U$36) -> 0 | P12: =SUMIF('Week 5'!$C$7:$C$36,Summary!C12,'Week 5'!$S$7:$S$36) -> 0 | Q12: =SUMIF('Week 5'!$C$7:$C$36,Summary!C12,'Week 5'!$T$7:$T$36) -> 0 | R12: =SUMIF('Week 5'!$C$7:$C$36,Summary!C12,'Week 5'!$U$7:$U$36) -> 0 | T12: =D12+G12+J12+M12+P12 -> 0 | U12: =E12+H12+K12+N12+Q12 -> 0 | V12: =U12+T12 -> 0
B13: =B12+1 -> 7 | D13: =SUMIF('Week 1'!$C$7:$C$36,Summary!C13,'Week 1'!$S$7:$S$36) -> 0 | E13: =SUMIF('Week 1'!$C$7:$C$36,Summary!C13,'Week 1'!$T$7:$T$36) -> 0 | F13: =SUMIF('Week 1'!$C$7:$C$36,Summary!C13,'Week 1'!$U$7:$U$36) -> 0 | G13: =SUMIF('Week 2'!$C$7:$C$36,Summary!C13,'Week 2'!$S$7:$S$36) -> 0 | H13: =SUMIF('Week 2'!$C$7:$C$36,Summary!C13,'Week 2'!$T$7:$T$36) -> 0 | I13: =SUMIF('Week 2'!$C$7:$C$36,Summary!C13,'Week 2'!$U$7:$U$36) -> 0 | J13: =SUMIF('Week 3'!$C$7:$C$36,Summary!C13,'Week 3'!$S$7:$S$36) -> 0 | K13: =SUMIF('Week 3'!$C$7:$C$36,Summary!C13,'Week 3'!$T$7:$T$36) -> 0 | L13: =SUMIF('Week 3'!$C$7:$C$36,Summary!C13,'Week 3'!$U$7:$U$36) -> 0 | M13: =SUMIF('Week 4'!$C$7:$C$36,Summary!C13,'Week 4'!$S$7:$S$36) -> 0 | N13: =SUMIF('Week 4'!$C$7:$C$36,Summary!C13,'Week 4'!$T$7:$T$36) -> 0 | O13: =SUMIF('Week 4'!$C$7:$C$36,Summary!C13,'Week 4'!$U$7:$U$36) -> 0 | P13: =SUMIF('Week 5'!$C$7:$C$36,Summary!C13,'Week 5'!$S$7:$S$36) -> 0 | Q13: =SUMIF('Week 5'!$C$7:$C$36,Summary!C13,'Week 5'!$T$7:$T$36) -> 0 | R13: =SUMIF('Week 5'!$C$7:$C$36,Summary!C13,'Week 5'!$U$7:$U$36) -> 0 | T13: =D13+G13+J13+M13+P13 -> 0 | U13: =E13+H13+K13+N13+Q13 -> 0 | V13: =U13+T13 -> 0
B14: =B13+1 -> 8 | D14: =SUMIF('Week 1'!$C$7:$C$36,Summary!C14,'Week 1'!$S$7:$S$36) -> 0 | E14: =SUMIF('Week 1'!$C$7:$C$36,Summary!C14,'Week 1'!$T$7:$T$36) -> 0 | F14: =SUMIF('Week 1'!$C$7:$C$36,Summary!C14,'Week 1'!$U$7:$U$36) -> 0 | G14: =SUMIF('Week 2'!$C$7:$C$36,Summary!C14,'Week 2'!$S$7:$S$36) -> 0 | H14: =SUMIF('Week 2'!$C$7:$C$36,Summary!C14,'Week 2'!$T$7:$T$36) -> 0 | I14: =SUMIF('Week 2'!$C$7:$C$36,Summary!C14,'Week 2'!$U$7:$U$36) -> 0 | J14: =SUMIF('Week 3'!$C$7:$C$36,Summary!C14,'Week 3'!$S$7:$S$36) -> 0 | K14: =SUMIF('Week 3'!$C$7:$C$36,Summary!C14,'Week 3'!$T$7:$T$36) -> 0 | L14: =SUMIF('Week 3'!$C$7:$C$36,Summary!C14,'Week 3'!$U$7:$U$36) -> 0 | M14: =SUMIF('Week 4'!$C$7:$C$36,Summary!C14,'Week 4'!$S$7:$S$36) -> 0 | N14: =SUMIF('Week 4'!$C$7:$C$36,Summary!C14,'Week 4'!$T$7:$T$36) -> 0 | O14: =SUMIF('Week 4'!$C$7:$C$36,Summary!C14,'Week 4'!$U$7:$U$36) -> 0 | P14: =SUMIF('Week 5'!$C$7:$C$36,Summary!C14,'Week 5'!$S$7:$S$36) -> 0 | Q14: =SUMIF('Week 5'!$C$7:$C$36,Summary!C14,'Week 5'!$T$7:$T$36) -> 0 | R14: =SUMIF('Week 5'!$C$7:$C$36,Summary!C14,'Week 5'!$U$7:$U$36) -> 0 | T14: =D14+G14+J14+M14+P14 -> 0 | U14: =E14+H14+K14+N14+Q14 -> 0 | V14: =U14+T14 -> 0
B15: =B14+1 -> 9 | D15: =SUMIF('Week 1'!$C$7:$C$36,Summary!C15,'Week 1'!$S$7:$S$36) -> 0 | E15: =SUMIF('Week 1'!$C$7:$C$36,Summary!C15,'Week 1'!$T$7:$T$36) -> 0 | F15: =SUMIF('Week 1'!$C$7:$C$36,Summary!C15,'Week 1'!$U$7:$U$36) -> 0 | G15: =SUMIF('Week 2'!$C$7:$C$36,Summary!C15,'Week 2'!$S$7:$S$36) -> 0 | H15: =SUMIF('Week 2'!$C$7:$C$36,Summary!C15,'Week 2'!$T$7:$T$36) -> 0 | I15: =SUMIF('Week 2'!$C$7:$C$36,Summary!C15,'Week 2'!$U$7:$U$36) -> 0 | J15: =SUMIF('Week 3'!$C$7:$C$36,Summary!C15,'Week 3'!$S$7:$S$36) -> 0 | K15: =SUMIF('Week 3'!$C$7:$C$36,Summary!C15,'Week 3'!$T$7:$T$36) -> 0 | L15: =SUMIF('Week 3'!$C$7:$C$36,Summary!C15,'Week 3'!$U$7:$U$36) -> 0 | M15: =SUMIF('Week 4'!$C$7:$C$36,Summary!C15,'Week 4'!$S$7:$S$36) -> 0 | N15: =SUMIF('Week 4'!$C$7:$C$36,Summary!C15,'Week 4'!$T$7:$T$36) -> 0 | O15: =SUMIF('Week 4'!$C$7:$C$36,Summary!C15,'Week 4'!$U$7:$U$36) -> 0 | P15: =SUMIF('Week 5'!$C$7:$C$36,Summary!C15,'Week 5'!$S$7:$S$36) -> 0 | Q15: =SUMIF('Week 5'!$C$7:$C$36,Summary!C15,'Week 5'!$T$7:$T$36) -> 0 | R15: =SUMIF('Week 5'!$C$7:$C$36,Summary!C15,'Week 5'!$U$7:$U$36) -> 0 | T15: =D15+G15+J15+M15+P15 -> 0 | U15: =E15+H15+K15+N15+Q15 -> 0 | V15: =U15+T15 -> 0
B16: =B15+1 -> 10 | D16: =SUMIF('Week 1'!$C$7:$C$36,Summary!C16,'Week 1'!$S$7:$S$36) -> 0 | E16: =SUMIF('Week 1'!$C$7:$C$36,Summary!C16,'Week 1'!$T$7:$T$36) -> 0 | F16: =SUMIF('Week 1'!$C$7:$C$36,Summary!C16,'Week 1'!$U$7:$U$36) -> 0 | G16: =SUMIF('Week 2'!$C$7:$C$36,Summary!C16,'Week 2'!$S$7:$S$36) -> 0 | H16: =SUMIF('Week 2'!$C$7:$C$36,Summary!C16,'Week 2'!$T$7:$T$36) -> 0 | I16: =SUMIF('Week 2'!$C$7:$C$36,Summary!C16,'Week 2'!$U$7:$U$36) -> 0 | J16: =SUMIF('Week 3'!$C$7:$C$36,Summary!C16,'Week 3'!$S$7:$S$36) -> 0 | K16: =SUMIF('Week 3'!$C$7:$C$36,Summary!C16,'Week 3'!$T$7:$T$36) -> 0 | L16: =SUMIF('Week 3'!$C$7:$C$36,Summary!C16,'Week 3'!$U$7:$U$36) -> 0 | M16: =SUMIF('Week 4'!$C$7:$C$36,Summary!C16,'Week 4'!$S$7:$S$36) -> 0 | N16: =SUMIF('Week 4'!$C$7:$C$36,Summary!C16,'Week 4'!$T$7:$T$36) -> 0 | O16: =SUMIF('Week 4'!$C$7:$C$36,Summary!C16,'Week 4'!$U$7:$U$36) -> 0 | P16: =SUMIF('Week 5'!$C$7:$C$36,Summary!C16,'Week 5'!$S$7:$S$36) -> 0 | Q16: =SUMIF('Week 5'!$C$7:$C$36,Summary!C16,'Week 5'!$T$7:$T$36) -> 0 | R16: =SUMIF('Week 5'!$C$7:$C$36,Summary!C16,'Week 5'!$U$7:$U$36) -> 0 | T16: =D16+G16+J16+M16+P16 -> 0 | U16: =E16+H16+K16+N16+Q16 -> 0 | V16: =U16+T16 -> 0
B17: =B16+1 -> 11 | D17: =SUMIF('Week 1'!$C$7:$C$36,Summary!C17,'Week 1'!$S$7:$S$36) -> 0 | E17: =SUMIF('Week 1'!$C$7:$C$36,Summary!C17,'Week 1'!$T$7:$T$36) -> 0 | F17: =SUMIF('Week 1'!$C$7:$C$36,Summary!C17,'Week 1'!$U$7:$U$36) -> 0 | G17: =SUMIF('Week 2'!$C$7:$C$36,Summary!C17,'Week 2'!$S$7:$S$36) -> 0 | H17: =SUMIF('Week 2'!$C$7:$C$36,Summary!C17,'Week 2'!$T$7:$T$36) -> 0 | I17: =SUMIF('Week 2'!$C$7:$C$36,Summary!C17,'Week 2'!$U$7:$U$36) -> 0 | J17: =SUMIF('Week 3'!$C$7:$C$36,Summary!C17,'Week 3'!$S$7:$S$36) -> 0 | K17: =SUMIF('Week 3'!$C$7:$C$36,Summary!C17,'Week 3'!$T$7:$T$36) -> 0 | L17: =SUMIF('Week 3'!$C$7:$C$36,Summary!C17,'Week 3'!$U$7:$U$36) -> 0 | M17: =SUMIF('Week 4'!$C$7:$C$36,Summary!C17,'Week 4'!$S$7:$S$36) -> 0 | N17: =SUMIF('Week 4'!$C$7:$C$36,Summary!C17,'Week 4'!$T$7:$T$36) -> 0 | O17: =SUMIF('Week 4'!$C$7:$C$36,Summary!C17,'Week 4'!$U$7:$U$36) -> 0 | P17: =SUMIF('Week 5'!$C$7:$C$36,Summary!C17,'Week 5'!$S$7:$S$36) -> 0 | Q17: =SUMIF('Week 5'!$C$7:$C$36,Summary!C17,'Week 5'!$T$7:$T$36) -> 0 | R17: =SUMIF('Week 5'!$C$7:$C$36,Summary!C17,'Week 5'!$U$7:$U$36) -> 0 | T17: =D17+G17+J17+M17+P17 -> 0 | U17: =E17+H17+K17+N17+Q17 -> 0 | V17: =U17+T17 -> 0
B18: =B17+1 -> 12 | D18: =SUMIF('Week 1'!$C$7:$C$36,Summary!C18,'Week 1'!$S$7:$S$36) -> 0 | E18: =SUMIF('Week 1'!$C$7:$C$36,Summary!C18,'Week 1'!$T$7:$T$36) -> 0 | F18: =SUMIF('Week 1'!$C$7:$C$36,Summary!C18,'Week 1'!$U$7:$U$36) -> 0 | G18: =SUMIF('Week 2'!$C$7:$C$36,Summary!C18,'Week 2'!$S$7:$S$36) -> 0 | H18: =SUMIF('Week 2'!$C$7:$C$36,Summary!C18,'Week 2'!$T$7:$T$36) -> 0 | I18: =SUMIF('Week 2'!$C$7:$C$36,Summary!C18,'Week 2'!$U$7:$U$36) -> 0 | J18: =SUMIF('Week 3'!$C$7:$C$36,Summary!C18,'Week 3'!$S$7:$S$36) -> 0 | K18: =SUMIF('Week 3'!$C$7:$C$36,Summary!C18,'Week 3'!$T$7:$T$36) -> 0 | L18: =SUMIF('Week 3'!$C$7:$C$36,Summary!C18,'Week 3'!$U$7:$U$36) -> 0 | M18: =SUMIF('Week 4'!$C$7:$C$36,Summary!C18,'Week 4'!$S$7:$S$36) -> 0 | N18: =SUMIF('Week 4'!$C$7:$C$36,Summary!C18,'Week 4'!$T$7:$T$36) -> 0 | O18: =SUMIF('Week 4'!$C$7:$C$36,Summary!C18,'Week 4'!$U$7:$U$36) -> 0 | P18: =SUMIF('Week 5'!$C$7:$C$36,Summary!C18,'Week 5'!$S$7:$S$36) -> 0 | Q18: =SUMIF('Week 5'!$C$7:$C$36,Summary!C18,'Week 5'!$T$7:$T$36) -> 0 | R18: =SUMIF('Week 5'!$C$7:$C$36,Summary!C18,'Week 5'!$U$7:$U$36) -> 0 | T18: =D18+G18+J18+M18+P18 -> 0 | U18: =E18+H18+K18+N18+Q18 -> 0 | V18: =U18+T18 -> 0
B19: =B18+1 -> 13 | D19: =SUMIF('Week 1'!$C$7:$C$36,Summary!C19,'Week 1'!$S$7:$S$36) -> 0 | E19: =SUMIF('Week 1'!$C$7:$C$36,Summary!C19,'Week 1'!$T$7:$T$36) -> 0 | F19: =SUMIF('Week 1'!$C$7:$C$36,Summary!C19,'Week 1'!$U$7:$U$36) -> 0 | G19: =SUMIF('Week 2'!$C$7:$C$36,Summary!C19,'Week 2'!$S$7:$S$36) -> 0 | H19: =SUMIF('Week 2'!$C$7:$C$36,Summary!C19,'Week 2'!$T$7:$T$36) -> 0 | I19: =SUMIF('Week 2'!$C$7:$C$36,Summary!C19,'Week 2'!$U$7:$U$36) -> 0 | J19: =SUMIF('Week 3'!$C$7:$C$36,Summary!C19,'Week 3'!$S$7:$S$36) -> 0 | K19: =SUMIF('Week 3'!$C$7:$C$36,Summary!C19,'Week 3'!$T$7:$T$36) -> 0 | L19: =SUMIF('Week 3'!$C$7:$C$36,Summary!C19,'Week 3'!$U$7:$U$36) -> 0 | M19: =SUMIF('Week 4'!$C$7:$C$36,Summary!C19,'Week 4'!$S$7:$S$36) -> 0 | N19: =SUMIF('Week 4'!$C$7:$C$36,Summary!C19,'Week 4'!$T$7:$T$36) -> 0 | O19: =SUMIF('Week 4'!$C$7:$C$36,Summary!C19,'Week 4'!$U$7:$U$36) -> 0 | P19: =SUMIF('Week 5'!$C$7:$C$36,Summary!C19,'Week 5'!$S$7:$S$36) -> 0 | Q19: =SUMIF('Week 5'!$C$7:$C$36,Summary!C19,'Week 5'!$T$7:$T$36) -> 0 | R19: =SUMIF('Week 5'!$C$7:$C$36,Summary!C19,'Week 5'!$U$7:$U$36) -> 0 | T19: =D19+G19+J19+M19+P19 -> 0 | U19: =E19+H19+K19+N19+Q19 -> 0 | V19: =U19+T19 -> 0
B20: =B19+1 -> 14 | D20: =SUMIF('Week 1'!$C$7:$C$36,Summary!C20,'Week 1'!$S$7:$S$36) -> 0 | E20: =SUMIF('Week 1'!$C$7:$C$36,Summary!C20,'Week 1'!$T$7:$T$36) -> 0 | F20: =SUMIF('Week 1'!$C$7:$C$36,Summary!C20,'Week 1'!$U$7:$U$36) -> 0 | G20: =SUMIF('Week 2'!$C$7:$C$36,Summary!C20,'Week 2'!$S$7:$S$36) -> 0 | H20: =SUMIF('Week 2'!$C$7:$C$36,Summary!C20,'Week 2'!$T$7:$T$36) -> 0 | I20: =SUMIF('Week 2'!$C$7:$C$36,Summary!C20,'Week 2'!$U$7:$U$36) -> 0 | J20: =SUMIF('Week 3'!$C$7:$C$36,Summary!C20,'Week 3'!$S$7:$S$36) -> 0 | K20: =SUMIF('Week 3'!$C$7:$C$36,Summary!C20,'Week 3'!$T$7:$T$36) -> 0 | L20: =SUMIF('Week 3'!$C$7:$C$36,Summary!C20,'Week 3'!$U$7:$U$36) -> 0 | M20: =SUMIF('Week 4'!$C$7:$C$36,Summary!C20,'Week 4'!$S$7:$S$36) -> 0 | N20: =SUMIF('Week 4'!$C$7:$C$36,Summary!C20,'Week 4'!$T$7:$T$36) -> 0 | O20: =SUMIF('Week 4'!$C$7:$C$36,Summary!C20,'Week 4'!$U$7:$U$36) -> 0 | P20: =SUMIF('Week 5'!$C$7:$C$36,Summary!C20,'Week 5'!$S$7:$S$36) -> 0 | Q20: =SUMIF('Week 5'!$C$7:$C$36,Summary!C20,'Week 5'!$T$7:$T$36) -> 0 | R20: =SUMIF('Week 5'!$C$7:$C$36,Summary!C20,'Week 5'!$U$7:$U$36) -> 0 | T20: =D20+G20+J20+M20+P20 -> 0 | U20: =E20+H20+K20+N20+Q20 -> 0 | V20: =U20+T20 -> 0
B21: =B20+1 -> 15 | D21: =SUMIF('Week 1'!$C$7:$C$36,Summary!C21,'Week 1'!$S$7:$S$36) -> 0 | E21: =SUMIF('Week 1'!$C$7:$C$36,Summary!C21,'Week 1'!$T$7:$T$36) -> 0 | F21: =SUMIF('Week 1'!$C$7:$C$36,Summary!C21,'Week 1'!$U$7:$U$36) -> 0 | G21: =SUMIF('Week 2'!$C$7:$C$36,Summary!C21,'Week 2'!$S$7:$S$36) -> 0 | H21: =SUMIF('Week 2'!$C$7:$C$36,Summary!C21,'Week 2'!$T$7:$T$36) -> 0 | I21: =SUMIF('Week 2'!$C$7:$C$36,Summary!C21,'Week 2'!$U$7:$U$36) -> 0 | J21: =SUMIF('Week 3'!$C$7:$C$36,Summary!C21,'Week 3'!$S$7:$S$36) -> 0 | K21: =SUMIF('Week 3'!$C$7:$C$36,Summary!C21,'Week 3'!$T$7:$T$36) -> 0 | L21: =SUMIF('Week 3'!$C$7:$C$36,Summary!C21,'Week 3'!$U$7:$U$36) -> 0 | M21: =SUMIF('Week 4'!$C$7:$C$36,Summary!C21,'Week 4'!$S$7:$S$36) -> 0 | N21: =SUMIF('Week 4'!$C$7:$C$36,Summary!C21,'Week 4'!$T$7:$T$36) -> 0 | O21: =SUMIF('Week 4'!$C$7:$C$36,Summary!C21,'Week 4'!$U$7:$U$36) -> 0 | P21: =SUMIF('Week 5'!$C$7:$C$36,Summary!C21,'Week 5'!$S$7:$S$36) -> 0 | Q21: =SUMIF('Week 5'!$C$7:$C$36,Summary!C21,'Week 5'!$T$7:$T$36) -> 0 | R21: =SUMIF('Week 5'!$C$7:$C$36,Summary!C21,'Week 5'!$U$7:$U$36) -> 0 | T21: =D21+G21+J21+M21+P21 -> 0 | U21: =E21+H21+K21+N21+Q21 -> 0 | V21: =U21+T21 -> 0
B22: =B21+1 -> 16 | D22: =SUMIF('Week 1'!$C$7:$C$36,Summary!C22,'Week 1'!$S$7:$S$36) -> 0 | E22: =SUMIF('Week 1'!$C$7:$C$36,Summary!C22,'Week 1'!$T$7:$T$36) -> 0 | F22: =SUMIF('Week 1'!$C$7:$C$36,Summary!C22,'Week 1'!$U$7:$U$36) -> 0 | G22: =SUMIF('Week 2'!$C$7:$C$36,Summary!C22,'Week 2'!$S$7:$S$36) -> 0 | H22: =SUMIF('Week 2'!$C$7:$C$36,Summary!C22,'Week 2'!$T$7:$T$36) -> 0 | I22: =SUMIF('Week 2'!$C$7:$C$36,Summary!C22,'Week 2'!$U$7:$U$36) -> 0 | J22: =SUMIF('Week 3'!$C$7:$C$36,Summary!C22,'Week 3'!$S$7:$S$36) -> 0 | K22: =SUMIF('Week 3'!$C$7:$C$36,Summary!C22,'Week 3'!$T$7:$T$36) -> 0 | L22: =SUMIF('Week 3'!$C$7:$C$36,Summary!C22,'Week 3'!$U$7:$U$36) -> 0 | M22: =SUMIF('Week 4'!$C$7:$C$36,Summary!C22,'Week 4'!$S$7:$S$36) -> 0 | N22: =SUMIF('Week 4'!$C$7:$C$36,Summary!C22,'Week 4'!$T$7:$T$36) -> 0 | O22: =SUMIF('Week 4'!$C$7:$C$36,Summary!C22,'Week 4'!$U$7:$U$36) -> 0 | P22: =SUMIF('Week 5'!$C$7:$C$36,Summary!C22,'Week 5'!$S$7:$S$36) -> 0 | Q22: =SUMIF('Week 5'!$C$7:$C$36,Summary!C22,'Week 5'!$T$7:$T$36) -> 0 | R22: =SUMIF('Week 5'!$C$7:$C$36,Summary!C22,'Week 5'!$U$7:$U$36) -> 0 | T22: =D22+G22+J22+M22+P22 -> 0 | U22: =E22+H22+K22+N22+Q22 -> 0 | V22: =U22+T22 -> 0
B23: =B22+1 -> 17 | D23: =SUMIF('Week 1'!$C$7:$C$36,Summary!C23,'Week 1'!$S$7:$S$36) -> 0 | E23: =SUMIF('Week 1'!$C$7:$C$36,Summary!C23,'Week 1'!$T$7:$T$36) -> 0 | F23: =SUMIF('Week 1'!$C$7:$C$36,Summary!C23,'Week 1'!$U$7:$U$36) -> 0 | G23: =SUMIF('Week 2'!$C$7:$C$36,Summary!C23,'Week 2'!$S$7:$S$36) -> 0 | H23: =SUMIF('Week 2'!$C$7:$C$36,Summary!C23,'Week 2'!$T$7:$T$36) -> 0 | I23: =SUMIF('Week 2'!$C$7:$C$36,Summary!C23,'Week 2'!$U$7:$U$36) -> 0 | J23: =SUMIF('Week 3'!$C$7:$C$36,Summary!C23,'Week 3'!$S$7:$S$36) -> 0 | K23: =SUMIF('Week 3'!$C$7:$C$36,Summary!C23,'Week 3'!$T$7:$T$36) -> 0 | L23: =SUMIF('Week 3'!$C$7:$C$36,Summary!C23,'Week 3'!$U$7:$U$36) -> 0 | M23: =SUMIF('Week 4'!$C$7:$C$36,Summary!C23,'Week 4'!$S$7:$S$36) -> 0 | N23: =SUMIF('Week 4'!$C$7:$C$36,Summary!C23,'Week 4'!$T$7:$T$36) -> 0 | O23: =SUMIF('Week 4'!$C$7:$C$36,Summary!C23,'Week 4'!$U$7:$U$36) -> 0 | P23: =SUMIF('Week 5'!$C$7:$C$36,Summary!C23,'Week 5'!$S$7:$S$36) -> 0 | Q23: =SUMIF('Week 5'!$C$7:$C$36,Summary!C23,'Week 5'!$T$7:$T$36) -> 0 | R23: =SUMIF('Week 5'!$C$7:$C$36,Summary!C23,'Week 5'!$U$7:$U$36) -> 0 | T23: =D23+G23+J23+M23+P23 -> 0 | U23: =E23+H23+K23+N23+Q23 -> 0 | V23: =U23+T23 -> 0
... B36: =B35+1 -> 30 | D36: =SUMIF('Week 1'!$C$7:$C$36,Summary!C36,'Week 1'!$S$7:$S$36) -> 0 | E36: =SUMIF('Week 1'!$C$7:$C$36,Summary!C36,'Week 1'!$T$7:$T$36) -> 0 | F36: =SUMIF('Week 1'!$C$7:$C$36,Summary!C36,'Week 1'!$U$7:$U$36) -> 0 | G36: =SUMIF('Week 2'!$C$7:$C$36,Summary!C36,'Week 2'!$S$7:$S$36) -> 0 | H36: =SUMIF('Week 2'!$C$7:$C$36,Summary!C36,'Week 2'!$T$7:$T$36) -> 0 | I36: =SUMIF('Week 2'!$C$7:$C$36,Summary!C36,'Week 2'!$U$7:$U$36) -> 0 | J36: =SUMIF('Week 3'!$C$7:$C$36,Summary!C36,'Week 3'!$S$7:$S$36) -> 0 | K36: =SUMIF('Week 3'!$C$7:$C$36,Summary!C36,'Week 3'!$T$7:$T$36) -> 0 | L36: =SUMIF('Week 3'!$C$7:$C$36,Summary!C36,'Week 3'!$U$7:$U$36) -> 0 | M36: =SUMIF('Week 4'!$C$7:$C$36,Summary!C36,'Week 4'!$S$7:$S$36) -> 0 | N36: =SUMIF('Week 4'!$C$7:$C$36,Summary!C36,'Week 4'!$T$7:$T$36) -> 0 | O36: =SUMIF('Week 4'!$C$7:$C$36,Summary!C36,'Week 4'!$U$7:$U$36) -> 0 | P36: =SUMIF('Week 5'!$C$7:$C$36,Summary!C36,'Week 5'!$S$7:$S$36) -> 0 | Q36: =SUMIF('Week 5'!$C$7:$C$36,Summary!C36,'Week 5'!$T$7:$T$36) -> 0 | R36: =SUMIF('Week 5'!$C$7:$C$36,Summary!C36,'Week 5'!$U$7:$U$36) -> 0 | T36: =D36+G36+J36+M36+P36 -> 0 | U36: =E36+H36+K36+N36+Q36 -> 0 | V36: =U36+T36 -> 0
B38: Total | D38: =SUM(D7:D36) -> 65 | E38: =SUM(E7:E36) -> 12 | F38: =SUM(F7:F36) -> 77 | G38: =SUM(G7:G36) -> 0 | H38: =SUM(H7:H36) -> 0 | I38: =SUM(I7:I36) -> 0 | J38: =SUM(J7:J36) -> 0 | K38: =SUM(K7:K36) -> 0 | ... R38: =SUM(R7:R36) -> 0 | T38: =SUM(T7:T36) -> 65 | U38: =SUM(U7:U36) -> 12 | V38: =SUM(V7:V36) -> 77

Sheet Week 1
B2: Minggu Pertama | D2: 44682
B4: S.No | C4: Nama | D4: =D2 -> 44682 | F4: =IFERROR((IF(MONTH(D4)=MONTH(D4+1),D4+1," ")),"") -> 44683 | H4: =IFERROR((IF(MONTH(F4)=MONTH(F4+1),F4+1," ")),"") -> 44684 | J4: =IFERROR((IF(MONTH(H4)=MONTH(H4+1),H4+1," ")),"") -> 44685 | L4: =IFERROR((IF(MONTH(J4)=MONTH(J4+1),J4+1," ")),"") -> 44686 | N4: =IFERROR((IF(MONTH(L4)=MONTH(L4+1),L4+1," ")),"") -> 44687 | P4: =IFERROR((IF(MONTH(N4)=MONTH(N4+1),N4+1," ")),"") -> 44688 | S4: Total Minggu Ini
D5: =TEXT(D4,"dddd") -> Sunday | F5: =TEXT(F4,"dddd") -> Monday | H5: =TEXT(H4,"dddd") -> Tuesday | J5: =TEXT(J4,"dddd") -> Wednesday | L5: =TEXT(L4,"dddd") -> Thursday | N5: =TEXT(N4,"dddd") -> Friday | P5: =TEXT(P4,"dddd") -> Saturday
D6: Total Jumlah | E6: Status | F6: Total Jumlah | G6: Status | H6: Total Jumlah | I6: Status | J6: Total Jumlah | K6: Status | L6: Total Jumlah | M6: Status | N6: Total Jumlah | O6: Status | P6: Total Jumlah | Q6: Status | S6: Total Dibayar | T6: Total Belum Dibayar | U6: Total
B7: 1 | C7: Mr. B | D7: 6 | E7: Not Paid | F7: 6 | G7: Not Paid | H7: 6 | I7: Paid | J7: 6 | K7: Paid | L7: 6 | M7: Paid | N7: 6 | O7: Paid | P7: 6 | Q7: Paid | S7: =IF(E7="Paid",D7,0)+IF(G7="Paid",F7,0)+IF(I7="Paid",H7,0)+IF(K7="Paid",J7,0)+IF(M7="Paid",L7,0)+IF(O7="Paid",N7,0)+IF(Q7="Paid",P7,0) -> 30 | T7: =IF(E7="Not Paid",D7,0)+IF(G7="Not Paid",F7,0)+IF(I7="Not Paid",H7,0)+IF(K7="Not Paid",J7,0)+IF(M7="Not Paid",L7,0)+IF(O7="Not Paid",N7,0)+IF(Q7="Not Paid",P7,0) -> 12 | U7: =T7+S7 -> 42
B8: =B7+1 -> 2 | C8: Mr. A | D8: 2 | E8: Paid | F8: 2 | G8: Paid | H8: 2 | I8: Paid | J8: 2 | K8: Paid | L8: 2 | M8: Paid | N8: 2 | O8: Paid | P8: 2 | Q8: Paid | S8: =IF(E8="Paid",D8,0)+IF(G8="Paid",F8,0)+IF(I8="Paid",H8,0)+IF(K8="Paid",J8,0)+IF(M8="Paid",L8,0)+IF(O8="Paid",N8,0)+IF(Q8="Paid",P8,0) -> 14 | T8: =IF(E8="Not Paid",D8,0)+IF(G8="Not Paid",F8,0)+IF(I8="Not Paid",H8,0)+IF(K8="Not Paid",J8,0)+IF(M8="Not Paid",L8,0)+IF(O8="Not Paid",N8,0)+IF(Q8="Not Paid",P8,0) -> 0 | U8: =T8+S8 -> 14
B9: =B8+1 -> 3 | C9: Mr. C | D9: 3 | E9: Paid | F9: 3 | G9: Paid | H9: 3 | I9: Paid | J9: 3 | K9: Paid | L9: 3 | M9: Paid | N9: 3 | O9: Paid | P9: 3 | Q9: Paid | S9: =IF(E9="Paid",D9,0)+IF(G9="Paid",F9,0)+IF(I9="Paid",H9,0)+IF(K9="Paid",J9,0)+IF(M9="Paid",L9,0)+IF(O9="Paid",N9,0)+IF(Q9="Paid",P9,0) -> 21 | T9: =IF(E9="Not Paid",D9,0)+IF(G9="Not Paid",F9,0)+IF(I9="Not Paid",H9,0)+IF(K9="Not Paid",J9,0)+IF(M9="Not Paid",L9,0)+IF(O9="Not Paid",N9,0)+IF(Q9="Not Paid",P9,0) -> 0 | U9: =T9+S9 -> 21
B10: =B9+1 -> 4 | C10: Juli | D10: 4 | E10: Paid | F10: 4 | G10: Paid | H10: 4 | I10: Paid | J10: 4 | K10: Paid | L10: 4 | M10: Paid | N10: 4 | O10: Paid | P10: 4 | Q10: Paid | S10: =IF(E10="Paid",D10,0)+IF(G10="Paid",F10,0)+IF(I10="Paid",H10,0)+IF(K10="Paid",J10,0)+IF(M10="Paid",L10,0)+IF(O10="Paid",N10,0)+IF(Q10="Paid",P10,0) -> 28 | T10: =IF(E10="Not Paid",D10,0)+IF(G10="Not Paid",F10,0)+IF(I10="Not Paid",H10,0)+IF(K10="Not Paid",J10,0)+IF(M10="Not Paid",L10,0)+IF(O10="Not Paid",N10,0)+IF(Q10="Not Paid",P10,0) -> 0 | U10: =T10+S10 -> 28
B11: =B10+1 -> 5 | C11: Juli | D11: 5 | E11: Paid | F11: 5 | G11: Paid | H11: 5 | I11: Paid | J11: 5 | K11: Paid | L11: 5 | M11: Paid | N11: 5 | O11: Paid | P11: 5 | Q11: Paid | S11: =IF(E11="Paid",D11,0)+IF(G11="Paid",F11,0)+IF(I11="Paid",H11,0)+IF(K11="Paid",J11,0)+IF(M11="Paid",L11,0)+IF(O11="Paid",N11,0)+IF(Q11="Paid",P11,0) -> 35 | T11: =IF(E11="Not Paid",D11,0)+IF(G11="Not Paid",F11,0)+IF(I11="Not Paid",H11,0)+IF(K11="Not Paid",J11,0)+IF(M11="Not Paid",L11,0)+IF(O11="Not Paid",N11,0)+IF(Q11="Not Paid",P11,0) -> 0 | U11: =T11+S11 -> 35
B12: =B11+1 -> 6 | C12: Juli | E12: Paid | G12: Paid | I12: Paid | K12: Paid | M12: Paid | O12: Paid | Q12: Paid | S12: =IF(E12="Paid",D12,0)+IF(G12="Paid",F12,0)+IF(I12="Paid",H12,0)+IF(K12="Paid",J12,0)+IF(M12="Paid",L12,0)+IF(O12="Paid",N12,0)+IF(Q12="Paid",P12,0) -> 0 | T12: =IF(E12="Not Paid",D12,0)+IF(G12="Not Paid",F12,0)+IF(I12="Not Paid",H12,0)+IF(K12="Not Paid",J12,0)+IF(M12="Not Paid",L12,0)+IF(O12="Not Paid",N12,0)+IF(Q12="Not Paid",P12,0) -> 0 | U12: =T12+S12 -> 0
B13: =B12+1 -> 7 | C13: Juli | E13: Paid | G13: Paid | I13: Paid | K13: Paid | M13: Paid | O13: Paid | Q13: Paid | S13: =IF(E13="Paid",D13,0)+IF(G13="Paid",F13,0)+IF(I13="Paid",H13,0)+IF(K13="Paid",J13,0)+IF(M13="Paid",L13,0)+IF(O13="Paid",N13,0)+IF(Q13="Paid",P13,0) -> 0 | T13: =IF(E13="Not Paid",D13,0)+IF(G13="Not Paid",F13,0)+IF(I13="Not Paid",H13,0)+IF(K13="Not Paid",J13,0)+IF(M13="Not Paid",L13,0)+IF(O13="Not Paid",N13,0)+IF(Q13="Not Paid",P13,0) -> 0 | U13: =T13+S13 -> 0
B14: =B13+1 -> 8 | C14: Juli | E14: Paid | G14: Paid | I14: Paid | K14: Paid | M14: Paid | O14: Paid | Q14: Paid | S14: =IF(E14="Paid",D14,0)+IF(G14="Paid",F14,0)+IF(I14="Paid",H14,0)+IF(K14="Paid",J14,0)+IF(M14="Paid",L14,0)+IF(O14="Paid",N14,0)+IF(Q14="Paid",P14,0) -> 0 | T14: =IF(E14="Not Paid",D14,0)+IF(G14="Not Paid",F14,0)+IF(I14="Not Paid",H14,0)+IF(K14="Not Paid",J14,0)+IF(M14="Not Paid",L14,0)+IF(O14="Not Paid",N14,0)+IF(Q14="Not Paid",P14,0) -> 0 | U14: =T14+S14 -> 0
B15: =B14+1 -> 9 | C15: Juli | E15: Paid | G15: Paid | I15: Paid | K15: Paid | M15: Paid | O15: Paid | Q15: Paid | S15: =IF(E15="Paid",D15,0)+IF(G15="Paid",F15,0)+IF(I15="Paid",H15,0)+IF(K15="Paid",J15,0)+IF(M15="Paid",L15,0)+IF(O15="Paid",N15,0)+IF(Q15="Paid",P15,0) -> 0 | T15: =IF(E15="Not Paid",D15,0)+IF(G15="Not Paid",F15,0)+IF(I15="Not Paid",H15,0)+IF(K15="Not Paid",J15,0)+IF(M15="Not Paid",L15,0)+IF(O15="Not Paid",N15,0)+IF(Q15="Not Paid",P15,0) -> 0 | U15: =T15+S15 -> 0
B16: =B15+1 -> 10 | C16: Juli | S16: =IF(E16="Paid",D16,0)+IF(G16="Paid",F16,0)+IF(I16="Paid",H16,0)+IF(K16="Paid",J16,0)+IF(M16="Paid",L16,0)+IF(O16="Paid",N16,0)+IF(Q16="Paid",P16,0) -> 0 | T16: =IF(E16="Not Paid",D16,0)+IF(G16="Not Paid",F16,0)+IF(I16="Not Paid",H16,0)+IF(K16="Not Paid",J16,0)+IF(M16="Not Paid",L16,0)+IF(O16="Not Paid",N16,0)+IF(Q16="Not Paid",P16,0) -> 0 | U16: =T16+S16 -> 0
B17: =B16+1 -> 11 | C17: Juli | S17: =IF(E17="Paid",D17,0)+IF(G17="Paid",F17,0)+IF(I17="Paid",H17,0)+IF(K17="Paid",J17,0)+IF(M17="Paid",L17,0)+IF(O17="Paid",N17,0)+IF(Q17="Paid",P17,0) -> 0 | T17: =IF(E17="Not Paid",D17,0)+IF(G17="Not Paid",F17,0)+IF(I17="Not Paid",H17,0)+IF(K17="Not Paid",J17,0)+IF(M17="Not Paid",L17,0)+IF(O17="Not Paid",N17,0)+IF(Q17="Not Paid",P17,0) -> 0 | U17: =T17+S17 -> 0
B18: =B17+1 -> 12 | C18: Juli | S18: =IF(E18="Paid",D18,0)+IF(G18="Paid",F18,0)+IF(I18="Paid",H18,0)+IF(K18="Paid",J18,0)+IF(M18="Paid",L18,0)+IF(O18="Paid",N18,0)+IF(Q18="Paid",P18,0) -> 0 | T18: =IF(E18="Not Paid",D18,0)+IF(G18="Not Paid",F18,0)+IF(I18="Not Paid",H18,0)+IF(K18="Not Paid",J18,0)+IF(M18="Not Paid",L18,0)+IF(O18="Not Paid",N18,0)+IF(Q18="Not Paid",P18,0) -> 0 | U18: =T18+S18 -> 0
B19: =B18+1 -> 13 | C19: Juli | S19: =IF(E19="Paid",D19,0)+IF(G19="Paid",F19,0)+IF(I19="Paid",H19,0)+IF(K19="Paid",J19,0)+IF(M19="Paid",L19,0)+IF(O19="Paid",N19,0)+IF(Q19="Paid",P19,0) -> 0 | T19: =IF(E19="Not Paid",D19,0)+IF(G19="Not Paid",F19,0)+IF(I19="Not Paid",H19,0)+IF(K19="Not Paid",J19,0)+IF(M19="Not Paid",L19,0)+IF(O19="Not Paid",N19,0)+IF(Q19="Not Paid",P19,0) -> 0 | U19: =T19+S19 -> 0
B20: =B19+1 -> 14 | S20: =IF(E20="Paid",D20,0)+IF(G20="Paid",F20,0)+IF(I20="Paid",H20,0)+IF(K20="Paid",J20,0)+IF(M20="Paid",L20,0)+IF(O20="Paid",N20,0)+IF(Q20="Paid",P20,0) -> 0 | T20: =IF(E20="Not Paid",D20,0)+IF(G20="Not Paid",F20,0)+IF(I20="Not Paid",H20,0)+IF(K20="Not Paid",J20,0)+IF(M20="Not Paid",L20,0)+IF(O20="Not Paid",N20,0)+IF(Q20="Not Paid",P20,0) -> 0 | U20: =T20+S20 -> 0
B21: =B20+1 -> 15 | S21: =IF(E21="Paid",D21,0)+IF(G21="Paid",F21,0)+IF(I21="Paid",H21,0)+IF(K21="Paid",J21,0)+IF(M21="Paid",L21,0)+IF(O21="Paid",N21,0)+IF(Q21="Paid",P21,0) -> 0 | T21: =IF(E21="Not Paid",D21,0)+IF(G21="Not Paid",F21,0)+IF(I21="Not Paid",H21,0)+IF(K21="Not Paid",J21,0)+IF(M21="Not Paid",L21,0)+IF(O21="Not Paid",N21,0)+IF(Q21="Not Paid",P21,0) -> 0 | U21: =T21+S21 -> 0
B22: =B21+1 -> 16 | S22: =IF(E22="Paid",D22,0)+IF(G22="Paid",F22,0)+IF(I22="Paid",H22,0)+IF(K22="Paid",J22,0)+IF(M22="Paid",L22,0)+IF(O22="Paid",N22,0)+IF(Q22="Paid",P22,0) -> 0 | T22: =IF(E22="Not Paid",D22,0)+IF(G22="Not Paid",F22,0)+IF(I22="Not Paid",H22,0)+IF(K22="Not Paid",J22,0)+IF(M22="Not Paid",L22,0)+IF(O22="Not Paid",N22,0)+IF(Q22="Not Paid",P22,0) -> 0 | U22: =T22+S22 -> 0
B23: =B22+1 -> 17 | S23: =IF(E23="Paid",D23,0)+IF(G23="Paid",F23,0)+IF(I23="Paid",H23,0)+IF(K23="Paid",J23,0)+IF(M23="Paid",L23,0)+IF(O23="Paid",N23,0)+IF(Q23="Paid",P23,0) -> 0 | T23: =IF(E23="Not Paid",D23,0)+IF(G23="Not Paid",F23,0)+IF(I23="Not Paid",H23,0)+IF(K23="Not Paid",J23,0)+IF(M23="Not Paid",L23,0)+IF(O23="Not Paid",N23,0)+IF(Q23="Not Paid",P23,0) -> 0 | U23: =T23+S23 -> 0
B24: =B23+1 -> 18 | S24: =IF(E24="Paid",D24,0)+IF(G24="Paid",F24,0)+IF(I24="Paid",H24,0)+IF(K24="Paid",J24,0)+IF(M24="Paid",L24,0)+IF(O24="Paid",N24,0)+IF(Q24="Paid",P24,0) -> 0 | T24: =IF(E24="Not Paid",D24,0)+IF(G24="Not Paid",F24,0)+IF(I24="Not Paid",H24,0)+IF(K24="Not Paid",J24,0)+IF(M24="Not Paid",L24,0)+IF(O24="Not Paid",N24,0)+IF(Q24="Not Paid",P24,0) -> 0 | U24: =T24+S24 -> 0
B25: =B24+1 -> 19 | S25: =IF(E25="Paid",D25,0)+IF(G25="Paid",F25,0)+IF(I25="Paid",H25,0)+IF(K25="Paid",J25,0)+IF(M25="Paid",L25,0)+IF(O25="Paid",N25,0)+IF(Q25="Paid",P25,0) -> 0 | T25: =IF(E25="Not Paid",D25,0)+IF(G25="Not Paid",F25,0)+IF(I25="Not Paid",H25,0)+IF(K25="Not Paid",J25,0)+IF(M25="Not Paid",L25,0)+IF(O25="Not Paid",N25,0)+IF(Q25="Not Paid",P25,0) -> 0 | U25: =T25+S25 -> 0
B26: =B25+1 -> 20 | S26: =IF(E26="Paid",D26,0)+IF(G26="Paid",F26,0)+IF(I26="Paid",H26,0)+IF(K26="Paid",J26,0)+IF(M26="Paid",L26,0)+IF(O26="Paid",N26,0)+IF(Q26="Paid",P26,0) -> 0 | T26: =IF(E26="Not Paid",D26,0)+IF(G26="Not Paid",F26,0)+IF(I26="Not Paid",H26,0)+IF(K26="Not Paid",J26,0)+IF(M26="Not Paid",L26,0)+IF(O26="Not Paid",N26,0)+IF(Q26="Not Paid",P26,0) -> 0 | U26: =T26+S26 -> 0
B27: =B26+1 -> 21 | S27: =IF(E27="Paid",D27,0)+IF(G27="Paid",F27,0)+IF(I27="Paid",H27,0)+IF(K27="Paid",J27,0)+IF(M27="Paid",L27,0)+IF(O27="Paid",N27,0)+IF(Q27="Paid",P27,0) -> 0 | T27: =IF(E27="Not Paid",D27,0)+IF(G27="Not Paid",F27,0)+IF(I27="Not Paid",H27,0)+IF(K27="Not Paid",J27,0)+IF(M27="Not Paid",L27,0)+IF(O27="Not Paid",N27,0)+IF(Q27="Not Paid",P27,0) -> 0 | U27: =T27+S27 -> 0
B28: =B27+1 -> 22 | S28: =IF(E28="Paid",D28,0)+IF(G28="Paid",F28,0)+IF(I28="Paid",H28,0)+IF(K28="Paid",J28,0)+IF(M28="Paid",L28,0)+IF(O28="Paid",N28,0)+IF(Q28="Paid",P28,0) -> 0 | T28: =IF(E28="Not Paid",D28,0)+IF(G28="Not Paid",F28,0)+IF(I28="Not Paid",H28,0)+IF(K28="Not Paid",J28,0)+IF(M28="Not Paid",L28,0)+IF(O28="Not Paid",N28,0)+IF(Q28="Not Paid",P28,0) -> 0 | U28: =T28+S28 -> 0
B29: =B28+1 -> 23 | S29: =IF(E29="Paid",D29,0)+IF(G29="Paid",F29,0)+IF(I29="Paid",H29,0)+IF(K29="Paid",J29,0)+IF(M29="Paid",L29,0)+IF(O29="Paid",N29,0)+IF(Q29="Paid",P29,0) -> 0 | T29: =IF(E29="Not Paid",D29,0)+IF(G29="Not Paid",F29,0)+IF(I29="Not Paid",H29,0)+IF(K29="Not Paid",J29,0)+IF(M29="Not Paid",L29,0)+IF(O29="Not Paid",N29,0)+IF(Q29="Not Paid",P29,0) -> 0 | U29: =T29+S29 -> 0
B30: =B29+1 -> 24 | S30: =IF(E30="Paid",D30,0)+IF(G30="Paid",F30,0)+IF(I30="Paid",H30,0)+IF(K30="Paid",J30,0)+IF(M30="Paid",L30,0)+IF(O30="Paid",N30,0)+IF(Q30="Paid",P30,0) -> 0 | T30: =IF(E30="Not Paid",D30,0)+IF(G30="Not Paid",F30,0)+IF(I30="Not Paid",H30,0)+IF(K30="Not Paid",J30,0)+IF(M30="Not Paid",L30,0)+IF(O30="Not Paid",N30,0)+IF(Q30="Not Paid",P30,0) -> 0 | U30: =T30+S30 -> 0
B31: =B30+1 -> 25 | S31: =IF(E31="Paid",D31,0)+IF(G31="Paid",F31,0)+IF(I31="Paid",H31,0)+IF(K31="Paid",J31,0)+IF(M31="Paid",L31,0)+IF(O31="Paid",N31,0)+IF(Q31="Paid",P31,0) -> 0 | T31: =IF(E31="Not Paid",D31,0)+IF(G31="Not Paid",F31,0)+IF(I31="Not Paid",H31,0)+IF(K31="Not Paid",J31,0)+IF(M31="Not Paid",L31,0)+IF(O31="Not Paid",N31,0)+IF(Q31="Not Paid",P31,0) -> 0 | U31: =T31+S31 -> 0
... B34: =B33+1 -> 28 | S34: =IF(E34="Paid",D34,0)+IF(G34="Paid",F34,0)+IF(I34="Paid",H34,0)+IF(K34="Paid",J34,0)+IF(M34="Paid",L34,0)+IF(O34="Paid",N34,0)+IF(Q34="Paid",P34,0) -> 0 | T34: =IF(E34="Not Paid",D34,0)+IF(G34="Not Paid",F34,0)+IF(I34="Not Paid",H34,0)+IF(K34="Not Paid",J34,0)+IF(M34="Not Paid",L34,0)+IF(O34="Not Paid",N34,0)+IF(Q34="Not Paid",P34,0) -> 0 | U34: =T34+S34 -> 0
B35: =B34+1 -> 29 | C35: Juli | S35: =IF(E35="Paid",D35,0)+IF(G35="Paid",F35,0)+IF(I35="Paid",H35,0)+IF(K35="Paid",J35,0)+IF(M35="Paid",L35,0)+IF(O35="Paid",N35,0)+IF(Q35="Paid",P35,0) -> 0 | T35: =IF(E35="Not Paid",D35,0)+IF(G35="Not Paid",F35,0)+IF(I35="Not Paid",H35,0)+IF(K35="Not Paid",J35,0)+IF(M35="Not Paid",L35,0)+IF(O35="Not Paid",N35,0)+IF(Q35="Not Paid",P35,0) -> 0 | U35: =T35+S35 -> 0
B36: =B35+1 -> 30 | C36: Juli | E36: Paid | G36: Paid | I36: Paid | K36: Paid | M36: Paid | O36: Paid | Q36: Paid | S36: =IF(E36="Paid",D36,0)+IF(G36="Paid",F36,0)+IF(I36="Paid",H36,0)+IF(K36="Paid",J36,0)+IF(M36="Paid",L36,0)+IF(O36="Paid",N36,0)+IF(Q36="Paid",P36,0) -> 0 | T36: =IF(E36="Not Paid",D36,0)+IF(G36="Not Paid",F36,0)+IF(I36="Not Paid",H36,0)+IF(K36="Not Paid",J36,0)+IF(M36="Not Paid",L36,0)+IF(O36="Not Paid",N36,0)+IF(Q36="Not Paid",P36,0) -> 0 | U36: =T36+S36 -> 0
B38: Total | D38: =SUM(D7:D36) -> 20 | F38: =SUM(F7:F36) -> 20 | H38: =SUM(H7:H36) -> 20 | J38: =SUM(J7:J36) -> 20 | L38: =SUM(L7:L36) -> 20 | N38: =SUM(N7:N36) -> 20 | P38: =SUM(P7:P36) -> 20 | S38: =SUM(S7:S36) -> 128 | T38: =SUM(T7:T36) -> 12 | U38: =SUM(U7:U36) -> 140

Sheet Week 2
B2: Minggu Kedua | D2: ='Week 1'!D2:E2 -> 44682
B4: S.No | C4: Nama | D4: =IFERROR((IF(MONTH('Week 1'!P4)=MONTH('Week 1'!P4+1),('Week 1'!P4+1),"")),"") -> 44689 | F4: =IFERROR((IF(MONTH(D4)=MONTH(D4+1),D4+1," ")),"") -> 44690 | H4: =IFERROR((IF(MONTH(F4)=MONTH(F4+1),F4+1," ")),"") -> 44691 | J4: =IFERROR((IF(MONTH(H4)=MONTH(H4+1),H4+1," ")),"") -> 44692 | L4: =IFERROR((IF(MONTH(J4)=MONTH(J4+1),J4+1," ")),"") -> 44693 | N4: =IFERROR((IF(MONTH(L4)=MONTH(L4+1),L4+1," ")),"") -> 44694 | P4: =IFERROR((IF(MONTH(N4)=MONTH(N4+1),N4+1," ")),"") -> 44695 | S4: Total Minggu Ini
D5: =TEXT(D4,"dddd") -> Sunday | F5: =TEXT(F4,"dddd") -> Monday | H5: =TEXT(H4,"dddd") -> Tuesday | J5: =TEXT(J4,"dddd") -> Wednesday | L5: =TEXT(L4,"dddd") -> Thursday | N5: =TEXT(N4,"dddd") -> Friday | P5: =TEXT(P4,"dddd") -> Saturday
D6: Total Jumlah | E6: Status | F6: Total Jumlah | G6: Status | H6: Total Jumlah | I6: Status | J6: Total Jumlah | K6: Status | L6: Total Jumlah | M6: Status | N6: Total Jumlah | O6: Status | P6: Total Jumlah | Q6: Status | S6: Total Dibayar | T6: Total Belum Dibayar | U6: Total
B7: 1 | C7: Juli | D7: 6 | E7: Paid | F7: 6 | G7: Paid | H7: 6 | I7: Paid | J7: 6 | K7: Paid | L7: 6 | M7: Paid | N7: 6 | O7: Paid | P7: 6 | Q7: Paid | S7: =IF(E7="Paid",D7,0)+IF(G7="Paid",F7,0)+IF(I7="Paid",H7,0)+IF(K7="Paid",J7,0)+IF(M7="Paid",L7,0)+IF(O7="Paid",N7,0)+IF(Q7="Paid",P7,0) -> 42 | T7: =IF(E7="Not Paid",D7,0)+IF(G7="Not Paid",F7,0)+IF(I7="Not Paid",H7,0)+IF(K7="Not Paid",J7,0)+IF(M7="Not Paid",L7,0)+IF(O7="Not Paid",N7,0)+IF(Q7="Not Paid",P7,0) -> 0 | U7: =T7+S7 -> 42
B8: =B7+1 -> 2 | C8: Juli | D8: 2 | E8: Paid | F8: 2 | G8: Paid | H8: 2 | I8: Paid | J8: 2 | K8: Paid | L8: 2 | M8: Paid | N8: 2 | O8: Paid | P8: 2 | Q8: Paid | S8: =IF(E8="Paid",D8,0)+IF(G8="Paid",F8,0)+IF(I8="Paid",H8,0)+IF(K8="Paid",J8,0)+IF(M8="Paid",L8,0)+IF(O8="Paid",N8,0)+IF(Q8="Paid",P8,0) -> 14 | T8: =IF(E8="Not Paid",D8,0)+IF(G8="Not Paid",F8,0)+IF(I8="Not Paid",H8,0)+IF(K8="Not Paid",J8,0)+IF(M8="Not Paid",L8,0)+IF(O8="Not Paid",N8,0)+IF(Q8="Not Paid",P8,0) -> 0 | U8: =T8+S8 -> 14
B9: =B8+1 -> 3 | C9: Juli | D9: 3 | E9: Paid | F9: 3 | G9: Paid | H9: 3 | I9: Paid | J9: 3 | K9: Paid | L9: 3 | M9: Paid | N9: 3 | O9: Paid | P9: 3 | Q9: Paid | S9: =IF(E9="Paid",D9,0)+IF(G9="Paid",F9,0)+IF(I9="Paid",H9,0)+IF(K9="Paid",J9,0)+IF(M9="Paid",L9,0)+IF(O9="Paid",N9,0)+IF(Q9="Paid",P9,0) -> 21 | T9: =IF(E9="Not Paid",D9,0)+IF(G9="Not Paid",F9,0)+IF(I9="Not Paid",H9,0)+IF(K9="Not Paid",J9,0)+IF(M9="Not Paid",L9,0)+IF(O9="Not Paid",N9,0)+IF(Q9="Not Paid",P9,0) -> 0 | U9: =T9+S9 -> 21
B10: =B9+1 -> 4 | C10: Juli | D10: 4 | E10: Paid | F10: 4 | G10: Paid | H10: 4 | I10: Paid | J10: 4 | K10: Paid | L10: 4 | M10: Paid | N10: 4 | O10: Paid | P10: 4 | Q10: Paid | S10: =IF(E10="Paid",D10,0)+IF(G10="Paid",F10,0)+IF(I10="Paid",H10,0)+IF(K10="Paid",J10,0)+IF(M10="Paid",L10,0)+IF(O10="Paid",N10,0)+IF(Q10="Paid",P10,0) -> 28 | T10: =IF(E10="Not Paid",D10,0)+IF(G10="Not Paid",F10,0)+IF(I10="Not Paid",H10,0)+IF(K10="Not Paid",J10,0)+IF(M10="Not Paid",L10,0)+IF(O10="Not Paid",N10,0)+IF(Q10="Not Paid",P10,0) -> 0 | U10: =T10+S10 -> 28
B11: =B10+1 -> 5 | C11: Juli | D11: 5 | E11: Paid | F11: 5 | G11: Paid | H11: 5 | I11: Paid | J11: 5 | K11: Paid | L11: 5 | M11: Paid | N11: 5 | O11: Paid | P11: 5 | Q11: Paid | S11: =IF(E11="Paid",D11,0)+IF(G11="Paid",F11,0)+IF(I11="Paid",H11,0)+IF(K11="Paid",J11,0)+IF(M11="Paid",L11,0)+IF(O11="Paid",N11,0)+IF(Q11="Paid",P11,0) -> 35 | T11: =IF(E11="Not Paid",D11,0)+IF(G11="Not Paid",F11,0)+IF(I11="Not Paid",H11,0)+IF(K11="Not Paid",J11,0)+IF(M11="Not Paid",L11,0)+IF(O11="Not Paid",N11,0)+IF(Q11="Not Paid",P11,0) -> 0 | U11: =T11+S11 -> 35
B12: =B11+1 -> 6 | C12: Juli | E12: Paid | G12: Paid | I12: Paid | K12: Paid | M12: Paid | O12: Paid | Q12: Paid | S12: =IF(E12="Paid",D12,0)+IF(G12="Paid",F12,0)+IF(I12="Paid",H12,0)+IF(K12="Paid",J12,0)+IF(M12="Paid",L12,0)+IF(O12="Paid",N12,0)+IF(Q12="Paid",P12,0) -> 0 | T12: =IF(E12="Not Paid",D12,0)+IF(G12="Not Paid",F12,0)+IF(I12="Not Paid",H12,0)+IF(K12="Not Paid",J12,0)+IF(M12="Not Paid",L12,0)+IF(O12="Not Paid",N12,0)+IF(Q12="Not Paid",P12,0) -> 0 | U12: =T12+S12 -> 0
B13: =B12+1 -> 7 | C13: Juli | E13: Paid | G13: Paid | I13: Paid | K13: Paid | M13: Paid | O13: Paid | Q13: Paid | S13: =IF(E13="Paid",D13,0)+IF(G13="Paid",F13,0)+IF(I13="Paid",H13,0)+IF(K13="Paid",J13,0)+IF(M13="Paid",L13,0)+IF(O13="Paid",N13,0)+IF(Q13="Paid",P13,0) -> 0 | T13: =IF(E13="Not Paid",D13,0)+IF(G13="Not Paid",F13,0)+IF(I13="Not Paid",H13,0)+IF(K13="Not Paid",J13,0)+IF(M13="Not Paid",L13,0)+IF(O13="Not Paid",N13,0)+IF(Q13="Not Paid",P13,0) -> 0 | U13: =T13+S13 -> 0
B14: =B13+1 -> 8 | C14: Juli | E14: Paid | G14: Paid | I14: Paid | K14: Paid | M14: Paid | O14: Paid | Q14: Paid | S14: =IF(E14="Paid",D14,0)+IF(G14="Paid",F14,0)+IF(I14="Paid",H14,0)+IF(K14="Paid",J14,0)+IF(M14="Paid",L14,0)+IF(O14="Paid",N14,0)+IF(Q14="Paid",P14,0) -> 0 | T14: =IF(E14="Not Paid",D14,0)+IF(G14="Not Paid",F14,0)+IF(I14="Not Paid",H14,0)+IF(K14="Not Paid",J14,0)+IF(M14="Not Paid",L14,0)+IF(O14="Not Paid",N14,0)+IF(Q14="Not Paid",P14,0) -> 0 | U14: =T14+S14 -> 0
B15: =B14+1 -> 9 | C15: Juli | E15: Paid | G15: Paid | I15: Paid | K15: Paid | M15: Paid | O15: Paid | Q15: Paid | S15: =IF(E15="Paid",D15,0)+IF(G15="Paid",F15,0)+IF(I15="Paid",H15,0)+IF(K15="Paid",J15,0)+IF(M15="Paid",L15,0)+IF(O15="Paid",N15,0)+IF(Q15="Paid",P15,0) -> 0 | T15: =IF(E15="Not Paid",D15,0)+IF(G15="Not Paid",F15,0)+IF(I15="Not Paid",H15,0)+IF(K15="Not Paid",J15,0)+IF(M15="Not Paid",L15,0)+IF(O15="Not Paid",N15,0)+IF(Q15="Not Paid",P15,0) -> 0 | U15: =T15+S15 -> 0
B16: =B15+1 -> 10 | C16: Juli | S16: =IF(E16="Paid",D16,0)+IF(G16="Paid",F16,0)+IF(I16="Paid",H16,0)+IF(K16="Paid",J16,0)+IF(M16="Paid",L16,0)+IF(O16="Paid",N16,0)+IF(Q16="Paid",P16,0) -> 0 | T16: =IF(E16="Not Paid",D16,0)+IF(G16="Not Paid",F16,0)+IF(I16="Not Paid",H16,0)+IF(K16="Not Paid",J16,0)+IF(M16="Not Paid",L16,0)+IF(O16="Not Paid",N16,0)+IF(Q16="Not Paid",P16,0) -> 0 | U16: =T16+S16 -> 0
B17: =B16+1 -> 11 | C17: Juli | S17: =IF(E17="Paid",D17,0)+IF(G17="Paid",F17,0)+IF(I17="Paid",H17,0)+IF(K17="Paid",J17,0)+IF(M17="Paid",L17,0)+IF(O17="Paid",N17,0)+IF(Q17="Paid",P17,0) -> 0 | T17: =IF(E17="Not Paid",D17,0)+IF(G17="Not Paid",F17,0)+IF(I17="Not Paid",H17,0)+IF(K17="Not Paid",J17,0)+IF(M17="Not Paid",L17,0)+IF(O17="Not Paid",N17,0)+IF(Q17="Not Paid",P17,0) -> 0 | U17: =T17+S17 -> 0
B18: =B17+1 -> 12 | C18: Juli | S18: =IF(E18="Paid",D18,0)+IF(G18="Paid",F18,0)+IF(I18="Paid",H18,0)+IF(K18="Paid",J18,0)+IF(M18="Paid",L18,0)+IF(O18="Paid",N18,0)+IF(Q18="Paid",P18,0) -> 0 | T18: =IF(E18="Not Paid",D18,0)+IF(G18="Not Paid",F18,0)+IF(I18="Not Paid",H18,0)+IF(K18="Not Paid",J18,0)+IF(M18="Not Paid",L18,0)+IF(O18="Not Paid",N18,0)+IF(Q18="Not Paid",P18,0) -> 0 | U18: =T18+S18 -> 0
B19: =B18+1 -> 13 | C19: Juli | S19: =IF(E19="Paid",D19,0)+IF(G19="Paid",F19,0)+IF(I19="Paid",H19,0)+IF(K19="Paid",J19,0)+IF(M19="Paid",L19,0)+IF(O19="Paid",N19,0)+IF(Q19="Paid",P19,0) -> 0 | T19: =IF(E19="Not Paid",D19,0)+IF(G19="Not Paid",F19,0)+IF(I19="Not Paid",H19,0)+IF(K19="Not Paid",J19,0)+IF(M19="Not Paid",L19,0)+IF(O19="Not Paid",N19,0)+IF(Q19="Not Paid",P19,0) -> 0 | U19: =T19+S19 -> 0
B20: =B19+1 -> 14 | S20: =IF(E20="Paid",D20,0)+IF(G20="Paid",F20,0)+IF(I20="Paid",H20,0)+IF(K20="Paid",J20,0)+IF(M20="Paid",L20,0)+IF(O20="Paid",N20,0)+IF(Q20="Paid",P20,0) -> 0 | T20: =IF(E20="Not Paid",D20,0)+IF(G20="Not Paid",F20,0)+IF(I20="Not Paid",H20,0)+IF(K20="Not Paid",J20,0)+IF(M20="Not Paid",L20,0)+IF(O20="Not Paid",N20,0)+IF(Q20="Not Paid",P20,0) -> 0 | U20: =T20+S20 -> 0
B21: =B20+1 -> 15 | S21: =IF(E21="Paid",D21,0)+IF(G21="Paid",F21,0)+IF(I21="Paid",H21,0)+IF(K21="Paid",J21,0)+IF(M21="Paid",L21,0)+IF(O21="Paid",N21,0)+IF(Q21="Paid",P21,0) -> 0 | T21: =IF(E21="Not Paid",D21,0)+IF(G21="Not Paid",F21,0)+IF(I21="Not Paid",H21,0)+IF(K21="Not Paid",J21,0)+IF(M21="Not Paid",L21,0)+IF(O21="Not Paid",N21,0)+IF(Q21="Not Paid",P21,0) -> 0 | U21: =T21+S21 -> 0
B22: =B21+1 -> 16 | S22: =IF(E22="Paid",D22,0)+IF(G22="Paid",F22,0)+IF(I22="Paid",H22,0)+IF(K22="Paid",J22,0)+IF(M22="Paid",L22,0)+IF(O22="Paid",N22,0)+IF(Q22="Paid",P22,0) -> 0 | T22: =IF(E22="Not Paid",D22,0)+IF(G22="Not Paid",F22,0)+IF(I22="Not Paid",H22,0)+IF(K22="Not Paid",J22,0)+IF(M22="Not Paid",L22,0)+IF(O22="Not Paid",N22,0)+IF(Q22="Not Paid",P22,0) -> 0 | U22: =T22+S22 -> 0
B23: =B22+1 -> 17 | S23: =IF(E23="Paid",D23,0)+IF(G23="Paid",F23,0)+IF(I23="Paid",H23,0)+IF(K23="Paid",J23,0)+IF(M23="Paid",L23,0)+IF(O23="Paid",N23,0)+IF(Q23="Paid",P23,0) -> 0 | T23: =IF(E23="Not Paid",D23,0)+IF(G23="Not Paid",F23,0)+IF(I23="Not Paid",H23,0)+IF(K23="Not Paid",J23,0)+IF(M23="Not Paid",L23,0)+IF(O23="Not Paid",N23,0)+IF(Q23="Not Paid",P23,0) -> 0 | U23: =T23+S23 -> 0
B24: =B23+1 -> 18 | S24: =IF(E24="Paid",D24,0)+IF(G24="Paid",F24,0)+IF(I24="Paid",H24,0)+IF(K24="Paid",J24,0)+IF(M24="Paid",L24,0)+IF(O24="Paid",N24,0)+IF(Q24="Paid",P24,0) -> 0 | T24: =IF(E24="Not Paid",D24,0)+IF(G24="Not Paid",F24,0)+IF(I24="Not Paid",H24,0)+IF(K24="Not Paid",J24,0)+IF(M24="Not Paid",L24,0)+IF(O24="Not Paid",N24,0)+IF(Q24="Not Paid",P24,0) -> 0 | U24: =T24+S24 -> 0
B25: =B24+1 -> 19 | S25: =IF(E25="Paid",D25,0)+IF(G25="Paid",F25,0)+IF(I25="Paid",H25,0)+IF(K25="Paid",J25,0)+IF(M25="Paid",L25,0)+IF(O25="Paid",N25,0)+IF(Q25="Paid",P25,0) -> 0 | T25: =IF(E25="Not Paid",D25,0)+IF(G25="Not Paid",F25,0)+IF(I25="Not Paid",H25,0)+IF(K25="Not Paid",J25,0)+IF(M25="Not Paid",L25,0)+IF(O25="Not Paid",N25,0)+IF(Q25="Not Paid",P25,0) -> 0 | U25: =T25+S25 -> 0
B26: =B25+1 -> 20 | S26: =IF(E26="Paid",D26,0)+IF(G26="Paid",F26,0)+IF(I26="Paid",H26,0)+IF(K26="Paid",J26,0)+IF(M26="Paid",L26,0)+IF(O26="Paid",N26,0)+IF(Q26="Paid",P26,0) -> 0 | T26: =IF(E26="Not Paid",D26,0)+IF(G26="Not Paid",F26,0)+IF(I26="Not Paid",H26,0)+IF(K26="Not Paid",J26,0)+IF(M26="Not Paid",L26,0)+IF(O26="Not Paid",N26,0)+IF(Q26="Not Paid",P26,0) -> 0 | U26: =T26+S26 -> 0
B27: =B26+1 -> 21 | S27: =IF(E27="Paid",D27,0)+IF(G27="Paid",F27,0)+IF(I27="Paid",H27,0)+IF(K27="Paid",J27,0)+IF(M27="Paid",L27,0)+IF(O27="Paid",N27,0)+IF(Q27="Paid",P27,0) -> 0 | T27: =IF(E27="Not Paid",D27,0)+IF(G27="Not Paid",F27,0)+IF(I27="Not Paid",H27,0)+IF(K27="Not Paid",J27,0)+IF(M27="Not Paid",L27,0)+IF(O27="Not Paid",N27,0)+IF(Q27="Not Paid",P27,0) -> 0 | U27: =T27+S27 -> 0
B28: =B27+1 -> 22 | S28: =IF(E28="Paid",D28,0)+IF(G28="Paid",F28,0)+IF(I28="Paid",H28,0)+IF(K28="Paid",J28,0)+IF(M28="Paid",L28,0)+IF(O28="Paid",N28,0)+IF(Q28="Paid",P28,0) -> 0 | T28: =IF(E28="Not Paid",D28,0)+IF(G28="Not Paid",F28,0)+IF(I28="Not Paid",H28,0)+IF(K28="Not Paid",J28,0)+IF(M28="Not Paid",L28,0)+IF(O28="Not Paid",N28,0)+IF(Q28="Not Paid",P28,0) -> 0 | U28: =T28+S28 -> 0
B29: =B28+1 -> 23 | S29: =IF(E29="Paid",D29,0)+IF(G29="Paid",F29,0)+IF(I29="Paid",H29,0)+IF(K29="Paid",J29,0)+IF(M29="Paid",L29,0)+IF(O29="Paid",N29,0)+IF(Q29="Paid",P29,0) -> 0 | T29: =IF(E29="Not Paid",D29,0)+IF(G29="Not Paid",F29,0)+IF(I29="Not Paid",H29,0)+IF(K29="Not Paid",J29,0)+IF(M29="Not Paid",L29,0)+IF(O29="Not Paid",N29,0)+IF(Q29="Not Paid",P29,0) -> 0 | U29: =T29+S29 -> 0
B30: =B29+1 -> 24 | S30: =IF(E30="Paid",D30,0)+IF(G30="Paid",F30,0)+IF(I30="Paid",H30,0)+IF(K30="Paid",J30,0)+IF(M30="Paid",L30,0)+IF(O30="Paid",N30,0)+IF(Q30="Paid",P30,0) -> 0 | T30: =IF(E30="Not Paid",D30,0)+IF(G30="Not Paid",F30,0)+IF(I30="Not Paid",H30,0)+IF(K30="Not Paid",J30,0)+IF(M30="Not Paid",L30,0)+IF(O30="Not Paid",N30,0)+IF(Q30="Not Paid",P30,0) -> 0 | U30: =T30+S30 -> 0
B31: =B30+1 -> 25 | S31: =IF(E31="Paid",D31,0)+IF(G31="Paid",F31,0)+IF(I31="Paid",H31,0)+IF(K31="Paid",J31,0)+IF(M31="Paid",L31,0)+IF(O31="Paid",N31,0)+IF(Q31="Paid",P31,0) -> 0 | T31: =IF(E31="Not Paid",D31,0)+IF(G31="Not Paid",F31,0)+IF(I31="Not Paid",H31,0)+IF(K31="Not Paid",J31,0)+IF(M31="Not Paid",L31,0)+IF(O31="Not Paid",N31,0)+IF(Q31="Not Paid",P31,0) -> 0 | U31: =T31+S31 -> 0
... B34: =B33+1 -> 28 | S34: =IF(E34="Paid",D34,0)+IF(G34="Paid",F34,0)+IF(I34="Paid",H34,0)+IF(K34="Paid",J34,0)+IF(M34="Paid",L34,0)+IF(O34="Paid",N34,0)+IF(Q34="Paid",P34,0) -> 0 | T34: =IF(E34="Not Paid",D34,0)+IF(G34="Not Paid",F34,0)+IF(I34="Not Paid",H34,0)+IF(K34="Not Paid",J34,0)+IF(M34="Not Paid",L34,0)+IF(O34="Not Paid",N34,0)+IF(Q34="Not Paid",P34,0) -> 0 | U34: =T34+S34 -> 0
B35: =B34+1 -> 29 | C35: Juli | S35: =IF(E35="Paid",D35,0)+IF(G35="Paid",F35,0)+IF(I35="Paid",H35,0)+IF(K35="Paid",J35,0)+IF(M35="Paid",L35,0)+IF(O35="Paid",N35,0)+IF(Q35="Paid",P35,0) -> 0 | T35: =IF(E35="Not Paid",D35,0)+IF(G35="Not Paid",F35,0)+IF(I35="Not Paid",H35,0)+IF(K35="Not Paid",J35,0)+IF(M35="Not Paid",L35,0)+IF(O35="Not Paid",N35,0)+IF(Q35="Not Paid",P35,0) -> 0 | U35: =T35+S35 -> 0
B36: =B35+1 -> 30 | C36: Juli | E36: Paid | G36: Paid | I36: Paid | K36: Paid | M36: Paid | O36: Paid | Q36: Paid | S36: =IF(E36="Paid",D36,0)+IF(G36="Paid",F36,0)+IF(I36="Paid",H36,0)+IF(K36="Paid",J36,0)+IF(M36="Paid",L36,0)+IF(O36="Paid",N36,0)+IF(Q36="Paid",P36,0) -> 0 | T36: =IF(E36="Not Paid",D36,0)+IF(G36="Not Paid",F36,0)+IF(I36="Not Paid",H36,0)+IF(K36="Not Paid",J36,0)+IF(M36="Not Paid",L36,0)+IF(O36="Not Paid",N36,0)+IF(Q36="Not Paid",P36,0) -> 0 | U36: =T36+S36 -> 0
B38: Total | D38: =SUM(D7:D36) -> 20 | F38: =SUM(F7:F36) -> 20 | H38: =SUM(H7:H36) -> 20 | J38: =SUM(J7:J36) -> 20 | L38: =SUM(L7:L36) -> 20 | N38: =SUM(N7:N36) -> 20 | P38: =SUM(P7:P36) -> 20 | S38: =SUM(S7:S36) -> 140 | T38: =SUM(T7:T36) -> 0 | U38: =SUM(U7:U36) -> 140

Sheet Week 3
B2: Minggu Ketiga | D2: ='Week 2'!D2:E2 -> 44682
B4: S.No | C4: Nama | D4: =IFERROR((IF(MONTH('Week 2'!P4)=MONTH('Week 2'!P4+1),('Week 2'!P4+1),"")),"") -> 44696 | F4: =IFERROR((IF(MONTH(D4)=MONTH(D4+1),D4+1," ")),"") -> 44697 | H4: =IFERROR((IF(MONTH(F4)=MONTH(F4+1),F4+1," ")),"") -> 44698 | J4: =IFERROR((IF(MONTH(H4)=MONTH(H4+1),H4+1," ")),"") -> 44699 | L4: =IFERROR((IF(MONTH(J4)=MONTH(J4+1),J4+1," ")),"") -> 44700 | N4: =IFERROR((IF(MONTH(L4)=MONTH(L4+1),L4+1," ")),"") -> 44701 | P4: =IFERROR((IF(MONTH(N4)=MONTH(N4+1),N4+1," ")),"") -> 44702 | S4: Total Minggu Ini
D5: =TEXT(D4,"dddd") -> Sunday | F5: =TEXT(F4,"dddd") -> Monday | H5: =TEXT(H4,"dddd") -> Tuesday | J5: =TEXT(J4,"dddd") -> Wednesday | L5: =TEXT(L4,"dddd") -> Thursday | N5: =TEXT(N4,"dddd") -> Friday | P5: =TEXT(P4,"dddd") -> Saturday
D6: Total Jumlah | E6: Status | F6: Total Jumlah | G6: Status | H6: Total Jumlah | I6: Status | J6: Total Jumlah | K6: Status | L6: Total Jumlah | M6: Status | N6: Total Jumlah | O6: Status | P6: Total Jumlah | Q6: Status | S6: Total Dibayar | T6: Total Belum Dibayar | U6: Total
B7: 1 | C7: Juli | D7: 6 | E7: Paid | F7: 6 | G7: Paid | H7: 6 | I7: Not Paid | J7: 6 | K7: Paid | L7: 6 | M7: Paid | N7: 6 | O7: Paid | P7: 6 | Q7: Paid | S7: =IF(E7="Paid",D7,0)+IF(G7="Paid",F7,0)+IF(I7="Paid",H7,0)+IF(K7="Paid",J7,0)+IF(M7="Paid",L7,0)+IF(O7="Paid",N7,0)+IF(Q7="Paid",P7,0) -> 36 | T7: =IF(E7="Not Paid",D7,0)+IF(G7="Not Paid",F7,0)+IF(I7="Not Paid",H7,0)+IF(K7="Not Paid",J7,0)+IF(M7="Not Paid",L7,0)+IF(O7="Not Paid",N7,0)+IF(Q7="Not Paid",P7,0) -> 6 | U7: =T7+S7 -> 42
B8: =B7+1 -> 2 | C8: Juli | D8: 2 | E8: Paid | F8: 2 | G8: Paid | H8: 2 | I8: Paid | J8: 2 | K8: Paid | L8: 2 | M8: Paid | N8: 2 | O8: Paid | P8: 2 | Q8: Paid | S8: =IF(E8="Paid",D8,0)+IF(G8="Paid",F8,0)+IF(I8="Paid",H8,0)+IF(K8="Paid",J8,0)+IF(M8="Paid",L8,0)+IF(O8="Paid",N8,0)+IF(Q8="Paid",P8,0) -> 14 | T8: =IF(E8="Not Paid",D8,0)+IF(G8="Not Paid",F8,0)+IF(I8="Not Paid",H8,0)+IF(K8="Not Paid",J8,0)+IF(M8="Not Paid",L8,0)+IF(O8="Not Paid",N8,0)+IF(Q8="Not Paid",P8,0) -> 0 | U8: =T8+S8 -> 14
B9: =B8+1 -> 3 | C9: Juli | D9: 3 | E9: Paid | F9: 3 | G9: Paid | H9: 3 | I9: Paid | J9: 3 | K9: Paid | L9: 3 | M9: Paid | N9: 3 | O9: Paid | P9: 3 | Q9: Paid | S9: =IF(E9="Paid",D9,0)+IF(G9="Paid",F9,0)+IF(I9="Paid",H9,0)+IF(K9="Paid",J9,0)+IF(M9="Paid",L9,0)+IF(O9="Paid",N9,0)+IF(Q9="Paid",P9,0) -> 21 | T9: =IF(E9="Not Paid",D9,0)+IF(G9="Not Paid",F9,0)+IF(I9="Not Paid",H9,0)+IF(K9="Not Paid",J9,0)+IF(M9="Not Paid",L9,0)+IF(O9="Not Paid",N9,0)+IF(Q9="Not Paid",P9,0) -> 0 | U9: =T9+S9 -> 21
B10: =B9+1 -> 4 | C10: Juli | D10: 4 | E10: Paid | F10: 4 | G10: Paid | H10: 4 | I10: Paid | J10: 4 | K10: Paid | L10: 4 | M10: Paid | N10: 4 | O10: Paid | P10: 4 | Q10: Paid | S10: =IF(E10="Paid",D10,0)+IF(G10="Paid",F10,0)+IF(I10="Paid",H10,0)+IF(K10="Paid",J10,0)+IF(M10="Paid",L10,0)+IF(O10="Paid",N10,0)+IF(Q10="Paid",P10,0) -> 28 | T10: =IF(E10="Not Paid",D10,0)+IF(G10="Not Paid",F10,0)+IF(I10="Not Paid",H10,0)+IF(K10="Not Paid",J10,0)+IF(M10="Not Paid",L10,0)+IF(O10="Not Paid",N10,0)+IF(Q10="Not Paid",P10,0) -> 0 | U10: =T10+S10 -> 28
B11: =B10+1 -> 5 | C11: Juli | D11: 5 | E11: Paid | F11: 5 | G11: Paid | H11: 5 | I11: Not Paid | J11: 5 | K11: Paid | L11: 5 | M11: Paid | N11: 5 | O11: Paid | P11: 5 | Q11: Paid | S11: =IF(E11="Paid",D11,0)+IF(G11="Paid",F11,0)+IF(I11="Paid",H11,0)+IF(K11="Paid",J11,0)+IF(M11="Paid",L11,0)+IF(O11="Paid",N11,0)+IF(Q11="Paid",P11,0) -> 30 | T11: =IF(E11="Not Paid",D11,0)+IF(G11="Not Paid",F11,0)+IF(I11="Not Paid",H11,0)+IF(K11="Not Paid",J11,0)+IF(M11="Not Paid",L11,0)+IF(O11="Not Paid",N11,0)+IF(Q11="Not Paid",P11,0) -> 5 | U11: =T11+S11 -> 35
B12: =B11+1 -> 6 | C12: Juli | E12: Paid | G12: Paid | I12: Paid | K12: Paid | M12: Paid | O12: Paid | Q12: Paid | S12: =IF(E12="Paid",D12,0)+IF(G12="Paid",F12,0)+IF(I12="Paid",H12,0)+IF(K12="Paid",J12,0)+IF(M12="Paid",L12,0)+IF(O12="Paid",N12,0)+IF(Q12="Paid",P12,0) -> 0 | T12: =IF(E12="Not Paid",D12,0)+IF(G12="Not Paid",F12,0)+IF(I12="Not Paid",H12,0)+IF(K12="Not Paid",J12,0)+IF(M12="Not Paid",L12,0)+IF(O12="Not Paid",N12,0)+IF(Q12="Not Paid",P12,0) -> 0 | U12: =T12+S12 -> 0
B13: =B12+1 -> 7 | C13: Juli | E13: Paid | G13: Paid | I13: Paid | K13: Paid | M13: Paid | O13: Paid | Q13: Paid | S13: =IF(E13="Paid",D13,0)+IF(G13="Paid",F13,0)+IF(I13="Paid",H13,0)+IF(K13="Paid",J13,0)+IF(M13="Paid",L13,0)+IF(O13="Paid",N13,0)+IF(Q13="Paid",P13,0) -> 0 | T13: =IF(E13="Not Paid",D13,0)+IF(G13="Not Paid",F13,0)+IF(I13="Not Paid",H13,0)+IF(K13="Not Paid",J13,0)+IF(M13="Not Paid",L13,0)+IF(O13="Not Paid",N13,0)+IF(Q13="Not Paid",P13,0) -> 0 | U13: =T13+S13 -> 0
B14: =B13+1 -> 8 | C14: Juli | E14: Paid | G14: Paid | I14: Paid | K14: Paid | M14: Paid | O14: Paid | Q14: Paid | S14: =IF(E14="Paid",D14,0)+IF(G14="Paid",F14,0)+IF(I14="Paid",H14,0)+IF(K14="Paid",J14,0)+IF(M14="Paid",L14,0)+IF(O14="Paid",N14,0)+IF(Q14="Paid",P14,0) -> 0 | T14: =IF(E14="Not Paid",D14,0)+IF(G14="Not Paid",F14,0)+IF(I14="Not Paid",H14,0)+IF(K14="Not Paid",J14,0)+IF(M14="Not Paid",L14,0)+IF(O14="Not Paid",N14,0)+IF(Q14="Not Paid",P14,0) -> 0 | U14: =T14+S14 -> 0
B15: =B14+1 -> 9 | C15: Juli | E15: Paid | G15: Paid | I15: Paid | K15: Paid | M15: Paid | O15: Paid | Q15: Paid | S15: =IF(E15="Paid",D15,0)+IF(G15="Paid",F15,0)+IF(I15="Paid",H15,0)+IF(K15="Paid",J15,0)+IF(M15="Paid",L15,0)+IF(O15="Paid",N15,0)+IF(Q15="Paid",P15,0) -> 0 | T15: =IF(E15="Not Paid",D15,0)+IF(G15="Not Paid",F15,0)+IF(I15="Not Paid",H15,0)+IF(K15="Not Paid",J15,0)+IF(M15="Not Paid",L15,0)+IF(O15="Not Paid",N15,0)+IF(Q15="Not Paid",P15,0) -> 0 | U15: =T15+S15 -> 0
B16: =B15+1 -> 10 | C16: Juli | S16: =IF(E16="Paid",D16,0)+IF(G16="Paid",F16,0)+IF(I16="Paid",H16,0)+IF(K16="Paid",J16,0)+IF(M16="Paid",L16,0)+IF(O16="Paid",N16,0)+IF(Q16="Paid",P16,0) -> 0 | T16: =IF(E16="Not Paid",D16,0)+IF(G16="Not Paid",F16,0)+IF(I16="Not Paid",H16,0)+IF(K16="Not Paid",J16,0)+IF(M16="Not Paid",L16,0)+IF(O16="Not Paid",N16,0)+IF(Q16="Not Paid",P16,0) -> 0 | U16: =T16+S16 -> 0
B17: =B16+1 -> 11 | C17: Juli | S17: =IF(E17="Paid",D17,0)+IF(G17="Paid",F17,0)+IF(I17="Paid",H17,0)+IF(K17="Paid",J17,0)+IF(M17="Paid",L17,0)+IF(O17="Paid",N17,0)+IF(Q17="Paid",P17,0) -> 0 | T17: =IF(E17="Not Paid",D17,0)+IF(G17="Not Paid",F17,0)+IF(I17="Not Paid",H17,0)+IF(K17="Not Paid",J17,0)+IF(M17="Not Paid",L17,0)+IF(O17="Not Paid",N17,0)+IF(Q17="Not Paid",P17,0) -> 0 | U17: =T17+S17 -> 0
B18: =B17+1 -> 12 | C18: Juli | S18: =IF(E18="Paid",D18,0)+IF(G18="Paid",F18,0)+IF(I18="Paid",H18,0)+IF(K18="Paid",J18,0)+IF(M18="Paid",L18,0)+IF(O18="Paid",N18,0)+IF(Q18="Paid",P18,0) -> 0 | T18: =IF(E18="Not Paid",D18,0)+IF(G18="Not Paid",F18,0)+IF(I18="Not Paid",H18,0)+IF(K18="Not Paid",J18,0)+IF(M18="Not Paid",L18,0)+IF(O18="Not Paid",N18,0)+IF(Q18="Not Paid",P18,0) -> 0 | U18: =T18+S18 -> 0
B19: =B18+1 -> 13 | C19: Juli | S19: =IF(E19="Paid",D19,0)+IF(G19="Paid",F19,0)+IF(I19="Paid",H19,0)+IF(K19="Paid",J19,0)+IF(M19="Paid",L19,0)+IF(O19="Paid",N19,0)+IF(Q19="Paid",P19,0) -> 0 | T19: =IF(E19="Not Paid",D19,0)+IF(G19="Not Paid",F19,0)+IF(I19="Not Paid",H19,0)+IF(K19="Not Paid",J19,0)+IF(M19="Not Paid",L19,0)+IF(O19="Not Paid",N19,0)+IF(Q19="Not Paid",P19,0) -> 0 | U19: =T19+S19 -> 0
B20: =B19+1 -> 14 | S20: =IF(E20="Paid",D20,0)+IF(G20="Paid",F20,0)+IF(I20="Paid",H20,0)+IF(K20="Paid",J20,0)+IF(M20="Paid",L20,0)+IF(O20="Paid",N20,0)+IF(Q20="Paid",P20,0) -> 0 | T20: =IF(E20="Not Paid",D20,0)+IF(G20="Not Paid",F20,0)+IF(I20="Not Paid",H20,0)+IF(K20="Not Paid",J20,0)+IF(M20="Not Paid",L20,0)+IF(O20="Not Paid",N20,0)+IF(Q20="Not Paid",P20,0) -> 0 | U20: =T20+S20 -> 0
B21: =B20+1 -> 15 | S21: =IF(E21="Paid",D21,0)+IF(G21="Paid",F21,0)+IF(I21="Paid",H21,0)+IF(K21="Paid",J21,0)+IF(M21="Paid",L21,0)+IF(O21="Paid",N21,0)+IF(Q21="Paid",P21,0) -> 0 | T21: =IF(E21="Not Paid",D21,0)+IF(G21="Not Paid",F21,0)+IF(I21="Not Paid",H21,0)+IF(K21="Not Paid",J21,0)+IF(M21="Not Paid",L21,0)+IF(O21="Not Paid",N21,0)+IF(Q21="Not Paid",P21,0) -> 0 | U21: =T21+S21 -> 0
B22: =B21+1 -> 16 | S22: =IF(E22="Paid",D22,0)+IF(G22="Paid",F22,0)+IF(I22="Paid",H22,0)+IF(K22="Paid",J22,0)+IF(M22="Paid",L22,0)+IF(O22="Paid",N22,0)+IF(Q22="Paid",P22,0) -> 0 | T22: =IF(E22="Not Paid",D22,0)+IF(G22="Not Paid",F22,0)+IF(I22="Not Paid",H22,0)+IF(K22="Not Paid",J22,0)+IF(M22="Not Paid",L22,0)+IF(O22="Not Paid",N22,0)+IF(Q22="Not Paid",P22,0) -> 0 | U22: =T22+S22 -> 0
B23: =B22+1 -> 17 | S23: =IF(E23="Paid",D23,0)+IF(G23="Paid",F23,0)+IF(I23="Paid",H23,0)+IF(K23="Paid",J23,0)+IF(M23="Paid",L23,0)+IF(O23="Paid",N23,0)+IF(Q23="Paid",P23,0) -> 0 | T23: =IF(E23="Not Paid",D23,0)+IF(G23="Not Paid",F23,0)+IF(I23="Not Paid",H23,0)+IF(K23="Not Paid",J23,0)+IF(M23="Not Paid",L23,0)+IF(O23="Not Paid",N23,0)+IF(Q23="Not Paid",P23,0) -> 0 | U23: =T23+S23 -> 0
B24: =B23+1 -> 18 | S24: =IF(E24="Paid",D24,0)+IF(G24="Paid",F24,0)+IF(I24="Paid",H24,0)+IF(K24="Paid",J24,0)+IF(M24="Paid",L24,0)+IF(O24="Paid",N24,0)+IF(Q24="Paid",P24,0) -> 0 | T24: =IF(E24="Not Paid",D24,0)+IF(G24="Not Paid",F24,0)+IF(I24="Not Paid",H24,0)+IF(K24="Not Paid",J24,0)+IF(M24="Not Paid",L24,0)+IF(O24="Not Paid",N24,0)+IF(Q24="Not Paid",P24,0) -> 0 | U24: =T24+S24 -> 0
B25: =B24+1 -> 19 | S25: =IF(E25="Paid",D25,0)+IF(G25="Paid",F25,0)+IF(I25="Paid",H25,0)+IF(K25="Paid",J25,0)+IF(M25="Paid",L25,0)+IF(O25="Paid",N25,0)+IF(Q25="Paid",P25,0) -> 0 | T25: =IF(E25="Not Paid",D25,0)+IF(G25="Not Paid",F25,0)+IF(I25="Not Paid",H25,0)+IF(K25="Not Paid",J25,0)+IF(M25="Not Paid",L25,0)+IF(O25="Not Paid",N25,0)+IF(Q25="Not Paid",P25,0) -> 0 | U25: =T25+S25 -> 0
B26: =B25+1 -> 20 | S26: =IF(E26="Paid",D26,0)+IF(G26="Paid",F26,0)+IF(I26="Paid",H26,0)+IF(K26="Paid",J26,0)+IF(M26="Paid",L26,0)+IF(O26="Paid",N26,0)+IF(Q26="Paid",P26,0) -> 0 | T26: =IF(E26="Not Paid",D26,0)+IF(G26="Not Paid",F26,0)+IF(I26="Not Paid",H26,0)+IF(K26="Not Paid",J26,0)+IF(M26="Not Paid",L26,0)+IF(O26="Not Paid",N26,0)+IF(Q26="Not Paid",P26,0) -> 0 | U26: =T26+S26 -> 0
B27: =B26+1 -> 21 | S27: =IF(E27="Paid",D27,0)+IF(G27="Paid",F27,0)+IF(I27="Paid",H27,0)+IF(K27="Paid",J27,0)+IF(M27="Paid",L27,0)+IF(O27="Paid",N27,0)+IF(Q27="Paid",P27,0) -> 0 | T27: =IF(E27="Not Paid",D27,0)+IF(G27="Not Paid",F27,0)+IF(I27="Not Paid",H27,0)+IF(K27="Not Paid",J27,0)+IF(M27="Not Paid",L27,0)+IF(O27="Not Paid",N27,0)+IF(Q27="Not Paid",P27,0) -> 0 | U27: =T27+S27 -> 0
B28: =B27+1 -> 22 | S28: =IF(E28="Paid",D28,0)+IF(G28="Paid",F28,0)+IF(I28="Paid",H28,0)+IF(K28="Paid",J28,0)+IF(M28="Paid",L28,0)+IF(O28="Paid",N28,0)+IF(Q28="Paid",P28,0) -> 0 | T28: =IF(E28="Not Paid",D28,0)+IF(G28="Not Paid",F28,0)+IF(I28="Not Paid",H28,0)+IF(K28="Not Paid",J28,0)+IF(M28="Not Paid",L28,0)+IF(O28="Not Paid",N28,0)+IF(Q28="Not Paid",P28,0) -> 0 | U28: =T28+S28 -> 0
B29: =B28+1 -> 23 | S29: =IF(E29="Paid",D29,0)+IF(G29="Paid",F29,0)+IF(I29="Paid",H29,0)+IF(K29="Paid",J29,0)+IF(M29="Paid",L29,0)+IF(O29="Paid",N29,0)+IF(Q29="Paid",P29,0) -> 0 | T29: =IF(E29="Not Paid",D29,0)+IF(G29="Not Paid",F29,0)+IF(I29="Not Paid",H29,0)+IF(K29="Not Paid",J29,0)+IF(M29="Not Paid",L29,0)+IF(O29="Not Paid",N29,0)+IF(Q29="Not Paid",P29,0) -> 0 | U29: =T29+S29 -> 0
