Workbook

Sheet Dashboard
C2: NAMA PERUSAHAAN
C3: DASBOR
C6: Tipe | D6: Minggu 1 | E6: Minggu 2 | F6: Minggu 3 | G6: Minggu 4 | H6: Minggu 5 | I6: Minggu 6 | M6: Job # | N6: Nama Projek | O6: Total Jam | T6: Total
C7: Total Jam | D7: =SUM(Table2[[#All],[Column10]]) -> 108 | E7: =SUM(Table24[[#All],[Column10]]) -> 114 | F7: =SUM(Table245[[#All],[Column10]]) -> 132 | G7: =SUM(Table2456[[#All],[Column10]]) -> 88 | H7: =SUM(Table24567[[#All],[Column10]]) -> 32 | I7: =SUM(Table8[[Minggu 1]:[Minggu 5]]) -> 474 | O7: Engineering | P7: CAD | Q7: Admin | R7: Clerical | S7: Miscellaneous
M8: ='(Drop Down) Data Base '!B5 -> 20-401 | N8: ='(Drop Down) Data Base '!C5 -> Projek 1 | O8: =SUMIFS('1st week'!$L$12:$L$60,'1st week'!$B$12:$B$60,Dashboard!M8,'1st week'!$D$12:$D$60,Dashboard!$O$7)+SUMIFS('2nd week'!$L$12:$L$60,'2nd week'!$B$12:$B$60,Dashboard!M8,'2nd week'!$D$12:$D$60,Dashboard!$O$7)+SUMIFS('3rd week'!$L$12:$L$60,'3rd week'!$B$12:$B$60,Dashboard!M8,'3rd week'!$D$12:$D$60,Dashboard!$O$7)+SUMIFS('4th week'!$L$12:$L$60,'4th week'!$B$12:$B$60,Dashboard!M8,'4th week'!$D$12:$D$60,Dashboard!$O$7)+SUMIFS('5th week'!$L$12:$L$60,'5th week'!$B$12:$B$60,Dashboard!M8,'5th week'!$D$12:$D$60,Dashboard!$O$7) -> 130 | P8: =SUMIFS('1st week'!$L$12:$L$60,'1st week'!$B$12:$B$60,Dashboard!M8,'1st week'!$D$12:$D$60,Dashboard!$P$7)+SUMIFS('2nd week'!$L$12:$L$60,'2nd week'!$B$12:$B$60,Dashboard!M8,'2nd week'!$D$12:$D$60,Dashboard!$P$7)+SUMIFS('3rd week'!$L$12:$L$60,'3rd week'!$B$12:$B$60,Dashboard!M8,'3rd week'!$D$12:$D$60,Dashboard!$P$7)+SUMIFS('4th week'!$L$12:$L$60,'4th week'!$B$12:$B$60,Dashboard!M8,'4th week'!$D$12:$D$60,Dashboard!$P$7)+SUMIFS('5th week'!$L$12:$L$60,'5th week'!$B$12:$B$60,Dashboard!M8,'5th week'!$D$12:$D$60,Dashboard!$P$7) -> 132 | Q8: =SUMIFS('1st week'!$L$12:$L$60,'1st week'!$B$12:$B$60,Dashboard!M8,'1st week'!$D$12:$D$60,Dashboard!$Q$7)+SUMIFS('2nd week'!$L$12:$L$60,'2nd week'!$B$12:$B$60,Dashboard!M8,'2nd week'!$D$12:$D$60,Dashboard!$Q$7)+SUMIFS('3rd week'!$L$12:$L$60,'3rd week'!$B$12:$B$60,Dashboard!M8,'3rd week'!$D$12:$D$60,Dashboard!$Q$7)+SUMIFS('4th week'!$L$12:$L$60,'4th week'!$B$12:$B$60,Dashboard!M8,'4th week'!$D$12:$D$60,Dashboard!$Q$7)+SUMIFS('5th week'!$L$12:$L$60,'5th week'!$B$12:$B$60,Dashboard!M8,'5th week'!$D$12:$D$60,Dashboard!$Q$7) -> 0 | R8: =SUMIFS('1st week'!$L$12:$L$60,'1st week'!$B$12:$B$60,Dashboard!M8,'1st week'!$D$12:$D$60,Dashboard!$R$7)+SUMIFS('2nd week'!$L$12:$L$60,'2nd week'!$B$12:$B$60,Dashboard!M8,'2nd week'!$D$12:$D$60,Dashboard!$R$7)+SUMIFS('3rd week'!$L$12:$L$60,'3rd week'!$B$12:$B$60,Dashboard!M8,'3rd week'!$D$12:$D$60,Dashboard!$R$7)+SUMIFS('4th week'!$L$12:$L$60,'4th week'!$B$12:$B$60,Dashboard!M8,'4th week'!$D$12:$D$60,Dashboard!$R$7)+SUMIFS('5th week'!$L$12:$L$60,'5th week'!$B$12:$B$60,Dashboard!M8,'5th week'!$D$12:$D$60,Dashboard!$R$7) -> 0 | S8: =SUMIFS('1st week'!$L$12:$L$60,'1st week'!$B$12:$B$60,Dashboard!M8,'1st week'!$D$12:$D$60,Dashboard!$S$7)+SUMIFS('2nd week'!$L$12:$L$60,'2nd week'!$B$12:$B$60,Dashboard!M8,'2nd week'!$D$12:$D$60,Dashboard!$S$7)+SUMIFS('3rd week'!$L$12:$L$60,'3rd week'!$B$12:$B$60,Dashboard!M8,'3rd week'!$D$12:$D$60,Dashboard!$S$7)+SUMIFS('4th week'!$L$12:$L$60,'4th week'!$B$12:$B$60,Dashboard!M8,'4th week'!$D$12:$D$60,Dashboard!$S$7)+SUMIFS('5th week'!$L$12:$L$60,'5th week'!$B$12:$B$60,Dashboard!M8,'5th week'!$D$12:$D$60,Dashboard!$S$7) -> 0 | T8: =SUM(O8:S8) -> 262
M9: ='(Drop Down) Data Base '!B6 -> 20-306 | N9: ='(Drop Down) Data Base '!C6 -> Projek 2 | O9: =SUMIFS('1st week'!$L$12:$L$60,'1st week'!$B$12:$B$60,Dashboard!M9,'1st week'!$D$12:$D$60,Dashboard!$O$7)+SUMIFS('2nd week'!$L$12:$L$60,'2nd week'!$B$12:$B$60,Dashboard!M9,'2nd week'!$D$12:$D$60,Dashboard!$O$7)+SUMIFS('3rd week'!$L$12:$L$60,'3rd week'!$B$12:$B$60,Dashboard!M9,'3rd week'!$D$12:$D$60,Dashboard!$O$7)+SUMIFS('4th week'!$L$12:$L$60,'4th week'!$B$12:$B$60,Dashboard!M9,'4th week'!$D$12:$D$60,Dashboard!$O$7)+SUMIFS('5th week'!$L$12:$L$60,'5th week'!$B$12:$B$60,Dashboard!M9,'5th week'!$D$12:$D$60,Dashboard!$O$7) -> 0 | P9: =SUMIFS('1st week'!$L$12:$L$60,'1st week'!$B$12:$B$60,Dashboard!M9,'1st week'!$D$12:$D$60,Dashboard!$P$7)+SUMIFS('2nd week'!$L$12:$L$60,'2nd week'!$B$12:$B$60,Dashboard!M9,'2nd week'!$D$12:$D$60,Dashboard!$P$7)+SUMIFS('3rd week'!$L$12:$L$60,'3rd week'!$B$12:$B$60,Dashboard!M9,'3rd week'!$D$12:$D$60,Dashboard!$P$7)+SUMIFS('4th week'!$L$12:$L$60,'4th week'!$B$12:$B$60,Dashboard!M9,'4th week'!$D$12:$D$60,Dashboard!$P$7)+SUMIFS('5th week'!$L$12:$L$60,'5th week'!$B$12:$B$60,Dashboard!M9,'5th week'!$D$12:$D$60,Dashboard!$P$7) -> 0 | Q9: =SUMIFS('1st week'!$L$12:$L$60,'1st week'!$B$12:$B$60,Dashboard!M9,'1st week'!$D$12:$D$60,Dashboard!$Q$7)+SUMIFS('2nd week'!$L$12:$L$60,'2nd week'!$B$12:$B$60,Dashboard!M9,'2nd week'!$D$12:$D$60,Dashboard!$Q$7)+SUMIFS('3rd week'!$L$12:$L$60,'3rd week'!$B$12:$B$60,Dashboard!M9,'3rd week'!$D$12:$D$60,Dashboard!$Q$7)+SUMIFS('4th week'!$L$12:$L$60,'4th week'!$B$12:$B$60,Dashboard!M9,'4th week'!$D$12:$D$60,Dashboard!$Q$7)+SUMIFS('5th week'!$L$12:$L$60,'5th week'!$B$12:$B$60,Dashboard!M9,'5th week'!$D$12:$D$60,Dashboard!$Q$7) -> 0 | R9: =SUMIFS('1st week'!$L$12:$L$60,'1st week'!$B$12:$B$60,Dashboard!M9,'1st week'!$D$12:$D$60,Dashboard!$R$7)+SUMIFS('2nd week'!$L$12:$L$60,'2nd week'!$B$12:$B$60,Dashboard!M9,'2nd week'!$D$12:$D$60,Dashboard!$R$7)+SUMIFS('3rd week'!$L$12:$L$60,'3rd week'!$B$12:$B$60,Dashboard!M9,'3rd week'!$D$12:$D$60,Dashboard!$R$7)+SUMIFS('4th week'!$L$12:$L$60,'4th week'!$B$12:$B$60,Dashboard!M9,'4th week'!$D$12:$D$60,Dashboard!$R$7)+SUMIFS('5th week'!$L$12:$L$60,'5th week'!$B$12:$B$60,Dashboard!M9,'5th week'!$D$12:$D$60,Dashboard!$R$7) -> 0 | S9: =SUMIFS('1st week'!$L$12:$L$60,'1st week'!$B$12:$B$60,Dashboard!M9,'1st week'!$D$12:$D$60,Dashboard!$S$7)+SUMIFS('2nd week'!$L$12:$L$60,'2nd week'!$B$12:$B$60,Dashboard!M9,'2nd week'!$D$12:$D$60,Dashboard!$S$7)+SUMIFS('3rd week'!$L$12:$L$60,'3rd week'!$B$12:$B$60,Dashboard!M9,'3rd week'!$D$12:$D$60,Dashboard!$S$7)+SUMIFS('4th week'!$L$12:$L$60,'4th week'!$B$12:$B$60,Dashboard!M9,'4th week'!$D$12:$D$60,Dashboard!$S$7)+SUMIFS('5th week'!$L$12:$L$60,'5th week'!$B$12:$B$60,Dashboard!M9,'5th week'!$D$12:$D$60,Dashboard!$S$7) -> 0 | T9: =SUM(O9:S9) -> 0
M10: ='(Drop Down) Data Base '!B7 -> 21-306 | N10: ='(Drop Down) Data Base '!C7 -> Projek 3 | O10: =SUMIFS('1st week'!$L$12:$L$60,'1st week'!$B$12:$B$60,Dashboard!M10,'1st week'!$D$12:$D$60,Dashboard!$O$7)+SUMIFS('2nd week'!$L$12:$L$60,'2nd week'!$B$12:$B$60,Dashboard!M10,'2nd week'!$D$12:$D$60,Dashboard!$O$7)+SUMIFS('3rd week'!$L$12:$L$60,'3rd week'!$B$12:$B$60,Dashboard!M10,'3rd week'!$D$12:$D$60,Dashboard!$O$7)+SUMIFS('4th week'!$L$12:$L$60,'4th week'!$B$12:$B$60,Dashboard!M10,'4th week'!$D$12:$D$60,Dashboard!$O$7)+SUMIFS('5th week'!$L$12:$L$60,'5th week'!$B$12:$B$60,Dashboard!M10,'5th week'!$D$12:$D$60,Dashboard!$O$7) -> 0 | P10: =SUMIFS('1st week'!$L$12:$L$60,'1st week'!$B$12:$B$60,Dashboard!M10,'1st week'!$D$12:$D$60,Dashboard!$P$7)+SUMIFS('2nd week'!$L$12:$L$60,'2nd week'!$B$12:$B$60,Dashboard!M10,'2nd week'!$D$12:$D$60,Dashboard!$P$7)+SUMIFS('3rd week'!$L$12:$L$60,'3rd week'!$B$12:$B$60,Dashboard!M10,'3rd week'!$D$12:$D$60,Dashboard!$P$7)+SUMIFS('4th week'!$L$12:$L$60,'4th week'!$B$12:$B$60,Dashboard!M10,'4th week'!$D$12:$D$60,Dashboard!$P$7)+SUMIFS('5th week'!$L$12:$L$60,'5th week'!$B$12:$B$60,Dashboard!M10,'5th week'!$D$12:$D$60,Dashboard!$P$7) -> 0 | Q10: =SUMIFS('1st week'!$L$12:$L$60,'1st week'!$B$12:$B$60,Dashboard!M10,'1st week'!$D$12:$D$60,Dashboard!$Q$7)+SUMIFS('2nd week'!$L$12:$L$60,'2nd week'!$B$12:$B$60,Dashboard!M10,'2nd week'!$D$12:$D$60,Dashboard!$Q$7)+SUMIFS('3rd week'!$L$12:$L$60,'3rd week'!$B$12:$B$60,Dashboard!M10,'3rd week'!$D$12:$D$60,Dashboard!$Q$7)+SUMIFS('4th week'!$L$12:$L$60,'4th week'!$B$12:$B$60,Dashboard!M10,'4th week'!$D$12:$D$60,Dashboard!$Q$7)+SUMIFS('5th week'!$L$12:$L$60,'5th week'!$B$12:$B$60,Dashboard!M10,'5th week'!$D$12:$D$60,Dashboard!$Q$7) -> 0 | R10: =SUMIFS('1st week'!$L$12:$L$60,'1st week'!$B$12:$B$60,Dashboard!M10,'1st week'!$D$12:$D$60,Dashboard!$R$7)+SUMIFS('2nd week'!$L$12:$L$60,'2nd week'!$B$12:$B$60,Dashboard!M10,'2nd week'!$D$12:$D$60,Dashboard!$R$7)+SUMIFS('3rd week'!$L$12:$L$60,'3rd week'!$B$12:$B$60,Dashboard!M10,'3rd week'!$D$12:$D$60,Dashboard!$R$7)+SUMIFS('4th week'!$L$12:$L$60,'4th week'!$B$12:$B$60,Dashboard!M10,'4th week'!$D$12:$D$60,Dashboard!$R$7)+SUMIFS('5th week'!$L$12:$L$60,'5th week'!$B$12:$B$60,Dashboard!M10,'5th week'!$D$12:$D$60,Dashboard!$R$7) -> 0 | S10: =SUMIFS('1st week'!$L$12:$L$60,'1st week'!$B$12:$B$60,Dashboard!M10,'1st week'!$D$12:$D$60,Dashboard!$S$7)+SUMIFS('2nd week'!$L$12:$L$60,'2nd week'!$B$12:$B$60,Dashboard!M10,'2nd week'!$D$12:$D$60,Dashboard!$S$7)+SUMIFS('3rd week'!$L$12:$L$60,'3rd week'!$B$12:$B$60,Dashboard!M10,'3rd week'!$D$12:$D$60,Dashboard!$S$7)+SUMIFS('4th week'!$L$12:$L$60,'4th week'!$B$12:$B$60,Dashboard!M10,'4th week'!$D$12:$D$60,Dashboard!$S$7)+SUMIFS('5th week'!$L$12:$L$60,'5th week'!$B$12:$B$60,Dashboard!M10,'5th week'!$D$12:$D$60,Dashboard!$S$7) -> 0 | T10: =SUM(O10:S10) -> 0
M11: ='(Drop Down) Data Base '!B8 -> 20-407 | N11: ='(Drop Down) Data Base '!C8 -> Projek 4 | O11: =SUMIFS('1st week'!$L$12:$L$60,'1st week'!$B$12:$B$60,Dashboard!M11,'1st week'!$D$12:$D$60,Dashboard!$O$7)+SUMIFS('2nd week'!$L$12:$L$60,'2nd week'!$B$12:$B$60,Dashboard!M11,'2nd week'!$D$12:$D$60,Dashboard!$O$7)+SUMIFS('3rd week'!$L$12:$L$60,'3rd week'!$B$12:$B$60,Dashboard!M11,'3rd week'!$D$12:$D$60,Dashboard!$O$7)+SUMIFS('4th week'!$L$12:$L$60,'4th week'!$B$12:$B$60,Dashboard!M11,'4th week'!$D$12:$D$60,Dashboard!$O$7)+SUMIFS('5th week'!$L$12:$L$60,'5th week'!$B$12:$B$60,Dashboard!M11,'5th week'!$D$12:$D$60,Dashboard!$O$7) -> 0 | P11: =SUMIFS('1st week'!$L$12:$L$60,'1st week'!$B$12:$B$60,Dashboard!M11,'1st week'!$D$12:$D$60,Dashboard!$P$7)+SUMIFS('2nd week'!$L$12:$L$60,'2nd week'!$B$12:$B$60,Dashboard!M11,'2nd week'!$D$12:$D$60,Dashboard!$P$7)+SUMIFS('3rd week'!$L$12:$L$60,'3rd week'!$B$12:$B$60,Dashboard!M11,'3rd week'!$D$12:$D$60,Dashboard!$P$7)+SUMIFS('4th week'!$L$12:$L$60,'4th week'!$B$12:$B$60,Dashboard!M11,'4th week'!$D$12:$D$60,Dashboard!$P$7)+SUMIFS('5th week'!$L$12:$L$60,'5th week'!$B$12:$B$60,Dashboard!M11,'5th week'!$D$12:$D$60,Dashboard!$P$7) -> 0 | Q11: =SUMIFS('1st week'!$L$12:$L$60,'1st week'!$B$12:$B$60,Dashboard!M11,'1st week'!$D$12:$D$60,Dashboard!$Q$7)+SUMIFS('2nd week'!$L$12:$L$60,'2nd week'!$B$12:$B$60,Dashboard!M11,'2nd week'!$D$12:$D$60,Dashboard!$Q$7)+SUMIFS('3rd week'!$L$12:$L$60,'3rd week'!$B$12:$B$60,Dashboard!M11,'3rd week'!$D$12:$D$60,Dashboard!$Q$7)+SUMIFS('4th week'!$L$12:$L$60,'4th week'!$B$12:$B$60,Dashboard!M11,'4th week'!$D$12:$D$60,Dashboard!$Q$7)+SUMIFS('5th week'!$L$12:$L$60,'5th week'!$B$12:$B$60,Dashboard!M11,'5th week'!$D$12:$D$60,Dashboard!$Q$7) -> 0 | R11: =SUMIFS('1st week'!$L$12:$L$60,'1st week'!$B$12:$B$60,Dashboard!M11,'1st week'!$D$12:$D$60,Dashboard!$R$7)+SUMIFS('2nd week'!$L$12:$L$60,'2nd week'!$B$12:$B$60,Dashboard!M11,'2nd week'!$D$12:$D$60,Dashboard!$R$7)+SUMIFS('3rd week'!$L$12:$L$60,'3rd week'!$B$12:$B$60,Dashboard!M11,'3rd week'!$D$12:$D$60,Dashboard!$R$7)+SUMIFS('4th week'!$L$12:$L$60,'4th week'!$B$12:$B$60,Dashboard!M11,'4th week'!$D$12:$D$60,Dashboard!$R$7)+SUMIFS('5th week'!$L$12:$L$60,'5th week'!$B$12:$B$60,Dashboard!M11,'5th week'!$D$12:$D$60,Dashboard!$R$7) -> 0 | S11: =SUMIFS('1st week'!$L$12:$L$60,'1st week'!$B$12:$B$60,Dashboard!M11,'1st week'!$D$12:$D$60,Dashboard!$S$7)+SUMIFS('2nd week'!$L$12:$L$60,'2nd week'!$B$12:$B$60,Dashboard!M11,'2nd week'!$D$12:$D$60,Dashboard!$S$7)+SUMIFS('3rd week'!$L$12:$L$60,'3rd week'!$B$12:$B$60,Dashboard!M11,'3rd week'!$D$12:$D$60,Dashboard!$S$7)+SUMIFS('4th week'!$L$12:$L$60,'4th week'!$B$12:$B$60,Dashboard!M11,'4th week'!$D$12:$D$60,Dashboard!$S$7)+SUMIFS('5th week'!$L$12:$L$60,'5th week'!$B$12:$B$60,Dashboard!M11,'5th week'!$D$12:$D$60,Dashboard!$S$7) -> 0 | T11: =SUM(O11:S11) -> 0
M12: ='(Drop Down) Data Base '!B9 -> 21-102 | N12: ='(Drop Down) Data Base '!C9 -> Projek 5 | O12: =SUMIFS('1st week'!$L$12:$L$60,'1st week'!$B$12:$B$60,Dashboard!M12,'1st week'!$D$12:$D$60,Dashboard!$O$7)+SUMIFS('2nd week'!$L$12:$L$60,'2nd week'!$B$12:$B$60,Dashboard!M12,'2nd week'!$D$12:$D$60,Dashboard!$O$7)+SUMIFS('3rd week'!$L$12:$L$60,'3rd week'!$B$12:$B$60,Dashboard!M12,'3rd week'!$D$12:$D$60,Dashboard!$O$7)+SUMIFS('4th week'!$L$12:$L$60,'4th week'!$B$12:$B$60,Dashboard!M12,'4th week'!$D$12:$D$60,Dashboard!$O$7)+SUMIFS('5th week'!$L$12:$L$60,'5th week'!$B$12:$B$60,Dashboard!M12,'5th week'!$D$12:$D$60,Dashboard!$O$7) -> 0 | P12: =SUMIFS('1st week'!$L$12:$L$60,'1st week'!$B$12:$B$60,Dashboard!M12,'1st week'!$D$12:$D$60,Dashboard!$P$7)+SUMIFS('2nd week'!$L$12:$L$60,'2nd week'!$B$12:$B$60,Dashboard!M12,'2nd week'!$D$12:$D$60,Dashboard!$P$7)+SUMIFS('3rd week'!$L$12:$L$60,'3rd week'!$B$12:$B$60,Dashboard!M12,'3rd week'!$D$12:$D$60,Dashboard!$P$7)+SUMIFS('4th week'!$L$12:$L$60,'4th week'!$B$12:$B$60,Dashboard!M12,'4th week'!$D$12:$D$60,Dashboard!$P$7)+SUMIFS('5th week'!$L$12:$L$60,'5th week'!$B$12:$B$60,Dashboard!M12,'5th week'!$D$12:$D$60,Dashboard!$P$7) -> 0 | Q12: =SUMIFS('1st week'!$L$12:$L$60,'1st week'!$B$12:$B$60,Dashboard!M12,'1st week'!$D$12:$D$60,Dashboard!$Q$7)+SUMIFS('2nd week'!$L$12:$L$60,'2nd week'!$B$12:$B$60,Dashboard!M12,'2nd week'!$D$12:$D$60,Dashboard!$Q$7)+SUMIFS('3rd week'!$L$12:$L$60,'3rd week'!$B$12:$B$60,Dashboard!M12,'3rd week'!$D$12:$D$60,Dashboard!$Q$7)+SUMIFS('4th week'!$L$12:$L$60,'4th week'!$B$12:$B$60,Dashboard!M12,'4th week'!$D$12:$D$60,Dashboard!$Q$7)+SUMIFS('5th week'!$L$12:$L$60,'5th week'!$B$12:$B$60,Dashboard!M12,'5th week'!$D$12:$D$60,Dashboard!$Q$7) -> 0 | R12: =SUMIFS('1st week'!$L$12:$L$60,'1st week'!$B$12:$B$60,Dashboard!M12,'1st week'!$D$12:$D$60,Dashboard!$R$7)+SUMIFS('2nd week'!$L$12:$L$60,'2nd week'!$B$12:$B$60,Dashboard!M12,'2nd week'!$D$12:$D$60,Dashboard!$R$7)+SUMIFS('3rd week'!$L$12:$L$60,'3rd week'!$B$12:$B$60,Dashboard!M12,'3rd week'!$D$12:$D$60,Dashboard!$R$7)+SUMIFS('4th week'!$L$12:$L$60,'4th week'!$B$12:$B$60,Dashboard!M12,'4th week'!$D$12:$D$60,Dashboard!$R$7)+SUMIFS('5th week'!$L$12:$L$60,'5th week'!$B$12:$B$60,Dashboard!M12,'5th week'!$D$12:$D$60,Dashboard!$R$7) -> 0 | S12: =SUMIFS('1st week'!$L$12:$L$60,'1st week'!$B$12:$B$60,Dashboard!M12,'1st week'!$D$12:$D$60,Dashboard!$S$7)+SUMIFS('2nd week'!$L$12:$L$60,'2nd week'!$B$12:$B$60,Dashboard!M12,'2nd week'!$D$12:$D$60,Dashboard!$S$7)+SUMIFS('3rd week'!$L$12:$L$60,'3rd week'!$B$12:$B$60,Dashboard!M12,'3rd week'!$D$12:$D$60,Dashboard!$S$7)+SUMIFS('4th week'!$L$12:$L$60,'4th week'!$B$12:$B$60,Dashboard!M12,'4th week'!$D$12:$D$60,Dashboard!$S$7)+SUMIFS('5th week'!$L$12:$L$60,'5th week'!$B$12:$B$60,Dashboard!M12,'5th week'!$D$12:$D$60,Dashboard!$S$7) -> 0 | T12: =SUM(O12:S12) -> 0
M13: ='(Drop Down) Data Base '!B10 -> 20-303 | N13: ='(Drop Down) Data Base '!C10 -> Projek 6 | O13: =SUMIFS('1st week'!$L$12:$L$60,'1st week'!$B$12:$B$60,Dashboard!M13,'1st week'!$D$12:$D$60,Dashboard!$O$7)+SUMIFS('2nd week'!$L$12:$L$60,'2nd week'!$B$12:$B$60,Dashboard!M13,'2nd week'!$D$12:$D$60,Dashboard!$O$7)+SUMIFS('3rd week'!$L$12:$L$60,'3rd week'!$B$12:$B$60,Dashboard!M13,'3rd week'!$D$12:$D$60,Dashboard!$O$7)+SUMIFS('4th week'!$L$12:$L$60,'4th week'!$B$12:$B$60,Dashboard!M13,'4th week'!$D$12:$D$60,Dashboard!$O$7)+SUMIFS('5th week'!$L$12:$L$60,'5th week'!$B$12:$B$60,Dashboard!M13,'5th week'!$D$12:$D$60,Dashboard!$O$7) -> 0 | P13: =SUMIFS('1st week'!$L$12:$L$60,'1st week'!$B$12:$B$60,Dashboard!M13,'1st week'!$D$12:$D$60,Dashboard!$P$7)+SUMIFS('2nd week'!$L$12:$L$60,'2nd week'!$B$12:$B$60,Dashboard!M13,'2nd week'!$D$12:$D$60,Dashboard!$P$7)+SUMIFS('3rd week'!$L$12:$L$60,'3rd week'!$B$12:$B$60,Dashboard!M13,'3rd week'!$D$12:$D$60,Dashboard!$P$7)+SUMIFS('4th week'!$L$12:$L$60,'4th week'!$B$12:$B$60,Dashboard!M13,'4th week'!$D$12:$D$60,Dashboard!$P$7)+SUMIFS('5th week'!$L$12:$L$60,'5th week'!$B$12:$B$60,Dashboard!M13,'5th week'!$D$12:$D$60,Dashboard!$P$7) -> 182 | Q13: =SUMIFS('1st week'!$L$12:$L$60,'1st week'!$B$12:$B$60,Dashboard!M13,'1st week'!$D$12:$D$60,Dashboard!$Q$7)+SUMIFS('2nd week'!$L$12:$L$60,'2nd week'!$B$12:$B$60,Dashboard!M13,'2nd week'!$D$12:$D$60,Dashboard!$Q$7)+SUMIFS('3rd week'!$L$12:$L$60,'3rd week'!$B$12:$B$60,Dashboard!M13,'3rd week'!$D$12:$D$60,Dashboard!$Q$7)+SUMIFS('4th week'!$L$12:$L$60,'4th week'!$B$12:$B$60,Dashboard!M13,'4th week'!$D$12:$D$60,Dashboard!$Q$7)+SUMIFS('5th week'!$L$12:$L$60,'5th week'!$B$12:$B$60,Dashboard!M13,'5th week'!$D$12:$D$60,Dashboard!$Q$7) -> 0 | R13: =SUMIFS('1st week'!$L$12:$L$60,'1st week'!$B$12:$B$60,Dashboard!M13,'1st week'!$D$12:$D$60,Dashboard!$R$7)+SUMIFS('2nd week'!$L$12:$L$60,'2nd week'!$B$12:$B$60,Dashboard!M13,'2nd week'!$D$12:$D$60,Dashboard!$R$7)+SUMIFS('3rd week'!$L$12:$L$60,'3rd week'!$B$12:$B$60,Dashboard!M13,'3rd week'!$D$12:$D$60,Dashboard!$R$7)+SUMIFS('4th week'!$L$12:$L$60,'4th week'!$B$12:$B$60,Dashboard!M13,'4th week'!$D$12:$D$60,Dashboard!$R$7)+SUMIFS('5th week'!$L$12:$L$60,'5th week'!$B$12:$B$60,Dashboard!M13,'5th week'!$D$12:$D$60,Dashboard!$R$7) -> 0 | S13: =SUMIFS('1st week'!$L$12:$L$60,'1st week'!$B$12:$B$60,Dashboard!M13,'1st week'!$D$12:$D$60,Dashboard!$S$7)+SUMIFS('2nd week'!$L$12:$L$60,'2nd week'!$B$12:$B$60,Dashboard!M13,'2nd week'!$D$12:$D$60,Dashboard!$S$7)+SUMIFS('3rd week'!$L$12:$L$60,'3rd week'!$B$12:$B$60,Dashboard!M13,'3rd week'!$D$12:$D$60,Dashboard!$S$7)+SUMIFS('4th week'!$L$12:$L$60,'4th week'!$B$12:$B$60,Dashboard!M13,'4th week'!$D$12:$D$60,Dashboard!$S$7)+SUMIFS('5th week'!$L$12:$L$60,'5th week'!$B$12:$B$60,Dashboard!M13,'5th week'!$D$12:$D$60,Dashboard!$S$7) -> 0 | T13: =SUM(O13:S13) -> 182
M14: ='(Drop Down) Data Base '!B11 -> 20-111 | N14: ='(Drop Down) Data Base '!C11 -> Projek 7 | O14: =SUMIFS('1st week'!$L$12:$L$60,'1st week'!$B$12:$B$60,Dashboard!M14,'1st week'!$D$12:$D$60,Dashboard!$O$7)+SUMIFS('2nd week'!$L$12:$L$60,'2nd week'!$B$12:$B$60,Dashboard!M14,'2nd week'!$D$12:$D$60,Dashboard!$O$7)+SUMIFS('3rd week'!$L$12:$L$60,'3rd week'!$B$12:$B$60,Dashboard!M14,'3rd week'!$D$12:$D$60,Dashboard!$O$7)+SUMIFS('4th week'!$L$12:$L$60,'4th week'!$B$12:$B$60,Dashboard!M14,'4th week'!$D$12:$D$60,Dashboard!$O$7)+SUMIFS('5th week'!$L$12:$L$60,'5th week'!$B$12:$B$60,Dashboard!M14,'5th week'!$D$12:$D$60,Dashboard!$O$7) -> 0 | P14: =SUMIFS('1st week'!$L$12:$L$60,'1st week'!$B$12:$B$60,Dashboard!M14,'1st week'!$D$12:$D$60,Dashboard!$P$7)+SUMIFS('2nd week'!$L$12:$L$60,'2nd week'!$B$12:$B$60,Dashboard!M14,'2nd week'!$D$12:$D$60,Dashboard!$P$7)+SUMIFS('3rd week'!$L$12:$L$60,'3rd week'!$B$12:$B$60,Dashboard!M14,'3rd week'!$D$12:$D$60,Dashboard!$P$7)+SUMIFS('4th week'!$L$12:$L$60,'4th week'!$B$12:$B$60,Dashboard!M14,'4th week'!$D$12:$D$60,Dashboard!$P$7)+SUMIFS('5th week'!$L$12:$L$60,'5th week'!$B$12:$B$60,Dashboard!M14,'5th week'!$D$12:$D$60,Dashboard!$P$7) -> 0 | Q14: =SUMIFS('1st week'!$L$12:$L$60,'1st week'!$B$12:$B$60,Dashboard!M14,'1st week'!$D$12:$D$60,Dashboard!$Q$7)+SUMIFS('2nd week'!$L$12:$L$60,'2nd week'!$B$12:$B$60,Dashboard!M14,'2nd week'!$D$12:$D$60,Dashboard!$Q$7)+SUMIFS('3rd week'!$L$12:$L$60,'3rd week'!$B$12:$B$60,Dashboard!M14,'3rd week'!$D$12:$D$60,Dashboard!$Q$7)+SUMIFS('4th week'!$L$12:$L$60,'4th week'!$B$12:$B$60,Dashboard!M14,'4th week'!$D$12:$D$60,Dashboard!$Q$7)+SUMIFS('5th week'!$L$12:$L$60,'5th week'!$B$12:$B$60,Dashboard!M14,'5th week'!$D$12:$D$60,Dashboard!$Q$7) -> 0 | R14: =SUMIFS('1st week'!$L$12:$L$60,'1st week'!$B$12:$B$60,Dashboard!M14,'1st week'!$D$12:$D$60,Dashboard!$R$7)+SUMIFS('2nd week'!$L$12:$L$60,'2nd week'!$B$12:$B$60,Dashboard!M14,'2nd week'!$D$12:$D$60,Dashboard!$R$7)+SUMIFS('3rd week'!$L$12:$L$60,'3rd week'!$B$12:$B$60,Dashboard!M14,'3rd week'!$D$12:$D$60,Dashboard!$R$7)+SUMIFS('4th week'!$L$12:$L$60,'4th week'!$B$12:$B$60,Dashboard!M14,'4th week'!$D$12:$D$60,Dashboard!$R$7)+SUMIFS('5th week'!$L$12:$L$60,'5th week'!$B$12:$B$60,Dashboard!M14,'5th week'!$D$12:$D$60,Dashboard!$R$7) -> 0 | S14: =SUMIFS('1st week'!$L$12:$L$60,'1st week'!$B$12:$B$60,Dashboard!M14,'1st week'!$D$12:$D$60,Dashboard!$S$7)+SUMIFS('2nd week'!$L$12:$L$60,'2nd week'!$B$12:$B$60,Dashboard!M14,'2nd week'!$D$12:$D$60,Dashboard!$S$7)+SUMIFS('3rd week'!$L$12:$L$60,'3rd week'!$B$12:$B$60,Dashboard!M14,'3rd week'!$D$12:$D$60,Dashboard!$S$7)+SUMIFS('4th week'!$L$12:$L$60,'4th week'!$B$12:$B$60,Dashboard!M14,'4th week'!$D$12:$D$60,Dashboard!$S$7)+SUMIFS('5th week'!$L$12:$L$60,'5th week'!$B$12:$B$60,Dashboard!M14,'5th week'!$D$12:$D$60,Dashboard!$S$7) -> 0 | T14: =SUM(O14:S14) -> 0
M15: ='(Drop Down) Data Base '!B12 -> 20-202 | N15: ='(Drop Down) Data Base '!C12 -> Projek 8 | O15: =SUMIFS('1st week'!$L$12:$L$60,'1st week'!$B$12:$B$60,Dashboard!M15,'1st week'!$D$12:$D$60,Dashboard!$O$7)+SUMIFS('2nd week'!$L$12:$L$60,'2nd week'!$B$12:$B$60,Dashboard!M15,'2nd week'!$D$12:$D$60,Dashboard!$O$7)+SUMIFS('3rd week'!$L$12:$L$60,'3rd week'!$B$12:$B$60,Dashboard!M15,'3rd week'!$D$12:$D$60,Dashboard!$O$7)+SUMIFS('4th week'!$L$12:$L$60,'4th week'!$B$12:$B$60,Dashboard!M15,'4th week'!$D$12:$D$60,Dashboard!$O$7)+SUMIFS('5th week'!$L$12:$L$60,'5th week'!$B$12:$B$60,Dashboard!M15,'5th week'!$D$12:$D$60,Dashboard!$O$7) -> 0 | P15: =SUMIFS('1st week'!$L$12:$L$60,'1st week'!$B$12:$B$60,Dashboard!M15,'1st week'!$D$12:$D$60,Dashboard!$P$7)+SUMIFS('2nd week'!$L$12:$L$60,'2nd week'!$B$12:$B$60,Dashboard!M15,'2nd week'!$D$12:$D$60,Dashboard!$P$7)+SUMIFS('3rd week'!$L$12:$L$60,'3rd week'!$B$12:$B$60,Dashboard!M15,'3rd week'!$D$12:$D$60,Dashboard!$P$7)+SUMIFS('4th week'!$L$12:$L$60,'4th week'!$B$12:$B$60,Dashboard!M15,'4th week'!$D$12:$D$60,Dashboard!$P$7)+SUMIFS('5th week'!$L$12:$L$60,'5th week'!$B$12:$B$60,Dashboard!M15,'5th week'!$D$12:$D$60,Dashboard!$P$7) -> 0 | Q15: =SUMIFS('1st week'!$L$12:$L$60,'1st week'!$B$12:$B$60,Dashboard!M15,'1st week'!$D$12:$D$60,Dashboard!$Q$7)+SUMIFS('2nd week'!$L$12:$L$60,'2nd week'!$B$12:$B$60,Dashboard!M15,'2nd week'!$D$12:$D$60,Dashboard!$Q$7)+SUMIFS('3rd week'!$L$12:$L$60,'3rd week'!$B$12:$B$60,Dashboard!M15,'3rd week'!$D$12:$D$60,Dashboard!$Q$7)+SUMIFS('4th week'!$L$12:$L$60,'4th week'!$B$12:$B$60,Dashboard!M15,'4th week'!$D$12:$D$60,Dashboard!$Q$7)+SUMIFS('5th week'!$L$12:$L$60,'5th week'!$B$12:$B$60,Dashboard!M15,'5th week'!$D$12:$D$60,Dashboard!$Q$7) -> 0 | R15: =SUMIFS('1st week'!$L$12:$L$60,'1st week'!$B$12:$B$60,Dashboard!M15,'1st week'!$D$12:$D$60,Dashboard!$R$7)+SUMIFS('2nd week'!$L$12:$L$60,'2nd week'!$B$12:$B$60,Dashboard!M15,'2nd week'!$D$12:$D$60,Dashboard!$R$7)+SUMIFS('3rd week'!$L$12:$L$60,'3rd week'!$B$12:$B$60,Dashboard!M15,'3rd week'!$D$12:$D$60,Dashboard!$R$7)+SUMIFS('4th week'!$L$12:$L$60,'4th week'!$B$12:$B$60,Dashboard!M15,'4th week'!$D$12:$D$60,Dashboard!$R$7)+SUMIFS('5th week'!$L$12:$L$60,'5th week'!$B$12:$B$60,Dashboard!M15,'5th week'!$D$12:$D$60,Dashboard!$R$7) -> 0 | S15: =SUMIFS('1st week'!$L$12:$L$60,'1st week'!$B$12:$B$60,Dashboard!M15,'1st week'!$D$12:$D$60,Dashboard!$S$7)+SUMIFS('2nd week'!$L$12:$L$60,'2nd week'!$B$12:$B$60,Dashboard!M15,'2nd week'!$D$12:$D$60,Dashboard!$S$7)+SUMIFS('3rd week'!$L$12:$L$60,'3rd week'!$B$12:$B$60,Dashboard!M15,'3rd week'!$D$12:$D$60,Dashboard!$S$7)+SUMIFS('4th week'!$L$12:$L$60,'4th week'!$B$12:$B$60,Dashboard!M15,'4th week'!$D$12:$D$60,Dashboard!$S$7)+SUMIFS('5th week'!$L$12:$L$60,'5th week'!$B$12:$B$60,Dashboard!M15,'5th week'!$D$12:$D$60,Dashboard!$S$7) -> 0 | T15: =SUM(O15:S15) -> 0
M16: ='(Drop Down) Data Base '!B13 -> 19-204 | N16: ='(Drop Down) Data Base '!C13 -> Projek 9 | O16: =SUMIFS('1st week'!$L$12:$L$60,'1st week'!$B$12:$B$60,Dashboard!M16,'1st week'!$D$12:$D$60,Dashboard!$O$7)+SUMIFS('2nd week'!$L$12:$L$60,'2nd week'!$B$12:$B$60,Dashboard!M16,'2nd week'!$D$12:$D$60,Dashboard!$O$7)+SUMIFS('3rd week'!$L$12:$L$60,'3rd week'!$B$12:$B$60,Dashboard!M16,'3rd week'!$D$12:$D$60,Dashboard!$O$7)+SUMIFS('4th week'!$L$12:$L$60,'4th week'!$B$12:$B$60,Dashboard!M16,'4th week'!$D$12:$D$60,Dashboard!$O$7)+SUMIFS('5th week'!$L$12:$L$60,'5th week'!$B$12:$B$60,Dashboard!M16,'5th week'!$D$12:$D$60,Dashboard!$O$7) -> 0 | P16: =SUMIFS('1st week'!$L$12:$L$60,'1st week'!$B$12:$B$60,Dashboard!M16,'1st week'!$D$12:$D$60,Dashboard!$P$7)+SUMIFS('2nd week'!$L$12:$L$60,'2nd week'!$B$12:$B$60,Dashboard!M16,'2nd week'!$D$12:$D$60,Dashboard!$P$7)+SUMIFS('3rd week'!$L$12:$L$60,'3rd week'!$B$12:$B$60,Dashboard!M16,'3rd week'!$D$12:$D$60,Dashboard!$P$7)+SUMIFS('4th week'!$L$12:$L$60,'4th week'!$B$12:$B$60,Dashboard!M16,'4th week'!$D$12:$D$60,Dashboard!$P$7)+SUMIFS('5th week'!$L$12:$L$60,'5th week'!$B$12:$B$60,Dashboard!M16,'5th week'!$D$12:$D$60,Dashboard!$P$7) -> 0 | Q16: =SUMIFS('1st week'!$L$12:$L$60,'1st week'!$B$12:$B$60,Dashboard!M16,'1st week'!$D$12:$D$60,Dashboard!$Q$7)+SUMIFS('2nd week'!$L$12:$L$60,'2nd week'!$B$12:$B$60,Dashboard!M16,'2nd week'!$D$12:$D$60,Dashboard!$Q$7)+SUMIFS('3rd week'!$L$12:$L$60,'3rd week'!$B$12:$B$60,Dashboard!M16,'3rd week'!$D$12:$D$60,Dashboard!$Q$7)+SUMIFS('4th week'!$L$12:$L$60,'4th week'!$B$12:$B$60,Dashboard!M16,'4th week'!$D$12:$D$60,Dashboard!$Q$7)+SUMIFS('5th week'!$L$12:$L$60,'5th week'!$B$12:$B$60,Dashboard!M16,'5th week'!$D$12:$D$60,Dashboard!$Q$7) -> 0 | R16: =SUMIFS('1st week'!$L$12:$L$60,'1st week'!$B$12:$B$60,Dashboard!M16,'1st week'!$D$12:$D$60,Dashboard!$R$7)+SUMIFS('2nd week'!$L$12:$L$60,'2nd week'!$B$12:$B$60,Dashboard!M16,'2nd week'!$D$12:$D$60,Dashboard!$R$7)+SUMIFS('3rd week'!$L$12:$L$60,'3rd week'!$B$12:$B$60,Dashboard!M16,'3rd week'!$D$12:$D$60,Dashboard!$R$7)+SUMIFS('4th week'!$L$12:$L$60,'4th week'!$B$12:$B$60,Dashboard!M16,'4th week'!$D$12:$D$60,Dashboard!$R$7)+SUMIFS('5th week'!$L$12:$L$60,'5th week'!$B$12:$B$60,Dashboard!M16,'5th week'!$D$12:$D$60,Dashboard!$R$7) -> 0 | S16: =SUMIFS('1st week'!$L$12:$L$60,'1st week'!$B$12:$B$60,Dashboard!M16,'1st week'!$D$12:$D$60,Dashboard!$S$7)+SUMIFS('2nd week'!$L$12:$L$60,'2nd week'!$B$12:$B$60,Dashboard!M16,'2nd week'!$D$12:$D$60,Dashboard!$S$7)+SUMIFS('3rd week'!$L$12:$L$60,'3rd week'!$B$12:$B$60,Dashboard!M16,'3rd week'!$D$12:$D$60,Dashboard!$S$7)+SUMIFS('4th week'!$L$12:$L$60,'4th week'!$B$12:$B$60,Dashboard!M16,'4th week'!$D$12:$D$60,Dashboard!$S$7)+SUMIFS('5th week'!$L$12:$L$60,'5th week'!$B$12:$B$60,Dashboard!M16,'5th week'!$D$12:$D$60,Dashboard!$S$7) -> 0 | T16: =SUM(O16:S16) -> 0
M17: ='(Drop Down) Data Base '!B14 -> 21-401 | N17: ='(Drop Down) Data Base '!C14 -> Projek 10 | O17: =SUMIFS('1st week'!$L$12:$L$60,'1st week'!$B$12:$B$60,Dashboard!M17,'1st week'!$D$12:$D$60,Dashboard!$O$7)+SUMIFS('2nd week'!$L$12:$L$60,'2nd week'!$B$12:$B$60,Dashboard!M17,'2nd week'!$D$12:$D$60,Dashboard!$O$7)+SUMIFS('3rd week'!$L$12:$L$60,'3rd week'!$B$12:$B$60,Dashboard!M17,'3rd week'!$D$12:$D$60,Dashboard!$O$7)+SUMIFS('4th week'!$L$12:$L$60,'4th week'!$B$12:$B$60,Dashboard!M17,'4th week'!$D$12:$D$60,Dashboard!$O$7)+SUMIFS('5th week'!$L$12:$L$60,'5th week'!$B$12:$B$60,Dashboard!M17,'5th week'!$D$12:$D$60,Dashboard!$O$7) -> 0 | P17: =SUMIFS('1st week'!$L$12:$L$60,'1st week'!$B$12:$B$60,Dashboard!M17,'1st week'!$D$12:$D$60,Dashboard!$P$7)+SUMIFS('2nd week'!$L$12:$L$60,'2nd week'!$B$12:$B$60,Dashboard!M17,'2nd week'!$D$12:$D$60,Dashboard!$P$7)+SUMIFS('3rd week'!$L$12:$L$60,'3rd week'!$B$12:$B$60,Dashboard!M17,'3rd week'!$D$12:$D$60,Dashboard!$P$7)+SUMIFS('4th week'!$L$12:$L$60,'4th week'!$B$12:$B$60,Dashboard!M17,'4th week'!$D$12:$D$60,Dashboard!$P$7)+SUMIFS('5th week'!$L$12:$L$60,'5th week'!$B$12:$B$60,Dashboard!M17,'5th week'!$D$12:$D$60,Dashboard!$P$7) -> 0 | Q17: =SUMIFS('1st week'!$L$12:$L$60,'1st week'!$B$12:$B$60,Dashboard!M17,'1st week'!$D$12:$D$60,Dashboard!$Q$7)+SUMIFS('2nd week'!$L$12:$L$60,'2nd week'!$B$12:$B$60,Dashboard!M17,'2nd week'!$D$12:$D$60,Dashboard!$Q$7)+SUMIFS('3rd week'!$L$12:$L$60,'3rd week'!$B$12:$B$60,Dashboard!M17,'3rd week'!$D$12:$D$60,Dashboard!$Q$7)+SUMIFS('4th week'!$L$12:$L$60,'4th week'!$B$12:$B$60,Dashboard!M17,'4th week'!$D$12:$D$60,Dashboard!$Q$7)+SUMIFS('5th week'!$L$12:$L$60,'5th week'!$B$12:$B$60,Dashboard!M17,'5th week'!$D$12:$D$60,Dashboard!$Q$7) -> 0 | R17: =SUMIFS('1st week'!$L$12:$L$60,'1st week'!$B$12:$B$60,Dashboard!M17,'1st week'!$D$12:$D$60,Dashboard!$R$7)+SUMIFS('2nd week'!$L$12:$L$60,'2nd week'!$B$12:$B$60,Dashboard!M17,'2nd week'!$D$12:$D$60,Dashboard!$R$7)+SUMIFS('3rd week'!$L$12:$L$60,'3rd week'!$B$12:$B$60,Dashboard!M17,'3rd week'!$D$12:$D$60,Dashboard!$R$7)+SUMIFS('4th week'!$L$12:$L$60,'4th week'!$B$12:$B$60,Dashboard!M17,'4th week'!$D$12:$D$60,Dashboard!$R$7)+SUMIFS('5th week'!$L$12:$L$60,'5th week'!$B$12:$B$60,Dashboard!M17,'5th week'!$D$12:$D$60,Dashboard!$R$7) -> 0 | S17: =SUMIFS('1st week'!$L$12:$L$60,'1st week'!$B$12:$B$60,Dashboard!M17,'1st week'!$D$12:$D$60,Dashboard!$S$7)+SUMIFS('2nd week'!$L$12:$L$60,'2nd week'!$B$12:$B$60,Dashboard!M17,'2nd week'!$D$12:$D$60,Dashboard!$S$7)+SUMIFS('3rd week'!$L$12:$L$60,'3rd week'!$B$12:$B$60,Dashboard!M17,'3rd week'!$D$12:$D$60,Dashboard!$S$7)+SUMIFS('4th week'!$L$12:$L$60,'4th week'!$B$12:$B$60,Dashboard!M17,'4th week'!$D$12:$D$60,Dashboard!$S$7)+SUMIFS('5th week'!$L$12:$L$60,'5th week'!$B$12:$B$60,Dashboard!M17,'5th week'!$D$12:$D$60,Dashboard!$S$7) -> 0 | T17: =SUM(O17:S17) -> 0
M18: ='(Drop Down) Data Base '!B15 -> 21-304 | N18: ='(Drop Down) Data Base '!C15 -> Projek 11 | O18: =SUMIFS('1st week'!$L$12:$L$60,'1st week'!$B$12:$B$60,Dashboard!M18,'1st week'!$D$12:$D$60,Dashboard!$O$7)+SUMIFS('2nd week'!$L$12:$L$60,'2nd week'!$B$12:$B$60,Dashboard!M18,'2nd week'!$D$12:$D$60,Dashboard!$O$7)+SUMIFS('3rd week'!$L$12:$L$60,'3rd week'!$B$12:$B$60,Dashboard!M18,'3rd week'!$D$12:$D$60,Dashboard!$O$7)+SUMIFS('4th week'!$L$12:$L$60,'4th week'!$B$12:$B$60,Dashboard!M18,'4th week'!$D$12:$D$60,Dashboard!$O$7)+SUMIFS('5th week'!$L$12:$L$60,'5th week'!$B$12:$B$60,Dashboard!M18,'5th week'!$D$12:$D$60,Dashboard!$O$7) -> 0 | P18: =SUMIFS('1st week'!$L$12:$L$60,'1st week'!$B$12:$B$60,Dashboard!M18,'1st week'!$D$12:$D$60,Dashboard!$P$7)+SUMIFS('2nd week'!$L$12:$L$60,'2nd week'!$B$12:$B$60,Dashboard!M18,'2nd week'!$D$12:$D$60,Dashboard!$P$7)+SUMIFS('3rd week'!$L$12:$L$60,'3rd week'!$B$12:$B$60,Dashboard!M18,'3rd week'!$D$12:$D$60,Dashboard!$P$7)+SUMIFS('4th week'!$L$12:$L$60,'4th week'!$B$12:$B$60,Dashboard!M18,'4th week'!$D$12:$D$60,Dashboard!$P$7)+SUMIFS('5th week'!$L$12:$L$60,'5th week'!$B$12:$B$60,Dashboard!M18,'5th week'!$D$12:$D$60,Dashboard!$P$7) -> 20 | Q18: =SUMIFS('1st week'!$L$12:$L$60,'1st week'!$B$12:$B$60,Dashboard!M18,'1st week'!$D$12:$D$60,Dashboard!$Q$7)+SUMIFS('2nd week'!$L$12:$L$60,'2nd week'!$B$12:$B$60,Dashboard!M18,'2nd week'!$D$12:$D$60,Dashboard!$Q$7)+SUMIFS('3rd week'!$L$12:$L$60,'3rd week'!$B$12:$B$60,Dashboard!M18,'3rd week'!$D$12:$D$60,Dashboard!$Q$7)+SUMIFS('4th week'!$L$12:$L$60,'4th week'!$B$12:$B$60,Dashboard!M18,'4th week'!$D$12:$D$60,Dashboard!$Q$7)+SUMIFS('5th week'!$L$12:$L$60,'5th week'!$B$12:$B$60,Dashboard!M18,'5th week'!$D$12:$D$60,Dashboard!$Q$7) -> 0 | R18: =SUMIFS('1st week'!$L$12:$L$60,'1st week'!$B$12:$B$60,Dashboard!M18,'1st week'!$D$12:$D$60,Dashboard!$R$7)+SUMIFS('2nd week'!$L$12:$L$60,'2nd week'!$B$12:$B$60,Dashboard!M18,'2nd week'!$D$12:$D$60,Dashboard!$R$7)+SUMIFS('3rd week'!$L$12:$L$60,'3rd week'!$B$12:$B$60,Dashboard!M18,'3rd week'!$D$12:$D$60,Dashboard!$R$7)+SUMIFS('4th week'!$L$12:$L$60,'4th week'!$B$12:$B$60,Dashboard!M18,'4th week'!$D$12:$D$60,Dashboard!$R$7)+SUMIFS('5th week'!$L$12:$L$60,'5th week'!$B$12:$B$60,Dashboard!M18,'5th week'!$D$12:$D$60,Dashboard!$R$7) -> 0 | S18: =SUMIFS('1st week'!$L$12:$L$60,'1st week'!$B$12:$B$60,Dashboard!M18,'1st week'!$D$12:$D$60,Dashboard!$S$7)+SUMIFS('2nd week'!$L$12:$L$60,'2nd week'!$B$12:$B$60,Dashboard!M18,'2nd week'!$D$12:$D$60,Dashboard!$S$7)+SUMIFS('3rd week'!$L$12:$L$60,'3rd week'!$B$12:$B$60,Dashboard!M18,'3rd week'!$D$12:$D$60,Dashboard!$S$7)+SUMIFS('4th week'!$L$12:$L$60,'4th week'!$B$12:$B$60,Dashboard!M18,'4th week'!$D$12:$D$60,Dashboard!$S$7)+SUMIFS('5th week'!$L$12:$L$60,'5th week'!$B$12:$B$60,Dashboard!M18,'5th week'!$D$12:$D$60,Dashboard!$S$7) -> 0 | T18: =SUM(O18:S18) -> 20
M19: ='(Drop Down) Data Base '!B16 -> 21-408 | N19: ='(Drop Down) Data Base '!C16 -> Projek 12 | O19: =SUMIFS('1st week'!$L$12:$L$60,'1st week'!$B$12:$B$60,Dashboard!M19,'1st week'!$D$12:$D$60,Dashboard!$O$7)+SUMIFS('2nd week'!$L$12:$L$60,'2nd week'!$B$12:$B$60,Dashboard!M19,'2nd week'!$D$12:$D$60,Dashboard!$O$7)+SUMIFS('3rd week'!$L$12:$L$60,'3rd week'!$B$12:$B$60,Dashboard!M19,'3rd week'!$D$12:$D$60,Dashboard!$O$7)+SUMIFS('4th week'!$L$12:$L$60,'4th week'!$B$12:$B$60,Dashboard!M19,'4th week'!$D$12:$D$60,Dashboard!$O$7)+SUMIFS('5th week'!$L$12:$L$60,'5th week'!$B$12:$B$60,Dashboard!M19,'5th week'!$D$12:$D$60,Dashboard!$O$7) -> 0 | P19: =SUMIFS('1st week'!$L$12:$L$60,'1st week'!$B$12:$B$60,Dashboard!M19,'1st week'!$D$12:$D$60,Dashboard!$P$7)+SUMIFS('2nd week'!$L$12:$L$60,'2nd week'!$B$12:$B$60,Dashboard!M19,'2nd week'!$D$12:$D$60,Dashboard!$P$7)+SUMIFS('3rd week'!$L$12:$L$60,'3rd week'!$B$12:$B$60,Dashboard!M19,'3rd week'!$D$12:$D$60,Dashboard!$P$7)+SUMIFS('4th week'!$L$12:$L$60,'4th week'!$B$12:$B$60,Dashboard!M19,'4th week'!$D$12:$D$60,Dashboard!$P$7)+SUMIFS('5th week'!$L$12:$L$60,'5th week'!$B$12:$B$60,Dashboard!M19,'5th week'!$D$12:$D$60,Dashboard!$P$7) -> 0 | Q19: =SUMIFS('1st week'!$L$12:$L$60,'1st week'!$B$12:$B$60,Dashboard!M19,'1st week'!$D$12:$D$60,Dashboard!$Q$7)+SUMIFS('2nd week'!$L$12:$L$60,'2nd week'!$B$12:$B$60,Dashboard!M19,'2nd week'!$D$12:$D$60,Dashboard!$Q$7)+SUMIFS('3rd week'!$L$12:$L$60,'3rd week'!$B$12:$B$60,Dashboard!M19,'3rd week'!$D$12:$D$60,Dashboard!$Q$7)+SUMIFS('4th week'!$L$12:$L$60,'4th week'!$B$12:$B$60,Dashboard!M19,'4th week'!$D$12:$D$60,Dashboard!$Q$7)+SUMIFS('5th week'!$L$12:$L$60,'5th week'!$B$12:$B$60,Dashboard!M19,'5th week'!$D$12:$D$60,Dashboard!$Q$7) -> 0 | R19: =SUMIFS('1st week'!$L$12:$L$60,'1st week'!$B$12:$B$60,Dashboard!M19,'1st week'!$D$12:$D$60,Dashboard!$R$7)+SUMIFS('2nd week'!$L$12:$L$60,'2nd week'!$B$12:$B$60,Dashboard!M19,'2nd week'!$D$12:$D$60,Dashboard!$R$7)+SUMIFS('3rd week'!$L$12:$L$60,'3rd week'!$B$12:$B$60,Dashboard!M19,'3rd week'!$D$12:$D$60,Dashboard!$R$7)+SUMIFS('4th week'!$L$12:$L$60,'4th week'!$B$12:$B$60,Dashboard!M19,'4th week'!$D$12:$D$60,Dashboard!$R$7)+SUMIFS('5th week'!$L$12:$L$60,'5th week'!$B$12:$B$60,Dashboard!M19,'5th week'!$D$12:$D$60,Dashboard!$R$7) -> 0 | S19: =SUMIFS('1st week'!$L$12:$L$60,'1st week'!$B$12:$B$60,Dashboard!M19,'1st week'!$D$12:$D$60,Dashboard!$S$7)+SUMIFS('2nd week'!$L$12:$L$60,'2nd week'!$B$12:$B$60,Dashboard!M19,'2nd week'!$D$12:$D$60,Dashboard!$S$7)+SUMIFS('3rd week'!$L$12:$L$60,'3rd week'!$B$12:$B$60,Dashboard!M19,'3rd week'!$D$12:$D$60,Dashboard!$S$7)+SUMIFS('4th week'!$L$12:$L$60,'4th week'!$B$12:$B$60,Dashboard!M19,'4th week'!$D$12:$D$60,Dashboard!$S$7)+SUMIFS('5th week'!$L$12:$L$60,'5th week'!$B$12:$B$60,Dashboard!M19,'5th week'!$D$12:$D$60,Dashboard!$S$7) -> 0 | T19: =SUM(O19:S19) -> 0
... M32: ='(Drop Down) Data Base '!B29 -> 0 | N32: ='(Drop Down) Data Base '!C29 -> 0 | O32: =SUMIFS('1st week'!$L$12:$L$60,'1st week'!$B$12:$B$60,Dashboard!M32,'1st week'!$D$12:$D$60,Dashboard!$O$7)+SUMIFS('2nd week'!$L$12:$L$60,'2nd week'!$B$12:$B$60,Dashboard!M32,'2nd week'!$D$12:$D$60,Dashboard!$O$7)+SUMIFS('3rd week'!$L$12:$L$60,'3rd week'!$B$12:$B$60,Dashboard!M32,'3rd week'!$D$12:$D$60,Dashboard!$O$7)+SUMIFS('4th week'!$L$12:$L$60,'4th week'!$B$12:$B$60,Dashboard!M32,'4th week'!$D$12:$D$60,Dashboard!$O$7)+SUMIFS('5th week'!$L$12:$L$60,'5th week'!$B$12:$B$60,Dashboard!M32,'5th week'!$D$12:$D$60,Dashboard!$O$7) -> 0 | P32: =SUMIFS('1st week'!$L$12:$L$60,'1st week'!$B$12:$B$60,Dashboard!M32,'1st week'!$D$12:$D$60,Dashboard!$P$7)+SUMIFS('2nd week'!$L$12:$L$60,'2nd week'!$B$12:$B$60,Dashboard!M32,'2nd week'!$D$12:$D$60,Dashboard!$P$7)+SUMIFS('3rd week'!$L$12:$L$60,'3rd week'!$B$12:$B$60,Dashboard!M32,'3rd week'!$D$12:$D$60,Dashboard!$P$7)+SUMIFS('4th week'!$L$12:$L$60,'4th week'!$B$12:$B$60,Dashboard!M32,'4th week'!$D$12:$D$60,Dashboard!$P$7)+SUMIFS('5th week'!$L$12:$L$60,'5th week'!$B$12:$B$60,Dashboard!M32,'5th week'!$D$12:$D$60,Dashboard!$P$7) -> 0 | Q32: =SUMIFS('1st week'!$L$12:$L$60,'1st week'!$B$12:$B$60,Dashboard!M32,'1st week'!$D$12:$D$60,Dashboard!$Q$7)+SUMIFS('2nd week'!$L$12:$L$60,'2nd week'!$B$12:$B$60,Dashboard!M32,'2nd week'!$D$12:$D$60,Dashboard!$Q$7)+SUMIFS('3rd week'!$L$12:$L$60,'3rd week'!$B$12:$B$60,Dashboard!M32,'3rd week'!$D$12:$D$60,Dashboard!$Q$7)+SUMIFS('4th week'!$L$12:$L$60,'4th week'!$B$12:$B$60,Dashboard!M32,'4th week'!$D$12:$D$60,Dashboard!$Q$7)+SUMIFS('5th week'!$L$12:$L$60,'5th week'!$B$12:$B$60,Dashboard!M32,'5th week'!$D$12:$D$60,Dashboard!$Q$7) -> 0 | R32: =SUMIFS('1st week'!$L$12:$L$60,'1st week'!$B$12:$B$60,Dashboard!M32,'1st week'!$D$12:$D$60,Dashboard!$R$7)+SUMIFS('2nd week'!$L$12:$L$60,'2nd week'!$B$12:$B$60,Dashboard!M32,'2nd week'!$D$12:$D$60,Dashboard!$R$7)+SUMIFS('3rd week'!$L$12:$L$60,'3rd week'!$B$12:$B$60,Dashboard!M32,'3rd week'!$D$12:$D$60,Dashboard!$R$7)+SUMIFS('4th week'!$L$12:$L$60,'4th week'!$B$12:$B$60,Dashboard!M32,'4th week'!$D$12:$D$60,Dashboard!$R$7)+SUMIFS('5th week'!$L$12:$L$60,'5th week'!$B$12:$B$60,Dashboard!M32,'5th week'!$D$12:$D$60,Dashboard!$R$7) -> 0 | S32: =SUMIFS('1st week'!$L$12:$L$60,'1st week'!$B$12:$B$60,Dashboard!M32,'1st week'!$D$12:$D$60,Dashboard!$S$7)+SUMIFS('2nd week'!$L$12:$L$60,'2nd week'!$B$12:$B$60,Dashboard!M32,'2nd week'!$D$12:$D$60,Dashboard!$S$7)+SUMIFS('3rd week'!$L$12:$L$60,'3rd week'!$B$12:$B$60,Dashboard!M32,'3rd week'!$D$12:$D$60,Dashboard!$S$7)+SUMIFS('4th week'!$L$12:$L$60,'4th week'!$B$12:$B$60,Dashboard!M32,'4th week'!$D$12:$D$60,Dashboard!$S$7)+SUMIFS('5th week'!$L$12:$L$60,'5th week'!$B$12:$B$60,Dashboard!M32,'5th week'!$D$12:$D$60,Dashboard!$S$7) -> 0 | T32: =SUM(O32:S32) -> 0

Sheet (Drop Down) Data Base 
B2: Drop Down List Data
B4: Job # | C4: Nama Projek | D4: Deskripsi Tugas
B5: 20-401 | C5: Projek 1 | D5: Engineering
B6: 20-306 | C6: Projek 2 | D6: CAD
B7: 21-306 | C7: Projek 3 | D7: Admin
B8: 20-407 | C8: Projek 4 | D8: Clerical
B9: 21-102 | C9: Projek 5 | D9: Miscellaneous
B10: 20-303 | C10: Projek 6
B11: 20-111 | C11: Projek 7
B12: 20-202 | C12: Projek 8
B13: 19-204 | C13: Projek 9
B14: 21-401 | C14: Projek 10
B15: 21-304 | C15: Projek 11
B16: 21-408 | C16: Projek 12
B17: 21-403 | C17: Projek 13
B18: 21-301 | C18: Projek 14
B19: 20-106 | C19: Projek 15
B20: 19-304 | C20: Projek 16
B21: 21-405 | C21: Projek 17
... B28: 21-406 | C28: Projek 24

Sheet 1st week
B2: NAMA PERUSAHAAN
B3: LEMBAR KERJA MINGGUAN
B6: NAMA : | C6: ABC
B7: TANGGAL MULAI : | C7: 44743
B9: Job # | C9: Nama Projek | D9: Deskripsi Tugas | E9: Jam Kerja | L9: Total Minggu | M9: Catatan
E10: =C7 -> 44743 | F10: =IFERROR((IF(MONTH(E10)=MONTH(E10+1),E10+1," ")),"") -> 44744 | G10: =IFERROR((IF(MONTH(F10)=MONTH(F10+1),F10+1," ")),"") -> 44745 | H10: =IFERROR((IF(MONTH(G10)=MONTH(G10+1),G10+1," ")),"") -> 44746 | I10: =IFERROR((IF(MONTH(H10)=MONTH(H10+1),H10+1," ")),"") -> 44747 | J10: =IFERROR((IF(MONTH(I10)=MONTH(I10+1),I10+1," ")),"") -> 44748 | K10: =IFERROR((IF(MONTH(J10)=MONTH(J10+1),J10+1," ")),"") -> 44749
E11: =TEXT(E10,"DDDD") -> Friday | F11: =TEXT(F10,"DDDD") -> Saturday | G11: =TEXT(G10,"DDDD") -> Sunday | H11: =TEXT(H10,"DDDD") -> Monday | I11: =TEXT(I10,"DDDD") -> Tuesday | J11: =TEXT(J10,"DDDD") -> Wednesday | K11: =TEXT(K10,"DDDD") -> Thursday
B12: 20-401 | C12: {=IFERROR((INDEX(Table7[Nama Projek],MATCH(Table2[[#This Row],[Column1]],Table7[Job '#],0))),"")} -> Projek 1 | D12: Engineering | E12: 5 | F12: 10 | G12: 11 | H12: 0 | L12: =SUM(E12:K12) -> 26 | M12: Hertz Roseville
B13: 20-401 | C13: {=IFERROR((INDEX(Table7[Nama Projek],MATCH(Table2[[#This Row],[Column1]],Table7[Job '#],0))),"")} -> Projek 1 | D13: CAD | E13: 11 | F13: 15 | G13: 50 | L13: =SUM(E13:K13) -> 76 | M13: Hertz Roseville
B14: 20-306 | C14: {=IFERROR((INDEX(Table7[Nama Projek],MATCH(Table2[[#This Row],[Column1]],Table7[Job '#],0))),"")} -> Projek 2 | D14: Admin | L14: =SUM(E14:K14) -> 0 | M14: EBMUD Arc Flash Analysis
B15: 21-102 | C15: {=IFERROR((INDEX(Table7[Nama Projek],MATCH(Table2[[#This Row],[Column1]],Table7[Job '#],0))),"")} -> Projek 5 | D15: CAD | L15: =SUM(E15:K15) -> 0 | M15: EBMUD Arc Flash Analysis
B16: 20-303 | C16: {=IFERROR((INDEX(Table7[Nama Projek],MATCH(Table2[[#This Row],[Column1]],Table7[Job '#],0))),"")} -> Projek 6 | D16: Miscellaneous | L16: =SUM(E16:K16) -> 0 | M16: Lagrange construction services
B17: 21-306 | C17: {=IFERROR((INDEX(Table7[Nama Projek],MATCH(Table2[[#This Row],[Column1]],Table7[Job '#],0))),"")} -> Projek 3 | D17: Admin | L17: =SUM(E17:K17) -> 0 | M17: Lagrange construction services
B18: 20-407 | C18: {=IFERROR((INDEX(Table7[Nama Projek],MATCH(Table2[[#This Row],[Column1]],Table7[Job '#],0))),"")} -> Projek 4 | D18: CAD | L18: =SUM(E18:K18) -> 0 | M18: Urban Farmer
B19: 20-111 | C19: {=IFERROR((INDEX(Table7[Nama Projek],MATCH(Table2[[#This Row],[Column1]],Table7[Job '#],0))),"")} -> Projek 7 | D19: Engineering | L19: =SUM(E19:K19) -> 0 | M19: Urban Farmer
B20: 21-102 | C20: {=IFERROR((INDEX(Table7[Nama Projek],MATCH(Table2[[#This Row],[Column1]],Table7[Job '#],0))),"")} -> Projek 5 | D20: CAD | L20: =SUM(E20:K20) -> 0 | M20: San Joaquin EGEN
B21: 21-102 | C21: {=IFERROR((INDEX(Table7[Nama Projek],MATCH(Table2[[#This Row],[Column1]],Table7[Job '#],0))),"")} -> Projek 5 | D21: Engineering | L21: =SUM(E21:K21) -> 0 | M21: San Joaquin EGEN
B22: 20-303 | C22: {=IFERROR((INDEX(Table7[Nama Projek],MATCH(Table2[[#This Row],[Column1]],Table7[Job '#],0))),"")} -> Projek 6 | D22: Engineering | L22: =SUM(E22:K22) -> 0 | M22: SJWD EGEN Replacement (Task 4 - Bacon Re-Design)
B23: 20-303 | C23: {=IFERROR((INDEX(Table7[Nama Projek],MATCH(Table2[[#This Row],[Column1]],Table7[Job '#],0))),"")} -> Projek 6 | D23: CAD | L23: =SUM(E23:K23) -> 0 | M23: SJWD EGEN Replacement (Task 4 - Bacon Re-Design)
B24: 20-303 | C24: {=IFERROR((INDEX(Table7[Nama Projek],MATCH(Table2[[#This Row],[Column1]],Table7[Job '#],0))),"")} -> Projek 6 | D24: Engineering | L24: =SUM(E24:K24) -> 0 | M24: SJWD EGEN Replacement (Task 5 - UGB Construction Services)
B25: 20-303 | C25: {=IFERROR((INDEX(Table7[Nama Projek],MATCH(Table2[[#This Row],[Column1]],Table7[Job '#],0))),"")} -> Projek 6 | D25: CAD | L25: =SUM(E25:K25) -> 0 | M25: SJWD EGEN Replacement (Task 5 - UGB Construction Services)
... B35: 21-304 | C35: {=IFERROR((INDEX(Table7[Nama Projek],MATCH(Table2[[#This Row],[Column1]],Table7[Job '#],0))),"")} -> Projek 11 | D35: Engineering | L35: =SUM(E35:K35) -> 0 | M35: Project Sunrise
B36: 21-304 | C36: {=IFERROR((INDEX(Table7[Nama Projek],MATCH(Table2[[#This Row],[Column1]],Table7[Job '#],0))),"")} -> Projek 11 | D36: CAD | E36: 4 | L36: =SUM(E36:K36) -> 4 | M36: Project Sunrise
B37: 21-408 | C37: {=IFERROR((INDEX(Table7[Nama Projek],MATCH(Table2[[#This Row],[Column1]],Table7[Job '#],0))),"")} -> Projek 12 | D37: Engineering | L37: =SUM(E37:K37) -> 0 | M37: OLWD Collection System Master Plan
B38: 21-408 | C38: {=IFERROR((INDEX(Table7[Nama Projek],MATCH(Table2[[#This Row],[Column1]],Table7[Job '#],0))),"")} -> Projek 12 | D38: CAD | L38: =SUM(E38:K38) -> 0 | M38: OLWD Collection System Master Plan
B39: 21-403 | C39: {=IFERROR((INDEX(Table7[Nama Projek],MATCH(Table2[[#This Row],[Column1]],Table7[Job '#],0))),"")} -> Projek 13 | D39: Engineering | L39: =SUM(E39:K39) -> 0 | M39: SBVMWD EBX Interie
B40: 21-403 | C40: {=IFERROR((INDEX(Table7[Nama Projek],MATCH(Table2[[#This Row],[Column1]],Table7[Job '#],0))),"")} -> Projek 13 | D40: CAD | L40: =SUM(E40:K40) -> 0 | M40: SBVMWD EBX Interie
B41: 21-301 | C41: {=IFERROR((INDEX(Table7[Nama Projek],MATCH(Table2[[#This Row],[Column1]],Table7[Job '#],0))),"")} -> Projek 14 | D41: Engineering | L41: =SUM(E41:K41) -> 0 | M41: CCWD PP1
B42: 21-301 | C42: {=IFERROR((INDEX(Table7[Nama Projek],MATCH(Table2[[#This Row],[Column1]],Table7[Job '#],0))),"")} -> Projek 14 | D42: CAD | L42: =SUM(E42:K42) -> 0 | M42: CCWD PP1
B43: 20-106 | C43: {=IFERROR((INDEX(Table7[Nama Projek],MATCH(Table2[[#This Row],[Column1]],Table7[Job '#],0))),"")} -> Projek 15 | D43: Admin | L43: =SUM(E43:K43) -> 0 | M43: EBMUD Chloramine
B44: 19-304 | C44: {=IFERROR((INDEX(Table7[Nama Projek],MATCH(Table2[[#This Row],[Column1]],Table7[Job '#],0))),"")} -> Projek 16 | D44: Engineering | L44: =SUM(E44:K44) -> 0 | M44: EBMUD general questions
B45: 21-405 | C45: {=IFERROR((INDEX(Table7[Nama Projek],MATCH(Table2[[#This Row],[Column1]],Table7[Job '#],0))),"")} -> Projek 17 | D45: Engineering | L45: =SUM(E45:K45) -> 0 | M45: SOL State Prison
B46: 21-405 | C46: {=IFERROR((INDEX(Table7[Nama Projek],MATCH(Table2[[#This Row],[Column1]],Table7[Job '#],0))),"")} -> Projek 17 | D46: CAD | L46: =SUM(E46:K46) -> 0 | M46: SOL State Prison
B47: 21-407 | C47: {=IFERROR((INDEX(Table7[Nama Projek],MATCH(Table2[[#This Row],[Column1]],Table7[Job '#],0))),"")} -> Projek 18 | D47: Engineering | L47: =SUM(E47:K47) -> 0 | M47: Lodi Police Shooting Range
B48: 21-407 | C48: {=IFERROR((INDEX(Table7[Nama Projek],MATCH(Table2[[#This Row],[Column1]],Table7[Job '#],0))),"")} -> Projek 18 | D48: CAD | L48: =SUM(E48:K48) -> 0 | M48: Lodi Police Shooting Range
... B57: 19-304 | C57: {=IFERROR((INDEX(Table7[Nama Projek],MATCH(Table2[[#This Row],[Column1]],Table7[Job '#],0))),"")} -> Projek 16 | D57: Engineering | L57: =SUM(E57:K57) -> 0 | M57: East Ridge Modifications
B58: 21-406 | C58: {=IFERROR((INDEX(Table7[Nama Projek],MATCH(Table2[[#This Row],[Column1]],Table7[Job '#],0))),"")} -> Projek 24 | D58: CAD | E58: 2 | L58: =SUM(E58:K58) -> 2 | M58: East Ridge Modifications
C59: {=IFERROR((INDEX(Table7[Nama Projek],MATCH(Table2[[#This Row],[Column1]],Table7[Job '#],0))),"")} | D59: Admin | L59: =SUM(E59:K59) -> 0
C60: {=IFERROR((INDEX(Table7[Nama Projek],MATCH(Table2[[#This Row],[Column1]],Table7[Job '#],0))),"")} | D60: Miscellaneous
B62: TOTAL | E62: =SUM(E12:E60) -> 22 | F62: =SUM(F12:F60) -> 25 | G62: =SUM(G12:G60) -> 61 | H62: =SUM(H12:H60) -> 0 | I62: =SUM(I12:I60) -> 0 | J62: =SUM(J12:J60) -> 0 | K62: =SUM(K12:K60) -> 0

Sheet 2nd week
B2: NAMA PERUSAHAAN
B3: LEMBAR KERJA MINGGUAN
B6: NAMA : | C6: ABC
B7: TANGGAL MULAI : | C7: =IFERROR((IF(MONTH('1st week'!K10)=MONTH('1st week'!K10+1),('1st week'!K10+1),"")),"") -> 44750
B9: Job # | C9: Nama Projek | D9: Deskripsi Tugas | E9: Jam Kerja | L9: Total Minggu | M9: Catatan
E10: =C7 -> 44750 | F10: =IFERROR((IF(MONTH(E10)=MONTH(E10+1),E10+1," ")),"") -> 44751 | G10: =IFERROR((IF(MONTH(F10)=MONTH(F10+1),F10+1," ")),"") -> 44752 | H10: =IFERROR((IF(MONTH(G10)=MONTH(G10+1),G10+1," ")),"") -> 44753 | I10: =IFERROR((IF(MONTH(H10)=MONTH(H10+1),H10+1," ")),"") -> 44754 | J10: =IFERROR((IF(MONTH(I10)=MONTH(I10+1),I10+1," ")),"") -> 44755 | K10: =IFERROR((IF(MONTH(J10)=MONTH(J10+1),J10+1," ")),"") -> 44756
E11: =TEXT(E10,"DDDD") -> Friday | F11: =TEXT(F10,"DDDD") -> Saturday | G11: =TEXT(G10,"DDDD") -> Sunday | H11: =TEXT(H10,"DDDD") -> Monday | I11: =TEXT(I10,"DDDD") -> Tuesday | J11: =TEXT(J10,"DDDD") -> Wednesday | K11: =TEXT(K10,"DDDD") -> Thursday
B12: 20-401 | C12: {=IFERROR((INDEX(Table7[Nama Projek],MATCH(Table24[[#This Row],[Column1]],Table7[Job '#],0))),"")} -> Projek 1 | D12: Engineering | E12: 5 | F12: 10 | G12: 11 | H12: 0 | L12: =SUM(E12:K12) -> 26 | M12: Hertz Roseville
B13: 20-401 | C13: {=IFERROR((INDEX(Table7[Nama Projek],MATCH(Table24[[#This Row],[Column1]],Table7[Job '#],0))),"")} -> Projek 1 | D13: CAD | L13: =SUM(E13:K13) -> 0 | M13: Hertz Roseville
B14: 20-303 | C14: {=IFERROR((INDEX(Table7[Nama Projek],MATCH(Table24[[#This Row],[Column1]],Table7[Job '#],0))),"")} -> Projek 6 | D14: CAD | E14: 20 | F14: 22 | G14: 40 | L14: =SUM(E14:K14) -> 82 | M14: EBMUD Arc Flash Analysis
B15: 20-306 | C15: {=IFERROR((INDEX(Table7[Nama Projek],MATCH(Table24[[#This Row],[Column1]],Table7[Job '#],0))),"")} -> Projek 2 | D15: CAD | L15: =SUM(E15:K15) -> 0 | M15: EBMUD Arc Flash Analysis
B16: 21-306 | C16: {=IFERROR((INDEX(Table7[Nama Projek],MATCH(Table24[[#This Row],[Column1]],Table7[Job '#],0))),"")} -> Projek 3 | D16: CAD | L16: =SUM(E16:K16) -> 0 | M16: Lagrange construction services
B17: 21-306 | C17: {=IFERROR((INDEX(Table7[Nama Projek],MATCH(Table24[[#This Row],[Column1]],Table7[Job '#],0))),"")} -> Projek 3 | D17: Engineering | L17: =SUM(E17:K17) -> 0 | M17: Lagrange construction services
B18: 20-407 | C18: {=IFERROR((INDEX(Table7[Nama Projek],MATCH(Table24[[#This Row],[Column1]],Table7[Job '#],0))),"")} -> Projek 4 | D18: CAD | L18: =SUM(E18:K18) -> 0 | M18: Urban Farmer
B19: 20-407 | C19: {=IFERROR((INDEX(Table7[Nama Projek],MATCH(Table24[[#This Row],[Column1]],Table7[Job '#],0))),"")} -> Projek 4 | D19: Engineering | L19: =SUM(E19:K19) -> 0 | M19: Urban Farmer
B20: 21-102 | C20: {=IFERROR((INDEX(Table7[Nama Projek],MATCH(Table24[[#This Row],[Column1]],Table7[Job '#],0))),"")} -> Projek 5 | D20: CAD | L20: =SUM(E20:K20) -> 0 | M20: San Joaquin EGEN
B21: 21-102 | C21: {=IFERROR((INDEX(Table7[Nama Projek],MATCH(Table24[[#This Row],[Column1]],Table7[Job '#],0))),"")} -> Projek 5 | D21: Engineering | L21: =SUM(E21:K21) -> 0 | M21: San Joaquin EGEN
B22: 20-303 | C22: {=IFERROR((INDEX(Table7[Nama Projek],MATCH(Table24[[#This Row],[Column1]],Table7[Job '#],0))),"")} -> Projek 6 | D22: Engineering | L22: =SUM(E22:K22) -> 0 | M22: SJWD EGEN Replacement (Task 4 - Bacon Re-Design)
B23: 20-303 | C23: {=IFERROR((INDEX(Table7[Nama Projek],MATCH(Table24[[#This Row],[Column1]],Table7[Job '#],0))),"")} -> Projek 6 | D23: CAD | L23: =SUM(E23:K23) -> 0 | M23: SJWD EGEN Replacement (Task 4 - Bacon Re-Design)
B24: 20-303 | C24: {=IFERROR((INDEX(Table7[Nama Projek],MATCH(Table24[[#This Row],[Column1]],Table7[Job '#],0))),"")} -> Projek 6 | D24: Engineering | L24: =SUM(E24:K24) -> 0 | M24: SJWD EGEN Replacement (Task 5 - UGB Construction Services)
B25: 20-303 | C25: {=IFERROR((INDEX(Table7[Nama Projek],MATCH(Table24[[#This Row],[Column1]],Table7[Job '#],0))),"")} -> Projek 6 | D25: CAD | L25: =SUM(E25:K25) -> 0 | M25: SJWD EGEN Replacement (Task 5 - UGB Construction Services)
B26: 20-111 | C26: {=IFERROR((INDEX(Table7[Nama Projek],MATCH(Table24[[#This Row],[Column1]],Table7[Job '#],0))),"")} -> Projek 7 | D26: Engineering | L26: =SUM(E26:K26) -> 0 | M26: Manteca Storm Drain (Zone 36/39)
... B35: 21-304 | C35: {=IFERROR((INDEX(Table7[Nama Projek],MATCH(Table24[[#This Row],[Column1]],Table7[Job '#],0))),"")} -> Projek 11 | D35: Engineering | L35: =SUM(E35:K35) -> 0 | M35: Project Sunrise
B36: 21-304 | C36: {=IFERROR((INDEX(Table7[Nama Projek],MATCH(Table24[[#This Row],[Column1]],Table7[Job '#],0))),"")} -> Projek 11 | D36: CAD | E36: 4 | L36: =SUM(E36:K36) -> 4 | M36: Project Sunrise
B37: 21-408 | C37: {=IFERROR((INDEX(Table7[Nama Projek],MATCH(Table24[[#This Row],[Column1]],Table7[Job '#],0))),"")} -> Projek 12 | D37: Engineering | L37: =SUM(E37:K37) -> 0 | M37: OLWD Collection System Master Plan
B38: 21-408 | C38: {=IFERROR((INDEX(Table7[Nama Projek],MATCH(Table24[[#This Row],[Column1]],Table7[Job '#],0))),"")} -> Projek 12 | D38: CAD | L38: =SUM(E38:K38) -> 0 | M38: OLWD Collection System Master Plan
B39: 21-403 | C39: {=IFERROR((INDEX(Table7[Nama Projek],MATCH(Table24[[#This Row],[Column1]],Table7[Job '#],0))),"")} -> Projek 13 | D39: Engineering | L39: =SUM(E39:K39) -> 0 | M39: SBVMWD EBX Interie
B40: 21-403 | C40: {=IFERROR((INDEX(Table7[Nama Projek],MATCH(Table24[[#This Row],[Column1]],Table7[Job '#],0))),"")} -> Projek 13 | D40: CAD | L40: =SUM(E40:K40) -> 0 | M40: SBVMWD EBX Interie
B41: 21-301 | C41: {=IFERROR((INDEX(Table7[Nama Projek],MATCH(Table24[[#This Row],[Column1]],Table7[Job '#],0))),"")} -> Projek 14 | D41: Engineering | L41: =SUM(E41:K41) -> 0 | M41: CCWD PP1
B42: 21-301 | C42: {=IFERROR((INDEX(Table7[Nama Projek],MATCH(Table24[[#This Row],[Column1]],Table7[Job '#],0))),"")} -> Projek 14 | D42: CAD | L42: =SUM(E42:K42) -> 0 | M42: CCWD PP1
B43: 20-106 | C43: {=IFERROR((INDEX(Table7[Nama Projek],MATCH(Table24[[#This Row],[Column1]],Table7[Job '#],0))),"")} -> Projek 15 | D43: Admin | L43: =SUM(E43:K43) -> 0 | M43: EBMUD Chloramine
B44: 19-304 | C44: {=IFERROR((INDEX(Table7[Nama Projek],MATCH(Table24[[#This Row],[Column1]],Table7[Job '#],0))),"")} -> Projek 16 | D44: Engineering | L44: =SUM(E44:K44) -> 0 | M44: EBMUD general questions
B45: 21-405 | C45: {=IFERROR((INDEX(Table7[Nama Projek],MATCH(Table24[[#This Row],[Column1]],Table7[Job '#],0))),"")} -> Projek 17 | D45: Engineering | L45: =SUM(E45:K45) -> 0 | M45: SOL State Prison
B46: 21-405 | C46: {=IFERROR((INDEX(Table7[Nama Projek],MATCH(Table24[[#This Row],[Column1]],Table7[Job '#],0))),"")} -> Projek 17 | D46: CAD | L46: =SUM(E46:K46) -> 0 | M46: SOL State Prison
B47: 21-407 | C47: {=IFERROR((INDEX(Table7[Nama Projek],MATCH(Table24[[#This Row],[Column1]],Table7[Job '#],0))),"")} -> Projek 18 | D47: Engineering | L47: =SUM(E47:K47) -> 0 | M47: Lodi Police Shooting Range
B48: 21-407 | C48: {=IFERROR((INDEX(Table7[Nama Projek],MATCH(Table24[[#This Row],[Column1]],Table7[Job '#],0))),"")} -> Projek 18 | D48: CAD | L48: =SUM(E48:K48) -> 0 | M48: Lodi Police Shooting Range
... B57: 21-406 | C57: {=IFERROR((INDEX(Table7[Nama Projek],MATCH(Table24[[#This Row],[Column1]],Table7[Job '#],0))),"")} -> Projek 24 | D57: Engineering | L57: =SUM(E57:K57) -> 0 | M57: East Ridge Modifications
B58: 21-406 | C58: {=IFERROR((INDEX(Table7[Nama Projek],MATCH(Table24[[#This Row],[Column1]],Table7[Job '#],0))),"")} -> Projek 24 | D58: CAD | E58: 2 | L58: =SUM(E58:K58) -> 2 | M58: East Ridge Modifications
C59: {=IFERROR((INDEX(Table7[Nama Projek],MATCH(Table24[[#This Row],[Column1]],Table7[Job '#],0))),"")} | D59: Miscellaneous | L59: =SUM(E59:K59) -> 0
C60: {=IFERROR((INDEX(Table7[Nama Projek],MATCH(Table24[[#This Row],[Column1]],Table7[Job '#],0))),"")} | D60: Engineering
...

Sheet 3rd week
B2: NAMA PERUSAHAAN
B3: LEMBAR KERJA MINGGUAN
B6: NAMA : | C6: ABC
B7: TANGGAL MULAI ; | C7: =IFERROR((IF(MONTH('1st week'!K10)=MONTH('1st week'!K10+1),('1st week'!K10+1),"")),"") -> 44750
B9: Job # | C9: Nama Projek | D9: Deskripsi Tugas | E9: Jam Kerja | L9: Total Minggu | M9: Catatan
E10: =C7 -> 44750 | F10: =IFERROR((IF(MONTH(E10)=MONTH(E10+1),E10+1," ")),"") -> 44751 | G10: =IFERROR((IF(MONTH(F10)=MONTH(F10+1),F10+1," ")),"") -> 44752 | H10: =IFERROR((IF(MONTH(G10)=MONTH(G10+1),G10+1," ")),"") -> 44753 | I10: =IFERROR((IF(MONTH(H10)=MONTH(H10+1),H10+1," ")),"") -> 44754 | J10: =IFERROR((IF(MONTH(I10)=MONTH(I10+1),I10+1," ")),"") -> 44755 | K10: =IFERROR((IF(MONTH(J10)=MONTH(J10+1),J10+1," ")),"") -> 44756
E11: =TEXT(E10,"DDDD") -> Friday | F11: =TEXT(F10,"DDDD") -> Saturday | G11: =TEXT(G10,"DDDD") -> Sunday | H11: =TEXT(H10,"DDDD") -> Monday | I11: =TEXT(I10,"DDDD") -> Tuesday | J11: =TEXT(J10,"DDDD") -> Wednesday | K11: =TEXT(K10,"DDDD") -> Thursday
B12: 20-401 | C12: {=IFERROR((INDEX(Table7[Nama Projek],MATCH(Table245[[#This Row],[Column1]],Table7[Job '#],0))),"")} -> Projek 1 | D12: Engineering | E12: 5 | F12: 10 | G12: 11 | H12: 0 | L12: =SUM(E12:K12) -> 26 | M12: Hertz Roseville
B13: 20-401 | C13: {=IFERROR((INDEX(Table7[Nama Projek],MATCH(Table245[[#This Row],[Column1]],Table7[Job '#],0))),"")} -> Projek 1 | D13: CAD | L13: =SUM(E13:K13) -> 0 | M13: Hertz Roseville
B14: 20-303 | C14: {=IFERROR((INDEX(Table7[Nama Projek],MATCH(Table245[[#This Row],[Column1]],Table7[Job '#],0))),"")} -> Projek 6 | D14: CAD | F14: 100 | L14: =SUM(E14:K14) -> 100 | M14: EBMUD Arc Flash Analysis
B15: 20-306 | C15: {=IFERROR((INDEX(Table7[Nama Projek],MATCH(Table245[[#This Row],[Column1]],Table7[Job '#],0))),"")} -> Projek 2 | D15: CAD | L15: =SUM(E15:K15) -> 0 | M15: EBMUD Arc Flash Analysis
B16: 21-306 | C16: {=IFERROR((INDEX(Table7[Nama Projek],MATCH(Table245[[#This Row],[Column1]],Table7[Job '#],0))),"")} -> Projek 3 | D16: CAD | L16: =SUM(E16:K16) -> 0 | M16: Lagrange construction services
B17: 21-306 | C17: {=IFERROR((INDEX(Table7[Nama Projek],MATCH(Table245[[#This Row],[Column1]],Table7[Job '#],0))),"")} -> Projek 3 | D17: Engineering | L17: =SUM(E17:K17) -> 0 | M17: Lagrange construction services
B18: 20-407 | C18: {=IFERROR((INDEX(Table7[Nama Projek],MATCH(Table245[[#This Row],[Column1]],Table7[Job '#],0))),"")} -> Projek 4 | D18: CAD | L18: =SUM(E18:K18) -> 0 | M18: Urban Farmer
B19: 20-407 | C19: {=IFERROR((INDEX(Table7[Nama Projek],MATCH(Table245[[#This Row],[Column1]],Table7[Job '#],0))),"")} -> Projek 4 | D19: Engineering | L19: =SUM(E19:K19) -> 0 | M19: Urban Farmer
B20: 21-102 | C20: {=IFERROR((INDEX(Table7[Nama Projek],MATCH(Table245[[#This Row],[Column1]],Table7[Job '#],0))),"")} -> Projek 5 | D20: CAD | L20: =SUM(E20:K20) -> 0 | M20: San Joaquin EGEN
B21: 21-102 | C21: {=IFERROR((INDEX(Table7[Nama Projek],MATCH(Table245[[#This Row],[Column1]],Table7[Job '#],0))),"")} -> Projek 5 | D21: Engineering | L21: =SUM(E21:K21) -> 0 | M21: San Joaquin EGEN
B22: 20-303 | C22: {=IFERROR((INDEX(Table7[Nama Projek],MATCH(Table245[[#This Row],[Column1]],Table7[Job '#],0))),"")} -> Projek 6 | D22: Engineering | L22: =SUM(E22:K22) -> 0 | M22: SJWD EGEN Replacement (Task 4 - Bacon Re-Design)
B23: 20-303 | C23: {=IFERROR((INDEX(Table7[Nama Projek],MATCH(Table245[[#This Row],[Column1]],Table7[Job '#],0))),"")} -> Projek 6 | D23: CAD | L23: =SUM(E23:K23) -> 0 | M23: SJWD EGEN Replacement (Task 4 - Bacon Re-Design)
B24: 20-303 | C24: {=IFERROR((INDEX(Table7[Nama Projek],MATCH(Table245[[#This Row],[Column1]],Table7[Job '#],0))),"")} -> Projek 6 | D24: Engineering | L24: =SUM(E24:K24) -> 0 | M24: SJWD EGEN Replacement (Task 5 - UGB Construction Services)
B25: 20-303 | C25: {=IFERROR((INDEX(Table7[Nama Projek],MATCH(Table245[[#This Row],[Column1]],Table7[Job '#],0))),"")} -> Projek 6 | D25: CAD | L25: =SUM(E25:K25) -> 0 | M25: SJWD EGEN Replacement (Task 5 - UGB Construction Services)
B26: 20-111 | C26: {=IFERROR((INDEX(Table7[Nama Projek],MATCH(Table245[[#This Row],[Column1]],Table7[Job '#],0))),"")} -> Projek 7 | D26: Engineering | L26: =SUM(E26:K26) -> 0 | M26: Manteca Storm Drain (Zone 36/39)
... B35: 21-304 | C35: {=IFERROR((INDEX(Table7[Nama Projek],MATCH(Table245[[#This Row],[Column1]],Table7[Job '#],0))),"")} -> Projek 11 | D35: Engineering | L35: =SUM(E35:K35) -> 0 | M35: Project Sunrise
B36: 21-304 | C36: {=IFERROR((INDEX(Table7[Nama Projek],MATCH(Table245[[#This Row],[Column1]],Table7[Job '#],0))),"")} -> Projek 11 | D36: CAD | E36: 4 | L36: =SUM(E36:K36) -> 4 | M36: Project Sunrise
B37: 21-408 | C37: {=IFERROR((INDEX(Table7[Nama Projek],MATCH(Table245[[#This Row],[Column1]],Table7[Job '#],0))),"")} -> Projek 12 | D37: Engineering | L37: =SUM(E37:K37) -> 0 | M37: OLWD Collection System Master Plan
B38: 21-408 | C38: {=IFERROR((INDEX(Table7[Nama Projek],MATCH(Table245[[#This Row],[Column1]],Table7[Job '#],0))),"")} -> Projek 12 | D38: CAD | L38: =SUM(E38:K38) -> 0 | M38: OLWD Collection System Master Plan
B39: 21-403 | C39: {=IFERROR((INDEX(Table7[Nama Projek],MATCH(Table245[[#This Row],[Column1]],Table7[Job '#],0))),"")} -> Projek 13 | D39: Engineering | L39: =SUM(E39:K39) -> 0 | M39: SBVMWD EBX Interie
B40: 21-403 | C40: {=IFERROR((INDEX(Table7[Nama Projek],MATCH(Table245[[#This Row],[Column1]],Table7[Job '#],0))),"")} -> Projek 13 | D40: CAD | L40: =SUM(E40:K40) -> 0 | M40: SBVMWD EBX Interie
B41: 21-301 | C41: {=IFERROR((INDEX(Table7[Nama Projek],MATCH(Table245[[#This Row],[Column1]],Table7[Job '#],0))),"")} -> Projek 14 | D41: Engineering | L41: =SUM(E41:K41) -> 0 | M41: CCWD PP1
B42: 21-301 | C42: {=IFERROR((INDEX(Table7[Nama Projek],MATCH(Table245[[#This Row],[Column1]],Table7[Job '#],0))),"")} -> Projek 14 | D42: CAD | L42: =SUM(E42:K42) -> 0 | M42: CCWD PP1
B43: 20-106 | C43: {=IFERROR((INDEX(Table7[Nama Projek],MATCH(Table245[[#This Row],[Column1]],Table7[Job '#],0))),"")} -> Projek 15 | D43: Admin | L43: =SUM(E43:K43) -> 0 | M43: EBMUD Chloramine
B44: 19-304 | C44: {=IFERROR((INDEX(Table7[Nama Projek],MATCH(Table245[[#This Row],[Column1]],Table7[Job '#],0))),"")} -> Projek 16 | D44: Engineering | L44: =SUM(E44:K44) -> 0 | M44: EBMUD general questions
B45: 21-405 | C45: {=IFERROR((INDEX(Table7[Nama Projek],MATCH(Table245[[#This Row],[Column1]],Table7[Job '#],0))),"")} -> Projek 17 | D45: Engineering | L45: =SUM(E45:K45) -> 0 | M45: SOL State Prison
B46: 21-405 | C46: {=IFERROR((INDEX(Table7[Nama Projek],MATCH(Table245[[#This Row],[Column1]],Table7[Job '#],0))),"")} -> Projek 17 | D46: CAD | L46: =SUM(E46:K46) -> 0 | M46: SOL State Prison
