Workbook
Name bakkontrol: 'Bak Kontrol'!$C$3:$I$75
Name besidanaluminium: 'Besi dan Aluminium'!$C$3:$I$123
Name beton: Beton!$C$3:$I$1055
Name galiantanah: 'Galian Tanah'!$C$3:$J$461
Name jaringanlistrik: 'Jaringan Listrik'!$C$3:$I$2542
Name kaca: Kaca!$C$3:$I$259
Name kayu: 'Struktur Kayu'!$C$3:$J$48
Name pasangdinding: 'Pasangan Dinding'!$C$3:$I$516
Name pembongkaran: Pembongkaran!$C$3:$J$146
Name pengecatandanpelitur: 'Pengecatan dan Pelituran'!$C$3:$I$484
Name penutupatap: 'Penutup Atap'!$C$3:$I$994
Name penutuplantaidandinding: 'Penutup Lantai dan Dinding'!$C$3:$I$2037
Name perpipaangedung: 'Perpipaan dan proteksi kebakar '!$C$3:$I$366
Name persiapan: Persiapan!$C$5:$K$682
Name pintudanjendela: 'Pintu dan Jendela'!$C$3:$I$954
Name plafon: Plafon!$C$3:$I$285
Name plesteranacian: 'Plesteran Dan Acian'!$C$3:$I$276
Name pondasi: Pondasi!$C$3:$J$607
Name rangkaatap: 'Rangka Atap'!$C$4:$J$199
Name sanitair: Sanitair!$C$3:$I$414
Name signage: Signage!$C$3:$I$109
Name sistemairlimbah: 'Sistem Air Limbah'!$C$3:$I$236
Name sistemairminum: 'Sistem Air Minum'!$C$3:$I$608
Name TENAGA: '[1]UPAH BAHAN'!$C$6:$C$19
Name timbunanpemadatan: 'Timbunan Pemadatan'!$C$3:$J$154
Name upahbahan: 'Upah Bahan'!$F$9:$H$2256

Sheet Daftar Harga Satuan Pekerjaan
B2: DAFTAR HARGA SATUAN PEKERJAAN (DHSP)
B3: BIDANG CIPTA KARYA
B4: Berdasarkan SE Bina Konstruksi Nomor 30/SE/Dk/2025
B6: NO | C6: URAIAN PEKERJAAN | D6: SATUAN | E6: HARGA SATUAN | F6: KETERANGAN
B7: 1 | C7: DIVISI 1 Persiapan lapangan/site work
B8: 1.1 | C8: PEKERJAAN PERSIAPAN
B9: 1.1.1 | C9: Pembuatan pagar proyek
B10: 1.1.1.1 | C10: Pembuatan 1 m’ pagar sementara dari kayu tinggi 2 meter | D10: m' | E10: =VLOOKUP(C10,Persiapan!$D$5:$K$679,8,FALSE) -> 787300
B11: 1.1.1.2 | C11: Pembuatan 1 m’ pagar sementara dari seng gelombang rangka kayu tinggi 2 meter | D11: m' | E11: =VLOOKUP(C11,Persiapan!$D$5:$K$679,8,FALSE) -> 635500
B12: 1.1.1.3 | C12: Pembuatan 1 m’ pagar sementara dari kawat duri tinggi 2 meter | D12: m' | E12: =VLOOKUP(C12,Persiapan!$D$5:$K$679,8,FALSE) -> 378200
B13: 1.1.1.4 | C13: Pembuatan 1 m’ pagar sementara seng gelombang rangka baja L.40.40.4 tinggi pagar 1.8 meter | D13: m' | E13: =VLOOKUP(C13,Persiapan!$D$5:$K$679,8,FALSE) -> 428900
B14: 1.1.1.5 | C14: Pembuatan 1 m2 pagar BRC Galvanis | D14: m2 | E14: =VLOOKUP(C14,Persiapan!$D$5:$K$679,8,FALSE) -> 17400
B15: 1.1.1.6 | C15: Pemasangan 1 m2 panel beton pracetak 50x50x240 untuk pagar | D15: m2 | E15: =VLOOKUP(C15,Persiapan!$D$5:$K$679,8,FALSE) -> 434000
B16: 1.1.2 | C16: Alat dan/atau sarana penunjang | E16: =VLOOKUP(C16,Persiapan!$D$5:$K$679,8,FALSE) -> 0
B17: 1.1.2.1 | C17: 1 buah papan nama pekerjaan ukuran 0.8x1.2 menggunakan multiflex 18 mm, frame besi siku dan tiang kayu 8/12 | D17: buah | E17: =VLOOKUP(C17,Persiapan!$D$5:$K$679,8,FALSE) -> 1909000
B18: 1.1.2.2 | C18: 1 buah papan nama pekerjaan ukuran 0.6x08 menggunakan multiplex 10 mm, frame allumunium siku dan tiang kayu 5/7, printing banner plastik | D18: buah | E18: =VLOOKUP(C18,Persiapan!$D$5:$K$679,8,FALSE) -> 702500
B19: 1.1.2.3 | C19: Pembuatan 1 m2 kantor sementara/rumah jaga/gudang semen dan peralatan lantai plesteran, dinding setengah tembok | D19: m2 | E19: =VLOOKUP(C19,Persiapan!$D$5:$K$679,8,FALSE) -> 3501200
B20: 1.1.2.4 | C20: Pembuatan 1 m2 direksi keet (Kantor), los kerja dan gudang | D20: m2 | E20: =VLOOKUP(C20,Persiapan!$D$5:$K$679,8,FALSE) -> 5699600
B21: 1.1.2.5 | C21: Pembuatan 1 m2 jalan sementara lapis macadam | D21: m2 | E21: =VLOOKUP(C21,Persiapan!$D$5:$K$679,8,FALSE) -> 1368300
B22: 1.1.2.6 | C22: Pembuatan 1 m2 jalan sementara (Jalan Tanah) | D22: m2 | E22: =VLOOKUP(C22,Persiapan!$D$5:$K$679,8,FALSE) -> 1281300
B23: 1.1.2.7 | C23: Pembuatan 1 m2 jalan sementara (Jalan Kerikil) | D23: m2 | E23: =VLOOKUP(C23,Persiapan!$D$5:$K$679,8,FALSE) -> 1343200
B24: 1.1.3 | C24: Pembersihan dan pengupasan permukaan tanah
B25: 1.1.3.1 | C25: 1 m3 Pembersihan dan pengupasan permukaan tanah (striping) s.d. tanaman ∅ 2 cm | D25: m2 | E25: =VLOOKUP(C25,Persiapan!$D$5:$K$679,8,FALSE) -> 12100
B26: 1.1.3.2 | C26: Tebas tebang 1 m2 tanaman/tumbuhan ∅ < 5 cm | D26: m2 | E26: =VLOOKUP(C26,Persiapan!$D$5:$K$679,8,FALSE) -> 3900
B27: 1.1.3.3 | C27: Tebas tebang 1 m 2 tanaman/tumbuhan ∅ >5 s.d. 15 cm | D27: m2 | E27: =VLOOKUP(C27,Persiapan!$D$5:$K$679,8,FALSE) -> 6600
B28: 1.1.3.4 | C28: Tebas tebang 1 batang pohon/tumbuhan ∅ >15 s.d. 30 cm | D28: btg | E28: =VLOOKUP(C28,Persiapan!$D$5:$K$679,8,FALSE) -> 22300
B29: 1.1.3.5 | C29: Tebas tebang 1 batang pohon/tumbuhan ∅ > 30 s.d 50 cm | D29: btg | E29: =VLOOKUP(C29,Persiapan!$D$5:$K$679,8,FALSE) -> 22200
B30: 1.1.3.6 | C30: Tebas tebang 1 batang pohon/tumbuhan ∅ > 50 s.d 75 cm (diameter pohon diukur 1 m di atas permukaan tanah) | D30: btg | E30: =VLOOKUP(C30,Persiapan!$D$5:$K$679,8,FALSE) -> 48800
B31: 1.1.3.7 | C31: Tebas tebang 1 batang pohon/tumbuhan ∅ > 75 cm (diameter pohon diukur 1 m di atas permukaan tanah) | D31: btg | E31: =VLOOKUP(C31,Persiapan!$D$5:$K$679,8,FALSE) -> 62700
B32: 1.1.3.8 | C32: Gali dan cabut 1 tunggul pohon tanaman keras ∅ > 5 s.d. 15 cm (termasuk pembuangan sisa tunggul tanpa menutup kembali bekas lubang) | D32: tgl | E32: =VLOOKUP(C32,Persiapan!$D$5:$K$679,8,FALSE) -> 48500
B33: 1.1.3.9 | C33: Gali dan cabut 1 tunggul pohon tanaman keras ∅ > 15 cm s.d. 30 cm (termasuk pembuangan sisa tunggul tanpa menutup kembali bekas lubang) | D33: tgl | E33: =VLOOKUP(C33,Persiapan!$D$5:$K$679,8,FALSE) -> 68300
B34: 1.1.3.10 | C34: Gali dan cabut 1 tunggul pohon tanaman keras ∅ > 30 cm s.d. 50 cm (termasuk pembuangan sisa tunggul tanpa menutup kembali bekas lubang) | D34: tgl | E34: =VLOOKUP(C34,Persiapan!$D$5:$K$679,8,FALSE) -> 96600
B35: 1.1.3.11 | C35: Gali dan cabut 1 tunggul pohon tanaman keras ∅ > 50 cm s.d. 75 cm (termasuk pembuangan sisa tunggul tanpa menutup kembali bekas lubang) | D35: tgl | E35: =VLOOKUP(C35,Persiapan!$D$5:$K$679,8,FALSE) -> 149900
B36: 1.1.3.12 | C36: Gali dan cabut 1 tunggul pohon tanaman keras ∅ > 75 cm (termasuk pembuangan sisa tunggul tanpa menutup kembali bekas lubang) | D36: tgl | E36: =VLOOKUP(C36,Persiapan!$D$5:$K$679,8,FALSE) -> 218200
... B41: 1.1.3.17 | C41: Gali dan cabut 1 tunggul pohon tanaman keras ∅ > 75 cm (termasuk pembuangan sisa tunggul dengan menutup kembali bekas lubang) | D41: m' | E41: =VLOOKUP(C41,Persiapan!$D$5:$K$679,8,FALSE) -> 271900
B42: 1.1.4 | C42: =Persiapan!D559 -> Pengukuran dan Pasangan Bouwplank | E42: =VLOOKUP(C42,Persiapan!$D$5:$K$679,8,FALSE) -> 0
B43: =Persiapan!C560 -> 1.1.4.1 | C43: =Persiapan!D560 -> Pengukuran ulang topografi seluas 1 Ha | D43: Ha | E43: =VLOOKUP(C43,Persiapan!$D$5:$K$679,8,FALSE) -> 3277000
B44: =Persiapan!C581 -> 1.1.4.2 | C44: =Persiapan!D581 -> Pasangan 1 m' bouwplank | D44: m' | E44: =VLOOKUP(C44,Persiapan!$D$5:$K$679,8,FALSE) -> 171500
B45: =Persiapan!C602 -> 1.1.4.3 | C45: =Persiapan!D602 -> Patok Kayu (kaso5/7) Panjang 0,5 m' | D45: m' | E45: =VLOOKUP(C45,Persiapan!$D$5:$K$679,8,FALSE) -> 191300
B46: =Persiapan!C622 -> 1.1.4.4 | C46: =Persiapan!D622 -> 1 Buah Patok Kayu (Kaso 5/7) panjang 1 m' | D46: m' | E46: =VLOOKUP(C46,Persiapan!$D$5:$K$679,8,FALSE) -> 85500
...

Sheet Upah Bahan
D4: HARGA SATUAN UPAH - MATERIAL - ALAT
D6: NO | E6: Kode | F6: UPAH - MATERIAL - ALAT | G6: SATUAN | H6: HARGA SATUAN | I6: KETERANGAN
D7: 1 | F7: 2 | G7: 3 | H7: 4 | I7: 5
D8: I. | F8: UPAH
D9: 1 | E9: L.01 | F9: Pekerja | G9: OH | H9: 100000
D10: 2 | E10: L.02 | F10: Tukang batu | G10: OH | H10: 145000
D11: 3 | E11: L.02 | F11: Tukang kayu | G11: OH | H11: 145000
D12: 4 | E12: L.02 | F12: Tukang besi | G12: OH | H12: 145000
D13: 5 | E13: L.02 | F13: Tukang cat | G13: OH | H13: 145000
E14: L.02 | F14: Tukang pelitur | G14: OH | H14: 145000
D15: 6 | E15: L.02 | F15: Tukang pipa | G15: OH | H15: 145000
D16: 7 | E16: L.02 | F16: Tukang penganyam bronjong | H16: 145000
D17: 8 | E17: L.02 | F17: Tukang tebas | H17: 145000
D18: 9 | E18: L.02 | F18: Tukang las | G18: OH | H18: 145000
D19: 10 | E19: L.02 | F19: Tukang las geotextile | H19: 145000
D20: 11 | E20: L.02 | F20: Tukang listrik | G20: OH | H20: 145000
D21: 12 | E21: L.02 | F21: Tukang alumunium | G21: OH | H21: 145000
D22: 13 | E22: L.02 | F22: Tukang kaca
D23: 14 | E23: L.02 | F23: Tukang erection | G23: OH | H23: 145000
D24: 15 | E24: L.02 | F24: Tukang tanam | G24: OH | H24: 145000
D25: 16 | E25: L.02 | F25: Tukang pemelihara taman | G25: OH | H25: 145000
D26: 10 | F26: Tukang gali | G26: OH | H26: 120000
D27: 11 | F27: Tukang aspal | G27: OH | H27: 120000
D28: 13 | E28: L.03 | F28: Kepala tukang | G28: OH | H28: 175000
D29: 14 | E29: L.04 | F29: Mandor | G29: OH | H29: 200000
D30: 21 | E30: L.05 | F30: Juru ukur | G30: OH | H30: 175000
D31: 28 | E31: L.06 | F31: Pembantu juru ukur | G31: OH | H31: 150000
D32: 24 | E32: L.07 | F32: Mekanik alat berat | G32: OH | H32: 220000
D33: 25 | E33: L.08 | F33: Operator alat berat | G33: OH | H33: 250000
D34: 30 | E34: L.09 | F34: Pembantu operator alat berat | G34: OH | H34: 130000
D35: 31 | E35: L.10 | F35: Sopir | G35: OH | H35: 200000
D36: 22 | E36: L.11 | F36: Kenek | G36: OH | H36: 135000
D37: 15 | F37: Administrasi bor | G37: OH | H37: 110000
D38: 16 | F38: Ahli geologist | G38: OH | H38: 400000
D39: 17 | F39: Ahli topografi | G39: OH | H39: 400000
D40: 18 | F40: Crew driller | G40: OH | H40: 125000
D41: 19 | F41: Driller | G41: OH | H41: 140000
D42: 20 | F42: Juru gambar | G42: OH | H42: 150000
D43: 23 | F43: Koordinator driller | G43: OH | H43: 155000
D44: 26 | F44: Operator pompa | G44: OH | H44: 130000
...

Sheet Persiapan
C3: 1.1 | D3: PEKERJAAN PERSIAPAN
C4: 1.1.1 | D4: Pembuatan Pagar Proyek
C5: 1.1.1.1 | D5: Pembuatan 1 m’ pagar sementara dari kayu tinggi 2 meter | K5: =ROUNDDOWN(J28,-2) -> 787300 | M5: 799800
C6: No | D6: Uraian | E6: Kode | F6: Sat. | G6: Koefisien | H6: Harga Satuan (Rp) | J6: Jumlah Harga (Rp)
C7: A | D7: TENAGA KERJA | M7: Catatan:
C8: 1 | D8: Pekerja | E8: L.01 | F8: OH | G8: 0.6 | H8: =VLOOKUP(D8,upahbahan,3,FALSE) -> 100000 | J8: =G8*H8 -> 60000 | M8: Biaya Umum dan Keuntungan | P8: 0.1
C9: 2 | D9: Tukang kayu | E9: L.02 | F9: OH | G9: 0.2 | H9: =VLOOKUP(D9,upahbahan,3,FALSE) -> 145000 | J9: =G9*H9 -> 29000
C10: 3 | D10: Tukang batu | E10: L.02 | F10: OH | G10: 0.2 | H10: =VLOOKUP(D10,upahbahan,3,FALSE) -> 145000 | J10: =G10*H10 -> 29000
C11: 4 | D11: Kepala tukang | E11: L.03 | F11: OH | G11: 0.04 | H11: =VLOOKUP(D11,upahbahan,3,FALSE) -> 175000 | J11: =G11*H11 -> 7000
C12: 5 | D12: Mandor | E12: L.04 | F12: OH | G12: 0.013 | H12: =VLOOKUP(D12,upahbahan,3,FALSE) -> 200000 | J12: =G12*H12 -> 2600
C13: JUMLAH HARGA TENAGA KERJA | J13: =SUM(J8:J12) -> 127600
C14: B | D14: BAHAN
C15: 1 | D15: Kaso 5/7 kayu kelas II | F15: m3 | G15: 0.0387 | H15: =VLOOKUP(D15,upahbahan,3,FALSE) -> 10214200 | J15: =G15*H15 -> 395289.54
C16: 2 | D16: Papan Kayu ukuran 2/20 cm | F16: m3 | G16: 0.0396 | H16: =VLOOKUP(D16,upahbahan,3,FALSE) -> 2500000 | J16: =G16*H16 -> 99000
C17: 3 | D17: Paku biasa 5 inchi | F17: kg | G17: 0.5872 | H17: =VLOOKUP(D17,upahbahan,3,FALSE) -> 20000 | J17: =G17*H17 -> 11744
C18: 4 | D18: Semen Portland (PC) | F18: kg | G18: 26.406 | H18: =VLOOKUP(D18,upahbahan,3,FALSE) -> 1300 | J18: =G18*H18 -> 34327.8
C19: 5 | D19: Pasir Beton | F19: kg | G19: 61.56 | H19: =VLOOKUP(D19,upahbahan,3,FALSE) -> 300 | J19: =G19*H19 -> 18468
C20: 6 | D20: Kerikil | F20: kg | G20: 83.349 | H20: =VLOOKUP(D20,upahbahan,3,FALSE) -> 210 | J20: =G20*H20 -> 17503.29
C21: 7 | D21: Air | F21: liter | G21: 17.415 | H21: =VLOOKUP(D21,upahbahan,3,FALSE) -> 200 | J21: =G21*H21 -> 3483
C22: 8 | D22: Residu | F22: liter | G22: 0.4 | H22: =VLOOKUP(D22,upahbahan,3,FALSE) -> 21000 | J22: =G22*H22 -> 8400
C23: JUMLAH HARGA BAHAN | J23: =SUM(J15:J22) -> 588215.63
C24: C | D24: PERALATAN
C25: JUMLAH HARGA ALAT | J25: 0
C26: D | D26: Jumlah (A+B+C) | J26: =J13+J23+J25 -> 715815.63
C27: E | D27: Biaya Umum dan Keuntungan 10%-15% x D | H27: =$P$8 -> 0.1 | J27: =J26*H27 -> 71581.563
C28: F | D28: Harga Satuan Pekerjaan (D+E) | J28: =SUM(J26:J27) -> 787397.19
C30: 1.1.1.2 | D30: Pembuatan 1 m’ pagar sementara dari seng gelombang rangka kayu tinggi 2 meter | K30: =ROUNDDOWN(J52,-2) -> 635500 | M30: 639300
C31: No | D31: Uraian | F31: Sat. | G31: Koefisien | H31: Harga Satuan (Rp) | J31: Jumlah Harga (Rp)
C32: A | D32: TENAGA KERJA
C33: 1 | D33: Pekerja | E33: L.01 | F33: OH | G33: 0.25 | H33: =VLOOKUP(D33,upahbahan,3,FALSE) -> 100000 | J33: =G33*H33 -> 25000
C34: 2 | D34: Tukang kayu | E34: L.02 | F34: OH | G34: 0.125 | H34: =VLOOKUP(D34,upahbahan,3,FALSE) -> 145000 | J34: =G34*H34 -> 18125
C35: 3 | D35: Tukang batu | E35: L.02 | F35: OH | G35: 0.125 | H35: =VLOOKUP(D35,upahbahan,3,FALSE) -> 145000 | J35: =G35*H35 -> 18125
C36: 4 | D36: Kepala tukang | E36: L.03 | F36: OH | G36: 0.025 | H36: =VLOOKUP(D36,upahbahan,3,FALSE) -> 175000 | J36: =G36*H36 -> 4375
C37: 5 | D37: Mandor | E37: L.04 | F37: OH | G37: 0.008 | H37: =VLOOKUP(D37,upahbahan,3,FALSE) -> 200000 | J37: =G37*H37 -> 1600
C38: JUMLAH HARGA TENAGA KERJA | J38: =SUM(J33:J37) -> 67225
C39: B | D39: BAHAN
C40: 1 | D40: Kaso 5/7 kayu kelas II | F40: m3 | G40: 0.031 | H40: =VLOOKUP(D40,upahbahan,3,FALSE) -> 10214200 | J40: =G40*H40 -> 316640.2
C41: 2 | D41: Seng gelombang | F41: lembar | G41: 1.3125 | H41: =VLOOKUP(D41,upahbahan,3,FALSE) -> 85000 | J41: =G41*H41 -> 111562.5
C42: 3 | D42: Paku biasa 5 inchi | F42: kg | G42: 0.4271 | H42: =VLOOKUP(D42,upahbahan,3,FALSE) -> 20000 | J42: =G42*H42 -> 8542
C43: 4 | D43: Semen Portland (PC) | F43: kg | G43: 26.406 | H43: =VLOOKUP(D43,upahbahan,3,FALSE) -> 1300 | J43: =G43*H43 -> 34327.8
...

Sheet Galian Tanah
C3: 1.2 | D3: PEKERJAAN GALIAN TANAH
C4: 1.2.1 | D4: Tanah Biasa
C5: 1.2.1.1 | D5: Cara Manual
C6: 1.2.1.1.1 | D6: Penggalian 1 m3 tanah biasa sedalam 0 s.d. 1 m untuk volume s.d. 200 m3 secara manual | J6: =ROUNDDOWN(I18,-2) -> 90800
C7: No | D7: Uraian | F7: Sat. | G7: Koefisien | H7: Harga Satuan (Rp) | I7: Jumlah Harga (Rp)
C8: A | D8: TENAGA KERJA
C9: 1 | D9: Pekerja | E9: L.01 | F9: OH | G9: 0.75 | H9: =VLOOKUP(D9,upahbahan,3,FALSE) -> 100000 | I9: =G9*H9 -> 75000
C10: 2 | D10: Mandor | E10: L.04 | F10: OH | G10: 0.038 | H10: =VLOOKUP(D10,upahbahan,3,FALSE) -> 200000 | I10: =G10*H10 -> 7600
C11: JUMLAH HARGA TENAGA KERJA | I11: =SUM(I9:I10) -> 82600
C12: B | D12: BAHAN
C13: JUMLAH HARGA BAHAN | I13: 0
C14: C | D14: PERALATAN
C15: JUMLAH HARGA ALAT | I15: 0
C16: D | D16: Jumlah (A+B+C) | I16: =I11+I13+I15 -> 82600
C17: E | D17: Biaya Umum dan Keuntungan 10%-15% x D | H17: 0.1 | I17: =I16*H17 -> 8260
C18: F | D18: Harga Satuan Pekerjaan (D+E) | I18: =SUM(I16:I17) -> 90860
C20: 1.2.1.1.2 | D20: Penggalian 1 m3 tanah biasa sedalam 0 s.d. 1 m untuk volume 200 m3 s.d 2.000 m3 secara manual | J20: =ROUNDDOWN(I32,-2) -> 74300
C21: No | D21: Uraian | F21: Sat. | G21: Koefisien | H21: Harga Satuan (Rp) | I21: Jumlah Harga (Rp)
C22: A | D22: TENAGA KERJA
C23: 1 | D23: Pekerja | E23: L.01 | F23: OH | G23: 0.563 | H23: =VLOOKUP(D23,upahbahan,3,FALSE) -> 100000 | I23: =G23*H23 -> 56300
C24: 2 | D24: Mandor | E24: L.04 | F24: OH | G24: 0.0563 | H24: =VLOOKUP(D24,upahbahan,3,FALSE) -> 200000 | I24: =G24*H24 -> 11260
C25: JUMLAH HARGA TENAGA KERJA | I25: =SUM(I23:I24) -> 67560
C26: B | D26: BAHAN
C27: JUMLAH HARGA BAHAN | I27: 0
C28: C | D28: PERALATAN
C29: JUMLAH HARGA ALAT | I29: 0
C30: D | D30: Jumlah (A+B+C) | I30: =I25+I27+I29 -> 67560
C31: E | D31: Biaya Umum dan Keuntungan 10%-15% x D | H31: 0.1 | I31: =I30*H31 -> 6756
C32: F | D32: Harga Satuan Pekerjaan (D+E) | I32: =SUM(I30:I31) -> 74316
C34: 1.2.1.1.3 | D34: Penggalian 1 m3 tanah biasa sedalam 0 s.d. 1 m untuk volume > 2.000 m3 secara Manual | J34: =ROUNDDOWN(I46,-2) -> 52800
C35: No | D35: Uraian | F35: Sat. | G35: Koefisien | H35: Harga Satuan (Rp) | I35: Jumlah Harga (Rp)
C36: A | D36: TENAGA KERJA
C37: 1 | D37: Pekerja | E37: L.01 | F37: OH | G37: 0.4 | H37: =VLOOKUP(D37,upahbahan,3,FALSE) -> 100000 | I37: =G37*H37 -> 40000
C38: 2 | D38: Mandor | E38: L.04 | F38: OH | G38: 0.04 | H38: =VLOOKUP(D38,upahbahan,3,FALSE) -> 200000 | I38: =G38*H38 -> 8000
C39: JUMLAH HARGA TENAGA KERJA | I39: =SUM(I37:I38) -> 48000
C40: B | D40: BAHAN
C41: JUMLAH HARGA BAHAN | I41: 0
C42: C | D42: PERALATAN
C43: JUMLAH HARGA ALAT | I43: 0
C44: D | D44: Jumlah (A+B+C) | I44: =I39+I41+I43 -> 48000
...

Sheet Timbunan Pemadatan
C3: 1.3 | D3: PEKERJAAN TIMBUNAN DAN PEMADATAN
C4: 1.3.1 | D4: Timbunan atau Urukan Secara Manual
C5: 1.3.1.1 | D5: 1 m3 urukan kembali galian tanah tanpa pemadatan secara manual | J5: =ROUNDDOWN(I17,-2) -> 60500
C6: No | D6: Uraian | E6: Kode | F6: Sat. | G6: Koefisien | H6: Harga Satuan (Rp) | I6: Jumlah Harga (Rp)
C7: A | D7: TENAGA KERJA | L7: Catatan:
C8: 1 | D8: Pekerja | E8: L.01 | F8: OH | G8: 0.5 | H8: =VLOOKUP(D8,upahbahan,3,FALSE) -> 100000 | I8: =G8*H8 -> 50000 | L8: Biaya Umum dan Keuntungan | O8: 0.1
C9: 2 | D9: Mandor | E9: L.04 | F9: OH | G9: 0.025 | H9: =VLOOKUP(D9,upahbahan,3,FALSE) -> 200000 | I9: =G9*H9 -> 5000
C10: JUMLAH HARGA TENAGA KERJA | I10: =SUM(I8:I9) -> 55000
C11: B | D11: BAHAN
C12: JUMLAH HARGA BAHAN | I12: 0
C13: C | D13: PERALATAN
C14: JUMLAH HARGA ALAT | I14: 0
C15: D | D15: Jumlah (A+B+C) | I15: =I10+I12+I14 -> 55000
C16: E | D16: Biaya Umum dan Keuntungan 10% - 15% x D | H16: =$O$8 -> 0.1 | I16: =I15*H16 -> 5500
C17: F | D17: Harga Satuan Pekerjaan (D+E) | I17: =SUM(I15:I16) -> 60500
C19: 1.3.1.2 | D19: 1 m3 urukan pasir uruk untuk volume s.d 200 m3 tanpa pemadatan secara manual | J19: =ROUNDDOWN(I32,-2) -> 372500
C20: No | D20: Uraian | E20: Kode | F20: Sat. | G20: Koefisien | H20: Harga Satuan (Rp) | I20: Jumlah Harga (Rp)
C21: A | D21: TENAGA KERJA
C22: 1 | D22: Pekerja | E22: L.01 | F22: OH | G22: 0.3 | H22: =VLOOKUP(D22,upahbahan,3,FALSE) -> 100000 | I22: =G22*H22 -> 30000
C23: 2 | D23: Mandor | E23: L.04 | F23: OH | G23: 0.015 | H23: =VLOOKUP(D23,upahbahan,3,FALSE) -> 200000 | I23: =G23*H23 -> 3000
C24: JUMLAH HARGA TENAGA KERJA | I24: =SUM(I22:I23) -> 33000
C25: B | D25: BAHAN
C26: 1 | D26: Pasir urug (quarry - lokasi pekerjaan) | F26: m3 | G26: 1.2 | H26: =VLOOKUP(D26,upahbahan,3,FALSE) -> 254700 | I26: =G26*H26 -> 305640
C27: JUMLAH HARGA BAHAN | I27: =SUM(I26) -> 305640
C28: C | D28: PERALATAN
C29: JUMLAH HARGA ALAT | I29: 0
C30: D | D30: Jumlah (A+B+C) | I30: =I24+I27+I29 -> 338640
C31: E | D31: Biaya Umum dan Keuntungan 10% - 15% x D | H31: =$O$8 -> 0.1 | I31: =I30*H31 -> 33864
C32: F | D32: Harga Satuan Pekerjaan (D+E) | I32: =SUM(I30:I31) -> 372504
C34: 1.3.1.3 | D34: 1 m3 urukan pasir uruk untuk volume > 200 m3 tanpa pemadatan secara manual | J34: =ROUNDDOWN(I47,-2) -> 344700
C35: No | D35: Uraian | F35: Sat. | G35: Koefisien | H35: Harga Satuan (Rp) | I35: Jumlah Harga (Rp)
C36: A | D36: TENAGA KERJA | E36: Kode
C37: 1 | D37: Pekerja | E37: L.01 | F37: OH | G37: 0.065 | H37: =VLOOKUP(D37,upahbahan,3,FALSE) -> 100000 | I37: =G37*H37 -> 6500
C38: 2 | D38: Mandor | E38: L.04 | F38: OH | G38: 0.0065 | H38: =VLOOKUP(D38,upahbahan,3,FALSE) -> 200000 | I38: =G38*H38 -> 1300
C39: JUMLAH HARGA TENAGA KERJA | I39: =SUM(I37:I38) -> 7800
C40: B | D40: BAHAN
C41: 1 | D41: Pasir urug (quarry - lokasi pekerjaan) | F41: m3 | G41: 1.2 | H41: =VLOOKUP(D41,upahbahan,3,FALSE) -> 254700 | I41: =G41*H41 -> 305640
C42: JUMLAH HARGA BAHAN | I42: =SUM(I41) -> 305640
C43: C | D43: PERALATAN
C44: JUMLAH HARGA ALAT | I44: 0
...

Sheet Angkut Material
C2: 1.4 | D2: Pekerjaan Angkut Materia dan/atau Hasil Galian
C3: 1.4.1 | D3: Angkut Tanah Lepas atau Hasil Galian untuk Jarak Horizontal dan medan landai naik serta turun >2"
C4: 1.4.1.1 | D4: Mengangkut 1 m3 tanah lepas, jarak angkut s.d 10 m | J4: =ROUNDDOWN(I16,-2) -> 25400
C5: No | D5: Uraian | E5: Kode | F5: Sat. | G5: Koefisien | H5: Harga Satuan (Rp) | I5: Jumlah Harga (Rp)
C6: A | D6: TENAGA KERJA
C7: 1 | D7: Pekerja | E7: L.01 | F7: OH | G7: 0.2104 | H7: =VLOOKUP(D7,upahbahan,3,FALSE) -> 100000 | I7: =H7*G7 -> 21040
C8: 2 | D8: Mandor | E8: L.04 | F8: OH | G8: 0.0105 | H8: =VLOOKUP(D8,upahbahan,3,FALSE) -> 200000 | I8: =H8*G8 -> 2100
C9: JUMLAH HARGA TENAGA KERJA | I9: =SUM(I7:I8) -> 23140
C10: B | D10: BAHAN
C11: JUMLAH HARGA BAHAN | I11: =SUM(I10) -> 0
C12: C | D12: PERALATAN
C13: JUMLAH HARGA ALAT | I13: =SUM(I12) -> 0
C14: D | D14: Jumlah (A+B+C) | I14: =I9+I11+I13 -> 23140
C15: E | D15: Biaya Umum dan Keuntungan 10% - 15% x D | H15: 0.1 | I15: =I14*H15 -> 2314
C16: F | D16: Harga Satuan Pekerjaan (D+E) | I16: =SUM(I14:I15) -> 25454
C19: 1.4.1.2 | D19: Mengangkut 1 m3 tanah lepas, jarak angkut > 10 m s.d 20 m | J19: =ROUNDDOWN(I31,-2) -> 27200
C20: No | D20: Uraian | E20: Kode | F20: Sat. | G20: Koefisien | H20: Harga Satuan (Rp) | I20: Jumlah Harga (Rp)
C21: A | D21: TENAGA KERJA
C22: 1 | D22: Pekerja | E22: L.01 | F22: OH | G22: 0.2254 | H22: =VLOOKUP(D22,upahbahan,3,FALSE) -> 100000 | I22: =H22*G22 -> 22540
C23: 2 | D23: Mandor | E23: L.04 | F23: OH | G23: 0.0112 | H23: =VLOOKUP(D23,upahbahan,3,FALSE) -> 200000 | I23: =H23*G23 -> 2240
C24: JUMLAH HARGA TENAGA KERJA | I24: =SUM(I22:I23) -> 24780
C25: B | D25: BAHAN
C26: JUMLAH HARGA BAHAN | I26: =SUM(I25) -> 0
C27: C | D27: PERALATAN
C28: JUMLAH HARGA ALAT | I28: =SUM(I27) -> 0
C29: D | D29: Jumlah (A+B+C) | I29: =I24+I26+I28 -> 24780
C30: E | D30: Biaya Umum dan Keuntungan 10% - 15% x D | H30: 0.1 | I30: =I29*H30 -> 2478
C31: F | D31: Harga Satuan Pekerjaan (D+E) | I31: =SUM(I29:I30) -> 27258
C33: 1.4.1.3 | D33: Mengangkut 1 m3 tanah lepas, jarak angkut > 20 m s.d 30 m | J33: =ROUNDDOWN(I45,-2) -> 29900
C34: No | D34: Uraian | E34: Kode | F34: Sat. | G34: Koefisien | H34: Harga Satuan (Rp) | I34: Jumlah Harga (Rp)
C35: A | D35: TENAGA KERJA
C36: 1 | D36: Pekerja | E36: L.01 | F36: OH | G36: 0.2363 | H36: =VLOOKUP(D36,upahbahan,3,FALSE) -> 100000 | I36: =H36*G36 -> 23630
C37: 2 | D37: Mandor | E37: L.04 | F37: OH | G37: 0.018 | H37: =VLOOKUP(D37,upahbahan,3,FALSE) -> 200000 | I37: =H37*G37 -> 3600
C38: JUMLAH HARGA TENAGA KERJA | I38: =SUM(I36:I37) -> 27230
C39: B | D39: BAHAN
C40: JUMLAH HARGA BAHAN | I40: =SUM(I39) -> 0
C41: C | D41: PERALATAN
C42: JUMLAH HARGA ALAT | I42: =SUM(I41) -> 0
C43: D | D43: Jumlah (A+B+C) | I43: =I38+I40+I42 -> 27230
C44: E | D44: Biaya Umum dan Keuntungan 10% - 15% x D | H44: 0.1 | I44: =I43*H44 -> 2723
...

Sheet Geotekstil & Geomembran 
C2: 1.5 | D2: Pekerjaan Geotekstil dan Geomembran
C3: 1.5.1 | D3: 1 m2 Pasangan Geotekstil, Tipis ( > 100 s.d <400 gr/m2), Secara Manual | J3: =ROUNDDOWN(I18,-2) -> 23100
C4: No | D4: Uraian | E4: Kode | F4: Sat. | G4: Koefisien | H4: Harga Satuan (Rp) | I4: Jumlah Harga (Rp)
C5: A | D5: TENAGA KERJA
C6: 1 | D6: Pekerja | E6: L.01 | F6: OH | G6: 0.0119 | H6: =VLOOKUP(D6,upahbahan,3,FALSE) -> 100000 | I6: =H6*G6 -> 1190
C7: 2 | D7: Tukang las geotextile | E7: L.02 | F7: OH | G7: 0.0024 | H7: =VLOOKUP(D7,upahbahan,3,FALSE) -> 145000 | I7: =H7*G7 -> 348
C8: 3 | D8: Mandor | E8: L.04 | F8: OH | G8: 0.0012 | H8: =VLOOKUP(D8,upahbahan,3,FALSE) -> 200000 | I8: =H8*G8 -> 240
C9: JUMLAH HARGA TENAGA KERJA | I9: =SUM(I6:I8) -> 1778
C10: B | D10: BAHAN
C11: 1 | D11: Geotextile >100 gr/m2 | F11: m2 | G11: 1.1 | H11: =VLOOKUP(D11,upahbahan,3,FALSE) -> 17500 | I11: =H11*G11 -> 19250
C12: JUMLAH HARGA BAHAN | I12: =SUM(I10:I11) -> 19250
C13: C | D13: PERALATAN
C14: 1 | D14: Mesin Las Gotextile | F14: hari | G14: 0.00238 | H14: =VLOOKUP(D14,upahbahan,3,FALSE) -> 25000 | I14: =H14*G14 -> 59.5
C15: JUMLAH HARGA ALAT | I15: =SUM(I13:I14) -> 59.5
C16: D | D16: Jumlah (A+B+C) | I16: =I9+I12+I15 -> 21087.5
C17: E | D17: Biaya Umum dan Keuntungan 10% - 15% x D | H17: 0.1 | I17: =I16*H17 -> 2108.75
C18: F | D18: Harga Satuan Pekerjaan (D+E) | I18: =SUM(I16:I17) -> 23196.25
C20: 1.5.2 | D20: 1 m2 Pasangan Geotekstil, Tipis ( > 100 s.d <400 gr/m2), Secara Mekanis | J20: =ROUNDDOWN(I36,-2) -> 21900
C21: No | D21: Uraian | E21: Kode | F21: Sat. | G21: Koefisien | H21: Harga Satuan (Rp) | I21: Jumlah Harga (Rp)
C22: A | D22: TENAGA KERJA
C23: 1 | D23: Pekerja | E23: L.01 | F23: OH | G23: 0.0016 | H23: =VLOOKUP(D23,upahbahan,3,FALSE) -> 100000 | I23: =H23*G23 -> 160
C24: 2 | D24: Tukang las geotextile | E24: L.02 | F24: OH | G24: 0.0008 | H24: =VLOOKUP(D24,upahbahan,3,FALSE) -> 145000 | I24: =H24*G24 -> 116
C25: 3 | D25: Mandor | E25: L.04 | F25: OH | G25: 0.0002 | H25: =VLOOKUP(D25,upahbahan,3,FALSE) -> 200000 | I25: =H25*G25 -> 40
C26: JUMLAH HARGA TENAGA KERJA | I26: =SUM(I23:I25) -> 316
C27: B | D27: BAHAN
C28: 1 | D28: Geotextile >100 gr/m2 | F28: m2 | G28: 1.1 | H28: =VLOOKUP(D28,upahbahan,3,FALSE) -> 17500 | I28: =H28*G28 -> 19250
C29: JUMLAH HARGA BAHAN | I29: =SUM(I27:I28) -> 19250
C30: C | D30: PERALATAN
C31: 1 | D31: Mesin Las Gotextile | F31: hari | G31: 0.0008 | H31: =VLOOKUP(D31,upahbahan,3,FALSE) -> 25000 | I31: =H31*G31 -> 20
C32: 2 | D32: Flat deck truck 7 ton | F32: hari | G32: 0.00015 | H32: =VLOOKUP(D32,upahbahan,3,FALSE) -> 2700000 | I32: =H32*G32 -> 405
C33: JUMLAH HARGA ALAT | I33: =SUM(I30:I32) -> 425
C34: D | D34: Jumlah (A+B+C) | I34: =I26+I29+I33 -> 19991
C35: E | D35: Biaya Umum dan Keuntungan 10% - 15% x D | H35: 0.1 | I35: =I34*H35 -> 1999.1
C36: F | D36: Harga Satuan Pekerjaan (D+E) | I36: =SUM(I34:I35) -> 21990.1
C39: 1.5.3 | D39: 1 m2 Pasangan Geotekstil, Tebal Sedang ( > 400 s.d <800 gr/m2), Secara Manual | J39: =ROUNDDOWN(I54,-2) -> 30400
C40: No | D40: Uraian | E40: Kode | F40: Sat. | G40: Koefisien | H40: Harga Satuan (Rp) | I40: Jumlah Harga (Rp)
C41: A | D41: TENAGA KERJA
C42: 1 | D42: Pekerja | E42: L.01 | F42: OH | G42: 0.016 | H42: =VLOOKUP(D42,upahbahan,3,FALSE) -> 100000 | I42: =H42*G42 -> 1600
C43: 2 | D43: Tukang las geotextile | E43: L.02 | F43: OH | G43: 0.0032 | H43: =VLOOKUP(D43,upahbahan,3,FALSE) -> 145000 | I43: =H43*G43 -> 464
C44: 3 | D44: Mandor | E44: L.04 | F44: OH | G44: 0.0016 | H44: =VLOOKUP(D44,upahbahan,3,FALSE) -> 200000 | I44: =H44*G44 -> 320
...

Sheet Pembongkaran
C3: 1.6 | D3: ='[1]Daftar HSP'!B51 -> PEKERJAAN PEMBONGKARAN
C4: 1.6.1 | D4: Bongkaran 1 m3 pasangan batu (manual) untuk bangunan gedung | J4: =ROUNDDOWN(I19,-2) -> 146100
C5: No | D5: Uraian | E5: Kode | F5: Sat. | G5: Koefisien | H5: Harga Satuan (Rp) | I5: Jumlah Harga (Rp)
C6: A | D6: TENAGA KERJA | K6: Catatan:
C7: 1 | D7: Pekerja | E7: L.01 | F7: OH | G7: 1.2 | H7: =VLOOKUP(D7,upahbahan,3,FALSE) -> 100000 | I7: =G7*H7 -> 120000 | K7: Biaya Umum dan Keuntungan | N7: 0.1
C8: 2 | D8: Mandor | E8: L.04 | F8: OH | G8: 0.06 | H8: =VLOOKUP(D8,upahbahan,3,FALSE) -> 200000 | I8: =G8*H8 -> 12000
C9: JUMLAH HARGA TENAGA KERJA | I9: =SUM(I7:I8) -> 132000
C10: B | D10: BAHAN
C11: JUMLAH HARGA BAHAN | I11: 0
C12: C | D12: PERALATAN
C13: 1 | D13: Palu/godam (baja keras) | F13: buah | G13: 0.006 | H13: =VLOOKUP(D13,upahbahan,3,FALSE) -> 25000 | I13: =G13*H13 -> 150
C14: 2 | D14: Pahat beton (baja keras) | F14: buah | G14: 0.009 | H14: =VLOOKUP(D14,upahbahan,3,FALSE) -> 15000 | I14: =G14*H14 -> 135
C15: 3 | D15: Linggis (baja keras) | F15: buah | G15: 0.02 | H15: =VLOOKUP(D15,upahbahan,3,FALSE) -> 30000 | I15: =G15*H15 -> 600
C16: JUMLAH HARGA ALAT | I16: =SUM(I13:I15) -> 885
C17: D | D17: Jumlah (A+B+C) | I17: =I9+I11+I16 -> 132885
C18: E | D18: Biaya Umum dan Keuntungan 10% - 15% x D | H18: =$N$7 -> 0.1 | I18: =I17*H18 -> 13288.5
C19: F | D19: Harga Satuan Pekerjaan (D+E) | I19: =SUM(I17:I18) -> 146173.5
D20: NB: Jika tidak menggunakan peralatan khusus (baja keras) maka Koefien C1, C2, C3 = 0)
D21: Hasil pembersihan 1m3 pasangan batu yang dibongkar, umumnya menghasilkan 0,55-0,66 m3 batu
C23: 1.6.2 | D23: Bongkaran 1 m3 pasangan batu dengan jack hammer untuk bangunan gedung | J23: =ROUNDDOWN(I36,-2) -> 150700
C24: No | D24: Uraian | E24: Kode | F24: Sat. | G24: Koefisien | H24: Harga Satuan (Rp) | I24: Jumlah Harga (Rp)
C25: A | D25: TENAGA KERJA
C26: 1 | D26: Pekerja | E26: L.01 | F26: OH | G26: 0.2 | H26: =VLOOKUP(D26,upahbahan,3,FALSE) -> 100000 | I26: =G26*H26 -> 20000
C27: 2 | D27: Mandor | E27: L.02 | F27: OH | G27: 0.01 | H27: =VLOOKUP(D27,upahbahan,3,FALSE) -> 200000 | I27: =G27*H27 -> 2000
C28: JUMLAH HARGA TENAGA KERJA | I28: =SUM(I26:I27) -> 22000
C29: B | D29: BAHAN
C30: JUMLAH HARGA BAHAN | I30: 0
C31: C | D31: PERALATAN
C32: 1 | D32: Jack hammer + genset | F32: hari | G32: 0.05 | H32: =VLOOKUP(D32,upahbahan,3,FALSE) -> 2300000 | I32: =G32*H32 -> 115000
C33: JUMLAH HARGA ALAT | I33: =SUM(I32:I32) -> 115000
C34: D | D34: Jumlah (A+B+C) | I34: =I28+I30+I33 -> 137000
C35: E | D35: Biaya Umum dan Keuntungan 10% - 15% x D | H35: =$N$7 -> 0.1 | I35: =I34*H35 -> 13700
C36: F | D36: Harga Satuan Pekerjaan (D+E) | I36: =SUM(I34:I35) -> 150700
C38: 1.6.3 | D38: Bongkaran 1 m3 beton mutu rendah f’c < 20 MPa secara manual | J38: =ROUNDDOWN(I55,-2) -> 211000
C39: No | D39: Uraian | E39: Kode | F39: Sat. | G39: Koefisien | H39: Harga Satuan (Rp) | I39: Jumlah Harga (Rp)
C40: A | D40: TENAGA KERJA
C41: 1 | D41: Pekerja | E41: L.01 | F41: OH | G41: 1.075 | H41: =VLOOKUP(D41,upahbahan,3,FALSE) -> 100000 | I41: =G41*H41 -> 107500
C42: 2 | D42: Mandor | E42: L.04 | F42: OH | G42: 0.108 | H42: =VLOOKUP(D42,upahbahan,3,FALSE) -> 200000 | I42: =G42*H42 -> 21600
C43: JUMLAH HARGA TENAGA KERJA | I43: =SUM(I41:I42) -> 129100
C44: B | D44: BAHAN
...

Sheet Rangka Atap
C2: 2 | D2: PEKERJAAN STRUKTUR
C3: 2.1 | D3: PEKERJAAN RANGKA ATAP
C4: 2.1.1 | D4: Rangka Atap Baja Ringan
C5: 2.1.1.1 | D5: Pemasangan 1 m2 rangka atap pelana baja ringan (canai dingin) profil C75 | J5: =ROUNDDOWN(I20,-2) -> 298600
C6: No | D6: Uraian | E6: Kode | F6: Sat. | G6: Koefisien | H6: Harga Satuan (Rp) | I6: Jumlah Harga (Rp)
C7: A | D7: TENAGA KERJA | K7: Catatan:
C8: 1 | D8: Pekerja | E8: L.01 | F8: OH | G8: 0.734 | H8: =VLOOKUP(D8,upahbahan,3,FALSE) -> 100000 | I8: =G8*H8 -> 73400 | K8: Biaya Umum dan Keuntungan | N8: 0.1
C9: 2 | D9: Tukang besi | E9: L.02 | F9: OH | G9: 0.734 | H9: =VLOOKUP(D9,upahbahan,3,FALSE) -> 145000 | I9: =G9*H9 -> 106430
C10: 3 | D10: Kepala tukang | E10: L.03 | F10: OH | G10: 0.073 | H10: =VLOOKUP(D10,upahbahan,3,FALSE) -> 175000 | I10: =G10*H10 -> 12775
C11: 4 | D11: Mandor | E11: L.04 | F11: OH | G11: 0.024 | H11: =VLOOKUP(D11,upahbahan,3,FALSE) -> 200000 | I11: =G11*H11 -> 4800
C12: JUMLAH HARGA TENAGA KERJA | I12: =SUM(I8:I11) -> 197405
C13: B | D13: BAHAN
C14: 1 | D14: Baja ringan C75 x 0,75 mm | F14: batang | G14: 0.9603 | H14: =VLOOKUP(D14,upahbahan,3,FALSE) -> 77200 | I14: =G14*H14 -> 74135.16
C15: JUMLAH HARGA BAHAN | I15: =SUM(I14) -> 74135.16
C16: C | D16: PERALATAN
C17: JUMLAH HARGA ALAT | I17: 0
C18: D | D18: Jumlah (A+B+C) | I18: =I17+I15+I12 -> 271540.16
C19: E | D19: Biaya Umum dan Keuntungan 10% - 15% x D | H19: =$N$8 -> 0.1 | I19: =I18*H19 -> 27154.016
C20: F | D20: Harga Satuan Pekerjaan (D+E) | I20: =SUM(I18:I19) -> 298694.18
C22: 2.1.1.2 | D22: Pemasangan 1 m2 rangka atap jurai/limasan baja ringan (canai dingin) profil C75 | J22: =ROUNDDOWN(I37,-2) -> 306600
C23: No | D23: Uraian | E23: Kode | F23: Sat. | G23: Koefisien | H23: Harga Satuan (Rp) | I23: Jumlah Harga (Rp)
C24: A | D24: TENAGA KERJA
C25: 1 | D25: Pekerja | E25: L.01 | F25: OH | G25: 0.7604 | H25: =VLOOKUP(D25,upahbahan,3,FALSE) -> 100000 | I25: =G25*H25 -> 76040
C26: 2 | D26: =D9 -> Tukang besi | E26: L.02 | F26: OH | G26: 0.7604 | H26: =VLOOKUP(D26,upahbahan,3,FALSE) -> 145000 | I26: =G26*H26 -> 110258
C27: 3 | D27: Kepala tukang | E27: L.03 | F27: OH | G27: 0.076 | H27: =VLOOKUP(D27,upahbahan,3,FALSE) -> 175000 | I27: =G27*H27 -> 13300
C28: 4 | D28: Mandor | E28: L.04 | F28: OH | G28: 0.0253 | H28: =VLOOKUP(D28,upahbahan,3,FALSE) -> 200000 | I28: =G28*H28 -> 5060
C29: JUMLAH HARGA TENAGA KERJA | I29: =SUM(I25:I28) -> 204658
C30: B | D30: BAHAN
C31: 1 | D31: Baja ringan C75 x 0,75 mm | F31: batang | G31: 0.9603 | H31: =VLOOKUP(D31,upahbahan,3,FALSE) -> 77200 | I31: =G31*H31 -> 74135.16
C32: JUMLAH HARGA BAHAN | I32: =SUM(I31) -> 74135.16
C33: C | D33: PERALATAN
C34: JUMLAH HARGA ALAT | I34: 0
C35: D | D35: Jumlah (A+B+C) | I35: =I34+I32+I29 -> 278793.16
C36: E | D36: Biaya Umum dan Keuntungan 10% - 15% x D | H36: =$N$8 -> 0.1 | I36: =I35*H36 -> 27879.316
C37: F | D37: Harga Satuan Pekerjaan (D+E) | I37: =SUM(I35:I36) -> 306672.48
C39: 2.1.1.3 | D39: Pemasangan 1 m Kaso Baja Ringan C75 tebal 0,75 mm | J39: =ROUNDDOWN(I55,-2) -> 24900
C40: No | D40: Uraian | E40: Kode | F40: Sat. | G40: Koefisien | H40: Harga Satuan (Rp) | I40: Jumlah Harga (Rp)
C41: A | D41: TENAGA KERJA
C42: 1 | D42: Pekerja | E42: L.01 | F42: OH | G42: 0.0476 | H42: =VLOOKUP(D42,upahbahan,3,FALSE) -> 100000 | I42: =G42*H42 -> 4760
C43: 2 | D43: =D26 -> Tukang besi | E43: L.02 | F43: OH | G43: 0.0238 | H43: =VLOOKUP(D43,upahbahan,3,FALSE) -> 145000 | I43: =G43*H43 -> 3451
...

Sheet Beton
C3: 2.2 | D3: PEKERJAAN STRUKTUR BETON
C4: 2.2.1 | D4: Struktur Atas
C5: 2.2.1.1 | D5: Penulangan Beton
C6: 2.2.1.1.1 | D6: 1 kg penulangan slab untuk BjTP atau BjTS atau BjTS dia. < 12 mm, cara manual (untuk bangunan gedung) | I6: =ROUNDDOWN(H22,-2) -> 18400
C7: No | D7: Uraian | E7: Sat. | F7: Koefisien | G7: Harga Satuan (Rp) | H7: Jumlah Harga (Rp)
C8: A | D8: TENAGA KERJA | J8: Catatan:
C9: 1 | D9: Pekerja | E9: OH | F9: 0.007 | G9: =VLOOKUP(D9,upahbahan,3,FALSE) -> 100000 | H9: =F9*G9 -> 700 | J9: Biaya Umum dan Keuntungan | M9: 0.1
C10: 2 | D10: Tukang besi | E10: OH | F10: 0.007 | G10: =VLOOKUP(D10,upahbahan,3,FALSE) -> 145000 | H10: =F10*G10 -> 1015
C11: 3 | D11: Kepala tukang | E11: OH | F11: 0.0007 | G11: =VLOOKUP(D11,upahbahan,3,FALSE) -> 175000 | H11: =F11*G11 -> 122.5
C12: 4 | D12: Mandor | E12: OH | F12: 0.0007 | G12: =VLOOKUP(D12,upahbahan,3,FALSE) -> 200000 | H12: =F12*G12 -> 140
C13: JUMLAH HARGA TENAGA KERJA | H13: =SUM(H9:H12) -> 1977.5
C14: B | D14: BAHAN
C15: 1 | D15: BjTP | E15: kg | F15: 1.02 | G15: =VLOOKUP(D15,upahbahan,3,FALSE) -> 14250 | H15: =F15*G15 -> 14535
C16: 2 | D16: Kawat beton | E16: kg | F16: 0.015 | G16: =VLOOKUP(D16,upahbahan,3,FALSE) -> 18800 | H16: =F16*G16 -> 282
C17: JUMLAH HARGA BAHAN | H17: =SUM(H15:H16) -> 14817
C18: C | D18: PERALATAN
C19: JUMLAH HARGA ALAT | H19: 0
C20: D | D20: Jumlah (A+B+C) | H20: =H19+H17+H13 -> 16794.5
C21: E | D21: Biaya Umum dan Keuntungan 10% - 15% x D | G21: =$M$9 -> 0.1 | H21: =H20*G21 -> 1679.45
C22: F | D22: Harga Satuan Pekerjaan (D+E) | H22: =SUM(H20:H21) -> 18473.95
C24: 2.2.1.1.2 | D24: 1 kg penulangan slab untuk BjTP atau BjTS atau BjTS dia. ≥ 12 mm, cara semi mekanis (untuk bangunan gedung) | I24: =ROUNDDOWN(H42,-2) -> 16800
C25: No | D25: Uraian | E25: Sat. | F25: Koefisien | G25: Harga Satuan (Rp) | H25: Jumlah Harga (Rp)
C26: A | D26: TENAGA KERJA
C27: 1 | D27: Pekerja | E27: OH | F27: 0.0008 | G27: =VLOOKUP(D27,upahbahan,3,FALSE) -> 100000 | H27: =F27*G27 -> 80
C28: 2 | D28: =D10 -> Tukang besi | E28: OH | F28: 0.0004 | G28: =VLOOKUP(D28,upahbahan,3,FALSE) -> 145000 | H28: =F28*G28 -> 58
C29: 3 | D29: Kepala tukang | E29: OH | F29: 4e-05 | G29: =VLOOKUP(D29,upahbahan,3,FALSE) -> 175000 | H29: =F29*G29 -> 7
C30: 4 | D30: Mandor | E30: OH | F30: 8e-05 | G30: =VLOOKUP(D30,upahbahan,3,FALSE) -> 200000 | H30: =F30*G30 -> 16
C31: JUMLAH HARGA TENAGA KERJA | H31: =SUM(H27:H30) -> 161
C32: B | D32: BAHAN
C33: 1 | D33: BjTP | E33: kg | F33: 1.02 | G33: =VLOOKUP(D33,upahbahan,3,FALSE) -> 14250 | H33: =F33*G33 -> 14535
C34: 2 | D34: Kawat beton | E34: kg | F34: 0.015 | G34: =VLOOKUP(D34,upahbahan,3,FALSE) -> 18800 | H34: =F34*G34 -> 282
C35: JUMLAH HARGA BAHAN | H35: =SUM(H33:H34) -> 14817
C36: C | D36: PERALATAN
C37: 1 | D37: Cutter baja beton | E37: hari | F37: 0.0002 | G37: =VLOOKUP(D37,upahbahan,3,FALSE) -> 800000 | H37: =F37*G37 -> 160
C38: 2 | D38: Bender baja beton | E38: hari | F38: 0.0002 | G38: =VLOOKUP(D38,upahbahan,3,FALSE) -> 850000 | H38: =F38*G38 -> 170
C39: JUMLAH HARGA ALAT | H39: =SUM(H37:H38) -> 330
C40: D | D40: Jumlah (A+B+C) | H40: =H39+H35+H31 -> 15308
C41: E | D41: Biaya Umum dan Keuntungan 10% - 15% x D | G41: =$M$9 -> 0.1 | H41: =H40*G41 -> 1530.8
C42: F | D42: Harga Satuan Pekerjaan (D+E) | H42: =SUM(H40:H41) -> 16838.8
C44: 2.2.1.1.3 | D44: 1 kg penulangan kolom, balok, ring balok, dan sloof untuk BjTP atau BjTS dia. < 12 mm, cara manual (untuk bangunan gedung) | I44: =ROUNDDOWN(H60,-2) -> 17000
...

Sheet Pondasi
C2: 2.2.2 | D2: Struktur Bawah
C3: 2.2.2.1 | D3: Fondasi Menerus Batu Belah
C4: 2.2.2.1.1 | D4: Pemasangan 1 m3 batu kosong (anstamping) untuk pondasi gedung | J4: =ROUNDDOWN(I20,-2) -> 657500
C5: No | D5: Uraian | E5: Kode | F5: Sat. | G5: Koefisien | H5: Harga Satuan (Rp) | I5: Jumlah Harga (Rp)
C6: A | D6: TENAGA KERJA | K6: Catatan:
C7: 1 | D7: Pekerja | E7: L.01 | F7: OH | G7: 0.78 | H7: =VLOOKUP(D7,upahbahan,3,FALSE) -> 100000 | I7: =G7*H7 -> 78000 | K7: Biaya Umum dan Keuntungan | N7: 0.1
C8: 2 | D8: Tukang batu | E8: L.02 | F8: OH | G8: 0.39 | H8: =VLOOKUP(D8,upahbahan,3,FALSE) -> 145000 | I8: =G8*H8 -> 56550
C9: 3 | D9: Kepala tukang | E9: L.03 | F9: OH | G9: 0.039 | H9: =VLOOKUP(D9,upahbahan,3,FALSE) -> 175000 | I9: =G9*H9 -> 6825
C10: 4 | D10: Mandor | E10: L.04 | F10: OH | G10: 0.013 | H10: =VLOOKUP(D10,upahbahan,3,FALSE) -> 200000 | I10: =G10*H10 -> 2600
C11: JUMLAH HARGA TENAGA KERJA | I11: =SUM(I7:I10) -> 143975
C12: B | D12: BAHAN
C13: 1 | D13: Batu belah (quarry - lokasi pekerjaan) | F13: m3 | G13: 1.2 | H13: =VLOOKUP(D13,upahbahan,3,FALSE) -> 286500 | I13: =G13*H13 -> 343800
C14: 2 | D14: Pasir urug (quarry - lokasi pekerjaan) | F14: m3 | G14: 0.432 | H14: =VLOOKUP(D14,upahbahan,3,FALSE) -> 254700 | I14: =G14*H14 -> 110030.4
C15: JUMLAH HARGA BAHAN | I15: =SUM(I13:I14) -> 453830.4
C16: C | D16: PERALATAN
C17: JUMLAH HARGA ALAT | I17: 0
C18: D | D18: Jumlah (A+B+C) | I18: =I17+I15+I11 -> 597805.4
C19: E | D19: Biaya Umum dan Keuntungan 10% - 15% x D | H19: =$N$7 -> 0.1 | I19: =I18*H19 -> 59780.54
C20: F | D20: Harga Satuan Pekerjaan (D+E) | I20: =SUM(I18:I19) -> 657585.94
C22: 2.2.2.1.2 | D22: Pemasangan 1 m3 pondasi batu belah mortar tipe M 17,5 Mpa setara 1SP : 2PP, cara manual | J22: =ROUNDDOWN(I38,-2) -> 1149300
C23: No | D23: Uraian | E23: Kode | F23: Sat. | G23: Koefisien | H23: Harga Satuan (Rp) | I23: Jumlah Harga (Rp)
C24: A | D24: TENAGA KERJA
C25: 1 | D25: Pekerja | E25: L.01 | F25: OH | G25: 1.5 | H25: =VLOOKUP(D25,upahbahan,3,FALSE) -> 100000 | I25: =G25*H25 -> 150000
C26: 2 | D26: Tukang batu | E26: L.02 | F26: OH | G26: 0.5 | H26: =VLOOKUP(D26,upahbahan,3,FALSE) -> 145000 | I26: =G26*H26 -> 72500
C27: 3 | D27: Mandor | E27: L.04 | F27: OH | G27: 0.15 | H27: =VLOOKUP(D27,upahbahan,3,FALSE) -> 200000 | I27: =G27*H27 -> 30000
C28: JUMLAH HARGA TENAGA KERJA | I28: =SUM(I24:I27) -> 252500
C29: B | D29: BAHAN
C30: 1 | D30: Batu belah (quarry - lokasi pekerjaan) | F30: m3 | G30: 1.2 | H30: =VLOOKUP(D30,upahbahan,3,FALSE) -> 286500 | I30: =G30*H30 -> 343800
C31: 2 | D31: Semen portland (pc) | F31: kg | G31: 252 | H31: =VLOOKUP(D31,upahbahan,3,FALSE) -> 1300 | I31: =G31*H31 -> 327600
C32: 3 | D32: Pasir pasang (quarry - lokasi pekerjaan) | F32: m3 | G32: 0.44 | H32: =VLOOKUP(D32,upahbahan,3,FALSE) -> 275000 | I32: =G32*H32 -> 121000
C33: JUMLAH HARGA BAHAN | I33: =SUM(I30:I32) -> 792400
C34: C | D34: PERALATAN
C35: JUMLAH HARGA ALAT | I35: 0
C36: D | D36: Jumlah (A+B+C) | I36: =I35+I33+I28 -> 1044900
C37: E | D37: Biaya Umum dan Keuntungan 10% - 15% x D | H37: =$N$7 -> 0.1 | I37: =I36*H37 -> 104490
C38: F | D38: Harga Satuan Pekerjaan (D+E) | I38: =SUM(I36:I37) -> 1149390
C40: 2.2.2.1.3 | D40: Pemasangan 1 m3 pondasi batu belah mortar tipe M 17,5 Mpa (setara 1SP : 2PP), cara semi mekanis | J40: =ROUNDDOWN(I57,-2) -> 1098000
C41: No | D41: Uraian | E41: Kode | F41: Sat. | G41: Koefisien | H41: Harga Satuan (Rp) | I41: Jumlah Harga (Rp)
C42: A | D42: TENAGA KERJA
C43: 1 | D43: Pekerja | E43: L.01 | F43: OH | G43: 1 | H43: =VLOOKUP(D43,upahbahan,3,FALSE) -> 100000 | I43: =G43*H43 -> 100000
...

Sheet BAJA
C2: 2.3 | D2: PEKERJAAN STRUKTUR BAJA
C3: 2.23.1 | D3: Struktur Atas
C4: 2.3.1.1 | D4: 1 kg Pabrikasi dan Ereksi Baja Profil | J4: =ROUNDDOWN(I23,-2) -> 55900
C5: No | D5: Uraian | E5: Kode | F5: Sat. | G5: Koefisien | H5: Harga Satuan (Rp) | I5: Jumlah Harga (Rp)
C6: A | D6: TENAGA KERJA | K6: Catatan:
C7: 1 | D7: Pekerja | E7: L.01 | F7: OH | G7: 0.0375 | H7: =VLOOKUP(D7,upahbahan,3,FALSE) -> 100000 | I7: =G7*H7 -> 3750 | K7: Biaya Umum dan Keuntungan | N7: 0.1
C8: 2 | D8: Tukang besi | E8: L.02 | F8: OH | G8: 0.0125 | H8: =VLOOKUP(D8,upahbahan,3,FALSE) -> 145000 | I8: =G8*H8 -> 1812.5
C9: 3 | D9: Tukang las | E9: L.02 | F9: OH | G9: 0.0125 | H9: =VLOOKUP(D9,upahbahan,3,FALSE) -> 145000 | I9: =G9*H9 -> 1812.5
C10: 4 | D10: Kepala tukang | E10: L.03 | F10: OH | G10: 0.0025 | H10: =VLOOKUP(D10,upahbahan,3,FALSE) -> 175000 | I10: =G10*H10 -> 437.5
C11: 5 | D11: Mandor | E11: L.04 | F11: OH | G11: 0.008 | H11: =VLOOKUP(D11,upahbahan,3,FALSE) -> 200000 | I11: =G11*H11 -> 1600
C12: JUMLAH HARGA TENAGA KERJA | I12: =SUM(I7:I11) -> 9412.5
C13: B | D13: BAHAN
C14: 1 | D14: Baja Profil | F14: kg | G14: 1.2 | H14: =VLOOKUP(D14,upahbahan,3,FALSE) -> 16480 | I14: =G14*H14 -> 19776
C15: 2 | D15: Kawat las | F15: kg | G15: 0.432 | H15: =VLOOKUP(D15,upahbahan,3,FALSE) -> 45550 | I15: =G15*H15 -> 19677.6
C16: JUMLAH HARGA BAHAN | I16: =SUM(I14:I15) -> 39453.6
C17: C | D17: PERALATAN
C18: 1 | D18: Alat Las Listrik | F18: jam | G18: 0.033 | H18: =VLOOKUP(D18,upahbahan,3,FALSE) -> 3125 | I18: =G18*H18 -> 103.125
C19: 2 | D19: Sewa mobil crane | F19: jam | G19: 0.0013 | H19: =VLOOKUP(D19,upahbahan,3,FALSE) -> 1450000 | I19: =G19*H19 -> 1885
C20: JUMLAH HARGA ALAT | I20: =SUM(I18:I19) -> 1988.125
C21: D | D21: Jumlah (A+B+C) | I21: =I20+I16+I12 -> 50854.225
C22: E | D22: Biaya Umum dan Keuntungan 10% - 15% x D | H22: =$N$7 -> 0.1 | I22: =I21*H22 -> 5085.4225
C23: F | D23: Harga Satuan Pekerjaan (D+E) | I23: =SUM(I21:I22) -> 55939.647
C25: 2.3.1.2 | D25: 1 kg Pemasangan angkur | J25: =ROUNDDOWN(I40,-2) -> 30300
C26: No | D26: Uraian | E26: Kode | F26: Sat. | G26: Koefisien | H26: Harga Satuan (Rp) | I26: Jumlah Harga (Rp)
C27: A | D27: TENAGA KERJA | K27: Catatan:
C28: 1 | D28: Pekerja | E28: L.01 | F28: OH | G28: 0.0406 | H28: =VLOOKUP(D28,upahbahan,3,FALSE) -> 100000 | I28: =G28*H28 -> 4060 | K28: Biaya Umum dan Keuntungan | N28: 0.1
C29: 2 | D29: Tukang las | E29: L.02 | F29: OH | G29: 0.0406 | H29: =VLOOKUP(D29,upahbahan,3,FALSE) -> 145000 | I29: =G29*H29 -> 5887
C30: 3 | D30: Kepala tukang | E30: L.03 | F30: OH | G30: 0.0041 | H30: =VLOOKUP(D30,upahbahan,3,FALSE) -> 175000 | I30: =G30*H30 -> 717.5
C31: 4 | D31: Mandor | E31: L.04 | F31: OH | G31: 0.0014 | H31: =VLOOKUP(D31,upahbahan,3,FALSE) -> 200000 | I31: =G31*H31 -> 280
C32: JUMLAH HARGA TENAGA KERJA | I32: =SUM(I28:I31) -> 10944.5
C33: B | D33: BAHAN
C34: 1 | D34: Besi angkur/mur/baut | F34: kg | G34: 1 | H34: =VLOOKUP(D34,upahbahan,3,FALSE) -> 16660 | I34: =G34*H34 -> 16660
C35: JUMLAH HARGA BAHAN | I35: =SUM(I34:I34) -> 16660
C36: C | D36: PERALATAN
C37: JUMLAH HARGA ALAT | I37: 0
C38: D | D38: Jumlah (A+B+C) | I38: =I37+I35+I32 -> 27604.5
C39: E | D39: Biaya Umum dan Keuntungan 10% - 15% x D | H39: =$N$7 -> 0.1 | I39: =I38*H39 -> 2760.45
C40: F | D40: Harga Satuan Pekerjaan (D+E) | I40: =SUM(I38:I39) -> 30364.95
C43: 2.3.1.3 | D43: 1 kg Pemasangan baut | J43: =ROUNDDOWN(I59,-2) -> 29200
C44: No | D44: Uraian | E44: Kode | F44: Sat. | G44: Koefisien | H44: Harga Satuan (Rp) | I44: Jumlah Harga (Rp)
...

Sheet Beton Pracetak
C2: 2.4 | D2: Pekerjaan Struktur Beton Pracetak
C3: 2.4.1 | D3: Pembuatan Bekisting
C4: 2.4.1.1 | D4: Pembuatan 1 m2 Bekisting untuk pelat Beton Pracetak Komponen Modular Bangunan gedung ( 5kali pakai ) | J4: =ROUNDDOWN(I24,-2) -> 264300
C5: No | D5: Uraian | E5: Kode | F5: Sat. | G5: Koefisien | H5: Harga Satuan (Rp) | I5: Jumlah Harga (Rp)
C6: A | D6: TENAGA KERJA | K6: Catatan:
C7: 1 | D7: Pekerja | E7: L.01 | F7: OH | G7: 0.007 | H7: =VLOOKUP(D7,upahbahan,3,FALSE) -> 100000 | I7: =G7*H7 -> 700 | K7: Biaya Umum dan Keuntungan | N7: 0.1
C8: 2 | D8: Tukang kayu | E8: L.02 | F8: OH | G8: 0.076 | H8: =VLOOKUP(D8,upahbahan,3,FALSE) -> 145000 | I8: =G8*H8 -> 11020
C9: 3 | D9: Kepala tukang | E9: L.03 | F9: OH | G9: 0.008 | H9: =VLOOKUP(D9,upahbahan,3,FALSE) -> 175000 | I9: =G9*H9 -> 1400
C10: 4 | D10: Mandor | E10: L.04 | F10: OH | G10: 0.003 | H10: =VLOOKUP(D10,upahbahan,3,FALSE) -> 200000 | I10: =G10*H10 -> 600
C11: JUMLAH HARGA TENAGA KERJA | I11: =SUM(I7:I10) -> 13720
C12: B | D12: BAHAN
C13: 1 | D13: Lantai kerja | F13: m3 | G13: 0.008 | H13: =VLOOKUP(D13,upahbahan,3,FALSE) -> 805000 | I13: =G13*H13 -> 6440
C14: 2 | D14: Besi hollow 50.50.3 | F14: kg | G14: 9.394 | H14: =VLOOKUP(D14,upahbahan,3,FALSE) -> 13800 | I14: =G14*H14 -> 129637.2
C15: 3 | D15: kaso 5/7 | F15: m3 | G15: 0.005 | H15: =VLOOKUP(D15,upahbahan,3,FALSE) -> 10214200 | I15: =G15*H15 -> 51071
D16: Phenol film 12mm | F16: lembar | G16: 0.08 | H16: =VLOOKUP(D16,upahbahan,3,FALSE) -> 230000 | I16: =G16*H16 -> 18400
C17: 4 | D17: Minyak bekisting | F17: liter | G17: 0.2 | H17: =VLOOKUP(D17,upahbahan,3,FALSE) -> 16800 | I17: =G17*H17 -> 3360
C18: 5 | D18: Dinabolt dia. 12mm (10-15 cm) | F18: buah | G18: 3.882 | H18: =VLOOKUP(D18,upahbahan,3,FALSE) -> 4550 | I18: =G18*H18 -> 17663.1
C19: JUMLAH HARGA BAHAN | I19: =SUM(I13:I18) -> 226571.3
C20: C | D20: PERALATAN
C21: JUMLAH HARGA ALAT | I21: 0
C22: D | D22: Jumlah (A+B+C) | I22: =I21+I19+I11 -> 240291.3
C23: E | D23: Biaya Umum dan Keuntungan 10% - 15% x D | H23: 0.1 | I23: =I22*H23 -> 24029.13
C24: F | D24: Harga Satuan Pekerjaan (D+E) | I24: =SUM(I22:I23) -> 264320.43
C27: 2.4.1.2 | D27: Pembuatan 1 m2 Bekisting untuk balok Beton Pracetak ( 10 - 12 kali pakai ) | J27: =ROUNDDOWN(I46,-2) -> 82600
C28: No | D28: Uraian | E28: Kode | F28: Sat. | G28: Koefisien | H28: Harga Satuan (Rp) | I28: Jumlah Harga (Rp)
C29: A | D29: TENAGA KERJA | K29: Catatan:
C30: 1 | D30: Pekerja | E30: L.01 | F30: OH | G30: 0.004 | H30: =VLOOKUP(D30,upahbahan,3,FALSE) -> 100000 | I30: =G30*H30 -> 400 | K30: Biaya Umum dan Keuntungan | N30: 0.1
C31: 2 | D31: Tukang kayu | E31: L.02 | F31: OH | G31: 0.038 | H31: =VLOOKUP(D31,upahbahan,3,FALSE) -> 145000 | I31: =G31*H31 -> 5510
C32: 3 | D32: Kepala tukang | E32: L.03 | F32: OH | G32: 0.004 | H32: =VLOOKUP(D32,upahbahan,3,FALSE) -> 175000 | I32: =G32*H32 -> 700
C33: 4 | D33: Mandor | E33: L.04 | F33: OH | G33: 0.001 | H33: =VLOOKUP(D33,upahbahan,3,FALSE) -> 200000 | I33: =G33*H33 -> 200
C34: JUMLAH HARGA TENAGA KERJA | I34: =SUM(I30:I33) -> 6810
C35: B | D35: BAHAN
C36: 1 | D36: kaso 5/7 | F36: m3 | G36: 0.005 | H36: =VLOOKUP(D36,upahbahan,3,FALSE) -> 10214200 | I36: =G36*H36 -> 51071
C37: 2 | D37: Phenol film 12mm | F37: lembar | G37: 0.043 | H37: =VLOOKUP(D37,upahbahan,3,FALSE) -> 230000 | I37: =G37*H37 -> 9890
C38: 3 | D38: Minyak bekisting | F38: liter | G38: 0.2 | H38: =VLOOKUP(D38,upahbahan,3,FALSE) -> 16800 | I38: =G38*H38 -> 3360
C39: 4 | D39: Paku 2 inch | F39: kg | G39: 0.046 | H39: =VLOOKUP(D39,upahbahan,3,FALSE) -> 18000 | I39: =G39*H39 -> 828
C40: 5 | D40: Dinabolt dia. 12mm (10-15 cm) | F40: buah | G40: 0.693 | H40: =VLOOKUP(D40,upahbahan,3,FALSE) -> 4550 | I40: =G40*H40 -> 3153.15
C41: JUMLAH HARGA BAHAN | I41: =SUM(I36:I40) -> 68302.15
C42: C | D42: PERALATAN
C43: JUMLAH HARGA ALAT | I43: 0
...

Sheet Beton Prategang 
C2: 2.5 | D2: PEKERJAAN STRUKTUR BETON PRATEGANG
C3: 2.5.1 | D3: Pemasangan 1 kg kabel prategang (prestressed) polos/strand | J3: =ROUNDDOWN(I20,-2) -> 90300
C4: No | D4: Uraian | E4: Kode | F4: Sat. | G4: Koefisien | H4: Harga Satuan (Rp) | I4: Jumlah Harga (Rp)
C5: A | D5: TENAGA KERJA | K5: Catatan:
C6: 1 | D6: Pekerja | E6: L.01 | F6: OH | G6: 0.005 | H6: =VLOOKUP(D6,upahbahan,3,FALSE) -> 100000 | I6: =G6*H6 -> 500 | K6: Biaya Umum dan Keuntungan | N6: 0.1
C7: 2 | D7: Tukang besi | E7: L.02 | F7: OH | G7: 0.005 | H7: =VLOOKUP(D7,upahbahan,3,FALSE) -> 145000 | I7: =G7*H7 -> 725
C8: 3 | D8: Kepala tukang | E8: L.03 | F8: OH | G8: 0.0005 | H8: =VLOOKUP(D8,upahbahan,3,FALSE) -> 175000 | I8: =G8*H8 -> 87.5
C9: 4 | D9: Mandor | E9: L.04 | F9: OH | G9: 0.0002 | H9: =VLOOKUP(D9,upahbahan,3,FALSE) -> 200000 | I9: =G9*H9 -> 40
C10: JUMLAH HARGA TENAGA KERJA | I10: =SUM(I6:I9) -> 1352.5
C11: B | D11: BAHAN
C12: 1 | D12: BjTS | F12: kg | G12: 1.05 | H12: =VLOOKUP(D12,upahbahan,3,FALSE) -> 14500 | I12: =G12*H12 -> 15225
C13: 2 | D13: Kawat beton | F13: kg | G13: 0.01 | H13: =VLOOKUP(D13,upahbahan,3,FALSE) -> 18800 | I13: =G13*H13 -> 188
C14: JUMLAH HARGA BAHAN | I14: =SUM(I12:I13) -> 15413
C15: C | D15: PERALATAN
C16: 1 | D16: Crane | F16: unit hari | G16: 0.019 | H16: =VLOOKUP(D16,upahbahan,3,FALSE) -> 3442900 | I16: =G16*H16 -> 65415.1
C17: JUMLAH HARGA ALAT | I17: =SUM(I16) -> 65415.1
C18: D | D18: Jumlah (A+B+C) | I18: =I17+I14+I10 -> 82180.6
C19: E | D19: Biaya Umum dan Keuntungan 10% - 15% x D | H19: 0.1 | I19: =I18*H19 -> 8218.06
C20: F | D20: Harga Satuan Pekerjaan (D+E) | I20: =SUM(I18:I19) -> 90398.66

Sheet Struktur Kayu
C1: 2.6 | D1: Pekerjaan Struktur Kayu
C2: 2.6.1 | D2: Struktur Atas
C3: 2.6.2 | D3: Pemancangan Tiang Kayu / Cerucuk Bambu/ Dolken
C4: 2.6.2.1 | D4: Pemancangan per m' tiang pancang kayu atau dolken dia. 6-8 cm | J4: =ROUNDDOWN(I20,-2) -> 167600
C5: No | D5: Uraian | E5: Kode | F5: Sat. | G5: Koefisien | H5: Harga Satuan (Rp) | I5: Jumlah Harga (Rp)
C6: A | D6: TENAGA KERJA | K6: Catatan:
C7: 1 | D7: Pekerja | E7: L.01 | F7: OH | G7: 0.0605 | H7: =VLOOKUP(D7,upahbahan,3,FALSE) -> 100000 | I7: =G7*H7 -> 6050 | K7: Biaya Umum dan Keuntungan | N7: 0.1
C8: 2 | D8: Tukang kayu | E8: L.02 | F8: OH | G8: 0.0605 | H8: =VLOOKUP(D8,upahbahan,3,FALSE) -> 145000 | I8: =G8*H8 -> 8772.5
C9: 3 | D9: Mandor | E9: L.03 | F9: OH | G9: 0.006 | H9: =VLOOKUP(D9,upahbahan,3,FALSE) -> 200000 | I9: =G9*H9 -> 1200
C10: JUMLAH HARGA TENAGA KERJA | I10: =SUM(I7:I9) -> 16022.5
C11: B | D11: BAHAN
C12: 1 | D12: Alat penyambung tiang pancang dolken | F12: buah | G12: 0.25 | H12: =VLOOKUP(D12,upahbahan,3,FALSE) -> 350000 | I12: =G12*H12 -> 87500
C13: 2 | D13: Sepatu Pancang | F13: buah | G13: 0.25 | H13: =VLOOKUP(D13,upahbahan,3,FALSE) -> 135000 | I13: =G13*H13 -> 33750
C14: JUMLAH HARGA BAHAN | I14: =SUM(I12:I13) -> 121250
C15: C | D15: PERALATAN
C16: 1 | D16: Alat Pancang Mini Pile | F16: hari | G16: 0.0605 | H16: =VLOOKUP(D16,upahbahan,3,FALSE) -> 250000 | I16: =G16*H16 -> 15125
C17: JUMLAH HARGA ALAT | I17: =SUM(I15:I16) -> 15125
C18: D | D18: Jumlah (A+B+C) | I18: =I17+I14+I10 -> 152397.5
C19: E | D19: Biaya Umum dan Keuntungan 10% - 15% x D | H19: =$N$7 -> 0.1 | I19: =I18*H19 -> 15239.75
C20: F | D20: Harga Satuan Pekerjaan (D+E) | I20: =SUM(I18:I19) -> 167637.25
C22: 2.6.2.2 | D22: Pemancangan per m' Tiang kayu Gelondongan dia. 18-20 cm | J22: =ROUNDDOWN(I39,-2) -> 273200
C23: No | D23: Uraian | E23: Kode | F23: Sat. | G23: Koefisien | H23: Harga Satuan (Rp) | I23: Jumlah Harga (Rp)
C24: A | D24: TENAGA KERJA
C25: 1 | D25: Pekerja | E25: L.01 | F25: OH | G25: 0.0759 | H25: =VLOOKUP(D25,upahbahan,3,FALSE) -> 100000 | I25: =G25*H25 -> 7590
C26: 2 | D26: Tukang kayu | E26: L.02 | F26: OH | G26: 0.0759 | H26: =VLOOKUP(D26,upahbahan,3,FALSE) -> 145000 | I26: =G26*H26 -> 11005.5
C27: 3 | D27: Mandor | E27: L.04 | F27: OH | G27: 0.0228 | H27: =VLOOKUP(D27,upahbahan,3,FALSE) -> 200000 | I27: =G27*H27 -> 4560
C28: JUMLAH HARGA TENAGA KERJA | I28: =SUM(I25:I27) -> 23155.5
C29: B | D29: BAHAN
C30: 1 | D30: Alat sambung kayu terbuat dari baja | F30: buah | G30: 0.25 | H30: =VLOOKUP(D30,upahbahan,3,FALSE) -> 250000 | I30: =G30*H30 -> 62500
C31: 2 | D31: Sepatu pancang | F31: buah | G31: 0.25 | H31: =VLOOKUP(D31,upahbahan,3,FALSE) -> 135000 | I31: =G31*H31 -> 33750
C32: JUMLAH HARGA BAHAN | I32: =SUM(I30:I31) -> 96250
C33: C | D33: PERALATAN
C34: 1 | D34: Sewa Mobil Crane | F34: hari | G34: 0.0759 | H34: =VLOOKUP(D34,upahbahan,3,FALSE) -> 1450000 | I34: =G34*H34 -> 110055
C35: 2 | D35: Alat Pancang Mini Pile | F35: hari | G35: 0.0759 | H35: =VLOOKUP(D35,upahbahan,3,FALSE) -> 250000 | I35: =G35*H35 -> 18975
C36: JUMLAH HARGA ALAT | I36: =SUM(I33:I35) -> 129030
C37: D | D37: Jumlah (A+B+C) | I37: =I36+I32+I28 -> 248435.5
C38: E | D38: Biaya Umum dan Keuntungan 10% - 15% x D | H38: =$N$7 -> 0.1 | I38: =I37*H38 -> 24843.55
C39: F | D39: Harga Satuan Pekerjaan (D+E) | I39: =SUM(I37:I38) -> 273279.05
C41: 2.6.2.3 | D41: 1 m2 Turap bambu dari geribig bambu secara manual, JAT < 0,5 m | J41: =ROUNDDOWN(I58,-2) -> 55500
C42: No | D42: Uraian | E42: Kode | F42: Sat. | G42: Koefisien | H42: Harga Satuan (Rp) | I42: Jumlah Harga (Rp)
...

Sheet Dinding Penahan Tanah 
C2: 2.7 | D2: Pekerjaan Dinding Penahan Tanah
C3: 2.7.1 | D3: Pemasangan 1 M' pipa suling -suling menggunakan pipa PVC dia. 1" (untuk bangunan gedung) | J3: =ROUNDDOWN(I19,-2) -> 29200
C4: No | D4: Uraian | E4: Kode | F4: Sat. | G4: Koefisien | H4: Harga Satuan (Rp) | I4: Jumlah Harga (Rp)
C5: A | D5: TENAGA KERJA | K5: Catatan:
C6: 1 | D6: Pekerja | E6: L.01 | F6: OH | G6: 0.01 | H6: =VLOOKUP(D6,upahbahan,3,FALSE) -> 100000 | I6: =G6*H6 -> 1000 | K6: Biaya Umum dan Keuntungan | N6: 0.1
C7: 2 | D7: Mandor | E7: L.04 | F7: OH | G7: 0.001 | H7: =VLOOKUP(D7,upahbahan,3,FALSE) -> 200000 | I7: =G7*H7 -> 200
C8: JUMLAH HARGA TENAGA KERJA | I8: =SUM(I6:I7) -> 1200
C9: B | D9: BAHAN
C10: 1 | D10: Pipa PVC dia. 1" | F10: m' | G10: 1.05 | H10: =VLOOKUP(D10,upahbahan,3,FALSE) -> 11250 | I10: =G10*H10 -> 11812.5
C11: 2 | D11: Ijuk | F11: kg | G11: 0.4561 | H11: =VLOOKUP(D11,upahbahan,3,FALSE) -> 7000 | I11: =G11*H11 -> 3192.7
C12: 3 | D12: Kerikil | F12: m3 | G12: 0.0196 | H12: =VLOOKUP(D12,upahbahan,3,FALSE) -> 352300 | I12: =G12*H12 -> 6905.08
C13: 4 | D13: Geotextile >100 gr/m2 | F13: m2 | G13: 0.2 | H13: =VLOOKUP(D13,upahbahan,3,FALSE) -> 17500 | I13: =G13*H13 -> 3500
C14: JUMLAH HARGA BAHAN | I14: =SUM(I10:I13) -> 25410.28
C15: C | D15: PERALATAN
C16: JUMLAH HARGA ALAT | I16: =SUM(I15:I15) -> 0
C17: D | D17: Jumlah (A+B+C) | I17: =I16+I14+I8 -> 26610.28
C18: E | D18: Biaya Umum dan Keuntungan 10% - 15% x D | H18: 0.1 | I18: =I17*H18 -> 2661.028
C19: F | D19: Harga Satuan Pekerjaan (D+E) | I19: =SUM(I17:I18) -> 29271.308
C22: 2.7.2 | D22: Pemasangan 1 M' pipa suling -suling menggunakan pipa PVC dia. 2" (untuk bangunan gedung) | J22: =ROUNDDOWN(I38,-2) -> 52400
C23: No | D23: Uraian | E23: Kode | F23: Sat. | G23: Koefisien | H23: Harga Satuan (Rp) | I23: Jumlah Harga (Rp)
C24: A | D24: TENAGA KERJA | K24: Catatan:
C25: 1 | D25: Pekerja | E25: L.01 | F25: OH | G25: 0.01 | H25: =VLOOKUP(D25,upahbahan,3,FALSE) -> 100000 | I25: =G25*H25 -> 1000 | K25: Biaya Umum dan Keuntungan | N25: 0.1
C26: 2 | D26: Mandor | E26: L.04 | F26: OH | G26: 0.001 | H26: =VLOOKUP(D26,upahbahan,3,FALSE) -> 200000 | I26: =G26*H26 -> 200
C27: JUMLAH HARGA TENAGA KERJA | I27: =SUM(I25:I26) -> 1200
C28: B | D28: BAHAN
C29: 1 | D29: Pipa PVC dia. 2" | F29: m' | G29: 1.05 | H29: =VLOOKUP(D29,upahbahan,3,FALSE) -> 26000 | I29: =G29*H29 -> 27300
C30: 2 | D30: Ijuk | F30: kg | G30: 0.6774 | H30: =VLOOKUP(D30,upahbahan,3,FALSE) -> 7000 | I30: =G30*H30 -> 4741.8
C31: 3 | D31: Kerikil | F31: m3 | G31: 0.0235 | H31: =VLOOKUP(D31,upahbahan,3,FALSE) -> 352300 | I31: =G31*H31 -> 8279.05
C32: 4 | D32: Geotextile >100 gr/m2 | F32: m2 | G32: 0.35 | H32: =VLOOKUP(D32,upahbahan,3,FALSE) -> 17500 | I32: =G32*H32 -> 6125
C33: JUMLAH HARGA BAHAN | I33: =SUM(I29:I32) -> 46445.85
C34: C | D34: PERALATAN
C35: JUMLAH HARGA ALAT | I35: =SUM(I34:I34) -> 0
C36: D | D36: Jumlah (A+B+C) | I36: =I35+I33+I27 -> 47645.85
C37: E | D37: Biaya Umum dan Keuntungan 10% - 15% x D | H37: 0.1 | I37: =I36*H37 -> 4764.585
C38: F | D38: Harga Satuan Pekerjaan (D+E) | I38: =SUM(I36:I37) -> 52410.435
C41: 2.7.3 | D41: Pemasangan 1 m2 Lapisan Ijuk tebal 10 cm | J41: =ROUNDDOWN(I54,-2) -> 66000
C42: No | D42: Uraian | E42: Kode | F42: Sat. | G42: Koefisien | H42: Harga Satuan (Rp) | I42: Jumlah Harga (Rp)
C43: A | D43: TENAGA KERJA | K43: Catatan:
C44: 1 | D44: Pekerja | E44: L.01 | F44: OH | G44: 0.15 | H44: =VLOOKUP(D44,upahbahan,3,FALSE) -> 100000 | I44: =G44*H44 -> 15000 | K44: Biaya Umum dan Keuntungan | N44: 0.1
C45: 2 | D45: Mandor | E45: L.04 | F45: OH | G45: 0.015 | H45: =VLOOKUP(D45,upahbahan,3,FALSE) -> 200000 | I45: =G45*H45 -> 3000
...

Sheet Penutup Atap
C2: 3 | D2: PEKERJAAN ARSITEKTUR
C3: 3.1 | D3: ='[1]Daftar HSP'!B186 -> PEKERJAAN PENUTUP ATAP
C4: 3.1.1 | D4: Atap Genteng
C5: 3.1.1.1 | D5: Pemasangan 1 m2 atap Genteng Palentong Kecil | I5: =ROUNDDOWN(H20,-2) -> 107400
C6: No | D6: Uraian | E6: Sat. | F6: Koefisien | G6: Harga Satuan (Rp) | H6: Jumlah Harga (Rp)
C7: A | D7: TENAGA KERJA | J7: Catatan:
C8: 1 | D8: Pekerja | E8: OH | F8: 0.15 | G8: =VLOOKUP(D8,upahbahan,3,FALSE) -> 100000 | H8: =F8*G8 -> 15000 | J8: Biaya Umum dan Keuntungan | M8: 0.1
C9: 2 | D9: Tukang kayu | E9: OH | F9: 0.075 | G9: =VLOOKUP(D9,upahbahan,3,FALSE) -> 145000 | H9: =F9*G9 -> 10875
C10: 3 | D10: Kepala tukang | E10: OH | F10: 0.0075 | G10: =VLOOKUP(D10,upahbahan,3,FALSE) -> 175000 | H10: =F10*G10 -> 1312.5
C11: 4 | D11: Mandor | E11: OH | F11: 0.0025 | G11: =VLOOKUP(D11,upahbahan,3,FALSE) -> 200000 | H11: =F11*G11 -> 500
C12: JUMLAH HARGA TENAGA KERJA | H12: =SUM(H8:H11) -> 27687.5
C13: B | D13: BAHAN
C14: 1 | D14: Genteng palentong | E14: buah | F14: 25 | G14: =VLOOKUP(D14,upahbahan,3,FALSE) -> 2800 | H14: =F14*G14 -> 70000
C15: JUMLAH HARGA BAHAN | H15: =SUM(H14) -> 70000
C16: C | D16: PERALATAN
C17: JUMLAH HARGA ALAT | H17: 0
C18: D | D18: Jumlah (A+B+C) | H18: =H17+H15+H12 -> 97687.5
C19: E | D19: Biaya Umum dan Keuntungan 10% - 15% x D | G19: =$M$8 -> 0.1 | H19: =H18*G19 -> 9768.75
C20: F | D20: Harga Satuan Pekerjaan (D+E) | H20: =SUM(H18:H19) -> 107456.25
C22: 3.1.1.2 | D22: Pemasangan 1 m2 atap genteng kodok glazuur | I22: =ROUNDDOWN(H37,-2) -> 189900
C23: No | D23: Uraian | E23: Sat. | F23: Koefisien | G23: Harga Satuan (Rp) | H23: Jumlah Harga (Rp)
C24: A | D24: TENAGA KERJA
C25: 1 | D25: Pekerja | E25: OH | F25: 0.15 | G25: =VLOOKUP(D25,upahbahan,3,FALSE) -> 100000 | H25: =F25*G25 -> 15000
C26: 2 | D26: Tukang kayu | E26: OH | F26: 0.075 | G26: =VLOOKUP(D26,upahbahan,3,FALSE) -> 145000 | H26: =F26*G26 -> 10875
C27: 3 | D27: Kepala tukang | E27: OH | F27: 0.0075 | G27: =VLOOKUP(D27,upahbahan,3,FALSE) -> 175000 | H27: =F27*G27 -> 1312.5
C28: 4 | D28: Mandor | E28: OH | F28: 0.0025 | G28: =VLOOKUP(D28,upahbahan,3,FALSE) -> 200000 | H28: =F28*G28 -> 500
C29: JUMLAH HARGA TENAGA KERJA | H29: =SUM(H25:H28) -> 27687.5
C30: B | D30: BAHAN
C31: 1 | D31: Genteng kodok glazuur | E31: buah | F31: 25 | G31: =VLOOKUP(D31,upahbahan,3,FALSE) -> 5800 | H31: =F31*G31 -> 145000
C32: JUMLAH HARGA BAHAN | H32: =SUM(H31) -> 145000
C33: C | D33: PERALATAN
C34: JUMLAH HARGA ALAT | H34: 0
C35: D | D35: Jumlah (A+B+C) | H35: =H34+H32+H29 -> 172687.5
C36: E | D36: Biaya Umum dan Keuntungan 10% - 15% x D | G36: =$M$8 -> 0.1 | H36: =H35*G36 -> 17268.75
C37: F | D37: Harga Satuan Pekerjaan (D+E) | H37: =SUM(H35:H36) -> 189956.25
C39: 3.1.1.3 | D39: Pemasangan 1 m2 atap genteng palentong besar | I39: =ROUNDDOWN(H54,-2) -> 100400
C40: No | D40: Uraian | E40: Sat. | F40: Koefisien | G40: Harga Satuan (Rp) | H40: Jumlah Harga (Rp)
C41: A | D41: TENAGA KERJA
C42: 1 | D42: Pekerja | E42: OH | F42: 0.15 | G42: =VLOOKUP(D42,upahbahan,3,FALSE) -> 100000 | H42: =F42*G42 -> 15000
C43: 2 | D43: Tukang kayu | E43: OH | F43: 0.075 | G43: =VLOOKUP(D43,upahbahan,3,FALSE) -> 145000 | H43: =F43*G43 -> 10875
...

Sheet Plafon
C3: 3,5 | D3: PEKERJAAN LANGIT-LANGIT (PLAFON)
C4: 3,5,1 | D4: Langit-Langit (Plafon) Akusik
C5: 3.2.1.1 | D5: Pemasangan 1 m2 plafon akustik uk. 30x30 cm | I5: =ROUNDDOWN(H20,-2) -> 117300
C6: No | D6: Uraian | E6: Sat. | F6: Koefisien | G6: Harga Satuan (Rp) | H6: Jumlah Harga (Rp)
C7: A | D7: TENAGA KERJA | J7: Catatan:
C8: 1 | D8: Pekerja | E8: OH | F8: 0.12 | G8: =VLOOKUP(D8,upahbahan,3,FALSE) -> 100000 | H8: =F8*G8 -> 12000 | J8: Biaya Umum dan Keuntungan | M8: 0.1
C9: 2 | D9: Tukang kayu | E9: OH | F9: 0.12 | G9: =VLOOKUP(D9,upahbahan,3,FALSE) -> 145000 | H9: =F9*G9 -> 17400
C10: 3 | D10: Kepala tukang | E10: OH | F10: 0.012 | G10: =VLOOKUP(D10,upahbahan,3,FALSE) -> 175000 | H10: =F10*G10 -> 2100
C11: 4 | D11: Mandor | E11: OH | F11: 0.004 | G11: =VLOOKUP(D11,upahbahan,3,FALSE) -> 200000 | H11: =F11*G11 -> 800
C12: JUMLAH HARGA TENAGA KERJA | H12: =SUM(H8:H11) -> 32300
C13: B | D13: BAHAN
