Workbook
Name Cash_Minimum: 'Cash Flow Forecast'!$J$3
Name Start_Date: 'Cash Flow Forecast'!$F$3

Sheet Cash Flow Summary
B3: Bulan | C3: Cash on Hand | M3: =B3 -> Bulan | N3: Not Below Minimum | O3: Below Minimum
B4: ='Cash Flow Forecast'!C5 -> 44652 | C4: ='Cash Flow Forecast'!C6 -> 10000 | M4: =B4 -> 44652 | N4: =IF(C4<Cash_Minimum,0,C4) -> 10000 | O4: =IF(C4<Cash_Minimum,C4,0) -> 0
B5: ='Cash Flow Forecast'!D5 -> 44682 | C5: ='Cash Flow Forecast'!D6 -> 8050 | M5: =B5 -> 44682 | N5: =IF(C5<Cash_Minimum,0,C5) -> 8050 | O5: =IF(C5<Cash_Minimum,C5,0) -> 0
B6: ='Cash Flow Forecast'!E5 -> 44713 | C6: ='Cash Flow Forecast'!E6 -> 9350 | M6: =B6 -> 44713 | N6: =IF(C6<Cash_Minimum,0,C6) -> 9350 | O6: =IF(C6<Cash_Minimum,C6,0) -> 0
B7: ='Cash Flow Forecast'!F5 -> 44743 | C7: ='Cash Flow Forecast'!F6 -> 890 | M7: =B7 -> 44743 | N7: =IF(C7<Cash_Minimum,0,C7) -> 0 | O7: =IF(C7<Cash_Minimum,C7,0) -> 890
B8: ='Cash Flow Forecast'!G5 -> 44774 | C8: ='Cash Flow Forecast'!G6 -> 2190 | M8: =B8 -> 44774 | N8: =IF(C8<Cash_Minimum,0,C8) -> 2190 | O8: =IF(C8<Cash_Minimum,C8,0) -> 0
B9: ='Cash Flow Forecast'!H5 -> 44805 | C9: ='Cash Flow Forecast'!H6 -> 13590 | M9: =B9 -> 44805 | N9: =IF(C9<Cash_Minimum,0,C9) -> 13590 | O9: =IF(C9<Cash_Minimum,C9,0) -> 0
B10: ='Cash Flow Forecast'!I5 -> 44835 | C10: ='Cash Flow Forecast'!I6 -> 13790 | M10: =B10 -> 44835 | N10: =IF(C10<Cash_Minimum,0,C10) -> 13790 | O10: =IF(C10<Cash_Minimum,C10,0) -> 0
B11: ='Cash Flow Forecast'!J5 -> 44866 | C11: ='Cash Flow Forecast'!J6 -> 15290 | M11: =B11 -> 44866 | N11: =IF(C11<Cash_Minimum,0,C11) -> 15290 | O11: =IF(C11<Cash_Minimum,C11,0) -> 0
B12: ='Cash Flow Forecast'!K5 -> 44896 | C12: ='Cash Flow Forecast'!K6 -> 16410 | M12: =B12 -> 44896 | N12: =IF(C12<Cash_Minimum,0,C12) -> 16410 | O12: =IF(C12<Cash_Minimum,C12,0) -> 0
B13: ='Cash Flow Forecast'!L5 -> 44927 | C13: ='Cash Flow Forecast'!L6 -> 14360 | M13: =B13 -> 44927 | N13: =IF(C13<Cash_Minimum,0,C13) -> 14360 | O13: =IF(C13<Cash_Minimum,C13,0) -> 0
B14: ='Cash Flow Forecast'!M5 -> 44958 | C14: ='Cash Flow Forecast'!M6 -> 16560 | M14: =B14 -> 44958 | N14: =IF(C14<Cash_Minimum,0,C14) -> 16560 | O14: =IF(C14<Cash_Minimum,C14,0) -> 0
B15: ='Cash Flow Forecast'!N5 -> 44986 | C15: ='Cash Flow Forecast'!N6 -> 18780 | M15: =B15 -> 44986 | N15: =IF(C15<Cash_Minimum,0,C15) -> 18780 | O15: =IF(C15<Cash_Minimum,C15,0) -> 0

Sheet Cash Flow Forecast
B3: Starting cash on hand | C3: 10000 | E3: Tanggal Mulai | F3: 44652 | H3: Peringatan saldo minimum tunai | J3: 2000
C5: =IF(Start_Date="","",Start_Date) -> 44652 | D5: =IF(C5="","",DATE(YEAR(C5),MONTH(C5)+1,1)) -> 44682 | E5: =IF(D5="","",DATE(YEAR(D5),MONTH(D5)+1,1)) -> 44713 | F5: =IF(E5="","",DATE(YEAR(E5),MONTH(E5)+1,1)) -> 44743 | G5: =IF(F5="","",DATE(YEAR(F5),MONTH(F5)+1,1)) -> 44774 | H5: =IF(G5="","",DATE(YEAR(G5),MONTH(G5)+1,1)) -> 44805 | I5: =IF(H5="","",DATE(YEAR(H5),MONTH(H5)+1,1)) -> 44835 | J5: =IF(I5="","",DATE(YEAR(I5),MONTH(I5)+1,1)) -> 44866 | K5: =IF(J5="","",DATE(YEAR(J5),MONTH(J5)+1,1)) -> 44896 | ... N5: =IF(M5="","",DATE(YEAR(M5),MONTH(M5)+1,1)) -> 44986 | O5: Total
B6: Uang tunai (awal bulan) | C6: =C3 -> 10000 | D6: =C55 -> 8050 | E6: =D55 -> 9350 | F6: =E55 -> 890 | G6: =F55 -> 2190 | H6: =G55 -> 13590 | I6: =H55 -> 13790 | J6: =I55 -> 15290 | K6: =J55 -> 16410 | ... N6: =M55 -> 18780
B8: Penerimaan Tunai
B10: Cash sales | C10: 2500 | D10: 3000 | E10: 3600 | F10: 3000 | G10: 14000 | H10: 6000 | I10: 3000 | J10: 2800 | K10: 3500 | L10: 4000 | M10: 3800 | N10: 4200 | O10: =SUM(C10:N10) -> 53400
B11: Returns and allowances | E11: 200 | O11: =SUM(C11:N11) -> 200
B12: Collections on accounts receivable | O12: =SUM(C12:N12) -> 0
B13: Interest, other income | O13: =SUM(C13:N13) -> 0
B14: Loan proceeds | O14: =SUM(C14:N14) -> 0
B15: Owner contributions | O15: =SUM(C15:N15) -> 0
B16: Other receipts | O16: =SUM(C16:N16) -> 0
B17: Jumlah Penerimaan Kas | C17: =SUM(C10,C12:C16,(C11*-1)) -> 2500 | D17: =SUM(D10,D12:D16,(D11*-1)) -> 3000 | E17: =SUM(E10,E12:E16,(E11*-1)) -> 3400 | F17: =SUM(F10,F12:F16,(F11*-1)) -> 3000 | G17: =SUM(G10,G12:G16,(G11*-1)) -> 14000 | H17: =SUM(H10,H12:H16,(H11*-1)) -> 6000 | I17: =SUM(I10,I12:I16,(I11*-1)) -> 3000 | J17: =SUM(J10,J12:J16,(J11*-1)) -> 2800 | ... N17: =SUM(N10,N12:N16,(N11*-1)) -> 4200 | O17: =SUM(O10:O16) -> 53600
B18: Total Kas Tersedia | C18: =(C6+C17) -> 12500 | D18: =(D6+D17) -> 11050 | E18: =(E6+E17) -> 12750 | F18: =(F6+F17) -> 3890 | G18: =(G6+G17) -> 16190 | H18: =(H6+H17) -> 19590 | I18: =(I6+I17) -> 16790 | J18: =(J6+J17) -> 18090 | ... N18: =(N6+N17) -> 22980
B20: Pembayaran Tunai
B22: Advertising | C22: 3000 | O22: =SUM(C22:N22) -> 3000
B23: Commissions and fees | C23: 250 | D23: 300 | E23: 360 | F23: 300 | G23: 1400 | H23: 400 | I23: 300 | J23: 280 | K23: 350 | L23: 400 | M23: 380 | N23: 420 | O23: =SUM(C23:N23) -> 5140
B24: Contract labor | D24: 200 | F24: 200 | H24: 200 | J24: 200 | L24: 200 | N24: 200 | O24: =SUM(C24:N24) -> 1200
B25: Employee benefit programs | O25: =SUM(C25:N25) -> 0
B26: Insurance (other than health) | E26: 4000 | H26: 4000 | K26: 4000 | N26: 4000 | O26: =SUM(C26:N26) -> 16000
B27: Interest expense | O27: =SUM(C27:N27) -> 0
B28: Materials and supplies (in COGS) | C28: 1200 | D28: 1200 | E28: 7500 | F28: 1200 | G28: 1200 | H28: 1200 | I28: 1200 | J28: 1200 | K28: 1200 | L28: 1200 | M28: 1200 | N28: 1200 | O28: =SUM(C28:N28) -> 20700
B29: Meals and entertainment | O29: =SUM(C29:N29) -> 0
B30: Mortgage interest | O30: =SUM(C30:N30) -> 0
B31: Office expense | O31: =SUM(C31:N31) -> 0
B32: Other interest expense | O32: =SUM(C32:N32) -> 0
B33: Pension and profit-sharing plan | O33: =SUM(C33:N33) -> 0
B34: Purchases for resale | O34: =SUM(C34:N34) -> 0
B35: Rent or lease | O35: =SUM(C35:N35) -> 0
B36: Rent or lease: vehicles, equipment | O36: =SUM(C36:N36) -> 0
B37: Repairs and maintenance | O37: =SUM(C37:N37) -> 0
B38: Supplies (not in COGS) | O38: =SUM(C38:N38) -> 0
B39: Taxes and licenses | O39: =SUM(C39:N39) -> 0
B40: Travel | O40: =SUM(C40:N40) -> 0
... B46: Miscellaneous | O46: =SUM(C46:N46) -> 0
B47: Subtotal | C47: =SUM(C22:C46) -> 4450 | D47: =SUM(D22:D46) -> 1700 | E47: =SUM(E22:E46) -> 11860 | F47: =SUM(F22:F46) -> 1700 | G47: =SUM(G22:G46) -> 2600 | H47: =SUM(H22:H46) -> 5800 | I47: =SUM(I22:I46) -> 1500 | J47: =SUM(J22:J46) -> 1680 | ... N47: =SUM(N22:N46) -> 5820 | O47: =SUM(C47:N47) -> 46040
B49: Loan principal payment | O49: =SUM(C49:N49) -> 0
B50: Capital purchases | O50: =SUM(C50:N50) -> 0
B51: Other startup costs | O51: =SUM(C51:N51) -> 0
B52: To reserve and/or escrow | O52: =SUM(C52:N52) -> 0
B53: Owners' withdrawal | O53: =SUM(C53:N53) -> 0
...
