Workbook

Sheet Vacation Summary
B3: RINGKASAN CUTI KARYAWAN
B9: No | C9: Nama Karyawan | D9: Tanggal Dipekerjakan | E9: Tanggal Pengunduran Diri | F9: Departemen | G9: Hari/Jam Kerja | H9: Hari Kerja | O9: ='Vacation Tracker'!PO9 -> 44927 | Q9: ='Vacation Tracker'!QI9 -> 44958 | S9: ='Vacation Tracker'!RC9 -> 44986 | U9: ='Vacation Tracker'!RW9 -> 45017 | W9: ='Vacation Tracker'!SQ9 -> 45047 | Y9: ='Vacation Tracker'!TK9 -> 45078 | AA9: ='Vacation Tracker'!UE9 -> 45108 | AC9: ='Vacation Tracker'!UY9 -> 45139 | AE9: ='Vacation Tracker'!VS9 -> 45170 | AG9: ='Vacation Tracker'!WM9 -> 45200 | AI9: ='Vacation Tracker'!XG9 -> 45231 | AK9: ='Vacation Tracker'!YA9 -> 45261
G10: (Jam) | H10: Sen | I10: Sel | J10: Rab | K10: Kam | L10: Jum | M10: Sab | N10: Min | O10: Hadir | P10: Tidak Hadir | Q10: Hadir | R10: Tidak Hadir | S10: Hadir | T10: Tidak Hadir | U10: Hadir | V10: Tidak Hadir | W10: Hadir | X10: Tidak Hadir | Y10: Hadir | Z10: Tidak Hadir | AA10: Hadir | AB10: Tidak Hadir | AC10: Hadir | AD10: Tidak Hadir | AE10: Hadir | AF10: Tidak Hadir | AG10: Hadir | AH10: Tidak Hadir | AI10: Hadir | AJ10: Tidak Hadir | AK10: Hadir | AL10: Tidak Hadir
B11: =IF('Vacation Tracker'!B11<>"",'Vacation Tracker'!B11,"") -> 1 | C11: =IF('Vacation Tracker'!C11<>"",'Vacation Tracker'!C11,"") -> John Doe 1 | D11: =IF('Vacation Tracker'!D11<>"",'Vacation Tracker'!D11,"") -> 42005 | E11: =IF('Vacation Tracker'!E11<>"",'Vacation Tracker'!E11,"") | F11: =IF('Vacation Tracker'!F11<>"",'Vacation Tracker'!F11,"") -> Marketing | G11: =IF('Vacation Tracker'!G11<>"",'Vacation Tracker'!G11,"") -> 8 | H11: =IF('Vacation Tracker'!H11<>"",'Vacation Tracker'!H11,"") -> v | I11: =IF('Vacation Tracker'!I11<>"",'Vacation Tracker'!I11,"") -> v | ... N11: =IF('Vacation Tracker'!N11<>"",'Vacation Tracker'!N11,"") | O11: ='Vacation Tracker'!QG11 -> 21 | P11: =SUM('Vacation Tracker'!PY11:QF11) -> 0 | Q11: ='Vacation Tracker'!RA11 -> 19 | R11: =SUM('Vacation Tracker'!QS11:QZ11) -> 0 | S11: ='Vacation Tracker'!RU11 -> 21 | T11: =SUM('Vacation Tracker'!RM11:RT11) -> 0 | U11: ='Vacation Tracker'!SO11 -> 19 | V11: =SUM('Vacation Tracker'!SG11:SN11) -> 0 | W11: ='Vacation Tracker'!TI11 -> 21 | X11: =SUM('Vacation Tracker'!TA11:TH11) -> 0 | Y11: ='Vacation Tracker'!UC11 -> 18 | Z11: =SUM('Vacation Tracker'!TU11:UB11) -> 0 | AA11: ='Vacation Tracker'!UW11 -> 19 | AB11: =SUM('Vacation Tracker'!UO11:UV11) -> 0 | AC11: ='Vacation Tracker'!VQ11 -> 21 | AD11: =SUM('Vacation Tracker'!VI11:VP11) -> 0 | AE11: ='Vacation Tracker'!WK11 -> 20 | AF11: =SUM('Vacation Tracker'!WC11:WJ11) -> 0 | AG11: ='Vacation Tracker'!XE11 -> 18 | AH11: =SUM('Vacation Tracker'!WW11:XD11) -> 0 | AI11: ='Vacation Tracker'!XY11 -> 20 | AJ11: =SUM('Vacation Tracker'!XQ11:XX11) -> 0 | AK11: ='Vacation Tracker'!YS11 -> 20 | AL11: =SUM('Vacation Tracker'!YK11:YR11) -> 0
B12: =IF('Vacation Tracker'!B12<>"",'Vacation Tracker'!B12,"") -> 2 | C12: =IF('Vacation Tracker'!C12<>"",'Vacation Tracker'!C12,"") -> John Doe 2 | D12: =IF('Vacation Tracker'!D12<>"",'Vacation Tracker'!D12,"") -> 41985 | E12: =IF('Vacation Tracker'!E12<>"",'Vacation Tracker'!E12,"") -> 42128 | F12: =IF('Vacation Tracker'!F12<>"",'Vacation Tracker'!F12,"") -> Marketing | G12: =IF('Vacation Tracker'!G12<>"",'Vacation Tracker'!G12,"") -> 8 | H12: =IF('Vacation Tracker'!H12<>"",'Vacation Tracker'!H12,"") -> v | I12: =IF('Vacation Tracker'!I12<>"",'Vacation Tracker'!I12,"") -> v | ... N12: =IF('Vacation Tracker'!N12<>"",'Vacation Tracker'!N12,"") | O12: ='Vacation Tracker'!QG12 -> 0 | P12: =SUM('Vacation Tracker'!PY12:QF12) -> 0 | Q12: ='Vacation Tracker'!RA12 -> 0 | R12: =SUM('Vacation Tracker'!QS12:QZ12) -> 0 | S12: ='Vacation Tracker'!RU12 -> 0 | T12: =SUM('Vacation Tracker'!RM12:RT12) -> 0 | U12: ='Vacation Tracker'!SO12 -> 0 | V12: =SUM('Vacation Tracker'!SG12:SN12) -> 0 | W12: ='Vacation Tracker'!TI12 -> 0 | X12: =SUM('Vacation Tracker'!TA12:TH12) -> 0 | Y12: ='Vacation Tracker'!UC12 -> 0 | Z12: =SUM('Vacation Tracker'!TU12:UB12) -> 0 | AA12: ='Vacation Tracker'!UW12 -> 0 | AB12: =SUM('Vacation Tracker'!UO12:UV12) -> 0 | AC12: ='Vacation Tracker'!VQ12 -> 0 | AD12: =SUM('Vacation Tracker'!VI12:VP12) -> 0 | AE12: ='Vacation Tracker'!WK12 -> 0 | AF12: =SUM('Vacation Tracker'!WC12:WJ12) -> 0 | AG12: ='Vacation Tracker'!XE12 -> 0 | AH12: =SUM('Vacation Tracker'!WW12:XD12) -> 0 | AI12: ='Vacation Tracker'!XY12 -> 0 | AJ12: =SUM('Vacation Tracker'!XQ12:XX12) -> 0 | AK12: ='Vacation Tracker'!YS12 -> 0 | AL12: =SUM('Vacation Tracker'!YK12:YR12) -> 0
B13: =IF('Vacation Tracker'!B13<>"",'Vacation Tracker'!B13,"") -> 3 | C13: =IF('Vacation Tracker'!C13<>"",'Vacation Tracker'!C13,"") -> John Doe 3 | D13: =IF('Vacation Tracker'!D13<>"",'Vacation Tracker'!D13,"") -> 41974 | E13: =IF('Vacation Tracker'!E13<>"",'Vacation Tracker'!E13,"") -> 42128 | F13: =IF('Vacation Tracker'!F13<>"",'Vacation Tracker'!F13,"") -> Marketing | G13: =IF('Vacation Tracker'!G13<>"",'Vacation Tracker'!G13,"") -> 8 | H13: =IF('Vacation Tracker'!H13<>"",'Vacation Tracker'!H13,"") -> v | I13: =IF('Vacation Tracker'!I13<>"",'Vacation Tracker'!I13,"") -> v | ... N13: =IF('Vacation Tracker'!N13<>"",'Vacation Tracker'!N13,"") | O13: ='Vacation Tracker'!QG13 -> 0 | P13: =SUM('Vacation Tracker'!PY13:QF13) -> 0 | Q13: ='Vacation Tracker'!RA13 -> 0 | R13: =SUM('Vacation Tracker'!QS13:QZ13) -> 0 | S13: ='Vacation Tracker'!RU13 -> 0 | T13: =SUM('Vacation Tracker'!RM13:RT13) -> 0 | U13: ='Vacation Tracker'!SO13 -> 0 | V13: =SUM('Vacation Tracker'!SG13:SN13) -> 0 | W13: ='Vacation Tracker'!TI13 -> 0 | X13: =SUM('Vacation Tracker'!TA13:TH13) -> 0 | Y13: ='Vacation Tracker'!UC13 -> 0 | Z13: =SUM('Vacation Tracker'!TU13:UB13) -> 0 | AA13: ='Vacation Tracker'!UW13 -> 0 | AB13: =SUM('Vacation Tracker'!UO13:UV13) -> 0 | AC13: ='Vacation Tracker'!VQ13 -> 0 | AD13: =SUM('Vacation Tracker'!VI13:VP13) -> 0 | AE13: ='Vacation Tracker'!WK13 -> 0 | AF13: =SUM('Vacation Tracker'!WC13:WJ13) -> 0 | AG13: ='Vacation Tracker'!XE13 -> 0 | AH13: =SUM('Vacation Tracker'!WW13:XD13) -> 0 | AI13: ='Vacation Tracker'!XY13 -> 0 | AJ13: =SUM('Vacation Tracker'!XQ13:XX13) -> 0 | AK13: ='Vacation Tracker'!YS13 -> 0 | AL13: =SUM('Vacation Tracker'!YK13:YR13) -> 0
B14: =IF('Vacation Tracker'!B14<>"",'Vacation Tracker'!B14,"") -> 4 | C14: =IF('Vacation Tracker'!C14<>"",'Vacation Tracker'!C14,"") -> John Doe 4 | D14: =IF('Vacation Tracker'!D14<>"",'Vacation Tracker'!D14,"") -> 42040 | E14: =IF('Vacation Tracker'!E14<>"",'Vacation Tracker'!E14,"") -> 42128 | F14: =IF('Vacation Tracker'!F14<>"",'Vacation Tracker'!F14,"") -> Technical | G14: =IF('Vacation Tracker'!G14<>"",'Vacation Tracker'!G14,"") -> 8 | H14: =IF('Vacation Tracker'!H14<>"",'Vacation Tracker'!H14,"") -> v | I14: =IF('Vacation Tracker'!I14<>"",'Vacation Tracker'!I14,"") -> v | ... N14: =IF('Vacation Tracker'!N14<>"",'Vacation Tracker'!N14,"") | O14: ='Vacation Tracker'!QG14 -> 0 | P14: =SUM('Vacation Tracker'!PY14:QF14) -> 0 | Q14: ='Vacation Tracker'!RA14 -> 0 | R14: =SUM('Vacation Tracker'!QS14:QZ14) -> 0 | S14: ='Vacation Tracker'!RU14 -> 0 | T14: =SUM('Vacation Tracker'!RM14:RT14) -> 0 | U14: ='Vacation Tracker'!SO14 -> 0 | V14: =SUM('Vacation Tracker'!SG14:SN14) -> 0 | W14: ='Vacation Tracker'!TI14 -> 0 | X14: =SUM('Vacation Tracker'!TA14:TH14) -> 0 | Y14: ='Vacation Tracker'!UC14 -> 0 | Z14: =SUM('Vacation Tracker'!TU14:UB14) -> 0 | AA14: ='Vacation Tracker'!UW14 -> 0 | AB14: =SUM('Vacation Tracker'!UO14:UV14) -> 0 | AC14: ='Vacation Tracker'!VQ14 -> 0 | AD14: =SUM('Vacation Tracker'!VI14:VP14) -> 0 | AE14: ='Vacation Tracker'!WK14 -> 0 | AF14: =SUM('Vacation Tracker'!WC14:WJ14) -> 0 | AG14: ='Vacation Tracker'!XE14 -> 0 | AH14: =SUM('Vacation Tracker'!WW14:XD14) -> 0 | AI14: ='Vacation Tracker'!XY14 -> 0 | AJ14: =SUM('Vacation Tracker'!XQ14:XX14) -> 0 | AK14: ='Vacation Tracker'!YS14 -> 0 | AL14: =SUM('Vacation Tracker'!YK14:YR14) -> 0
B15: =IF('Vacation Tracker'!B15<>"",'Vacation Tracker'!B15,"") -> 5 | C15: =IF('Vacation Tracker'!C15<>"",'Vacation Tracker'!C15,"") -> John Doe 5 | D15: =IF('Vacation Tracker'!D15<>"",'Vacation Tracker'!D15,"") -> 41985 | E15: =IF('Vacation Tracker'!E15<>"",'Vacation Tracker'!E15,"") -> 42217 | F15: =IF('Vacation Tracker'!F15<>"",'Vacation Tracker'!F15,"") -> Technical | G15: =IF('Vacation Tracker'!G15<>"",'Vacation Tracker'!G15,"") -> 4 | H15: =IF('Vacation Tracker'!H15<>"",'Vacation Tracker'!H15,"") | I15: =IF('Vacation Tracker'!I15<>"",'Vacation Tracker'!I15,"") | ... N15: =IF('Vacation Tracker'!N15<>"",'Vacation Tracker'!N15,"") -> v | O15: ='Vacation Tracker'!QG15 -> 0 | P15: =SUM('Vacation Tracker'!PY15:QF15) -> 0 | Q15: ='Vacation Tracker'!RA15 -> 0 | R15: =SUM('Vacation Tracker'!QS15:QZ15) -> 0 | S15: ='Vacation Tracker'!RU15 -> 0 | T15: =SUM('Vacation Tracker'!RM15:RT15) -> 0 | U15: ='Vacation Tracker'!SO15 -> 0 | V15: =SUM('Vacation Tracker'!SG15:SN15) -> 0 | W15: ='Vacation Tracker'!TI15 -> 0 | X15: =SUM('Vacation Tracker'!TA15:TH15) -> 0 | Y15: ='Vacation Tracker'!UC15 -> 0 | Z15: =SUM('Vacation Tracker'!TU15:UB15) -> 0 | AA15: ='Vacation Tracker'!UW15 -> 0 | AB15: =SUM('Vacation Tracker'!UO15:UV15) -> 0 | AC15: ='Vacation Tracker'!VQ15 -> 0 | AD15: =SUM('Vacation Tracker'!VI15:VP15) -> 0 | AE15: ='Vacation Tracker'!WK15 -> 0 | AF15: =SUM('Vacation Tracker'!WC15:WJ15) -> 0 | AG15: ='Vacation Tracker'!XE15 -> 0 | AH15: =SUM('Vacation Tracker'!WW15:XD15) -> 0 | AI15: ='Vacation Tracker'!XY15 -> 0 | AJ15: =SUM('Vacation Tracker'!XQ15:XX15) -> 0 | AK15: ='Vacation Tracker'!YS15 -> 0 | AL15: =SUM('Vacation Tracker'!YK15:YR15) -> 0
B16: =IF('Vacation Tracker'!B16<>"",'Vacation Tracker'!B16,"") -> 6 | C16: =IF('Vacation Tracker'!C16<>"",'Vacation Tracker'!C16,"") -> John Doe 6 | D16: =IF('Vacation Tracker'!D16<>"",'Vacation Tracker'!D16,"") -> 41974 | E16: =IF('Vacation Tracker'!E16<>"",'Vacation Tracker'!E16,"") -> 42217 | F16: =IF('Vacation Tracker'!F16<>"",'Vacation Tracker'!F16,"") -> Technical | G16: =IF('Vacation Tracker'!G16<>"",'Vacation Tracker'!G16,"") -> 4 | H16: =IF('Vacation Tracker'!H16<>"",'Vacation Tracker'!H16,"") | I16: =IF('Vacation Tracker'!I16<>"",'Vacation Tracker'!I16,"") | ... N16: =IF('Vacation Tracker'!N16<>"",'Vacation Tracker'!N16,"") -> v | O16: ='Vacation Tracker'!QG16 -> 0 | P16: =SUM('Vacation Tracker'!PY16:QF16) -> 0 | Q16: ='Vacation Tracker'!RA16 -> 0 | R16: =SUM('Vacation Tracker'!QS16:QZ16) -> 0 | S16: ='Vacation Tracker'!RU16 -> 0 | T16: =SUM('Vacation Tracker'!RM16:RT16) -> 0 | U16: ='Vacation Tracker'!SO16 -> 0 | V16: =SUM('Vacation Tracker'!SG16:SN16) -> 0 | W16: ='Vacation Tracker'!TI16 -> 0 | X16: =SUM('Vacation Tracker'!TA16:TH16) -> 0 | Y16: ='Vacation Tracker'!UC16 -> 0 | Z16: =SUM('Vacation Tracker'!TU16:UB16) -> 0 | AA16: ='Vacation Tracker'!UW16 -> 0 | AB16: =SUM('Vacation Tracker'!UO16:UV16) -> 0 | AC16: ='Vacation Tracker'!VQ16 -> 0 | AD16: =SUM('Vacation Tracker'!VI16:VP16) -> 0 | AE16: ='Vacation Tracker'!WK16 -> 0 | AF16: =SUM('Vacation Tracker'!WC16:WJ16) -> 0 | AG16: ='Vacation Tracker'!XE16 -> 0 | AH16: =SUM('Vacation Tracker'!WW16:XD16) -> 0 | AI16: ='Vacation Tracker'!XY16 -> 0 | AJ16: =SUM('Vacation Tracker'!XQ16:XX16) -> 0 | AK16: ='Vacation Tracker'!YS16 -> 0 | AL16: =SUM('Vacation Tracker'!YK16:YR16) -> 0
B17: =IF('Vacation Tracker'!B17<>"",'Vacation Tracker'!B17,"") -> 7 | C17: =IF('Vacation Tracker'!C17<>"",'Vacation Tracker'!C17,"") -> John Doe 7 | D17: =IF('Vacation Tracker'!D17<>"",'Vacation Tracker'!D17,"") -> 42040 | E17: =IF('Vacation Tracker'!E17<>"",'Vacation Tracker'!E17,"") -> 42217 | F17: =IF('Vacation Tracker'!F17<>"",'Vacation Tracker'!F17,"") -> Operational | G17: =IF('Vacation Tracker'!G17<>"",'Vacation Tracker'!G17,"") -> 4 | H17: =IF('Vacation Tracker'!H17<>"",'Vacation Tracker'!H17,"") | I17: =IF('Vacation Tracker'!I17<>"",'Vacation Tracker'!I17,"") | ... N17: =IF('Vacation Tracker'!N17<>"",'Vacation Tracker'!N17,"") -> v | O17: ='Vacation Tracker'!QG17 -> 0 | P17: =SUM('Vacation Tracker'!PY17:QF17) -> 0 | Q17: ='Vacation Tracker'!RA17 -> 0 | R17: =SUM('Vacation Tracker'!QS17:QZ17) -> 0 | S17: ='Vacation Tracker'!RU17 -> 0 | T17: =SUM('Vacation Tracker'!RM17:RT17) -> 0 | U17: ='Vacation Tracker'!SO17 -> 0 | V17: =SUM('Vacation Tracker'!SG17:SN17) -> 0 | W17: ='Vacation Tracker'!TI17 -> 0 | X17: =SUM('Vacation Tracker'!TA17:TH17) -> 0 | Y17: ='Vacation Tracker'!UC17 -> 0 | Z17: =SUM('Vacation Tracker'!TU17:UB17) -> 0 | AA17: ='Vacation Tracker'!UW17 -> 0 | AB17: =SUM('Vacation Tracker'!UO17:UV17) -> 0 | AC17: ='Vacation Tracker'!VQ17 -> 0 | AD17: =SUM('Vacation Tracker'!VI17:VP17) -> 0 | AE17: ='Vacation Tracker'!WK17 -> 0 | AF17: =SUM('Vacation Tracker'!WC17:WJ17) -> 0 | AG17: ='Vacation Tracker'!XE17 -> 0 | AH17: =SUM('Vacation Tracker'!WW17:XD17) -> 0 | AI17: ='Vacation Tracker'!XY17 -> 0 | AJ17: =SUM('Vacation Tracker'!XQ17:XX17) -> 0 | AK17: ='Vacation Tracker'!YS17 -> 0 | AL17: =SUM('Vacation Tracker'!YK17:YR17) -> 0
B18: =IF('Vacation Tracker'!B18<>"",'Vacation Tracker'!B18,"") -> 8 | C18: =IF('Vacation Tracker'!C18<>"",'Vacation Tracker'!C18,"") -> John Doe 8 | D18: =IF('Vacation Tracker'!D18<>"",'Vacation Tracker'!D18,"") | E18: =IF('Vacation Tracker'!E18<>"",'Vacation Tracker'!E18,"") -> 42128 | F18: =IF('Vacation Tracker'!F18<>"",'Vacation Tracker'!F18,"") -> Operational | G18: =IF('Vacation Tracker'!G18<>"",'Vacation Tracker'!G18,"") -> 4 | H18: =IF('Vacation Tracker'!H18<>"",'Vacation Tracker'!H18,"") | I18: =IF('Vacation Tracker'!I18<>"",'Vacation Tracker'!I18,"") | ... N18: =IF('Vacation Tracker'!N18<>"",'Vacation Tracker'!N18,"") -> v | O18: ='Vacation Tracker'!QG18 -> 0 | P18: =SUM('Vacation Tracker'!PY18:QF18) -> 0 | Q18: ='Vacation Tracker'!RA18 -> 0 | R18: =SUM('Vacation Tracker'!QS18:QZ18) -> 0 | S18: ='Vacation Tracker'!RU18 -> 0 | T18: =SUM('Vacation Tracker'!RM18:RT18) -> 0 | U18: ='Vacation Tracker'!SO18 -> 0 | V18: =SUM('Vacation Tracker'!SG18:SN18) -> 0 | W18: ='Vacation Tracker'!TI18 -> 0 | X18: =SUM('Vacation Tracker'!TA18:TH18) -> 0 | Y18: ='Vacation Tracker'!UC18 -> 0 | Z18: =SUM('Vacation Tracker'!TU18:UB18) -> 0 | AA18: ='Vacation Tracker'!UW18 -> 0 | AB18: =SUM('Vacation Tracker'!UO18:UV18) -> 0 | AC18: ='Vacation Tracker'!VQ18 -> 0 | AD18: =SUM('Vacation Tracker'!VI18:VP18) -> 0 | AE18: ='Vacation Tracker'!WK18 -> 0 | AF18: =SUM('Vacation Tracker'!WC18:WJ18) -> 0 | AG18: ='Vacation Tracker'!XE18 -> 0 | AH18: =SUM('Vacation Tracker'!WW18:XD18) -> 0 | AI18: ='Vacation Tracker'!XY18 -> 0 | AJ18: =SUM('Vacation Tracker'!XQ18:XX18) -> 0 | AK18: ='Vacation Tracker'!YS18 -> 0 | AL18: =SUM('Vacation Tracker'!YK18:YR18) -> 0
B19: =IF('Vacation Tracker'!B19<>"",'Vacation Tracker'!B19,"") -> 9 | C19: =IF('Vacation Tracker'!C19<>"",'Vacation Tracker'!C19,"") -> John Doe 9 | D19: =IF('Vacation Tracker'!D19<>"",'Vacation Tracker'!D19,"") | E19: =IF('Vacation Tracker'!E19<>"",'Vacation Tracker'!E19,"") -> 42217 | F19: =IF('Vacation Tracker'!F19<>"",'Vacation Tracker'!F19,"") -> Operational | G19: =IF('Vacation Tracker'!G19<>"",'Vacation Tracker'!G19,"") -> 8 | H19: =IF('Vacation Tracker'!H19<>"",'Vacation Tracker'!H19,"") | I19: =IF('Vacation Tracker'!I19<>"",'Vacation Tracker'!I19,"") | ... N19: =IF('Vacation Tracker'!N19<>"",'Vacation Tracker'!N19,"") -> v | O19: ='Vacation Tracker'!QG19 -> 0 | P19: =SUM('Vacation Tracker'!PY19:QF19) -> 0 | Q19: ='Vacation Tracker'!RA19 -> 0 | R19: =SUM('Vacation Tracker'!QS19:QZ19) -> 0 | S19: ='Vacation Tracker'!RU19 -> 0 | T19: =SUM('Vacation Tracker'!RM19:RT19) -> 0 | U19: ='Vacation Tracker'!SO19 -> 0 | V19: =SUM('Vacation Tracker'!SG19:SN19) -> 0 | W19: ='Vacation Tracker'!TI19 -> 0 | X19: =SUM('Vacation Tracker'!TA19:TH19) -> 0 | Y19: ='Vacation Tracker'!UC19 -> 0 | Z19: =SUM('Vacation Tracker'!TU19:UB19) -> 0 | AA19: ='Vacation Tracker'!UW19 -> 0 | AB19: =SUM('Vacation Tracker'!UO19:UV19) -> 0 | AC19: ='Vacation Tracker'!VQ19 -> 0 | AD19: =SUM('Vacation Tracker'!VI19:VP19) -> 0 | AE19: ='Vacation Tracker'!WK19 -> 0 | AF19: =SUM('Vacation Tracker'!WC19:WJ19) -> 0 | AG19: ='Vacation Tracker'!XE19 -> 0 | AH19: =SUM('Vacation Tracker'!WW19:XD19) -> 0 | AI19: ='Vacation Tracker'!XY19 -> 0 | AJ19: =SUM('Vacation Tracker'!XQ19:XX19) -> 0 | AK19: ='Vacation Tracker'!YS19 -> 0 | AL19: =SUM('Vacation Tracker'!YK19:YR19) -> 0
B20: =IF('Vacation Tracker'!B20<>"",'Vacation Tracker'!B20,"") -> 10 | C20: =IF('Vacation Tracker'!C20<>"",'Vacation Tracker'!C20,"") -> John Doe 10 | D20: =IF('Vacation Tracker'!D20<>"",'Vacation Tracker'!D20,"") -> 45272 | E20: =IF('Vacation Tracker'!E20<>"",'Vacation Tracker'!E20,"") | F20: =IF('Vacation Tracker'!F20<>"",'Vacation Tracker'!F20,"") -> Sales | G20: =IF('Vacation Tracker'!G20<>"",'Vacation Tracker'!G20,"") -> 8 | H20: =IF('Vacation Tracker'!H20<>"",'Vacation Tracker'!H20,"") -> v | I20: =IF('Vacation Tracker'!I20<>"",'Vacation Tracker'!I20,"") -> v | ... N20: =IF('Vacation Tracker'!N20<>"",'Vacation Tracker'!N20,"") | O20: ='Vacation Tracker'!QG20 -> 0 | P20: =SUM('Vacation Tracker'!PY20:QF20) -> 0 | Q20: ='Vacation Tracker'!RA20 -> 0 | R20: =SUM('Vacation Tracker'!QS20:QZ20) -> 0 | S20: ='Vacation Tracker'!RU20 -> 0 | T20: =SUM('Vacation Tracker'!RM20:RT20) -> 0 | U20: ='Vacation Tracker'!SO20 -> 0 | V20: =SUM('Vacation Tracker'!SG20:SN20) -> 0 | W20: ='Vacation Tracker'!TI20 -> 0 | X20: =SUM('Vacation Tracker'!TA20:TH20) -> 0 | Y20: ='Vacation Tracker'!UC20 -> 0 | Z20: =SUM('Vacation Tracker'!TU20:UB20) -> 0 | AA20: ='Vacation Tracker'!UW20 -> 0 | AB20: =SUM('Vacation Tracker'!UO20:UV20) -> 0 | AC20: ='Vacation Tracker'!VQ20 -> 0 | AD20: =SUM('Vacation Tracker'!VI20:VP20) -> 0 | AE20: ='Vacation Tracker'!WK20 -> 0 | AF20: =SUM('Vacation Tracker'!WC20:WJ20) -> 0 | AG20: ='Vacation Tracker'!XE20 -> 0 | AH20: =SUM('Vacation Tracker'!WW20:XD20) -> 0 | AI20: ='Vacation Tracker'!XY20 -> 0 | AJ20: =SUM('Vacation Tracker'!XQ20:XX20) -> 0 | AK20: ='Vacation Tracker'!YS20 -> 13 | AL20: =SUM('Vacation Tracker'!YK20:YR20) -> 0
B21: =IF('Vacation Tracker'!B21<>"",'Vacation Tracker'!B21,"") -> 11 | C21: =IF('Vacation Tracker'!C21<>"",'Vacation Tracker'!C21,"") -> John Doe 11 | D21: =IF('Vacation Tracker'!D21<>"",'Vacation Tracker'!D21,"") -> 44962 | E21: =IF('Vacation Tracker'!E21<>"",'Vacation Tracker'!E21,"") | F21: =IF('Vacation Tracker'!F21<>"",'Vacation Tracker'!F21,"") -> Sales | G21: =IF('Vacation Tracker'!G21<>"",'Vacation Tracker'!G21,"") -> 8 | H21: =IF('Vacation Tracker'!H21<>"",'Vacation Tracker'!H21,"") -> v | I21: =IF('Vacation Tracker'!I21<>"",'Vacation Tracker'!I21,"") -> v | ... N21: =IF('Vacation Tracker'!N21<>"",'Vacation Tracker'!N21,"") | O21: ='Vacation Tracker'!QG21 -> 0 | P21: =SUM('Vacation Tracker'!PY21:QF21) -> 0 | Q21: ='Vacation Tracker'!RA21 -> 16 | R21: =SUM('Vacation Tracker'!QS21:QZ21) -> 0 | S21: ='Vacation Tracker'!RU21 -> 21 | T21: =SUM('Vacation Tracker'!RM21:RT21) -> 0 | U21: ='Vacation Tracker'!SO21 -> 19 | V21: =SUM('Vacation Tracker'!SG21:SN21) -> 0 | W21: ='Vacation Tracker'!TI21 -> 21 | X21: =SUM('Vacation Tracker'!TA21:TH21) -> 0 | Y21: ='Vacation Tracker'!UC21 -> 18 | Z21: =SUM('Vacation Tracker'!TU21:UB21) -> 0 | AA21: ='Vacation Tracker'!UW21 -> 20 | AB21: =SUM('Vacation Tracker'!UO21:UV21) -> 0 | AC21: ='Vacation Tracker'!VQ21 -> 21 | AD21: =SUM('Vacation Tracker'!VI21:VP21) -> 0 | AE21: ='Vacation Tracker'!WK21 -> 20 | AF21: =SUM('Vacation Tracker'!WC21:WJ21) -> 0 | AG21: ='Vacation Tracker'!XE21 -> 19 | AH21: =SUM('Vacation Tracker'!WW21:XD21) -> 0 | AI21: ='Vacation Tracker'!XY21 -> 20 | AJ21: =SUM('Vacation Tracker'!XQ21:XX21) -> 0 | AK21: ='Vacation Tracker'!YS21 -> 20 | AL21: =SUM('Vacation Tracker'!YK21:YR21) -> 0
B22: =IF('Vacation Tracker'!B22<>"",'Vacation Tracker'!B22,"") -> 12 | C22: =IF('Vacation Tracker'!C22<>"",'Vacation Tracker'!C22,"") -> John Doe 12 | D22: =IF('Vacation Tracker'!D22<>"",'Vacation Tracker'!D22,"") | E22: =IF('Vacation Tracker'!E22<>"",'Vacation Tracker'!E22,"") | F22: =IF('Vacation Tracker'!F22<>"",'Vacation Tracker'!F22,"") -> Sales | G22: =IF('Vacation Tracker'!G22<>"",'Vacation Tracker'!G22,"") -> 8 | H22: =IF('Vacation Tracker'!H22<>"",'Vacation Tracker'!H22,"") -> v | I22: =IF('Vacation Tracker'!I22<>"",'Vacation Tracker'!I22,"") -> v | ... N22: =IF('Vacation Tracker'!N22<>"",'Vacation Tracker'!N22,"") | O22: ='Vacation Tracker'!QG22 -> 21 | P22: =SUM('Vacation Tracker'!PY22:QF22) -> 0 | Q22: ='Vacation Tracker'!RA22 -> 19 | R22: =SUM('Vacation Tracker'!QS22:QZ22) -> 0 | S22: ='Vacation Tracker'!RU22 -> 21 | T22: =SUM('Vacation Tracker'!RM22:RT22) -> 0 | U22: ='Vacation Tracker'!SO22 -> 19 | V22: =SUM('Vacation Tracker'!SG22:SN22) -> 0 | W22: ='Vacation Tracker'!TI22 -> 21 | X22: =SUM('Vacation Tracker'!TA22:TH22) -> 0 | Y22: ='Vacation Tracker'!UC22 -> 18 | Z22: =SUM('Vacation Tracker'!TU22:UB22) -> 0 | AA22: ='Vacation Tracker'!UW22 -> 19 | AB22: =SUM('Vacation Tracker'!UO22:UV22) -> 0 | AC22: ='Vacation Tracker'!VQ22 -> 21 | AD22: =SUM('Vacation Tracker'!VI22:VP22) -> 0 | AE22: ='Vacation Tracker'!WK22 -> 20 | AF22: =SUM('Vacation Tracker'!WC22:WJ22) -> 0 | AG22: ='Vacation Tracker'!XE22 -> 18 | AH22: =SUM('Vacation Tracker'!WW22:XD22) -> 0 | AI22: ='Vacation Tracker'!XY22 -> 20 | AJ22: =SUM('Vacation Tracker'!XQ22:XX22) -> 0 | AK22: ='Vacation Tracker'!YS22 -> 20 | AL22: =SUM('Vacation Tracker'!YK22:YR22) -> 0
... B260: =IF('Vacation Tracker'!B260<>"",'Vacation Tracker'!B260,"") -> 250 | C260: =IF('Vacation Tracker'!C260<>"",'Vacation Tracker'!C260,"") | D260: =IF('Vacation Tracker'!D260<>"",'Vacation Tracker'!D260,"") | E260: =IF('Vacation Tracker'!E260<>"",'Vacation Tracker'!E260,"") | F260: =IF('Vacation Tracker'!F260<>"",'Vacation Tracker'!F260,"") | G260: =IF('Vacation Tracker'!G260<>"",'Vacation Tracker'!G260,"") | H260: =IF('Vacation Tracker'!H260<>"",'Vacation Tracker'!H260,"") | I260: =IF('Vacation Tracker'!I260<>"",'Vacation Tracker'!I260,"") | ... N260: =IF('Vacation Tracker'!N260<>"",'Vacation Tracker'!N260,"") | O260: ='Vacation Tracker'!QG260 -> 0 | P260: =SUM('Vacation Tracker'!PY260:QF260) -> 0 | Q260: ='Vacation Tracker'!RA260 -> 0 | R260: =SUM('Vacation Tracker'!QS260:QZ260) -> 0 | S260: ='Vacation Tracker'!RU260 -> 0 | T260: =SUM('Vacation Tracker'!RM260:RT260) -> 0 | U260: ='Vacation Tracker'!SO260 -> 0 | V260: =SUM('Vacation Tracker'!SG260:SN260) -> 0 | W260: ='Vacation Tracker'!TI260 -> 0 | X260: =SUM('Vacation Tracker'!TA260:TH260) -> 0 | Y260: ='Vacation Tracker'!UC260 -> 0 | Z260: =SUM('Vacation Tracker'!TU260:UB260) -> 0 | AA260: ='Vacation Tracker'!UW260 -> 0 | AB260: =SUM('Vacation Tracker'!UO260:UV260) -> 0 | AC260: ='Vacation Tracker'!VQ260 -> 0 | AD260: =SUM('Vacation Tracker'!VI260:VP260) -> 0 | AE260: ='Vacation Tracker'!WK260 -> 0 | AF260: =SUM('Vacation Tracker'!WC260:WJ260) -> 0 | AG260: ='Vacation Tracker'!XE260 -> 0 | AH260: =SUM('Vacation Tracker'!WW260:XD260) -> 0 | AI260: ='Vacation Tracker'!XY260 -> 0 | AJ260: =SUM('Vacation Tracker'!XQ260:XX260) -> 0 | AK260: ='Vacation Tracker'!YS260 -> 0 | AL260: =SUM('Vacation Tracker'!YK260:YR260) -> 0

Sheet Vacation Tracker
OP1: =WEEKDAY(PC11) -> 1
B3: PERENCANA DAN PELACAK CUTI KARYAWAN | H3: Kode Vacation | V3: Kode Liburan
H4: A | I4: : | J4: Vacation Code 1 | O4: E | P4: : | Q4: Vacation Code 5 | V4: R | W4: : | X4: Holiday Code
H5: B | I5: : | J5: Vacation Code 2 | O5: F | P5: : | Q5: Vacation Code 6
C6: Periode Mulai | D6: 44927 | H6: C | I6: : | J6: Vacation Code 3 | O6: G | P6: : | Q6: Vacation Code 7 | V6: Warna Bukan Hari Kerja
C7: Periode Pengamatan | D7: Today | H7: D | I7: : | J7: Vacation Code 4 | O7: H | P7: : | Q7: Vacation Code 8
B9: No | C9: Nama Karyawan | D9: Tanggal Dipekerjakan | E9: Tanggal Pengunduran Diri | F9: Departemen | G9: Hari/Jam Kerja | H9: Hari Kerja | O9: Alokasi Vacation per Tahun | W9: =D6 -> 44927 | X9: =W9+1 -> 44928 | Y9: =X9+1 -> 44929 | Z9: =Y9+1 -> 44930 | AA9: =Z9+1 -> 44931 | AB9: =AA9+1 -> 44932 | AC9: =AB9+1 -> 44933 | AD9: =AC9+1 -> 44934 | AE9: =AD9+1 -> 44935 | ... NW9: =NV9+1 -> 45291 | NX9: =IF(MONTH(NW9)<>MONTH(NW9+1),"",NW9+1) | NY9: Vacation Digunakan | OG9: Vacation Left | OO9: Total Hari Kerja hingga saat ini | OP9: Total Hadir sampai saat ini : | PN9: 1 | PO9: =W9 -> 44927 | PP9: =EOMONTH(PO9,0) -> 44957 | QH9: =PN9+1 -> 2 | QI9: =PP9+1 -> 44958 | QJ9: =EOMONTH(QI9,0) -> 44985 | RB9: =QH9+1 -> 3 | RC9: =QJ9+1 -> 44986 | RD9: =EOMONTH(RC9,0) -> 45016 | RV9: =RB9+1 -> 4 | RW9: =RD9+1 -> 45017 | RX9: =EOMONTH(RW9,0) -> 45046 | SP9: =RV9+1 -> 5 | SQ9: =RX9+1 -> 45047 | SR9: =EOMONTH(SQ9,0) -> 45077 | TJ9: =SP9+1 -> 6 | TK9: =SR9+1 -> 45078 | TL9: =EOMONTH(TK9,0) -> 45107 | UD9: =TJ9+1 -> 7 | UE9: =TL9+1 -> 45108 | UF9: =EOMONTH(UE9,0) -> 45138 | UX9: =UD9+1 -> 8 | UY9: =UF9+1 -> 45139 | UZ9: =EOMONTH(UY9,0) -> 45169 | VR9: =UX9+1 -> 9 | VS9: =UZ9+1 -> 45170 | VT9: =EOMONTH(VS9,0) -> 45199 | WL9: =VR9+1 -> 10 | WM9: =VT9+1 -> 45200 | WN9: =EOMONTH(WM9,0) -> 45230 | XF9: =WL9+1 -> 11 | XG9: =WN9+1 -> 45231 | XH9: =EOMONTH(XG9,0) -> 45260 | XZ9: =XF9+1 -> 12 | YA9: =XH9+1 -> 45261 | YB9: =EOMONTH(YA9,0) -> 45291
G10: (Jam) | H10: Sen | I10: Sel | J10: Rab | K10: Kam | L10: Jum | M10: Sab | N10: Min | O10: =H4 -> A | P10: =H5 -> B | Q10: =H6 -> C | R10: =H7 -> D | S10: =O4 -> E | T10: =O5 -> F | U10: =O6 -> G | V10: =O7 -> H | W10: =W9 -> 44927 | X10: =X9 -> 44928 | Y10: =Y9 -> 44929 | Z10: =Z9 -> 44930 | AA10: =AA9 -> 44931 | AB10: =AB9 -> 44932 | AC10: =AC9 -> 44933 | AD10: =AD9 -> 44934 | ... NX10: =NX9 | NY10: =O10 -> A | NZ10: =P10 -> B | OA10: =Q10 -> C | OB10: =R10 -> D | OC10: =S10 -> E | OD10: =T10 -> F | OE10: =U10 -> G | OF10: =V10 -> H | OG10: =NY10 -> A | OH10: =NZ10 -> B | OI10: =OA10 -> C | OJ10: =OB10 -> D | OK10: =OC10 -> E | OL10: =OD10 -> F | OM10: =OE10 -> G | ON10: =OF10 -> H | OO10: =IF(PC10=1,TODAY(),PD10) -> 45488 | OP10: =OO10 -> 45488 | PC10: =IF(D7="Today",1,0) -> 1 | PD10: =IF(NX10<>"",NX10,NW10) -> 45291 | PE10: M | PF10: T | PG10: W | PH10: T | PI10: F | PJ10: S | PK10: S | PL10: T | PO10: =PC10 -> 1 | PP10: =PD10 -> 45291 | PQ10: M | PR10: T | PS10: W | PT10: T | PU10: F | PV10: S | PW10: S | PX10: T | PY10: =OG10 -> A | PZ10: =OH10 -> B | QA10: =OI10 -> C | QB10: =OJ10 -> D | QC10: =OK10 -> E | QD10: =OL10 -> F | QE10: =OM10 -> G | QF10: =ON10 -> H | QI10: =PO10 -> 1 | QJ10: =PP10 -> 45291 | QK10: M | QL10: T | QM10: W | QN10: T | QO10: F | QP10: S | QQ10: S | QR10: T | QS10: =PY10 -> A | QT10: =PZ10 -> B | QU10: =QA10 -> C | QV10: =QB10 -> D | QW10: =QC10 -> E | QX10: =QD10 -> F | QY10: =QE10 -> G | QZ10: =QF10 -> H | RC10: =QI10 -> 1 | RD10: =QJ10 -> 45291 | RE10: M | RF10: T | RG10: W | RH10: T | RI10: F | RJ10: S | RK10: S | RL10: T | RM10: =QS10 -> A | RN10: =QT10 -> B | RO10: =QU10 -> C | RP10: =QV10 -> D | RQ10: =QW10 -> E | RR10: =QX10 -> F | RS10: =QY10 -> G | RT10: =QZ10 -> H | RW10: =RC10 -> 1 | RX10: =RD10 -> 45291 | RY10: M | RZ10: T | SA10: W | SB10: T | SC10: F | SD10: S | SE10: S | SF10: T | SG10: =RM10 -> A | SH10: =RN10 -> B | SI10: =RO10 -> C | SJ10: =RP10 -> D | SK10: =RQ10 -> E | SL10: =RR10 -> F | SM10: =RS10 -> G | SN10: =RT10 -> H | SQ10: =RW10 -> 1 | SR10: =RX10 -> 45291 | SS10: M | ST10: T | SU10: W | SV10: T | SW10: F | SX10: S | SY10: S | SZ10: T | TA10: =SG10 -> A | TB10: =SH10 -> B | TC10: =SI10 -> C | TD10: =SJ10 -> D | TE10: =SK10 -> E | TF10: =SL10 -> F | TG10: =SM10 -> G | TH10: =SN10 -> H | TK10: =SQ10 -> 1 | TL10: =SR10 -> 45291 | TM10: M | TN10: T | TO10: W | TP10: T | TQ10: F | TR10: S | TS10: S | TT10: T | TU10: =TA10 -> A | TV10: =TB10 -> B | TW10: =TC10 -> C | TX10: =TD10 -> D | TY10: =TE10 -> E | TZ10: =TF10 -> F | UA10: =TG10 -> G | UB10: =TH10 -> H | UE10: =TK10 -> 1 | UF10: =TL10 -> 45291 | UG10: M | UH10: T | UI10: W | UJ10: T | UK10: F | UL10: S | UM10: S | UN10: T | UO10: =TU10 -> A | UP10: =TV10 -> B | UQ10: =TW10 -> C | UR10: =TX10 -> D | US10: =TY10 -> E | UT10: =TZ10 -> F | UU10: =UA10 -> G | UV10: =UB10 -> H | UY10: =UE10 -> 1 | UZ10: =UF10 -> 45291 | VA10: M | VB10: T | VC10: W | VD10: T | VE10: F | VF10: S | VG10: S | VH10: T | VI10: =UO10 -> A | VJ10: =UP10 -> B | VK10: =UQ10 -> C | VL10: =UR10 -> D | VM10: =US10 -> E | VN10: =UT10 -> F | VO10: =UU10 -> G | VP10: =UV10 -> H | VS10: =UY10 -> 1 | VT10: =UZ10 -> 45291 | VU10: M | VV10: T | VW10: W | VX10: T | VY10: F | VZ10: S | WA10: S | WB10: T | WC10: =VI10 -> A | WD10: =VJ10 -> B | WE10: =VK10 -> C | WF10: =VL10 -> D | WG10: =VM10 -> E | WH10: =VN10 -> F | WI10: =VO10 -> G | WJ10: =VP10 -> H | WM10: =VS10 -> 1 | WN10: =VT10 -> 45291 | WO10: M | WP10: T | WQ10: W | WR10: T | WS10: F | WT10: S | WU10: S | WV10: T | WW10: =WC10 -> A | WX10: =WD10 -> B | WY10: =WE10 -> C | WZ10: =WF10 -> D | XA10: =WG10 -> E | XB10: =WH10 -> F | XC10: =WI10 -> G | XD10: =WJ10 -> H | XG10: =WM10 -> 1 | XH10: =WN10 -> 45291 | XI10: M | XJ10: T | XK10: W | XL10: T | XM10: F | XN10: S | XO10: S | XP10: T | XQ10: =WW10 -> A | XR10: =WX10 -> B | XS10: =WY10 -> C | XT10: =WZ10 -> D | XU10: =XA10 -> E | XV10: =XB10 -> F | XW10: =XC10 -> G | XX10: =XD10 -> H | YA10: =XG10 -> 1 | YB10: =XH10 -> 45291 | YC10: M | YD10: T | YE10: W | YF10: T | YG10: F | YH10: S | YI10: S | YJ10: T | YK10: =XQ10 -> A | YL10: =XR10 -> B | YM10: =XS10 -> C | YN10: =XT10 -> D | YO10: =XU10 -> E | YP10: =XV10 -> F | YQ10: =XW10 -> G | YR10: =XX10 -> H
