Workbook
Name FromTable: OFFSET(Dummy!$M$6,0,0,Dummy!$M$5,1)
Name MonthList: Dummy!$D$6:$D$19
Name MonthMatch: Dummy!$J$6:$J$19
Name RefAttendance: Dummy!$K$6:$K$383
Name RefCustom: OFFSET(Dummy!$P$5,0,0,Dummy!$P$4,1)
Name ToTable: OFFSET(Dummy!$O$6,0,0,Dummy!$O$4,1)
Name WeekList: Dummy!$B$6:$B$59

Sheet Vacation Summary - Weekly
B2: RINGKASAN LIBURAN KARYAWAN - MINGGUAN
L4: 0 | M4: ='Vacation Tracker'!Q10 -> 44921 | P4: =L4+14 -> 14 | Q4: =M4+7 -> 44928 | T4: =P4+14 -> 28 | U4: =Q4+7 -> 44935 | X4: =T4+14 -> 42 | Y4: =U4+7 -> 44942 | AB4: =X4+14 -> 56 | AC4: =Y4+7 -> 44949 | AF4: =AB4+14 -> 70 | AG4: =AC4+7 -> 44956 | AJ4: =AF4+14 -> 84 | AK4: =AG4+7 -> 44963 | AN4: =AJ4+14 -> 98 | AO4: =AK4+7 -> 44970 | AR4: =AN4+14 -> 112 | AS4: =AO4+7 -> 44977 | AV4: =AR4+14 -> 126 | AW4: =AS4+7 -> 44984 | AZ4: =AV4+14 -> 140 | BA4: =AW4+7 -> 44991 | BD4: =AZ4+14 -> 154 | BE4: =BA4+7 -> 44998 | BH4: =BD4+14 -> 168 | BI4: =BE4+7 -> 45005 | BL4: =BH4+14 -> 182 | BM4: =BI4+7 -> 45012 | BP4: =BL4+14 -> 196 | BQ4: =BM4+7 -> 45019 | BT4: =BP4+14 -> 210 | BU4: =BQ4+7 -> 45026 | BX4: =BT4+14 -> 224 | BY4: =BU4+7 -> 45033 | CB4: =BX4+14 -> 238 | CC4: =BY4+7 -> 45040 | CF4: =CB4+14 -> 252 | CG4: =CC4+7 -> 45047 | CJ4: =CF4+14 -> 266 | CK4: =CG4+7 -> 45054 | CN4: =CJ4+14 -> 280 | CO4: =CK4+7 -> 45061 | CR4: =CN4+14 -> 294 | CS4: =CO4+7 -> 45068 | CV4: =CR4+14 -> 308 | CW4: =CS4+7 -> 45075 | CZ4: =CV4+14 -> 322 | DA4: =CW4+7 -> 45082 | DD4: =CZ4+14 -> 336 | DE4: =DA4+7 -> 45089 | DH4: =DD4+14 -> 350 | DI4: =DE4+7 -> 45096 | DL4: =DH4+14 -> 364 | DM4: =DI4+7 -> 45103 | DP4: =DL4+14 -> 378 | DQ4: =DM4+7 -> 45110 | DT4: =DP4+14 -> 392 | DU4: =DQ4+7 -> 45117 | DX4: =DT4+14 -> 406 | DY4: =DU4+7 -> 45124 | EB4: =DX4+14 -> 420 | EC4: =DY4+7 -> 45131 | EF4: =EB4+14 -> 434 | EG4: =EC4+7 -> 45138 | EJ4: =EF4+14 -> 448 | EK4: =EG4+7 -> 45145 | EN4: =EJ4+14 -> 462 | EO4: =EK4+7 -> 45152 | ER4: =EN4+14 -> 476 | ES4: =EO4+7 -> 45159 | EV4: =ER4+14 -> 490 | EW4: =ES4+7 -> 45166 | EZ4: =EV4+14 -> 504 | FA4: =EW4+7 -> 45173 | FD4: =EZ4+14 -> 518 | FE4: =FA4+7 -> 45180 | FH4: =FD4+14 -> 532 | FI4: =FE4+7 -> 45187 | FL4: =FH4+14 -> 546 | FM4: =FI4+7 -> 45194 | FP4: =FL4+14 -> 560 | FQ4: =FM4+7 -> 45201 | FT4: =FP4+14 -> 574 | FU4: =FQ4+7 -> 45208 | FX4: =FT4+14 -> 588 | FY4: =FU4+7 -> 45215 | GB4: =FX4+14 -> 602 | GC4: =FY4+7 -> 45222 | GF4: =GB4+14 -> 616 | GG4: =GC4+7 -> 45229 | GJ4: =GF4+14 -> 630 | GK4: =GG4+7 -> 45236 | GN4: =GJ4+14 -> 644 | GO4: =GK4+7 -> 45243 | GR4: =GN4+14 -> 658 | GS4: =GO4+7 -> 45250 | GV4: =GR4+14 -> 672 | GW4: =GS4+7 -> 45257 | GZ4: =GV4+14 -> 686 | HA4: =GW4+7 -> 45264 | HD4: =GZ4+14 -> 700 | HE4: =HA4+7 -> 45271 | HH4: =HD4+14 -> 714 | HI4: =HE4+7 -> 45278 | HL4: =HH4+14 -> 728 | HM4: =HI4+7 -> 45285 | HP4: =HL4+14 -> 742 | HQ4: =HM4+7 -> 45292
H5: Total | L5: Minggu 1 | P5: Minggu 2 | T5: Minggu 3 | X5: Minggu 4 | AB5: Minggu 5 | AF5: Minggu 6 | AJ5: Minggu 7 | AN5: Minggu 8 | AR5: Minggu 9 | AV5: Minggu 10 | AZ5: Minggu 11 | BD5: Minggu 12 | BH5: Minggu 13 | BL5: Minggu 14 | BP5: Minggu 15 | BT5: Minggu 16 | BX5: Minggu 17 | CB5: Minggu 18 | CF5: Minggu 19 | CJ5: Minggu 20 | CN5: Minggu 21 | CR5: Minggu 22 | CV5: Minggu 23 | CZ5: Minggu 24 | DD5: Minggu 25 | DH5: Minggu 26 | DL5: Minggu 27 | DP5: Minggu 28 | DT5: Minggu 29 | DX5: Minggu 30 | EB5: Minggu 31 | EF5: Minggu 32 | EJ5: Minggu 33 | EN5: Minggu 34 | ER5: Minggu 35 | EV5: Minggu 36 | EZ5: Minggu 37 | FD5: Minggu 38 | FH5: Minggu 39 | FL5: Minggu 40 | FP5: Minggu 41 | FT5: Minggu 42 | FX5: Minggu 43 | GB5: Minggu 44 | GF5: Minggu 45 | GJ5: Minggu 46 | GN5: Minggu 47 | GR5: Minggu 48 | GV5: Minggu 49 | GZ5: Minggu 50 | HD5: Minggu 51 | HH5: Minggu 52 | HL5: Minggu 53 | HP5: Minggu 54
H6: Jam Kerja | I6: Hadir | J6: Absen | K6: Lembur | L6: =TEXT(M4,"mm/dd/yy") -> 12/26/22 | P6: =TEXT(Q4,"mm/dd/yy") -> 01/02/23 | T6: =TEXT(U4,"mm/dd/yy") -> 01/09/23 | X6: =TEXT(Y4,"mm/dd/yy") -> 01/16/23 | AB6: =TEXT(AC4,"mm/dd/yy") -> 01/23/23 | AF6: =TEXT(AG4,"mm/dd/yy") -> 01/30/23 | AJ6: =TEXT(AK4,"mm/dd/yy") -> 02/06/23 | AN6: =TEXT(AO4,"mm/dd/yy") -> 02/13/23 | AR6: =TEXT(AS4,"mm/dd/yy") -> 02/20/23 | AV6: =TEXT(AW4,"mm/dd/yy") -> 02/27/23 | AZ6: =TEXT(BA4,"mm/dd/yy") -> 03/06/23 | BD6: =TEXT(BE4,"mm/dd/yy") -> 03/13/23 | BH6: =TEXT(BI4,"mm/dd/yy") -> 03/20/23 | BL6: =TEXT(BM4,"mm/dd/yy") -> 03/27/23 | BP6: =TEXT(BQ4,"mm/dd/yy") -> 04/03/23 | BT6: =TEXT(BU4,"mm/dd/yy") -> 04/10/23 | BX6: =TEXT(BY4,"mm/dd/yy") -> 04/17/23 | CB6: =TEXT(CC4,"mm/dd/yy") -> 04/24/23 | CF6: =TEXT(CG4,"mm/dd/yy") -> 05/01/23 | CJ6: =TEXT(CK4,"mm/dd/yy") -> 05/08/23 | CN6: =TEXT(CO4,"mm/dd/yy") -> 05/15/23 | CR6: =TEXT(CS4,"mm/dd/yy") -> 05/22/23 | CV6: =TEXT(CW4,"mm/dd/yy") -> 05/29/23 | CZ6: =TEXT(DA4,"mm/dd/yy") -> 06/05/23 | DD6: =TEXT(DE4,"mm/dd/yy") -> 06/12/23 | DH6: =TEXT(DI4,"mm/dd/yy") -> 06/19/23 | DL6: =TEXT(DM4,"mm/dd/yy") -> 06/26/23 | DP6: =TEXT(DQ4,"mm/dd/yy") -> 07/03/23 | DT6: =TEXT(DU4,"mm/dd/yy") -> 07/10/23 | DX6: =TEXT(DY4,"mm/dd/yy") -> 07/17/23 | EB6: =TEXT(EC4,"mm/dd/yy") -> 07/24/23 | EF6: =TEXT(EG4,"mm/dd/yy") -> 07/31/23 | EJ6: =TEXT(EK4,"mm/dd/yy") -> 08/07/23 | EN6: =TEXT(EO4,"mm/dd/yy") -> 08/14/23 | ER6: =TEXT(ES4,"mm/dd/yy") -> 08/21/23 | EV6: =TEXT(EW4,"mm/dd/yy") -> 08/28/23 | EZ6: =TEXT(FA4,"mm/dd/yy") -> 09/04/23 | FD6: =TEXT(FE4,"mm/dd/yy") -> 09/11/23 | FH6: =TEXT(FI4,"mm/dd/yy") -> 09/18/23 | FL6: =TEXT(FM4,"mm/dd/yy") -> 09/25/23 | FP6: =TEXT(FQ4,"mm/dd/yy") -> 10/02/23 | FT6: =TEXT(FU4,"mm/dd/yy") -> 10/09/23 | FX6: =TEXT(FY4,"mm/dd/yy") -> 10/16/23 | GB6: =TEXT(GC4,"mm/dd/yy") -> 10/23/23 | GF6: =TEXT(GG4,"mm/dd/yy") -> 10/30/23 | GJ6: =TEXT(GK4,"mm/dd/yy") -> 11/06/23 | GN6: =TEXT(GO4,"mm/dd/yy") -> 11/13/23 | GR6: =TEXT(GS4,"mm/dd/yy") -> 11/20/23 | GV6: =TEXT(GW4,"mm/dd/yy") -> 11/27/23 | GZ6: =TEXT(HA4,"mm/dd/yy") -> 12/04/23 | HD6: =TEXT(HE4,"mm/dd/yy") -> 12/11/23 | HH6: =TEXT(HI4,"mm/dd/yy") -> 12/18/23 | HL6: =TEXT(HM4,"mm/dd/yy") -> 12/25/23 | HP6: =TEXT(HQ4,"mm/dd/yy") -> 01/01/24
B7: No | C7: Nama Karyawan | D7: Tanggal Dipekerjakan | E7: Tanggal Pengunduran Diri | F7: Departemen | G7: Status | L7: =TEXT(M4+6,"mm/dd/yy") -> 01/01/23 | P7: =TEXT(Q4+6,"mm/dd/yy") -> 01/08/23 | T7: =TEXT(U4+6,"mm/dd/yy") -> 01/15/23 | X7: =TEXT(Y4+6,"mm/dd/yy") -> 01/22/23 | AB7: =TEXT(AC4+6,"mm/dd/yy") -> 01/29/23 | AF7: =TEXT(AG4+6,"mm/dd/yy") -> 02/05/23 | AJ7: =TEXT(AK4+6,"mm/dd/yy") -> 02/12/23 | AN7: =TEXT(AO4+6,"mm/dd/yy") -> 02/19/23 | AR7: =TEXT(AS4+6,"mm/dd/yy") -> 02/26/23 | AV7: =TEXT(AW4+6,"mm/dd/yy") -> 03/05/23 | AZ7: =TEXT(BA4+6,"mm/dd/yy") -> 03/12/23 | BD7: =TEXT(BE4+6,"mm/dd/yy") -> 03/19/23 | BH7: =TEXT(BI4+6,"mm/dd/yy") -> 03/26/23 | BL7: =TEXT(BM4+6,"mm/dd/yy") -> 04/02/23 | BP7: =TEXT(BQ4+6,"mm/dd/yy") -> 04/09/23 | BT7: =TEXT(BU4+6,"mm/dd/yy") -> 04/16/23 | BX7: =TEXT(BY4+6,"mm/dd/yy") -> 04/23/23 | CB7: =TEXT(CC4+6,"mm/dd/yy") -> 04/30/23 | CF7: =TEXT(CG4+6,"mm/dd/yy") -> 05/07/23 | CJ7: =TEXT(CK4+6,"mm/dd/yy") -> 05/14/23 | CN7: =TEXT(CO4+6,"mm/dd/yy") -> 05/21/23 | CR7: =TEXT(CS4+6,"mm/dd/yy") -> 05/28/23 | CV7: =TEXT(CW4+6,"mm/dd/yy") -> 06/04/23 | CZ7: =TEXT(DA4+6,"mm/dd/yy") -> 06/11/23 | DD7: =TEXT(DE4+6,"mm/dd/yy") -> 06/18/23 | DH7: =TEXT(DI4+6,"mm/dd/yy") -> 06/25/23 | DL7: =TEXT(DM4+6,"mm/dd/yy") -> 07/02/23 | DP7: =TEXT(DQ4+6,"mm/dd/yy") -> 07/09/23 | DT7: =TEXT(DU4+6,"mm/dd/yy") -> 07/16/23 | DX7: =TEXT(DY4+6,"mm/dd/yy") -> 07/23/23 | EB7: =TEXT(EC4+6,"mm/dd/yy") -> 07/30/23 | EF7: =TEXT(EG4+6,"mm/dd/yy") -> 08/06/23 | EJ7: =TEXT(EK4+6,"mm/dd/yy") -> 08/13/23 | EN7: =TEXT(EO4+6,"mm/dd/yy") -> 08/20/23 | ER7: =TEXT(ES4+6,"mm/dd/yy") -> 08/27/23 | EV7: =TEXT(EW4+6,"mm/dd/yy") -> 09/03/23 | EZ7: =TEXT(FA4+6,"mm/dd/yy") -> 09/10/23 | FD7: =TEXT(FE4+6,"mm/dd/yy") -> 09/17/23 | FH7: =TEXT(FI4+6,"mm/dd/yy") -> 09/24/23 | FL7: =TEXT(FM4+6,"mm/dd/yy") -> 10/01/23 | FP7: =TEXT(FQ4+6,"mm/dd/yy") -> 10/08/23 | FT7: =TEXT(FU4+6,"mm/dd/yy") -> 10/15/23 | FX7: =TEXT(FY4+6,"mm/dd/yy") -> 10/22/23 | GB7: =TEXT(GC4+6,"mm/dd/yy") -> 10/29/23 | GF7: =TEXT(GG4+6,"mm/dd/yy") -> 11/05/23 | GJ7: =TEXT(GK4+6,"mm/dd/yy") -> 11/12/23 | GN7: =TEXT(GO4+6,"mm/dd/yy") -> 11/19/23 | GR7: =TEXT(GS4+6,"mm/dd/yy") -> 11/26/23 | GV7: =TEXT(GW4+6,"mm/dd/yy") -> 12/03/23 | GZ7: =TEXT(HA4+6,"mm/dd/yy") -> 12/10/23 | HD7: =TEXT(HE4+6,"mm/dd/yy") -> 12/17/23 | HH7: =TEXT(HI4+6,"mm/dd/yy") -> 12/24/23 | HL7: =TEXT(HM4+6,"mm/dd/yy") -> 12/31/23 | HP7: =TEXT(HQ4+6,"mm/dd/yy") -> 01/07/24
H8: JK | I8: H | J8: A | K8: L | L8: JK | M8: H | N8: A | O8: L | P8: JK | Q8: H | R8: A | S8: L | T8: JK | U8: H | V8: A | W8: L | X8: JK | Y8: H | Z8: A | AA8: L | AB8: JK | AC8: H | AD8: A | AE8: L | AF8: JK | AG8: H | AH8: A | AI8: L | AJ8: JK | AK8: H | AL8: A | AM8: L | AN8: JK | AO8: H | AP8: A | AQ8: L | AR8: JK | AS8: H | AT8: A | AU8: L | AV8: JK | AW8: H | AX8: A | AY8: L | AZ8: JK | BA8: H | BB8: A | BC8: L | BD8: JK | BE8: H | BF8: A | BG8: L | BH8: JK | BI8: H | BJ8: A | BK8: L | BL8: JK | BM8: H | BN8: A | BO8: L | BP8: JK | BQ8: H | BR8: A | BS8: L | BT8: JK | BU8: H | BV8: A | BW8: L | BX8: JK | BY8: H | BZ8: A | CA8: L | CB8: JK | CC8: H | CD8: A | CE8: L | CF8: JK | CG8: H | CH8: A | CI8: L | CJ8: JK | CK8: H | CL8: A | CM8: L | CN8: JK | CO8: H | CP8: A | CQ8: L | CR8: JK | CS8: H | CT8: A | CU8: L | CV8: JK | CW8: H | CX8: A | CY8: L | CZ8: JK | DA8: H | DB8: A | DC8: L | DD8: JK | DE8: H | DF8: A | DG8: L | DH8: JK | DI8: H | DJ8: A | DK8: L | DL8: JK | DM8: H | DN8: A | DO8: L | DP8: JK | DQ8: H | DR8: A | DS8: L | DT8: JK | DU8: H | DV8: A | DW8: L | DX8: JK | DY8: H | DZ8: A | EA8: L | EB8: JK | EC8: H | ED8: A | EE8: L | EF8: JK | EG8: H | EH8: A | EI8: L | EJ8: JK | EK8: H | EL8: A | EM8: L | EN8: JK | EO8: H | EP8: A | EQ8: L | ER8: JK | ES8: H | ET8: A | EU8: L | EV8: JK | EW8: H | EX8: A | EY8: L | EZ8: JK | FA8: H | FB8: A | FC8: L | FD8: JK | FE8: H | FF8: A | FG8: L | FH8: JK | FI8: H | FJ8: A | FK8: L | FL8: JK | FM8: H | FN8: A | FO8: L | FP8: JK | FQ8: H | FR8: A | FS8: L | FT8: JK | FU8: H | FV8: A | FW8: L | FX8: JK | FY8: H | FZ8: A | GA8: L | GB8: JK | GC8: H | GD8: A | GE8: L | GF8: JK | GG8: H | GH8: A | GI8: L | GJ8: JK | GK8: H | GL8: A | GM8: L | GN8: JK | GO8: H | GP8: A | GQ8: L | GR8: JK | GS8: H | GT8: A | GU8: L | GV8: JK | GW8: H | GX8: A | GY8: L | GZ8: JK | HA8: H | HB8: A | HC8: L | HD8: JK | HE8: H | HF8: A | HG8: L | HH8: JK | HI8: H | HJ8: A | HK8: L | HL8: JK | HM8: H | HN8: A | HO8: L | HP8: JK | HQ8: H | HR8: A | HS8: L
B9: =IF('Vacation Tracker'!B12<>"",'Vacation Tracker'!B12,"") -> 1 | C9: =IF('Vacation Tracker'!C12<>"",'Vacation Tracker'!C12,"") -> John Doe 1 | D9: =IF('Vacation Tracker'!D12<>"",'Vacation Tracker'!D12,"") -> 44927 | E9: =IF('Vacation Tracker'!E12<>"",'Vacation Tracker'!E12,"") | F9: =IF('Vacation Tracker'!F12<>"",'Vacation Tracker'!F12,"") -> Marketing | G9: =IF('Vacation Tracker'!G12<>"",'Vacation Tracker'!G12,"") -> Permanent | H9: =IF($C9<>"",SUMPRODUCT(($L$8:$FU$8=H$8)*$L9:$FU9),"") -> 16 | I9: =IF($C9<>"",SUMPRODUCT(($L$8:$FU$8=I$8)*$L9:$FU9),"") -> 10 | J9: =IF($C9<>"",SUMPRODUCT(($L$8:$FU$8=J$8)*$L9:$FU9),"") -> 6 | K9: =IF($C9<>"",SUMPRODUCT(($L$8:$FU$8=K$8)*$L9:$FU9),"") -> 0 | L9: =SUM(OFFSET('Vacation Tracker'!$Q12:$AD12,0,L$4)) -> 8 | M9: =L9-N9 -> 8 | N9: {=SUM(IF(RIGHT(OFFSET('Vacation Tracker'!$Q12:$AD12,0,L$4))<>"O",IFERROR(--LEFT(OFFSET('Vacation Tracker'!$Q12:$AD12,0,L$4),LEN(OFFSET('Vacation Tracker'!$Q12:$AD12,0,L$4))-1),0)))} -> 0 | O9: {=SUM(IF(RIGHT(OFFSET('Vacation Tracker'!$Q12:$AD12,0,L$4))=O$8,IFERROR(--LEFT(OFFSET('Vacation Tracker'!$Q12:$AD12,0,L$4),LEN(OFFSET('Vacation Tracker'!$Q12:$AD12,0,L$4))-1),0)))} -> 0 | P9: =SUM(OFFSET('Vacation Tracker'!$Q12:$AD12,0,P$4)) -> 8 | Q9: =P9-R9 -> 8 | R9: {=SUM(IF(RIGHT(OFFSET('Vacation Tracker'!$Q12:$AD12,0,P$4))<>"O",IFERROR(--LEFT(OFFSET('Vacation Tracker'!$Q12:$AD12,0,P$4),LEN(OFFSET('Vacation Tracker'!$Q12:$AD12,0,P$4))-1),0)))} -> 0 | S9: {=SUM(IF(RIGHT(OFFSET('Vacation Tracker'!$Q12:$AD12,0,P$4))=S$8,IFERROR(--LEFT(OFFSET('Vacation Tracker'!$Q12:$AD12,0,P$4),LEN(OFFSET('Vacation Tracker'!$Q12:$AD12,0,P$4))-1),0)))} -> 0 | T9: =SUM(OFFSET('Vacation Tracker'!$Q12:$AD12,0,T$4)) -> 0 | U9: =T9-V9 -> 0 | V9: {=SUM(IF(RIGHT(OFFSET('Vacation Tracker'!$Q12:$AD12,0,T$4))<>"O",IFERROR(--LEFT(OFFSET('Vacation Tracker'!$Q12:$AD12,0,T$4),LEN(OFFSET('Vacation Tracker'!$Q12:$AD12,0,T$4))-1),0)))} -> 0 | W9: {=SUM(IF(RIGHT(OFFSET('Vacation Tracker'!$Q12:$AD12,0,T$4))=W$8,IFERROR(--LEFT(OFFSET('Vacation Tracker'!$Q12:$AD12,0,T$4),LEN(OFFSET('Vacation Tracker'!$Q12:$AD12,0,T$4))-1),0)))} -> 0 | X9: =SUM(OFFSET('Vacation Tracker'!$Q12:$AD12,0,X$4)) -> 0 | Y9: =X9-Z9 -> -6 | Z9: {=SUM(IF(RIGHT(OFFSET('Vacation Tracker'!$Q12:$AD12,0,X$4))<>"O",IFERROR(--LEFT(OFFSET('Vacation Tracker'!$Q12:$AD12,0,X$4),LEN(OFFSET('Vacation Tracker'!$Q12:$AD12,0,X$4))-1),0)))} -> 6 | AA9: {=SUM(IF(RIGHT(OFFSET('Vacation Tracker'!$Q12:$AD12,0,X$4))=AA$8,IFERROR(--LEFT(OFFSET('Vacation Tracker'!$Q12:$AD12,0,X$4),LEN(OFFSET('Vacation Tracker'!$Q12:$AD12,0,X$4))-1),0)))} -> 0 | AB9: =SUM(OFFSET('Vacation Tracker'!$Q12:$AD12,0,AB$4)) -> 0 | AC9: =AB9-AD9 -> 0 | AD9: {=SUM(IF(RIGHT(OFFSET('Vacation Tracker'!$Q12:$AD12,0,AB$4))<>"O",IFERROR(--LEFT(OFFSET('Vacation Tracker'!$Q12:$AD12,0,AB$4),LEN(OFFSET('Vacation Tracker'!$Q12:$AD12,0,AB$4))-1),0)))} -> 0 | AE9: {=SUM(IF(RIGHT(OFFSET('Vacation Tracker'!$Q12:$AD12,0,AB$4))=AE$8,IFERROR(--LEFT(OFFSET('Vacation Tracker'!$Q12:$AD12,0,AB$4),LEN(OFFSET('Vacation Tracker'!$Q12:$AD12,0,AB$4))-1),0)))} -> 0 | AF9: =SUM(OFFSET('Vacation Tracker'!$Q12:$AD12,0,AF$4)) -> 0 | AG9: =AF9-AH9 -> 0 | AH9: {=SUM(IF(RIGHT(OFFSET('Vacation Tracker'!$Q12:$AD12,0,AF$4))<>"O",IFERROR(--LEFT(OFFSET('Vacation Tracker'!$Q12:$AD12,0,AF$4),LEN(OFFSET('Vacation Tracker'!$Q12:$AD12,0,AF$4))-1),0)))} -> 0 | AI9: {=SUM(IF(RIGHT(OFFSET('Vacation Tracker'!$Q12:$AD12,0,AF$4))=AI$8,IFERROR(--LEFT(OFFSET('Vacation Tracker'!$Q12:$AD12,0,AF$4),LEN(OFFSET('Vacation Tracker'!$Q12:$AD12,0,AF$4))-1),0)))} -> 0 | AJ9: =SUM(OFFSET('Vacation Tracker'!$Q12:$AD12,0,AJ$4)) -> 0 | AK9: =AJ9-AL9 -> 0 | AL9: {=SUM(IF(RIGHT(OFFSET('Vacation Tracker'!$Q12:$AD12,0,AJ$4))<>"O",IFERROR(--LEFT(OFFSET('Vacation Tracker'!$Q12:$AD12,0,AJ$4),LEN(OFFSET('Vacation Tracker'!$Q12:$AD12,0,AJ$4))-1),0)))} -> 0 | AM9: {=SUM(IF(RIGHT(OFFSET('Vacation Tracker'!$Q12:$AD12,0,AJ$4))=AM$8,IFERROR(--LEFT(OFFSET('Vacation Tracker'!$Q12:$AD12,0,AJ$4),LEN(OFFSET('Vacation Tracker'!$Q12:$AD12,0,AJ$4))-1),0)))} -> 0 | AN9: =SUM(OFFSET('Vacation Tracker'!$Q12:$AD12,0,AN$4)) -> 0 | AO9: =AN9-AP9 -> 0 | AP9: {=SUM(IF(RIGHT(OFFSET('Vacation Tracker'!$Q12:$AD12,0,AN$4))<>"O",IFERROR(--LEFT(OFFSET('Vacation Tracker'!$Q12:$AD12,0,AN$4),LEN(OFFSET('Vacation Tracker'!$Q12:$AD12,0,AN$4))-1),0)))} -> 0 | AQ9: {=SUM(IF(RIGHT(OFFSET('Vacation Tracker'!$Q12:$AD12,0,AN$4))=AQ$8,IFERROR(--LEFT(OFFSET('Vacation Tracker'!$Q12:$AD12,0,AN$4),LEN(OFFSET('Vacation Tracker'!$Q12:$AD12,0,AN$4))-1),0)))} -> 0 | AR9: =SUM(OFFSET('Vacation Tracker'!$Q12:$AD12,0,AR$4)) -> 0 | AS9: =AR9-AT9 -> 0 | AT9: {=SUM(IF(RIGHT(OFFSET('Vacation Tracker'!$Q12:$AD12,0,AR$4))<>"O",IFERROR(--LEFT(OFFSET('Vacation Tracker'!$Q12:$AD12,0,AR$4),LEN(OFFSET('Vacation Tracker'!$Q12:$AD12,0,AR$4))-1),0)))} -> 0 | AU9: {=SUM(IF(RIGHT(OFFSET('Vacation Tracker'!$Q12:$AD12,0,AR$4))=AU$8,IFERROR(--LEFT(OFFSET('Vacation Tracker'!$Q12:$AD12,0,AR$4),LEN(OFFSET('Vacation Tracker'!$Q12:$AD12,0,AR$4))-1),0)))} -> 0 | AV9: =SUM(OFFSET('Vacation Tracker'!$Q12:$AD12,0,AV$4)) -> 0 | AW9: =AV9-AX9 -> 0 | AX9: {=SUM(IF(RIGHT(OFFSET('Vacation Tracker'!$Q12:$AD12,0,AV$4))<>"O",IFERROR(--LEFT(OFFSET('Vacation Tracker'!$Q12:$AD12,0,AV$4),LEN(OFFSET('Vacation Tracker'!$Q12:$AD12,0,AV$4))-1),0)))} -> 0 | AY9: {=SUM(IF(RIGHT(OFFSET('Vacation Tracker'!$Q12:$AD12,0,AV$4))=AY$8,IFERROR(--LEFT(OFFSET('Vacation Tracker'!$Q12:$AD12,0,AV$4),LEN(OFFSET('Vacation Tracker'!$Q12:$AD12,0,AV$4))-1),0)))} -> 0 | AZ9: =SUM(OFFSET('Vacation Tracker'!$Q12:$AD12,0,AZ$4)) -> 0 | BA9: =AZ9-BB9 -> 0 | BB9: {=SUM(IF(RIGHT(OFFSET('Vacation Tracker'!$Q12:$AD12,0,AZ$4))<>"O",IFERROR(--LEFT(OFFSET('Vacation Tracker'!$Q12:$AD12,0,AZ$4),LEN(OFFSET('Vacation Tracker'!$Q12:$AD12,0,AZ$4))-1),0)))} -> 0 | BC9: {=SUM(IF(RIGHT(OFFSET('Vacation Tracker'!$Q12:$AD12,0,AZ$4))=BC$8,IFERROR(--LEFT(OFFSET('Vacation Tracker'!$Q12:$AD12,0,AZ$4),LEN(OFFSET('Vacation Tracker'!$Q12:$AD12,0,AZ$4))-1),0)))} -> 0 | BD9: =SUM(OFFSET('Vacation Tracker'!$Q12:$AD12,0,BD$4)) -> 0 | BE9: =BD9-BF9 -> 0 | BF9: {=SUM(IF(RIGHT(OFFSET('Vacation Tracker'!$Q12:$AD12,0,BD$4))<>"O",IFERROR(--LEFT(OFFSET('Vacation Tracker'!$Q12:$AD12,0,BD$4),LEN(OFFSET('Vacation Tracker'!$Q12:$AD12,0,BD$4))-1),0)))} -> 0 | BG9: {=SUM(IF(RIGHT(OFFSET('Vacation Tracker'!$Q12:$AD12,0,BD$4))=BG$8,IFERROR(--LEFT(OFFSET('Vacation Tracker'!$Q12:$AD12,0,BD$4),LEN(OFFSET('Vacation Tracker'!$Q12:$AD12,0,BD$4))-1),0)))} -> 0 | BH9: =SUM(OFFSET('Vacation Tracker'!$Q12:$AD12,0,BH$4)) -> 0 | BI9: =BH9-BJ9 -> 0 | BJ9: {=SUM(IF(RIGHT(OFFSET('Vacation Tracker'!$Q12:$AD12,0,BH$4))<>"O",IFERROR(--LEFT(OFFSET('Vacation Tracker'!$Q12:$AD12,0,BH$4),LEN(OFFSET('Vacation Tracker'!$Q12:$AD12,0,BH$4))-1),0)))} -> 0 | BK9: {=SUM(IF(RIGHT(OFFSET('Vacation Tracker'!$Q12:$AD12,0,BH$4))=BK$8,IFERROR(--LEFT(OFFSET('Vacation Tracker'!$Q12:$AD12,0,BH$4),LEN(OFFSET('Vacation Tracker'!$Q12:$AD12,0,BH$4))-1),0)))} -> 0 | BL9: =SUM(OFFSET('Vacation Tracker'!$Q12:$AD12,0,BL$4)) -> 0 | BM9: =BL9-BN9 -> 0 | BN9: {=SUM(IF(RIGHT(OFFSET('Vacation Tracker'!$Q12:$AD12,0,BL$4))<>"O",IFERROR(--LEFT(OFFSET('Vacation Tracker'!$Q12:$AD12,0,BL$4),LEN(OFFSET('Vacation Tracker'!$Q12:$AD12,0,BL$4))-1),0)))} -> 0 | BO9: {=SUM(IF(RIGHT(OFFSET('Vacation Tracker'!$Q12:$AD12,0,BL$4))=BO$8,IFERROR(--LEFT(OFFSET('Vacation Tracker'!$Q12:$AD12,0,BL$4),LEN(OFFSET('Vacation Tracker'!$Q12:$AD12,0,BL$4))-1),0)))} -> 0 | BP9: =SUM(OFFSET('Vacation Tracker'!$Q12:$AD12,0,BP$4)) -> 0 | BQ9: =BP9-BR9 -> 0 | BR9: {=SUM(IF(RIGHT(OFFSET('Vacation Tracker'!$Q12:$AD12,0,BP$4))<>"O",IFERROR(--LEFT(OFFSET('Vacation Tracker'!$Q12:$AD12,0,BP$4),LEN(OFFSET('Vacation Tracker'!$Q12:$AD12,0,BP$4))-1),0)))} -> 0 | BS9: {=SUM(IF(RIGHT(OFFSET('Vacation Tracker'!$Q12:$AD12,0,BP$4))=BS$8,IFERROR(--LEFT(OFFSET('Vacation Tracker'!$Q12:$AD12,0,BP$4),LEN(OFFSET('Vacation Tracker'!$Q12:$AD12,0,BP$4))-1),0)))} -> 0 | BT9: =SUM(OFFSET('Vacation Tracker'!$Q12:$AD12,0,BT$4)) -> 0 | BU9: =BT9-BV9 -> 0 | BV9: {=SUM(IF(RIGHT(OFFSET('Vacation Tracker'!$Q12:$AD12,0,BT$4))<>"O",IFERROR(--LEFT(OFFSET('Vacation Tracker'!$Q12:$AD12,0,BT$4),LEN(OFFSET('Vacation Tracker'!$Q12:$AD12,0,BT$4))-1),0)))} -> 0 | BW9: {=SUM(IF(RIGHT(OFFSET('Vacation Tracker'!$Q12:$AD12,0,BT$4))=BW$8,IFERROR(--LEFT(OFFSET('Vacation Tracker'!$Q12:$AD12,0,BT$4),LEN(OFFSET('Vacation Tracker'!$Q12:$AD12,0,BT$4))-1),0)))} -> 0 | BX9: =SUM(OFFSET('Vacation Tracker'!$Q12:$AD12,0,BX$4)) -> 0 | BY9: =BX9-BZ9 -> 0 | BZ9: {=SUM(IF(RIGHT(OFFSET('Vacation Tracker'!$Q12:$AD12,0,BX$4))<>"O",IFERROR(--LEFT(OFFSET('Vacation Tracker'!$Q12:$AD12,0,BX$4),LEN(OFFSET('Vacation Tracker'!$Q12:$AD12,0,BX$4))-1),0)))} -> 0 | CA9: {=SUM(IF(RIGHT(OFFSET('Vacation Tracker'!$Q12:$AD12,0,BX$4))=CA$8,IFERROR(--LEFT(OFFSET('Vacation Tracker'!$Q12:$AD12,0,BX$4),LEN(OFFSET('Vacation Tracker'!$Q12:$AD12,0,BX$4))-1),0)))} -> 0 | CB9: =SUM(OFFSET('Vacation Tracker'!$Q12:$AD12,0,CB$4)) -> 0 | CC9: =CB9-CD9 -> 0 | CD9: {=SUM(IF(RIGHT(OFFSET('Vacation Tracker'!$Q12:$AD12,0,CB$4))<>"O",IFERROR(--LEFT(OFFSET('Vacation Tracker'!$Q12:$AD12,0,CB$4),LEN(OFFSET('Vacation Tracker'!$Q12:$AD12,0,CB$4))-1),0)))} -> 0 | CE9: {=SUM(IF(RIGHT(OFFSET('Vacation Tracker'!$Q12:$AD12,0,CB$4))=CE$8,IFERROR(--LEFT(OFFSET('Vacation Tracker'!$Q12:$AD12,0,CB$4),LEN(OFFSET('Vacation Tracker'!$Q12:$AD12,0,CB$4))-1),0)))} -> 0 | CF9: =SUM(OFFSET('Vacation Tracker'!$Q12:$AD12,0,CF$4)) -> 0 | CG9: =CF9-CH9 -> 0 | CH9: {=SUM(IF(RIGHT(OFFSET('Vacation Tracker'!$Q12:$AD12,0,CF$4))<>"O",IFERROR(--LEFT(OFFSET('Vacation Tracker'!$Q12:$AD12,0,CF$4),LEN(OFFSET('Vacation Tracker'!$Q12:$AD12,0,CF$4))-1),0)))} -> 0 | CI9: {=SUM(IF(RIGHT(OFFSET('Vacation Tracker'!$Q12:$AD12,0,CF$4))=CI$8,IFERROR(--LEFT(OFFSET('Vacation Tracker'!$Q12:$AD12,0,CF$4),LEN(OFFSET('Vacation Tracker'!$Q12:$AD12,0,CF$4))-1),0)))} -> 0 | CJ9: =SUM(OFFSET('Vacation Tracker'!$Q12:$AD12,0,CJ$4)) -> 0 | CK9: =CJ9-CL9 -> 0 | CL9: {=SUM(IF(RIGHT(OFFSET('Vacation Tracker'!$Q12:$AD12,0,CJ$4))<>"O",IFERROR(--LEFT(OFFSET('Vacation Tracker'!$Q12:$AD12,0,CJ$4),LEN(OFFSET('Vacation Tracker'!$Q12:$AD12,0,CJ$4))-1),0)))} -> 0 | CM9: {=SUM(IF(RIGHT(OFFSET('Vacation Tracker'!$Q12:$AD12,0,CJ$4))=CM$8,IFERROR(--LEFT(OFFSET('Vacation Tracker'!$Q12:$AD12,0,CJ$4),LEN(OFFSET('Vacation Tracker'!$Q12:$AD12,0,CJ$4))-1),0)))} -> 0 | CN9: =SUM(OFFSET('Vacation Tracker'!$Q12:$AD12,0,CN$4)) -> 0 | CO9: =CN9-CP9 -> 0 | CP9: {=SUM(IF(RIGHT(OFFSET('Vacation Tracker'!$Q12:$AD12,0,CN$4))<>"O",IFERROR(--LEFT(OFFSET('Vacation Tracker'!$Q12:$AD12,0,CN$4),LEN(OFFSET('Vacation Tracker'!$Q12:$AD12,0,CN$4))-1),0)))} -> 0 | CQ9: {=SUM(IF(RIGHT(OFFSET('Vacation Tracker'!$Q12:$AD12,0,CN$4))=CQ$8,IFERROR(--LEFT(OFFSET('Vacation Tracker'!$Q12:$AD12,0,CN$4),LEN(OFFSET('Vacation Tracker'!$Q12:$AD12,0,CN$4))-1),0)))} -> 0 | CR9: =SUM(OFFSET('Vacation Tracker'!$Q12:$AD12,0,CR$4)) -> 0 | CS9: =CR9-CT9 -> 0 | CT9: {=SUM(IF(RIGHT(OFFSET('Vacation Tracker'!$Q12:$AD12,0,CR$4))<>"O",IFERROR(--LEFT(OFFSET('Vacation Tracker'!$Q12:$AD12,0,CR$4),LEN(OFFSET('Vacation Tracker'!$Q12:$AD12,0,CR$4))-1),0)))} -> 0 | CU9: {=SUM(IF(RIGHT(OFFSET('Vacation Tracker'!$Q12:$AD12,0,CR$4))=CU$8,IFERROR(--LEFT(OFFSET('Vacation Tracker'!$Q12:$AD12,0,CR$4),LEN(OFFSET('Vacation Tracker'!$Q12:$AD12,0,CR$4))-1),0)))} -> 0 | CV9: =SUM(OFFSET('Vacation Tracker'!$Q12:$AD12,0,CV$4)) -> 0 | CW9: =CV9-CX9 -> 0 | CX9: {=SUM(IF(RIGHT(OFFSET('Vacation Tracker'!$Q12:$AD12,0,CV$4))<>"O",IFERROR(--LEFT(OFFSET('Vacation Tracker'!$Q12:$AD12,0,CV$4),LEN(OFFSET('Vacation Tracker'!$Q12:$AD12,0,CV$4))-1),0)))} -> 0 | CY9: {=SUM(IF(RIGHT(OFFSET('Vacation Tracker'!$Q12:$AD12,0,CV$4))=CY$8,IFERROR(--LEFT(OFFSET('Vacation Tracker'!$Q12:$AD12,0,CV$4),LEN(OFFSET('Vacation Tracker'!$Q12:$AD12,0,CV$4))-1),0)))} -> 0 | CZ9: =SUM(OFFSET('Vacation Tracker'!$Q12:$AD12,0,CZ$4)) -> 0 | DA9: =CZ9-DB9 -> 0 | DB9: {=SUM(IF(RIGHT(OFFSET('Vacation Tracker'!$Q12:$AD12,0,CZ$4))<>"O",IFERROR(--LEFT(OFFSET('Vacation Tracker'!$Q12:$AD12,0,CZ$4),LEN(OFFSET('Vacation Tracker'!$Q12:$AD12,0,CZ$4))-1),0)))} -> 0 | DC9: {=SUM(IF(RIGHT(OFFSET('Vacation Tracker'!$Q12:$AD12,0,CZ$4))=DC$8,IFERROR(--LEFT(OFFSET('Vacation Tracker'!$Q12:$AD12,0,CZ$4),LEN(OFFSET('Vacation Tracker'!$Q12:$AD12,0,CZ$4))-1),0)))} -> 0 | DD9: =SUM(OFFSET('Vacation Tracker'!$Q12:$AD12,0,DD$4)) -> 0 | DE9: =DD9-DF9 -> 0 | DF9: {=SUM(IF(RIGHT(OFFSET('Vacation Tracker'!$Q12:$AD12,0,DD$4))<>"O",IFERROR(--LEFT(OFFSET('Vacation Tracker'!$Q12:$AD12,0,DD$4),LEN(OFFSET('Vacation Tracker'!$Q12:$AD12,0,DD$4))-1),0)))} -> 0 | DG9: {=SUM(IF(RIGHT(OFFSET('Vacation Tracker'!$Q12:$AD12,0,DD$4))=DG$8,IFERROR(--LEFT(OFFSET('Vacation Tracker'!$Q12:$AD12,0,DD$4),LEN(OFFSET('Vacation Tracker'!$Q12:$AD12,0,DD$4))-1),0)))} -> 0 | DH9: =SUM(OFFSET('Vacation Tracker'!$Q12:$AD12,0,DH$4)) -> 0 | DI9: =DH9-DJ9 -> 0 | DJ9: {=SUM(IF(RIGHT(OFFSET('Vacation Tracker'!$Q12:$AD12,0,DH$4))<>"O",IFERROR(--LEFT(OFFSET('Vacation Tracker'!$Q12:$AD12,0,DH$4),LEN(OFFSET('Vacation Tracker'!$Q12:$AD12,0,DH$4))-1),0)))} -> 0 | DK9: {=SUM(IF(RIGHT(OFFSET('Vacation Tracker'!$Q12:$AD12,0,DH$4))=DK$8,IFERROR(--LEFT(OFFSET('Vacation Tracker'!$Q12:$AD12,0,DH$4),LEN(OFFSET('Vacation Tracker'!$Q12:$AD12,0,DH$4))-1),0)))} -> 0 | DL9: =SUM(OFFSET('Vacation Tracker'!$Q12:$AD12,0,DL$4)) -> 0 | DM9: =DL9-DN9 -> 0 | DN9: {=SUM(IF(RIGHT(OFFSET('Vacation Tracker'!$Q12:$AD12,0,DL$4))<>"O",IFERROR(--LEFT(OFFSET('Vacation Tracker'!$Q12:$AD12,0,DL$4),LEN(OFFSET('Vacation Tracker'!$Q12:$AD12,0,DL$4))-1),0)))} -> 0 | DO9: {=SUM(IF(RIGHT(OFFSET('Vacation Tracker'!$Q12:$AD12,0,DL$4))=DO$8,IFERROR(--LEFT(OFFSET('Vacation Tracker'!$Q12:$AD12,0,DL$4),LEN(OFFSET('Vacation Tracker'!$Q12:$AD12,0,DL$4))-1),0)))} -> 0 | DP9: =SUM(OFFSET('Vacation Tracker'!$Q12:$AD12,0,DP$4)) -> 0 | DQ9: =DP9-DR9 -> 0 | DR9: {=SUM(IF(RIGHT(OFFSET('Vacation Tracker'!$Q12:$AD12,0,DP$4))<>"O",IFERROR(--LEFT(OFFSET('Vacation Tracker'!$Q12:$AD12,0,DP$4),LEN(OFFSET('Vacation Tracker'!$Q12:$AD12,0,DP$4))-1),0)))} -> 0 | DS9: {=SUM(IF(RIGHT(OFFSET('Vacation Tracker'!$Q12:$AD12,0,DP$4))=DS$8,IFERROR(--LEFT(OFFSET('Vacation Tracker'!$Q12:$AD12,0,DP$4),LEN(OFFSET('Vacation Tracker'!$Q12:$AD12,0,DP$4))-1),0)))} -> 0 | DT9: =SUM(OFFSET('Vacation Tracker'!$Q12:$AD12,0,DT$4)) -> 0 | DU9: =DT9-DV9 -> 0 | DV9: {=SUM(IF(RIGHT(OFFSET('Vacation Tracker'!$Q12:$AD12,0,DT$4))<>"O",IFERROR(--LEFT(OFFSET('Vacation Tracker'!$Q12:$AD12,0,DT$4),LEN(OFFSET('Vacation Tracker'!$Q12:$AD12,0,DT$4))-1),0)))} -> 0 | DW9: {=SUM(IF(RIGHT(OFFSET('Vacation Tracker'!$Q12:$AD12,0,DT$4))=DW$8,IFERROR(--LEFT(OFFSET('Vacation Tracker'!$Q12:$AD12,0,DT$4),LEN(OFFSET('Vacation Tracker'!$Q12:$AD12,0,DT$4))-1),0)))} -> 0 | DX9: =SUM(OFFSET('Vacation Tracker'!$Q12:$AD12,0,DX$4)) -> 0 | DY9: =DX9-DZ9 -> 0 | DZ9: {=SUM(IF(RIGHT(OFFSET('Vacation Tracker'!$Q12:$AD12,0,DX$4))<>"O",IFERROR(--LEFT(OFFSET('Vacation Tracker'!$Q12:$AD12,0,DX$4),LEN(OFFSET('Vacation Tracker'!$Q12:$AD12,0,DX$4))-1),0)))} -> 0 | EA9: {=SUM(IF(RIGHT(OFFSET('Vacation Tracker'!$Q12:$AD12,0,DX$4))=EA$8,IFERROR(--LEFT(OFFSET('Vacation Tracker'!$Q12:$AD12,0,DX$4),LEN(OFFSET('Vacation Tracker'!$Q12:$AD12,0,DX$4))-1),0)))} -> 0 | EB9: =SUM(OFFSET('Vacation Tracker'!$Q12:$AD12,0,EB$4)) -> 0 | EC9: =EB9-ED9 -> 0 | ED9: {=SUM(IF(RIGHT(OFFSET('Vacation Tracker'!$Q12:$AD12,0,EB$4))<>"O",IFERROR(--LEFT(OFFSET('Vacation Tracker'!$Q12:$AD12,0,EB$4),LEN(OFFSET('Vacation Tracker'!$Q12:$AD12,0,EB$4))-1),0)))} -> 0 | EE9: {=SUM(IF(RIGHT(OFFSET('Vacation Tracker'!$Q12:$AD12,0,EB$4))=EE$8,IFERROR(--LEFT(OFFSET('Vacation Tracker'!$Q12:$AD12,0,EB$4),LEN(OFFSET('Vacation Tracker'!$Q12:$AD12,0,EB$4))-1),0)))} -> 0 | EF9: =SUM(OFFSET('Vacation Tracker'!$Q12:$AD12,0,EF$4)) -> 0 | EG9: =EF9-EH9 -> 0 | EH9: {=SUM(IF(RIGHT(OFFSET('Vacation Tracker'!$Q12:$AD12,0,EF$4))<>"O",IFERROR(--LEFT(OFFSET('Vacation Tracker'!$Q12:$AD12,0,EF$4),LEN(OFFSET('Vacation Tracker'!$Q12:$AD12,0,EF$4))-1),0)))} -> 0 | EI9: {=SUM(IF(RIGHT(OFFSET('Vacation Tracker'!$Q12:$AD12,0,EF$4))=EI$8,IFERROR(--LEFT(OFFSET('Vacation Tracker'!$Q12:$AD12,0,EF$4),LEN(OFFSET('Vacation Tracker'!$Q12:$AD12,0,EF$4))-1),0)))} -> 0 | EJ9: =SUM(OFFSET('Vacation Tracker'!$Q12:$AD12,0,EJ$4)) -> 0 | EK9: =EJ9-EL9 -> 0 | EL9: {=SUM(IF(RIGHT(OFFSET('Vacation Tracker'!$Q12:$AD12,0,EJ$4))<>"O",IFERROR(--LEFT(OFFSET('Vacation Tracker'!$Q12:$AD12,0,EJ$4),LEN(OFFSET('Vacation Tracker'!$Q12:$AD12,0,EJ$4))-1),0)))} -> 0 | EM9: {=SUM(IF(RIGHT(OFFSET('Vacation Tracker'!$Q12:$AD12,0,EJ$4))=EM$8,IFERROR(--LEFT(OFFSET('Vacation Tracker'!$Q12:$AD12,0,EJ$4),LEN(OFFSET('Vacation Tracker'!$Q12:$AD12,0,EJ$4))-1),0)))} -> 0 | EN9: =SUM(OFFSET('Vacation Tracker'!$Q12:$AD12,0,EN$4)) -> 0 | EO9: =EN9-EP9 -> 0 | EP9: {=SUM(IF(RIGHT(OFFSET('Vacation Tracker'!$Q12:$AD12,0,EN$4))<>"O",IFERROR(--LEFT(OFFSET('Vacation Tracker'!$Q12:$AD12,0,EN$4),LEN(OFFSET('Vacation Tracker'!$Q12:$AD12,0,EN$4))-1),0)))} -> 0 | EQ9: {=SUM(IF(RIGHT(OFFSET('Vacation Tracker'!$Q12:$AD12,0,EN$4))=EQ$8,IFERROR(--LEFT(OFFSET('Vacation Tracker'!$Q12:$AD12,0,EN$4),LEN(OFFSET('Vacation Tracker'!$Q12:$AD12,0,EN$4))-1),0)))} -> 0 | ER9: =SUM(OFFSET('Vacation Tracker'!$Q12:$AD12,0,ER$4)) -> 0 | ES9: =ER9-ET9 -> 0 | ET9: {=SUM(IF(RIGHT(OFFSET('Vacation Tracker'!$Q12:$AD12,0,ER$4))<>"O",IFERROR(--LEFT(OFFSET('Vacation Tracker'!$Q12:$AD12,0,ER$4),LEN(OFFSET('Vacation Tracker'!$Q12:$AD12,0,ER$4))-1),0)))} -> 0 | EU9: {=SUM(IF(RIGHT(OFFSET('Vacation Tracker'!$Q12:$AD12,0,ER$4))=EU$8,IFERROR(--LEFT(OFFSET('Vacation Tracker'!$Q12:$AD12,0,ER$4),LEN(OFFSET('Vacation Tracker'!$Q12:$AD12,0,ER$4))-1),0)))} -> 0 | EV9: =SUM(OFFSET('Vacation Tracker'!$Q12:$AD12,0,EV$4)) -> 0 | EW9: =EV9-EX9 -> 0 | EX9: {=SUM(IF(RIGHT(OFFSET('Vacation Tracker'!$Q12:$AD12,0,EV$4))<>"O",IFERROR(--LEFT(OFFSET('Vacation Tracker'!$Q12:$AD12,0,EV$4),LEN(OFFSET('Vacation Tracker'!$Q12:$AD12,0,EV$4))-1),0)))} -> 0 | EY9: {=SUM(IF(RIGHT(OFFSET('Vacation Tracker'!$Q12:$AD12,0,EV$4))=EY$8,IFERROR(--LEFT(OFFSET('Vacation Tracker'!$Q12:$AD12,0,EV$4),LEN(OFFSET('Vacation Tracker'!$Q12:$AD12,0,EV$4))-1),0)))} -> 0 | EZ9: =SUM(OFFSET('Vacation Tracker'!$Q12:$AD12,0,EZ$4)) -> 0 | FA9: =EZ9-FB9 -> 0 | FB9: {=SUM(IF(RIGHT(OFFSET('Vacation Tracker'!$Q12:$AD12,0,EZ$4))<>"O",IFERROR(--LEFT(OFFSET('Vacation Tracker'!$Q12:$AD12,0,EZ$4),LEN(OFFSET('Vacation Tracker'!$Q12:$AD12,0,EZ$4))-1),0)))} -> 0 | FC9: {=SUM(IF(RIGHT(OFFSET('Vacation Tracker'!$Q12:$AD12,0,EZ$4))=FC$8,IFERROR(--LEFT(OFFSET('Vacation Tracker'!$Q12:$AD12,0,EZ$4),LEN(OFFSET('Vacation Tracker'!$Q12:$AD12,0,EZ$4))-1),0)))} -> 0 | FD9: =SUM(OFFSET('Vacation Tracker'!$Q12:$AD12,0,FD$4)) -> 0 | FE9: =FD9-FF9 -> 0 | FF9: {=SUM(IF(RIGHT(OFFSET('Vacation Tracker'!$Q12:$AD12,0,FD$4))<>"O",IFERROR(--LEFT(OFFSET('Vacation Tracker'!$Q12:$AD12,0,FD$4),LEN(OFFSET('Vacation Tracker'!$Q12:$AD12,0,FD$4))-1),0)))} -> 0 | FG9: {=SUM(IF(RIGHT(OFFSET('Vacation Tracker'!$Q12:$AD12,0,FD$4))=FG$8,IFERROR(--LEFT(OFFSET('Vacation Tracker'!$Q12:$AD12,0,FD$4),LEN(OFFSET('Vacation Tracker'!$Q12:$AD12,0,FD$4))-1),0)))} -> 0 | FH9: =SUM(OFFSET('Vacation Tracker'!$Q12:$AD12,0,FH$4)) -> 0 | FI9: =FH9-FJ9 -> 0 | FJ9: {=SUM(IF(RIGHT(OFFSET('Vacation Tracker'!$Q12:$AD12,0,FH$4))<>"O",IFERROR(--LEFT(OFFSET('Vacation Tracker'!$Q12:$AD12,0,FH$4),LEN(OFFSET('Vacation Tracker'!$Q12:$AD12,0,FH$4))-1),0)))} -> 0 | FK9: {=SUM(IF(RIGHT(OFFSET('Vacation Tracker'!$Q12:$AD12,0,FH$4))=FK$8,IFERROR(--LEFT(OFFSET('Vacation Tracker'!$Q12:$AD12,0,FH$4),LEN(OFFSET('Vacation Tracker'!$Q12:$AD12,0,FH$4))-1),0)))} -> 0 | FL9: =SUM(OFFSET('Vacation Tracker'!$Q12:$AD12,0,FL$4)) -> 0 | FM9: =FL9-FN9 -> 0 | FN9: {=SUM(IF(RIGHT(OFFSET('Vacation Tracker'!$Q12:$AD12,0,FL$4))<>"O",IFERROR(--LEFT(OFFSET('Vacation Tracker'!$Q12:$AD12,0,FL$4),LEN(OFFSET('Vacation Tracker'!$Q12:$AD12,0,FL$4))-1),0)))} -> 0 | FO9: {=SUM(IF(RIGHT(OFFSET('Vacation Tracker'!$Q12:$AD12,0,FL$4))=FO$8,IFERROR(--LEFT(OFFSET('Vacation Tracker'!$Q12:$AD12,0,FL$4),LEN(OFFSET('Vacation Tracker'!$Q12:$AD12,0,FL$4))-1),0)))} -> 0 | FP9: =SUM(OFFSET('Vacation Tracker'!$Q12:$AD12,0,FP$4)) -> 0 | FQ9: =FP9-FR9 -> 0 | FR9: {=SUM(IF(RIGHT(OFFSET('Vacation Tracker'!$Q12:$AD12,0,FP$4))<>"O",IFERROR(--LEFT(OFFSET('Vacation Tracker'!$Q12:$AD12,0,FP$4),LEN(OFFSET('Vacation Tracker'!$Q12:$AD12,0,FP$4))-1),0)))} -> 0 | FS9: {=SUM(IF(RIGHT(OFFSET('Vacation Tracker'!$Q12:$AD12,0,FP$4))=FS$8,IFERROR(--LEFT(OFFSET('Vacation Tracker'!$Q12:$AD12,0,FP$4),LEN(OFFSET('Vacation Tracker'!$Q12:$AD12,0,FP$4))-1),0)))} -> 0 | FT9: =SUM(OFFSET('Vacation Tracker'!$Q12:$AD12,0,FT$4)) -> 0 | FU9: =FT9-FV9 -> 0 | FV9: {=SUM(IF(RIGHT(OFFSET('Vacation Tracker'!$Q12:$AD12,0,FT$4))<>"O",IFERROR(--LEFT(OFFSET('Vacation Tracker'!$Q12:$AD12,0,FT$4),LEN(OFFSET('Vacation Tracker'!$Q12:$AD12,0,FT$4))-1),0)))} -> 0 | FW9: {=SUM(IF(RIGHT(OFFSET('Vacation Tracker'!$Q12:$AD12,0,FT$4))=FW$8,IFERROR(--LEFT(OFFSET('Vacation Tracker'!$Q12:$AD12,0,FT$4),LEN(OFFSET('Vacation Tracker'!$Q12:$AD12,0,FT$4))-1),0)))} -> 0 | FX9: =SUM(OFFSET('Vacation Tracker'!$Q12:$AD12,0,FX$4)) -> 0 | FY9: =FX9-FZ9 -> 0 | FZ9: {=SUM(IF(RIGHT(OFFSET('Vacation Tracker'!$Q12:$AD12,0,FX$4))<>"O",IFERROR(--LEFT(OFFSET('Vacation Tracker'!$Q12:$AD12,0,FX$4),LEN(OFFSET('Vacation Tracker'!$Q12:$AD12,0,FX$4))-1),0)))} -> 0 | GA9: {=SUM(IF(RIGHT(OFFSET('Vacation Tracker'!$Q12:$AD12,0,FX$4))=GA$8,IFERROR(--LEFT(OFFSET('Vacation Tracker'!$Q12:$AD12,0,FX$4),LEN(OFFSET('Vacation Tracker'!$Q12:$AD12,0,FX$4))-1),0)))} -> 0 | GB9: =SUM(OFFSET('Vacation Tracker'!$Q12:$AD12,0,GB$4)) -> 0 | GC9: =GB9-GD9 -> 0 | GD9: {=SUM(IF(RIGHT(OFFSET('Vacation Tracker'!$Q12:$AD12,0,GB$4))<>"O",IFERROR(--LEFT(OFFSET('Vacation Tracker'!$Q12:$AD12,0,GB$4),LEN(OFFSET('Vacation Tracker'!$Q12:$AD12,0,GB$4))-1),0)))} -> 0 | GE9: {=SUM(IF(RIGHT(OFFSET('Vacation Tracker'!$Q12:$AD12,0,GB$4))=GE$8,IFERROR(--LEFT(OFFSET('Vacation Tracker'!$Q12:$AD12,0,GB$4),LEN(OFFSET('Vacation Tracker'!$Q12:$AD12,0,GB$4))-1),0)))} -> 0 | GF9: =SUM(OFFSET('Vacation Tracker'!$Q12:$AD12,0,GF$4)) -> 0 | GG9: =GF9-GH9 -> 0 | GH9: {=SUM(IF(RIGHT(OFFSET('Vacation Tracker'!$Q12:$AD12,0,GF$4))<>"O",IFERROR(--LEFT(OFFSET('Vacation Tracker'!$Q12:$AD12,0,GF$4),LEN(OFFSET('Vacation Tracker'!$Q12:$AD12,0,GF$4))-1),0)))} -> 0 | GI9: {=SUM(IF(RIGHT(OFFSET('Vacation Tracker'!$Q12:$AD12,0,GF$4))=GI$8,IFERROR(--LEFT(OFFSET('Vacation Tracker'!$Q12:$AD12,0,GF$4),LEN(OFFSET('Vacation Tracker'!$Q12:$AD12,0,GF$4))-1),0)))} -> 0 | GJ9: =SUM(OFFSET('Vacation Tracker'!$Q12:$AD12,0,GJ$4)) -> 0 | GK9: =GJ9-GL9 -> 0 | GL9: {=SUM(IF(RIGHT(OFFSET('Vacation Tracker'!$Q12:$AD12,0,GJ$4))<>"O",IFERROR(--LEFT(OFFSET('Vacation Tracker'!$Q12:$AD12,0,GJ$4),LEN(OFFSET('Vacation Tracker'!$Q12:$AD12,0,GJ$4))-1),0)))} -> 0 | GM9: {=SUM(IF(RIGHT(OFFSET('Vacation Tracker'!$Q12:$AD12,0,GJ$4))=GM$8,IFERROR(--LEFT(OFFSET('Vacation Tracker'!$Q12:$AD12,0,GJ$4),LEN(OFFSET('Vacation Tracker'!$Q12:$AD12,0,GJ$4))-1),0)))} -> 0 | GN9: =SUM(OFFSET('Vacation Tracker'!$Q12:$AD12,0,GN$4)) -> 0 | GO9: =GN9-GP9 -> 0 | GP9: {=SUM(IF(RIGHT(OFFSET('Vacation Tracker'!$Q12:$AD12,0,GN$4))<>"O",IFERROR(--LEFT(OFFSET('Vacation Tracker'!$Q12:$AD12,0,GN$4),LEN(OFFSET('Vacation Tracker'!$Q12:$AD12,0,GN$4))-1),0)))} -> 0 | GQ9: {=SUM(IF(RIGHT(OFFSET('Vacation Tracker'!$Q12:$AD12,0,GN$4))=GQ$8,IFERROR(--LEFT(OFFSET('Vacation Tracker'!$Q12:$AD12,0,GN$4),LEN(OFFSET('Vacation Tracker'!$Q12:$AD12,0,GN$4))-1),0)))} -> 0 | GR9: =SUM(OFFSET('Vacation Tracker'!$Q12:$AD12,0,GR$4)) -> 0 | GS9: =GR9-GT9 -> 0 | GT9: {=SUM(IF(RIGHT(OFFSET('Vacation Tracker'!$Q12:$AD12,0,GR$4))<>"O",IFERROR(--LEFT(OFFSET('Vacation Tracker'!$Q12:$AD12,0,GR$4),LEN(OFFSET('Vacation Tracker'!$Q12:$AD12,0,GR$4))-1),0)))} -> 0 | GU9: {=SUM(IF(RIGHT(OFFSET('Vacation Tracker'!$Q12:$AD12,0,GR$4))=GU$8,IFERROR(--LEFT(OFFSET('Vacation Tracker'!$Q12:$AD12,0,GR$4),LEN(OFFSET('Vacation Tracker'!$Q12:$AD12,0,GR$4))-1),0)))} -> 0 | GV9: =SUM(OFFSET('Vacation Tracker'!$Q12:$AD12,0,GV$4)) -> 0 | GW9: =GV9-GX9 -> 0 | GX9: {=SUM(IF(RIGHT(OFFSET('Vacation Tracker'!$Q12:$AD12,0,GV$4))<>"O",IFERROR(--LEFT(OFFSET('Vacation Tracker'!$Q12:$AD12,0,GV$4),LEN(OFFSET('Vacation Tracker'!$Q12:$AD12,0,GV$4))-1),0)))} -> 0 | GY9: {=SUM(IF(RIGHT(OFFSET('Vacation Tracker'!$Q12:$AD12,0,GV$4))=GY$8,IFERROR(--LEFT(OFFSET('Vacation Tracker'!$Q12:$AD12,0,GV$4),LEN(OFFSET('Vacation Tracker'!$Q12:$AD12,0,GV$4))-1),0)))} -> 0 | GZ9: =SUM(OFFSET('Vacation Tracker'!$Q12:$AD12,0,GZ$4)) -> 0 | HA9: =GZ9-HB9 -> 0 | HB9: {=SUM(IF(RIGHT(OFFSET('Vacation Tracker'!$Q12:$AD12,0,GZ$4))<>"O",IFERROR(--LEFT(OFFSET('Vacation Tracker'!$Q12:$AD12,0,GZ$4),LEN(OFFSET('Vacation Tracker'!$Q12:$AD12,0,GZ$4))-1),0)))} -> 0 | HC9: {=SUM(IF(RIGHT(OFFSET('Vacation Tracker'!$Q12:$AD12,0,GZ$4))=HC$8,IFERROR(--LEFT(OFFSET('Vacation Tracker'!$Q12:$AD12,0,GZ$4),LEN(OFFSET('Vacation Tracker'!$Q12:$AD12,0,GZ$4))-1),0)))} -> 0 | HD9: =SUM(OFFSET('Vacation Tracker'!$Q12:$AD12,0,HD$4)) -> 0 | HE9: =HD9-HF9 -> 0 | HF9: {=SUM(IF(RIGHT(OFFSET('Vacation Tracker'!$Q12:$AD12,0,HD$4))<>"O",IFERROR(--LEFT(OFFSET('Vacation Tracker'!$Q12:$AD12,0,HD$4),LEN(OFFSET('Vacation Tracker'!$Q12:$AD12,0,HD$4))-1),0)))} -> 0 | HG9: {=SUM(IF(RIGHT(OFFSET('Vacation Tracker'!$Q12:$AD12,0,HD$4))=HG$8,IFERROR(--LEFT(OFFSET('Vacation Tracker'!$Q12:$AD12,0,HD$4),LEN(OFFSET('Vacation Tracker'!$Q12:$AD12,0,HD$4))-1),0)))} -> 0 | HH9: =SUM(OFFSET('Vacation Tracker'!$Q12:$AD12,0,HH$4)) -> 0 | HI9: =HH9-HJ9 -> 0 | HJ9: {=SUM(IF(RIGHT(OFFSET('Vacation Tracker'!$Q12:$AD12,0,HH$4))<>"O",IFERROR(--LEFT(OFFSET('Vacation Tracker'!$Q12:$AD12,0,HH$4),LEN(OFFSET('Vacation Tracker'!$Q12:$AD12,0,HH$4))-1),0)))} -> 0 | HK9: {=SUM(IF(RIGHT(OFFSET('Vacation Tracker'!$Q12:$AD12,0,HH$4))=HK$8,IFERROR(--LEFT(OFFSET('Vacation Tracker'!$Q12:$AD12,0,HH$4),LEN(OFFSET('Vacation Tracker'!$Q12:$AD12,0,HH$4))-1),0)))} -> 0 | HL9: =SUM(OFFSET('Vacation Tracker'!$Q12:$AD12,0,HL$4)) -> 0 | HM9: =HL9-HN9 -> 0 | HN9: {=SUM(IF(RIGHT(OFFSET('Vacation Tracker'!$Q12:$AD12,0,HL$4))<>"O",IFERROR(--LEFT(OFFSET('Vacation Tracker'!$Q12:$AD12,0,HL$4),LEN(OFFSET('Vacation Tracker'!$Q12:$AD12,0,HL$4))-1),0)))} -> 0 | HO9: {=SUM(IF(RIGHT(OFFSET('Vacation Tracker'!$Q12:$AD12,0,HL$4))=HO$8,IFERROR(--LEFT(OFFSET('Vacation Tracker'!$Q12:$AD12,0,HL$4),LEN(OFFSET('Vacation Tracker'!$Q12:$AD12,0,HL$4))-1),0)))} -> 0 | HP9: =SUM(OFFSET('Vacation Tracker'!$Q12:$AD12,0,HP$4)) -> 0 | HQ9: =HP9-HR9 -> 0 | HR9: {=SUM(IF(RIGHT(OFFSET('Vacation Tracker'!$Q12:$AD12,0,HP$4))<>"O",IFERROR(--LEFT(OFFSET('Vacation Tracker'!$Q12:$AD12,0,HP$4),LEN(OFFSET('Vacation Tracker'!$Q12:$AD12,0,HP$4))-1),0)))} -> 0 | HS9: {=SUM(IF(RIGHT(OFFSET('Vacation Tracker'!$Q12:$AD12,0,HP$4))=HS$8,IFERROR(--LEFT(OFFSET('Vacation Tracker'!$Q12:$AD12,0,HP$4),LEN(OFFSET('Vacation Tracker'!$Q12:$AD12,0,HP$4))-1),0)))} -> 0
